[2024-09-11 08:09:51,956][basic_search][INFO][color_logger.py:203] Logfile: /gyc_data/fray_data/project_hw/logs_gray_clapboard_search/basic_search_2024-09-11-08-09-51-955809.log
[2024-09-11 08:09:52,320][basic_search][INFO][generic_advisor.py:231] [BO auto selection]  acq_type: ei. acq_optimizer_type: local_random.
[2024-09-11 08:09:52,328][basic_search][INFO][html_visualizer.py:462] Please open the html file to view visualization result: file:///gyc_data/fray_data/project_hw/logs_gray_clapboard_search/history/basic_search/basic_search_2024-09-11-08-09-52-326212.html
[2024-09-11 08:09:52,330][basic_search][ERROR][generic_smbo.py:290] Exception in objective function:
Traceback (most recent call last):
  File "/gyc_data/fray_data/py38hwvenv/lib/python3.8/site-packages/openbox/utils/limit.py", line 62, in run_without_time_limit
    ret = obj_func(*obj_args, **obj_kwargs)
  File "/gyc_data/fray_data/project_hw/BO_partition3.py", line 99, in obj_func
    cost = self.black_box.get_cost_from_partitions(partitions, scan_method)
  File "/gyc_data/fray_data/project_hw/BO_partition3.py", line 60, in get_cost_from_partitions
    scan_method_cpp[i] = scan_method[i]
IndexError: list index out of range

config: Configuration(values={
  's_0': 0,
  's_1': 0,
  's_10': 0,
  's_100': 0,
  's_101': 0,
  's_102': 0,
  's_103': 0,
  's_104': 0,
  's_105': 0,
  's_106': 0,
  's_107': 0,
  's_108': 0,
  's_109': 0,
  's_11': 0,
  's_110': 0,
  's_111': 0,
  's_112': 0,
  's_113': 0,
  's_114': 0,
  's_115': 0,
  's_116': 0,
  's_117': 0,
  's_118': 0,
  's_119': 0,
  's_12': 0,
  's_120': 0,
  's_121': 0,
  's_122': 0,
  's_123': 0,
  's_124': 0,
  's_125': 0,
  's_126': 0,
  's_127': 0,
  's_128': 0,
  's_129': 0,
  's_13': 0,
  's_130': 0,
  's_131': 0,
  's_132': 0,
  's_133': 0,
  's_134': 0,
  's_135': 0,
  's_136': 0,
  's_137': 0,
  's_138': 0,
  's_139': 0,
  's_14': 0,
  's_140': 0,
  's_141': 0,
  's_142': 0,
  's_143': 0,
  's_144': 0,
  's_145': 0,
  's_146': 0,
  's_15': 0,
  's_16': 0,
  's_17': 0,
  's_18': 0,
  's_19': 0,
  's_2': 0,
  's_20': 0,
  's_21': 0,
  's_22': 0,
  's_23': 0,
  's_24': 0,
  's_25': 0,
  's_26': 0,
  's_27': 0,
  's_28': 0,
  's_29': 0,
  's_3': 0,
  's_30': 0,
  's_31': 0,
  's_32': 0,
  's_33': 0,
  's_34': 0,
  's_35': 0,
  's_36': 0,
  's_37': 0,
  's_38': 0,
  's_39': 0,
  's_4': 0,
  's_40': 0,
  's_41': 0,
  's_42': 0,
  's_43': 0,
  's_44': 0,
  's_45': 0,
  's_46': 0,
  's_47': 0,
  's_48': 0,
  's_49': 0,
  's_5': 0,
  's_50': 0,
  's_51': 0,
  's_52': 0,
  's_53': 0,
  's_54': 0,
  's_55': 0,
  's_56': 0,
  's_57': 0,
  's_58': 0,
  's_59': 0,
  's_6': 0,
  's_60': 0,
  's_61': 0,
  's_62': 0,
  's_63': 0,
  's_64': 0,
  's_65': 0,
  's_66': 0,
  's_67': 0,
  's_68': 0,
  's_69': 0,
  's_7': 0,
  's_70': 0,
  's_71': 0,
  's_72': 0,
  's_73': 0,
  's_74': 0,
  's_75': 0,
  's_76': 0,
  's_77': 0,
  's_78': 0,
  's_79': 0,
  's_8': 0,
  's_80': 0,
  's_81': 0,
  's_82': 0,
  's_83': 0,
  's_84': 0,
  's_85': 0,
  's_86': 0,
  's_87': 0,
  's_88': 0,
  's_89': 0,
  's_9': 0,
  's_90': 0,
  's_91': 0,
  's_92': 0,
  's_93': 0,
  's_94': 0,
  's_95': 0,
  's_96': 0,
  's_97': 0,
  's_98': 0,
  's_99': 0,
  'x': 1,
})

[2024-09-11 08:09:52,330][basic_search][INFO][generic_smbo.py:310] Iter 1, objectives: [inf].
[2024-09-11 08:09:52,331][basic_search][ERROR][generic_smbo.py:290] Exception in objective function:
Traceback (most recent call last):
  File "/gyc_data/fray_data/py38hwvenv/lib/python3.8/site-packages/openbox/utils/limit.py", line 62, in run_without_time_limit
    ret = obj_func(*obj_args, **obj_kwargs)
  File "/gyc_data/fray_data/project_hw/BO_partition3.py", line 99, in obj_func
    cost = self.black_box.get_cost_from_partitions(partitions, scan_method)
  File "/gyc_data/fray_data/project_hw/BO_partition3.py", line 60, in get_cost_from_partitions
    scan_method_cpp[i] = scan_method[i]
IndexError: list index out of range

config: Configuration(values={
  's_0': 0,
  's_1': 1,
  's_10': 1,
  's_100': 0,
  's_101': 0,
  's_102': 1,
  's_103': 0,
  's_104': 1,
  's_105': 1,
  's_106': 1,
  's_107': 1,
  's_108': 0,
  's_109': 1,
  's_11': 1,
  's_110': 0,
  's_111': 1,
  's_112': 1,
  's_113': 0,
  's_114': 1,
  's_115': 0,
  's_116': 1,
  's_117': 1,
  's_118': 1,
  's_119': 1,
  's_12': 1,
  's_120': 0,
  's_121': 1,
  's_122': 0,
  's_123': 1,
  's_124': 1,
  's_125': 0,
  's_126': 1,
  's_127': 1,
  's_128': 1,
  's_129': 1,
  's_13': 1,
  's_130': 0,
  's_131': 0,
  's_132': 0,
  's_133': 1,
  's_134': 1,
  's_135': 0,
  's_136': 1,
  's_137': 0,
  's_138': 1,
  's_139': 1,
  's_14': 0,
  's_140': 0,
  's_141': 1,
  's_142': 0,
  's_143': 1,
  's_144': 0,
  's_145': 1,
  's_146': 1,
  's_15': 0,
  's_16': 1,
  's_17': 0,
  's_18': 1,
  's_19': 1,
  's_2': 0,
  's_20': 0,
  's_21': 1,
  's_22': 1,
  's_23': 1,
  's_24': 0,
  's_25': 0,
  's_26': 1,
  's_27': 1,
  's_28': 1,
  's_29': 0,
  's_3': 0,
  's_30': 1,
  's_31': 1,
  's_32': 0,
  's_33': 0,
  's_34': 1,
  's_35': 1,
  's_36': 1,
  's_37': 1,
  's_38': 0,
  's_39': 1,
  's_4': 1,
  's_40': 0,
  's_41': 0,
  's_42': 0,
  's_43': 1,
  's_44': 0,
  's_45': 1,
  's_46': 1,
  's_47': 1,
  's_48': 0,
  's_49': 0,
  's_5': 1,
  's_50': 1,
  's_51': 1,
  's_52': 0,
  's_53': 0,
  's_54': 0,
  's_55': 1,
  's_56': 0,
  's_57': 0,
  's_58': 1,
  's_59': 0,
  's_6': 0,
  's_60': 1,
  's_61': 1,
  's_62': 1,
  's_63': 1,
  's_64': 1,
  's_65': 0,
  's_66': 1,
  's_67': 0,
  's_68': 1,
  's_69': 1,
  's_7': 1,
  's_70': 0,
  's_71': 0,
  's_72': 1,
  's_73': 0,
  's_74': 1,
  's_75': 0,
  's_76': 0,
  's_77': 1,
  's_78': 1,
  's_79': 1,
  's_8': 1,
  's_80': 1,
  's_81': 0,
  's_82': 1,
  's_83': 1,
  's_84': 0,
  's_85': 1,
  's_86': 0,
  's_87': 1,
  's_88': 1,
  's_89': 1,
  's_9': 1,
  's_90': 1,
  's_91': 1,
  's_92': 1,
  's_93': 1,
  's_94': 0,
  's_95': 1,
  's_96': 1,
  's_97': 1,
  's_98': 1,
  's_99': 1,
  'x': 261,
})

[2024-09-11 08:09:52,331][basic_search][INFO][generic_smbo.py:310] Iter 2, objectives: [inf].
[2024-09-11 08:09:52,332][basic_search][ERROR][generic_smbo.py:290] Exception in objective function:
Traceback (most recent call last):
  File "/gyc_data/fray_data/py38hwvenv/lib/python3.8/site-packages/openbox/utils/limit.py", line 62, in run_without_time_limit
    ret = obj_func(*obj_args, **obj_kwargs)
  File "/gyc_data/fray_data/project_hw/BO_partition3.py", line 99, in obj_func
    cost = self.black_box.get_cost_from_partitions(partitions, scan_method)
  File "/gyc_data/fray_data/project_hw/BO_partition3.py", line 60, in get_cost_from_partitions
    scan_method_cpp[i] = scan_method[i]
IndexError: list index out of range

config: Configuration(values={
  's_0': 1,
  's_1': 0,
  's_10': 1,
  's_100': 1,
  's_101': 1,
  's_102': 0,
  's_103': 0,
  's_104': 1,
  's_105': 0,
  's_106': 0,
  's_107': 0,
  's_108': 1,
  's_109': 0,
  's_11': 1,
  's_110': 1,
  's_111': 1,
  's_112': 1,
  's_113': 1,
  's_114': 0,
  's_115': 1,
  's_116': 0,
  's_117': 1,
  's_118': 0,
  's_119': 1,
  's_12': 0,
  's_120': 1,
  's_121': 1,
  's_122': 1,
  's_123': 0,
  's_124': 1,
  's_125': 1,
  's_126': 0,
  's_127': 0,
  's_128': 1,
  's_129': 1,
  's_13': 1,
  's_130': 0,
  's_131': 0,
  's_132': 1,
  's_133': 1,
  's_134': 0,
  's_135': 1,
  's_136': 0,
  's_137': 1,
  's_138': 0,
  's_139': 1,
  's_14': 0,
  's_140': 1,
  's_141': 1,
  's_142': 0,
  's_143': 1,
  's_144': 1,
  's_145': 1,
  's_146': 1,
  's_15': 1,
  's_16': 1,
  's_17': 1,
  's_18': 1,
  's_19': 0,
  's_2': 0,
  's_20': 0,
  's_21': 1,
  's_22': 1,
  's_23': 0,
  's_24': 1,
  's_25': 1,
  's_26': 0,
  's_27': 0,
  's_28': 0,
  's_29': 0,
  's_3': 0,
  's_30': 1,
  's_31': 1,
  's_32': 1,
  's_33': 0,
  's_34': 1,
  's_35': 1,
  's_36': 1,
  's_37': 1,
  's_38': 1,
  's_39': 0,
  's_4': 1,
  's_40': 0,
  's_41': 1,
  's_42': 0,
  's_43': 1,
  's_44': 0,
  's_45': 1,
  's_46': 1,
  's_47': 0,
  's_48': 1,
  's_49': 1,
  's_5': 0,
  's_50': 0,
  's_51': 1,
  's_52': 0,
  's_53': 1,
  's_54': 1,
  's_55': 1,
  's_56': 0,
  's_57': 1,
  's_58': 0,
  's_59': 1,
  's_6': 0,
  's_60': 0,
  's_61': 0,
  's_62': 0,
  's_63': 0,
  's_64': 1,
  's_65': 0,
  's_66': 0,
  's_67': 1,
  's_68': 0,
  's_69': 0,
  's_7': 1,
  's_70': 1,
  's_71': 0,
  's_72': 0,
  's_73': 0,
  's_74': 0,
  's_75': 1,
  's_76': 1,
  's_77': 0,
  's_78': 0,
  's_79': 0,
  's_8': 0,
  's_80': 1,
  's_81': 1,
  's_82': 0,
  's_83': 1,
  's_84': 1,
  's_85': 1,
  's_86': 0,
  's_87': 1,
  's_88': 0,
  's_89': 1,
  's_9': 0,
  's_90': 0,
  's_91': 1,
  's_92': 0,
  's_93': 1,
  's_94': 1,
  's_95': 0,
  's_96': 0,
  's_97': 0,
  's_98': 1,
  's_99': 1,
  'x': 252,
})

[2024-09-11 08:09:52,333][basic_search][INFO][generic_smbo.py:310] Iter 3, objectives: [inf].
[2024-09-11 08:09:52,334][basic_search][ERROR][generic_smbo.py:290] Exception in objective function:
Traceback (most recent call last):
  File "/gyc_data/fray_data/py38hwvenv/lib/python3.8/site-packages/openbox/utils/limit.py", line 62, in run_without_time_limit
    ret = obj_func(*obj_args, **obj_kwargs)
  File "/gyc_data/fray_data/project_hw/BO_partition3.py", line 99, in obj_func
    cost = self.black_box.get_cost_from_partitions(partitions, scan_method)
  File "/gyc_data/fray_data/project_hw/BO_partition3.py", line 60, in get_cost_from_partitions
    scan_method_cpp[i] = scan_method[i]
IndexError: list index out of range

config: Configuration(values={
  's_0': 1,
  's_1': 1,
  's_10': 0,
  's_100': 0,
  's_101': 0,
  's_102': 1,
  's_103': 1,
  's_104': 0,
  's_105': 0,
  's_106': 0,
  's_107': 1,
  's_108': 1,
  's_109': 1,
  's_11': 0,
  's_110': 1,
  's_111': 1,
  's_112': 0,
  's_113': 0,
  's_114': 1,
  's_115': 0,
  's_116': 1,
  's_117': 0,
  's_118': 1,
  's_119': 0,
  's_12': 0,
  's_120': 1,
  's_121': 0,
  's_122': 0,
  's_123': 1,
  's_124': 1,
  's_125': 1,
  's_126': 1,
  's_127': 1,
  's_128': 0,
  's_129': 0,
  's_13': 1,
  's_130': 0,
  's_131': 1,
  's_132': 1,
  's_133': 1,
  's_134': 0,
  's_135': 0,
  's_136': 0,
  's_137': 0,
  's_138': 1,
  's_139': 0,
  's_14': 1,
  's_140': 1,
  's_141': 0,
  's_142': 1,
  's_143': 0,
  's_144': 1,
  's_145': 1,
  's_146': 0,
  's_15': 1,
  's_16': 1,
  's_17': 1,
  's_18': 1,
  's_19': 1,
  's_2': 0,
  's_20': 0,
  's_21': 0,
  's_22': 0,
  's_23': 0,
  's_24': 0,
  's_25': 1,
  's_26': 0,
  's_27': 1,
  's_28': 0,
  's_29': 0,
  's_3': 1,
  's_30': 0,
  's_31': 0,
  's_32': 1,
  's_33': 0,
  's_34': 0,
  's_35': 1,
  's_36': 1,
  's_37': 0,
  's_38': 1,
  's_39': 0,
  's_4': 0,
  's_40': 1,
  's_41': 1,
  's_42': 0,
  's_43': 1,
  's_44': 0,
  's_45': 0,
  's_46': 0,
  's_47': 1,
  's_48': 0,
  's_49': 1,
  's_5': 0,
  's_50': 1,
  's_51': 1,
  's_52': 1,
  's_53': 1,
  's_54': 0,
  's_55': 1,
  's_56': 1,
  's_57': 1,
  's_58': 0,
  's_59': 0,
  's_6': 1,
  's_60': 0,
  's_61': 1,
  's_62': 0,
  's_63': 1,
  's_64': 0,
  's_65': 1,
  's_66': 0,
  's_67': 1,
  's_68': 0,
  's_69': 1,
  's_7': 0,
  's_70': 1,
  's_71': 1,
  's_72': 1,
  's_73': 1,
  's_74': 1,
  's_75': 1,
  's_76': 0,
  's_77': 0,
  's_78': 1,
  's_79': 1,
  's_8': 1,
  's_80': 1,
  's_81': 1,
  's_82': 1,
  's_83': 1,
  's_84': 0,
  's_85': 0,
  's_86': 0,
  's_87': 0,
  's_88': 1,
  's_89': 0,
  's_9': 1,
  's_90': 0,
  's_91': 0,
  's_92': 1,
  's_93': 0,
  's_94': 1,
  's_95': 1,
  's_96': 0,
  's_97': 1,
  's_98': 0,
  's_99': 1,
  'x': 152,
})

[2024-09-11 08:09:52,334][basic_search][INFO][generic_smbo.py:310] Iter 4, objectives: [inf].
[2024-09-11 08:09:52,336][basic_search][ERROR][generic_smbo.py:290] Exception in objective function:
Traceback (most recent call last):
  File "/gyc_data/fray_data/py38hwvenv/lib/python3.8/site-packages/openbox/utils/limit.py", line 62, in run_without_time_limit
    ret = obj_func(*obj_args, **obj_kwargs)
  File "/gyc_data/fray_data/project_hw/BO_partition3.py", line 99, in obj_func
    cost = self.black_box.get_cost_from_partitions(partitions, scan_method)
  File "/gyc_data/fray_data/project_hw/BO_partition3.py", line 60, in get_cost_from_partitions
    scan_method_cpp[i] = scan_method[i]
IndexError: list index out of range

config: Configuration(values={
  's_0': 1,
  's_1': 1,
  's_10': 0,
  's_100': 0,
  's_101': 0,
  's_102': 0,
  's_103': 0,
  's_104': 0,
  's_105': 0,
  's_106': 1,
  's_107': 0,
  's_108': 0,
  's_109': 0,
  's_11': 0,
  's_110': 1,
  's_111': 0,
  's_112': 0,
  's_113': 0,
  's_114': 0,
  's_115': 1,
  's_116': 1,
  's_117': 0,
  's_118': 0,
  's_119': 0,
  's_12': 1,
  's_120': 0,
  's_121': 1,
  's_122': 1,
  's_123': 0,
  's_124': 0,
  's_125': 0,
  's_126': 0,
  's_127': 1,
  's_128': 1,
  's_129': 0,
  's_13': 1,
  's_130': 1,
  's_131': 1,
  's_132': 1,
  's_133': 0,
  's_134': 0,
  's_135': 1,
  's_136': 0,
  's_137': 1,
  's_138': 0,
  's_139': 1,
  's_14': 0,
  's_140': 1,
  's_141': 1,
  's_142': 0,
  's_143': 1,
  's_144': 0,
  's_145': 0,
  's_146': 1,
  's_15': 1,
  's_16': 1,
  's_17': 0,
  's_18': 1,
  's_19': 0,
  's_2': 0,
  's_20': 1,
  's_21': 0,
  's_22': 0,
  's_23': 0,
  's_24': 0,
  's_25': 0,
  's_26': 0,
  's_27': 1,
  's_28': 0,
  's_29': 1,
  's_3': 0,
  's_30': 1,
  's_31': 0,
  's_32': 1,
  's_33': 1,
  's_34': 1,
  's_35': 1,
  's_36': 1,
  's_37': 1,
  's_38': 1,
  's_39': 1,
  's_4': 1,
  's_40': 0,
  's_41': 0,
  's_42': 1,
  's_43': 0,
  's_44': 1,
  's_45': 0,
  's_46': 0,
  's_47': 0,
  's_48': 0,
  's_49': 1,
  's_5': 1,
  's_50': 1,
  's_51': 0,
  's_52': 1,
  's_53': 1,
  's_54': 0,
  's_55': 0,
  's_56': 0,
  's_57': 0,
  's_58': 1,
  's_59': 0,
  's_6': 1,
  's_60': 1,
  's_61': 0,
  's_62': 1,
  's_63': 0,
  's_64': 1,
  's_65': 1,
  's_66': 1,
  's_67': 1,
  's_68': 0,
  's_69': 1,
  's_7': 1,
  's_70': 0,
  's_71': 0,
  's_72': 1,
  's_73': 1,
  's_74': 1,
  's_75': 0,
  's_76': 1,
  's_77': 1,
  's_78': 0,
  's_79': 0,
  's_8': 0,
  's_80': 0,
  's_81': 0,
  's_82': 0,
  's_83': 1,
  's_84': 1,
  's_85': 1,
  's_86': 1,
  's_87': 1,
  's_88': 1,
  's_89': 1,
  's_9': 0,
  's_90': 1,
  's_91': 0,
  's_92': 1,
  's_93': 1,
  's_94': 1,
  's_95': 1,
  's_96': 1,
  's_97': 1,
  's_98': 1,
  's_99': 1,
  'x': 85,
})

[2024-09-11 08:09:52,336][basic_search][INFO][generic_smbo.py:310] Iter 5, objectives: [inf].
[2024-09-11 08:09:52,338][basic_search][ERROR][generic_smbo.py:290] Exception in objective function:
Traceback (most recent call last):
  File "/gyc_data/fray_data/py38hwvenv/lib/python3.8/site-packages/openbox/utils/limit.py", line 62, in run_without_time_limit
    ret = obj_func(*obj_args, **obj_kwargs)
  File "/gyc_data/fray_data/project_hw/BO_partition3.py", line 99, in obj_func
    cost = self.black_box.get_cost_from_partitions(partitions, scan_method)
  File "/gyc_data/fray_data/project_hw/BO_partition3.py", line 60, in get_cost_from_partitions
    scan_method_cpp[i] = scan_method[i]
IndexError: list index out of range

config: Configuration(values={
  's_0': 1,
  's_1': 1,
  's_10': 1,
  's_100': 0,
  's_101': 1,
  's_102': 0,
  's_103': 1,
  's_104': 0,
  's_105': 1,
  's_106': 1,
  's_107': 0,
  's_108': 1,
  's_109': 0,
  's_11': 1,
  's_110': 0,
  's_111': 0,
  's_112': 1,
  's_113': 1,
  's_114': 0,
  's_115': 1,
  's_116': 1,
  's_117': 0,
  's_118': 1,
  's_119': 1,
  's_12': 0,
  's_120': 0,
  's_121': 1,
  's_122': 1,
  's_123': 0,
  's_124': 0,
  's_125': 0,
  's_126': 1,
  's_127': 0,
  's_128': 0,
  's_129': 0,
  's_13': 1,
  's_130': 1,
  's_131': 0,
  's_132': 1,
  's_133': 0,
  's_134': 0,
  's_135': 1,
  's_136': 0,
  's_137': 1,
  's_138': 0,
  's_139': 0,
  's_14': 1,
  's_140': 0,
  's_141': 0,
  's_142': 1,
  's_143': 1,
  's_144': 0,
  's_145': 1,
  's_146': 0,
  's_15': 1,
  's_16': 0,
  's_17': 1,
  's_18': 0,
  's_19': 0,
  's_2': 1,
  's_20': 0,
  's_21': 1,
  's_22': 0,
  's_23': 1,
  's_24': 1,
  's_25': 0,
  's_26': 0,
  's_27': 1,
  's_28': 1,
  's_29': 0,
  's_3': 0,
  's_30': 1,
  's_31': 1,
  's_32': 0,
  's_33': 1,
  's_34': 1,
  's_35': 1,
  's_36': 0,
  's_37': 0,
  's_38': 1,
  's_39': 0,
  's_4': 0,
  's_40': 1,
  's_41': 0,
  's_42': 0,
  's_43': 0,
  's_44': 1,
  's_45': 1,
  's_46': 1,
  's_47': 0,
  's_48': 1,
  's_49': 0,
  's_5': 0,
  's_50': 1,
  's_51': 1,
  's_52': 0,
  's_53': 1,
  's_54': 0,
  's_55': 0,
  's_56': 0,
  's_57': 1,
  's_58': 0,
  's_59': 1,
  's_6': 1,
  's_60': 0,
  's_61': 0,
  's_62': 0,
  's_63': 1,
  's_64': 0,
  's_65': 1,
  's_66': 1,
  's_67': 0,
  's_68': 1,
  's_69': 1,
  's_7': 1,
  's_70': 1,
  's_71': 0,
  's_72': 1,
  's_73': 0,
  's_74': 0,
  's_75': 0,
  's_76': 1,
  's_77': 1,
  's_78': 1,
  's_79': 1,
  's_8': 1,
  's_80': 0,
  's_81': 0,
  's_82': 0,
  's_83': 0,
  's_84': 0,
  's_85': 1,
  's_86': 1,
  's_87': 0,
  's_88': 0,
  's_89': 0,
  's_9': 1,
  's_90': 0,
  's_91': 1,
  's_92': 0,
  's_93': 1,
  's_94': 0,
  's_95': 1,
  's_96': 1,
  's_97': 1,
  's_98': 1,
  's_99': 1,
  'x': 200,
})

[2024-09-11 08:09:52,338][basic_search][INFO][generic_smbo.py:310] Iter 6, objectives: [inf].
[2024-09-11 08:09:52,341][basic_search][ERROR][generic_smbo.py:290] Exception in objective function:
Traceback (most recent call last):
  File "/gyc_data/fray_data/py38hwvenv/lib/python3.8/site-packages/openbox/utils/limit.py", line 62, in run_without_time_limit
    ret = obj_func(*obj_args, **obj_kwargs)
  File "/gyc_data/fray_data/project_hw/BO_partition3.py", line 99, in obj_func
    cost = self.black_box.get_cost_from_partitions(partitions, scan_method)
  File "/gyc_data/fray_data/project_hw/BO_partition3.py", line 60, in get_cost_from_partitions
    scan_method_cpp[i] = scan_method[i]
IndexError: list index out of range

config: Configuration(values={
  's_0': 0,
  's_1': 1,
  's_10': 0,
  's_100': 1,
  's_101': 1,
  's_102': 0,
  's_103': 1,
  's_104': 1,
  's_105': 0,
  's_106': 1,
  's_107': 1,
  's_108': 0,
  's_109': 1,
  's_11': 0,
  's_110': 0,
  's_111': 1,
  's_112': 1,
  's_113': 1,
  's_114': 1,
  's_115': 1,
  's_116': 0,
  's_117': 0,
  's_118': 0,
  's_119': 1,
  's_12': 1,
  's_120': 1,
  's_121': 0,
  's_122': 1,
  's_123': 1,
  's_124': 0,
  's_125': 1,
  's_126': 0,
  's_127': 0,
  's_128': 1,
  's_129': 0,
  's_13': 1,
  's_130': 1,
  's_131': 1,
  's_132': 0,
  's_133': 1,
  's_134': 1,
  's_135': 0,
  's_136': 1,
  's_137': 0,
  's_138': 0,
  's_139': 1,
  's_14': 0,
  's_140': 1,
  's_141': 1,
  's_142': 1,
  's_143': 1,
  's_144': 1,
  's_145': 0,
  's_146': 0,
  's_15': 1,
  's_16': 1,
  's_17': 0,
  's_18': 1,
  's_19': 1,
  's_2': 1,
  's_20': 0,
  's_21': 1,
  's_22': 0,
  's_23': 1,
  's_24': 0,
  's_25': 0,
  's_26': 0,
  's_27': 0,
  's_28': 0,
  's_29': 1,
  's_3': 0,
  's_30': 1,
  's_31': 0,
  's_32': 0,
  's_33': 0,
  's_34': 1,
  's_35': 0,
  's_36': 1,
  's_37': 0,
  's_38': 0,
  's_39': 0,
  's_4': 0,
  's_40': 0,
  's_41': 1,
  's_42': 1,
  's_43': 1,
  's_44': 1,
  's_45': 1,
  's_46': 0,
  's_47': 0,
  's_48': 0,
  's_49': 1,
  's_5': 0,
  's_50': 0,
  's_51': 0,
  's_52': 1,
  's_53': 1,
  's_54': 0,
  's_55': 0,
  's_56': 1,
  's_57': 0,
  's_58': 1,
  's_59': 0,
  's_6': 0,
  's_60': 1,
  's_61': 1,
  's_62': 0,
  's_63': 1,
  's_64': 1,
  's_65': 1,
  's_66': 0,
  's_67': 1,
  's_68': 0,
  's_69': 0,
  's_7': 0,
  's_70': 0,
  's_71': 1,
  's_72': 1,
  's_73': 1,
  's_74': 0,
  's_75': 1,
  's_76': 1,
  's_77': 1,
  's_78': 1,
  's_79': 1,
  's_8': 1,
  's_80': 0,
  's_81': 1,
  's_82': 0,
  's_83': 1,
  's_84': 0,
  's_85': 1,
  's_86': 0,
  's_87': 0,
  's_88': 1,
  's_89': 0,
  's_9': 0,
  's_90': 0,
  's_91': 1,
  's_92': 0,
  's_93': 0,
  's_94': 0,
  's_95': 0,
  's_96': 1,
  's_97': 0,
  's_98': 0,
  's_99': 0,
  'x': 91,
})

[2024-09-11 08:09:52,341][basic_search][INFO][generic_smbo.py:310] Iter 7, objectives: [inf].
[2024-09-11 08:09:52,343][basic_search][ERROR][generic_smbo.py:290] Exception in objective function:
Traceback (most recent call last):
  File "/gyc_data/fray_data/py38hwvenv/lib/python3.8/site-packages/openbox/utils/limit.py", line 62, in run_without_time_limit
    ret = obj_func(*obj_args, **obj_kwargs)
  File "/gyc_data/fray_data/project_hw/BO_partition3.py", line 99, in obj_func
    cost = self.black_box.get_cost_from_partitions(partitions, scan_method)
  File "/gyc_data/fray_data/project_hw/BO_partition3.py", line 60, in get_cost_from_partitions
    scan_method_cpp[i] = scan_method[i]
IndexError: list index out of range

config: Configuration(values={
  's_0': 0,
  's_1': 1,
  's_10': 0,
  's_100': 1,
  's_101': 0,
  's_102': 0,
  's_103': 1,
  's_104': 1,
  's_105': 1,
  's_106': 0,
  's_107': 0,
  's_108': 0,
  's_109': 1,
  's_11': 1,
  's_110': 1,
  's_111': 0,
  's_112': 1,
  's_113': 1,
  's_114': 1,
  's_115': 0,
  's_116': 1,
  's_117': 1,
  's_118': 0,
  's_119': 1,
  's_12': 1,
  's_120': 1,
  's_121': 1,
  's_122': 1,
  's_123': 0,
  's_124': 0,
  's_125': 1,
  's_126': 0,
  's_127': 1,
  's_128': 1,
  's_129': 1,
  's_13': 1,
  's_130': 1,
  's_131': 0,
  's_132': 0,
  's_133': 1,
  's_134': 1,
  's_135': 1,
  's_136': 1,
  's_137': 1,
  's_138': 1,
  's_139': 1,
  's_14': 1,
  's_140': 0,
  's_141': 0,
  's_142': 1,
  's_143': 1,
  's_144': 1,
  's_145': 0,
  's_146': 1,
  's_15': 1,
  's_16': 1,
  's_17': 1,
  's_18': 1,
  's_19': 0,
  's_2': 1,
  's_20': 0,
  's_21': 1,
  's_22': 0,
  's_23': 0,
  's_24': 0,
  's_25': 1,
  's_26': 0,
  's_27': 0,
  's_28': 0,
  's_29': 1,
  's_3': 0,
  's_30': 0,
  's_31': 0,
  's_32': 1,
  's_33': 0,
  's_34': 0,
  's_35': 0,
  's_36': 0,
  's_37': 0,
  's_38': 1,
  's_39': 1,
  's_4': 0,
  's_40': 1,
  's_41': 0,
  's_42': 1,
  's_43': 1,
  's_44': 0,
  's_45': 1,
  's_46': 0,
  's_47': 1,
  's_48': 1,
  's_49': 0,
  's_5': 0,
  's_50': 0,
  's_51': 1,
  's_52': 1,
  's_53': 0,
  's_54': 1,
  's_55': 0,
  's_56': 0,
  's_57': 0,
  's_58': 1,
  's_59': 1,
  's_6': 0,
  's_60': 0,
  's_61': 0,
  's_62': 1,
  's_63': 0,
  's_64': 0,
  's_65': 0,
  's_66': 0,
  's_67': 0,
  's_68': 0,
  's_69': 0,
  's_7': 1,
  's_70': 0,
  's_71': 1,
  's_72': 0,
  's_73': 0,
  's_74': 1,
  's_75': 0,
  's_76': 0,
  's_77': 0,
  's_78': 1,
  's_79': 0,
  's_8': 1,
  's_80': 1,
  's_81': 0,
  's_82': 1,
  's_83': 0,
  's_84': 0,
  's_85': 0,
  's_86': 1,
  's_87': 1,
  's_88': 0,
  's_89': 1,
  's_9': 1,
  's_90': 1,
  's_91': 0,
  's_92': 1,
  's_93': 1,
  's_94': 0,
  's_95': 0,
  's_96': 1,
  's_97': 0,
  's_98': 0,
  's_99': 1,
  'x': 174,
})

[2024-09-11 08:09:52,344][basic_search][INFO][generic_smbo.py:310] Iter 8, objectives: [inf].
[2024-09-11 08:09:52,346][basic_search][ERROR][generic_smbo.py:290] Exception in objective function:
Traceback (most recent call last):
  File "/gyc_data/fray_data/py38hwvenv/lib/python3.8/site-packages/openbox/utils/limit.py", line 62, in run_without_time_limit
    ret = obj_func(*obj_args, **obj_kwargs)
  File "/gyc_data/fray_data/project_hw/BO_partition3.py", line 99, in obj_func
    cost = self.black_box.get_cost_from_partitions(partitions, scan_method)
  File "/gyc_data/fray_data/project_hw/BO_partition3.py", line 60, in get_cost_from_partitions
    scan_method_cpp[i] = scan_method[i]
IndexError: list index out of range

config: Configuration(values={
  's_0': 1,
  's_1': 1,
  's_10': 1,
  's_100': 0,
  's_101': 1,
  's_102': 1,
  's_103': 0,
  's_104': 1,
  's_105': 1,
  's_106': 0,
  's_107': 1,
  's_108': 1,
  's_109': 1,
  's_11': 0,
  's_110': 1,
  's_111': 1,
  's_112': 0,
  's_113': 1,
  's_114': 1,
  's_115': 0,
  's_116': 0,
  's_117': 0,
  's_118': 1,
  's_119': 0,
  's_12': 1,
  's_120': 0,
  's_121': 1,
  's_122': 1,
  's_123': 0,
  's_124': 1,
  's_125': 0,
  's_126': 0,
  's_127': 1,
  's_128': 0,
  's_129': 0,
  's_13': 1,
  's_130': 0,
  's_131': 0,
  's_132': 0,
  's_133': 0,
  's_134': 1,
  's_135': 1,
  's_136': 1,
  's_137': 0,
  's_138': 0,
  's_139': 0,
  's_14': 0,
  's_140': 0,
  's_141': 0,
  's_142': 1,
  's_143': 1,
  's_144': 0,
  's_145': 0,
  's_146': 0,
  's_15': 0,
  's_16': 1,
  's_17': 1,
  's_18': 1,
  's_19': 1,
  's_2': 1,
  's_20': 1,
  's_21': 0,
  's_22': 0,
  's_23': 0,
  's_24': 1,
  's_25': 1,
  's_26': 1,
  's_27': 0,
  's_28': 1,
  's_29': 1,
  's_3': 0,
  's_30': 1,
  's_31': 0,
  's_32': 1,
  's_33': 1,
  's_34': 1,
  's_35': 0,
  's_36': 0,
  's_37': 0,
  's_38': 0,
  's_39': 1,
  's_4': 0,
  's_40': 0,
  's_41': 1,
  's_42': 1,
  's_43': 1,
  's_44': 1,
  's_45': 1,
  's_46': 1,
  's_47': 1,
  's_48': 0,
  's_49': 0,
  's_5': 0,
  's_50': 0,
  's_51': 1,
  's_52': 0,
  's_53': 1,
  's_54': 0,
  's_55': 0,
  's_56': 1,
  's_57': 0,
  's_58': 0,
  's_59': 0,
  's_6': 1,
  's_60': 0,
  's_61': 0,
  's_62': 1,
  's_63': 0,
  's_64': 1,
  's_65': 0,
  's_66': 1,
  's_67': 1,
  's_68': 1,
  's_69': 0,
  's_7': 0,
  's_70': 0,
  's_71': 0,
  's_72': 0,
  's_73': 1,
  's_74': 0,
  's_75': 1,
  's_76': 1,
  's_77': 0,
  's_78': 1,
  's_79': 1,
  's_8': 0,
  's_80': 0,
  's_81': 0,
  's_82': 0,
  's_83': 0,
  's_84': 0,
  's_85': 1,
  's_86': 1,
  's_87': 0,
  's_88': 0,
  's_89': 1,
  's_9': 1,
  's_90': 0,
  's_91': 1,
  's_92': 1,
  's_93': 0,
  's_94': 1,
  's_95': 1,
  's_96': 0,
  's_97': 0,
  's_98': 0,
  's_99': 1,
  'x': 166,
})

[2024-09-11 08:09:52,347][basic_search][INFO][generic_smbo.py:310] Iter 9, objectives: [inf].
[2024-09-11 08:09:52,350][basic_search][ERROR][generic_smbo.py:290] Exception in objective function:
Traceback (most recent call last):
  File "/gyc_data/fray_data/py38hwvenv/lib/python3.8/site-packages/openbox/utils/limit.py", line 62, in run_without_time_limit
    ret = obj_func(*obj_args, **obj_kwargs)
  File "/gyc_data/fray_data/project_hw/BO_partition3.py", line 99, in obj_func
    cost = self.black_box.get_cost_from_partitions(partitions, scan_method)
  File "/gyc_data/fray_data/project_hw/BO_partition3.py", line 60, in get_cost_from_partitions
    scan_method_cpp[i] = scan_method[i]
IndexError: list index out of range

config: Configuration(values={
  's_0': 1,
  's_1': 1,
  's_10': 0,
  's_100': 0,
  's_101': 0,
  's_102': 0,
  's_103': 1,
  's_104': 0,
  's_105': 0,
  's_106': 0,
  's_107': 1,
  's_108': 1,
  's_109': 0,
  's_11': 0,
  's_110': 0,
  's_111': 0,
  's_112': 0,
  's_113': 0,
  's_114': 1,
  's_115': 1,
  's_116': 0,
  's_117': 0,
  's_118': 0,
  's_119': 0,
  's_12': 0,
  's_120': 0,
  's_121': 1,
  's_122': 0,
  's_123': 1,
  's_124': 0,
  's_125': 1,
  's_126': 1,
  's_127': 0,
  's_128': 0,
  's_129': 0,
  's_13': 0,
  's_130': 0,
  's_131': 1,
  's_132': 1,
  's_133': 0,
  's_134': 1,
  's_135': 1,
  's_136': 1,
  's_137': 0,
  's_138': 0,
  's_139': 1,
  's_14': 1,
  's_140': 1,
  's_141': 0,
  's_142': 1,
  's_143': 0,
  's_144': 1,
  's_145': 0,
  's_146': 0,
  's_15': 1,
  's_16': 0,
  's_17': 1,
  's_18': 0,
  's_19': 1,
  's_2': 0,
  's_20': 0,
  's_21': 0,
  's_22': 1,
  's_23': 1,
  's_24': 0,
  's_25': 0,
  's_26': 0,
  's_27': 0,
  's_28': 1,
  's_29': 1,
  's_3': 1,
  's_30': 0,
  's_31': 0,
  's_32': 1,
  's_33': 0,
  's_34': 0,
  's_35': 1,
  's_36': 1,
  's_37': 1,
  's_38': 1,
  's_39': 1,
  's_4': 1,
  's_40': 0,
  's_41': 0,
  's_42': 1,
  's_43': 1,
  's_44': 1,
  's_45': 1,
  's_46': 1,
  's_47': 0,
  's_48': 1,
  's_49': 0,
  's_5': 0,
  's_50': 1,
  's_51': 0,
  's_52': 0,
  's_53': 0,
  's_54': 1,
  's_55': 1,
  's_56': 1,
  's_57': 0,
  's_58': 0,
  's_59': 1,
  's_6': 0,
  's_60': 0,
  's_61': 1,
  's_62': 0,
  's_63': 0,
  's_64': 1,
  's_65': 0,
  's_66': 0,
  's_67': 1,
  's_68': 0,
  's_69': 1,
  's_7': 1,
  's_70': 1,
  's_71': 0,
  's_72': 1,
  's_73': 0,
  's_74': 1,
  's_75': 1,
  's_76': 1,
  's_77': 1,
  's_78': 0,
  's_79': 1,
  's_8': 1,
  's_80': 0,
  's_81': 0,
  's_82': 0,
  's_83': 1,
  's_84': 0,
  's_85': 1,
  's_86': 1,
  's_87': 0,
  's_88': 0,
  's_89': 1,
  's_9': 1,
  's_90': 1,
  's_91': 1,
  's_92': 1,
  's_93': 1,
  's_94': 0,
  's_95': 0,
  's_96': 0,
  's_97': 0,
  's_98': 0,
  's_99': 0,
  'x': 105,
})

[2024-09-11 08:09:52,350][basic_search][INFO][generic_smbo.py:310] Iter 10, objectives: [inf].
[2024-09-11 08:09:52,353][basic_search][ERROR][generic_smbo.py:290] Exception in objective function:
Traceback (most recent call last):
  File "/gyc_data/fray_data/py38hwvenv/lib/python3.8/site-packages/openbox/utils/limit.py", line 62, in run_without_time_limit
    ret = obj_func(*obj_args, **obj_kwargs)
  File "/gyc_data/fray_data/project_hw/BO_partition3.py", line 99, in obj_func
    cost = self.black_box.get_cost_from_partitions(partitions, scan_method)
  File "/gyc_data/fray_data/project_hw/BO_partition3.py", line 60, in get_cost_from_partitions
    scan_method_cpp[i] = scan_method[i]
IndexError: list index out of range

config: Configuration(values={
  's_0': 0,
  's_1': 1,
  's_10': 0,
  's_100': 0,
  's_101': 0,
  's_102': 1,
  's_103': 0,
  's_104': 1,
  's_105': 0,
  's_106': 1,
  's_107': 0,
  's_108': 1,
  's_109': 1,
  's_11': 0,
  's_110': 0,
  's_111': 0,
  's_112': 0,
  's_113': 1,
  's_114': 1,
  's_115': 0,
  's_116': 0,
  's_117': 1,
  's_118': 1,
  's_119': 1,
  's_12': 0,
  's_120': 1,
  's_121': 0,
  's_122': 0,
  's_123': 1,
  's_124': 1,
  's_125': 1,
  's_126': 0,
  's_127': 0,
  's_128': 0,
  's_129': 1,
  's_13': 0,
  's_130': 0,
  's_131': 0,
  's_132': 1,
  's_133': 0,
  's_134': 0,
  's_135': 0,
  's_136': 0,
  's_137': 0,
  's_138': 1,
  's_139': 0,
  's_14': 0,
  's_140': 1,
  's_141': 1,
  's_142': 1,
  's_143': 1,
  's_144': 1,
  's_145': 1,
  's_146': 1,
  's_15': 0,
  's_16': 1,
  's_17': 0,
  's_18': 0,
  's_19': 1,
  's_2': 1,
  's_20': 0,
  's_21': 1,
  's_22': 1,
  's_23': 1,
  's_24': 0,
  's_25': 1,
  's_26': 0,
  's_27': 0,
  's_28': 0,
  's_29': 0,
  's_3': 1,
  's_30': 0,
  's_31': 1,
  's_32': 1,
  's_33': 0,
  's_34': 1,
  's_35': 0,
  's_36': 1,
  's_37': 1,
  's_38': 0,
  's_39': 0,
  's_4': 1,
  's_40': 0,
  's_41': 0,
  's_42': 1,
  's_43': 0,
  's_44': 1,
  's_45': 1,
  's_46': 1,
  's_47': 1,
  's_48': 1,
  's_49': 0,
  's_5': 0,
  's_50': 0,
  's_51': 1,
  's_52': 1,
  's_53': 1,
  's_54': 1,
  's_55': 0,
  's_56': 0,
  's_57': 1,
  's_58': 1,
  's_59': 1,
  's_6': 0,
  's_60': 1,
  's_61': 0,
  's_62': 1,
  's_63': 0,
  's_64': 0,
  's_65': 0,
  's_66': 1,
  's_67': 0,
  's_68': 1,
  's_69': 0,
  's_7': 1,
  's_70': 0,
  's_71': 1,
  's_72': 0,
  's_73': 1,
  's_74': 1,
  's_75': 0,
  's_76': 0,
  's_77': 0,
  's_78': 1,
  's_79': 1,
  's_8': 0,
  's_80': 1,
  's_81': 0,
  's_82': 1,
  's_83': 0,
  's_84': 1,
  's_85': 0,
  's_86': 1,
  's_87': 0,
  's_88': 0,
  's_89': 0,
  's_9': 1,
  's_90': 0,
  's_91': 1,
  's_92': 0,
  's_93': 0,
  's_94': 1,
  's_95': 1,
  's_96': 1,
  's_97': 0,
  's_98': 1,
  's_99': 0,
  'x': 192,
})

[2024-09-11 08:09:52,353][basic_search][INFO][generic_smbo.py:310] Iter 11, objectives: [inf].
[2024-09-11 08:09:52,357][basic_search][ERROR][generic_smbo.py:290] Exception in objective function:
Traceback (most recent call last):
  File "/gyc_data/fray_data/py38hwvenv/lib/python3.8/site-packages/openbox/utils/limit.py", line 62, in run_without_time_limit
    ret = obj_func(*obj_args, **obj_kwargs)
  File "/gyc_data/fray_data/project_hw/BO_partition3.py", line 99, in obj_func
    cost = self.black_box.get_cost_from_partitions(partitions, scan_method)
  File "/gyc_data/fray_data/project_hw/BO_partition3.py", line 60, in get_cost_from_partitions
    scan_method_cpp[i] = scan_method[i]
IndexError: list index out of range

config: Configuration(values={
  's_0': 1,
  's_1': 0,
  's_10': 0,
  's_100': 0,
  's_101': 1,
  's_102': 1,
  's_103': 1,
  's_104': 0,
  's_105': 0,
  's_106': 0,
  's_107': 0,
  's_108': 1,
  's_109': 1,
  's_11': 0,
  's_110': 1,
  's_111': 1,
  's_112': 0,
  's_113': 0,
  's_114': 0,
  's_115': 0,
  's_116': 1,
  's_117': 1,
  's_118': 0,
  's_119': 0,
  's_12': 1,
  's_120': 1,
  's_121': 1,
  's_122': 0,
  's_123': 1,
  's_124': 0,
  's_125': 1,
  's_126': 0,
  's_127': 1,
  's_128': 1,
  's_129': 0,
  's_13': 1,
  's_130': 1,
  's_131': 1,
  's_132': 1,
  's_133': 0,
  's_134': 0,
  's_135': 1,
  's_136': 1,
  's_137': 0,
  's_138': 1,
  's_139': 0,
  's_14': 0,
  's_140': 0,
  's_141': 1,
  's_142': 0,
  's_143': 1,
  's_144': 0,
  's_145': 0,
  's_146': 0,
  's_15': 0,
  's_16': 0,
  's_17': 0,
  's_18': 1,
  's_19': 0,
  's_2': 1,
  's_20': 1,
  's_21': 1,
  's_22': 0,
  's_23': 0,
  's_24': 0,
  's_25': 1,
  's_26': 1,
  's_27': 0,
  's_28': 1,
  's_29': 0,
  's_3': 1,
  's_30': 0,
  's_31': 1,
  's_32': 0,
  's_33': 1,
  's_34': 0,
  's_35': 0,
  's_36': 1,
  's_37': 1,
  's_38': 1,
  's_39': 0,
  's_4': 1,
  's_40': 0,
  's_41': 1,
  's_42': 1,
  's_43': 1,
  's_44': 1,
  's_45': 1,
  's_46': 1,
  's_47': 0,
  's_48': 1,
  's_49': 1,
  's_5': 0,
  's_50': 1,
  's_51': 0,
  's_52': 0,
  's_53': 0,
  's_54': 1,
  's_55': 1,
  's_56': 0,
  's_57': 0,
  's_58': 0,
  's_59': 0,
  's_6': 0,
  's_60': 1,
  's_61': 0,
  's_62': 1,
  's_63': 1,
  's_64': 1,
  's_65': 0,
  's_66': 0,
  's_67': 0,
  's_68': 1,
  's_69': 0,
  's_7': 1,
  's_70': 1,
  's_71': 0,
  's_72': 0,
  's_73': 0,
  's_74': 1,
  's_75': 1,
  's_76': 0,
  's_77': 0,
  's_78': 0,
  's_79': 1,
  's_8': 0,
  's_80': 0,
  's_81': 0,
  's_82': 1,
  's_83': 0,
  's_84': 0,
  's_85': 0,
  's_86': 1,
  's_87': 0,
  's_88': 0,
  's_89': 1,
  's_9': 0,
  's_90': 0,
  's_91': 0,
  's_92': 1,
  's_93': 1,
  's_94': 0,
  's_95': 1,
  's_96': 1,
  's_97': 1,
  's_98': 1,
  's_99': 1,
  'x': 95,
})

[2024-09-11 08:09:52,357][basic_search][INFO][generic_smbo.py:310] Iter 12, objectives: [inf].
[2024-09-11 08:09:52,361][basic_search][ERROR][generic_smbo.py:290] Exception in objective function:
Traceback (most recent call last):
  File "/gyc_data/fray_data/py38hwvenv/lib/python3.8/site-packages/openbox/utils/limit.py", line 62, in run_without_time_limit
    ret = obj_func(*obj_args, **obj_kwargs)
  File "/gyc_data/fray_data/project_hw/BO_partition3.py", line 99, in obj_func
    cost = self.black_box.get_cost_from_partitions(partitions, scan_method)
  File "/gyc_data/fray_data/project_hw/BO_partition3.py", line 60, in get_cost_from_partitions
    scan_method_cpp[i] = scan_method[i]
IndexError: list index out of range

config: Configuration(values={
  's_0': 0,
  's_1': 0,
  's_10': 0,
  's_100': 1,
  's_101': 0,
  's_102': 0,
  's_103': 1,
  's_104': 1,
  's_105': 1,
  's_106': 0,
  's_107': 1,
  's_108': 1,
  's_109': 1,
  's_11': 1,
  's_110': 1,
  's_111': 1,
  's_112': 0,
  's_113': 0,
  's_114': 1,
  's_115': 0,
  's_116': 1,
  's_117': 0,
  's_118': 0,
  's_119': 1,
  's_12': 0,
  's_120': 1,
  's_121': 1,
  's_122': 0,
  's_123': 0,
  's_124': 0,
  's_125': 0,
  's_126': 0,
  's_127': 0,
  's_128': 0,
  's_129': 0,
  's_13': 1,
  's_130': 1,
  's_131': 1,
  's_132': 0,
  's_133': 1,
  's_134': 0,
  's_135': 1,
  's_136': 1,
  's_137': 1,
  's_138': 0,
  's_139': 1,
  's_14': 0,
  's_140': 0,
  's_141': 0,
  's_142': 1,
  's_143': 1,
  's_144': 0,
  's_145': 1,
  's_146': 0,
  's_15': 1,
  's_16': 1,
  's_17': 1,
  's_18': 0,
  's_19': 1,
  's_2': 1,
  's_20': 1,
  's_21': 1,
  's_22': 1,
  's_23': 0,
  's_24': 1,
  's_25': 0,
  's_26': 0,
  's_27': 1,
  's_28': 1,
  's_29': 1,
  's_3': 1,
  's_30': 1,
  's_31': 0,
  's_32': 0,
  's_33': 1,
  's_34': 0,
  's_35': 1,
  's_36': 1,
  's_37': 0,
  's_38': 1,
  's_39': 1,
  's_4': 1,
  's_40': 0,
  's_41': 0,
  's_42': 0,
  's_43': 1,
  's_44': 0,
  's_45': 1,
  's_46': 0,
  's_47': 1,
  's_48': 0,
  's_49': 1,
  's_5': 1,
  's_50': 0,
  's_51': 1,
  's_52': 0,
  's_53': 1,
  's_54': 0,
  's_55': 1,
  's_56': 1,
  's_57': 1,
  's_58': 1,
  's_59': 1,
  's_6': 1,
  's_60': 1,
  's_61': 1,
  's_62': 0,
  's_63': 0,
  's_64': 0,
  's_65': 1,
  's_66': 1,
  's_67': 0,
  's_68': 1,
  's_69': 1,
  's_7': 1,
  's_70': 0,
  's_71': 0,
  's_72': 0,
  's_73': 1,
  's_74': 1,
  's_75': 1,
  's_76': 1,
  's_77': 0,
  's_78': 1,
  's_79': 0,
  's_8': 1,
  's_80': 0,
  's_81': 0,
  's_82': 0,
  's_83': 1,
  's_84': 1,
  's_85': 1,
  's_86': 0,
  's_87': 1,
  's_88': 1,
  's_89': 0,
  's_9': 0,
  's_90': 1,
  's_91': 1,
  's_92': 0,
  's_93': 1,
  's_94': 1,
  's_95': 0,
  's_96': 1,
  's_97': 0,
  's_98': 1,
  's_99': 1,
  'x': 187,
})

[2024-09-11 08:09:52,361][basic_search][INFO][generic_smbo.py:310] Iter 13, objectives: [inf].
[2024-09-11 08:09:52,365][basic_search][ERROR][generic_smbo.py:290] Exception in objective function:
Traceback (most recent call last):
  File "/gyc_data/fray_data/py38hwvenv/lib/python3.8/site-packages/openbox/utils/limit.py", line 62, in run_without_time_limit
    ret = obj_func(*obj_args, **obj_kwargs)
  File "/gyc_data/fray_data/project_hw/BO_partition3.py", line 99, in obj_func
    cost = self.black_box.get_cost_from_partitions(partitions, scan_method)
  File "/gyc_data/fray_data/project_hw/BO_partition3.py", line 60, in get_cost_from_partitions
    scan_method_cpp[i] = scan_method[i]
IndexError: list index out of range

config: Configuration(values={
  's_0': 1,
  's_1': 0,
  's_10': 0,
  's_100': 1,
  's_101': 0,
  's_102': 1,
  's_103': 1,
  's_104': 0,
  's_105': 0,
  's_106': 0,
  's_107': 0,
  's_108': 0,
  's_109': 0,
  's_11': 1,
  's_110': 0,
  's_111': 0,
  's_112': 1,
  's_113': 1,
  's_114': 1,
  's_115': 0,
  's_116': 1,
  's_117': 1,
  's_118': 0,
  's_119': 1,
  's_12': 1,
  's_120': 0,
  's_121': 1,
  's_122': 0,
  's_123': 1,
  's_124': 1,
  's_125': 1,
  's_126': 0,
  's_127': 0,
  's_128': 0,
  's_129': 0,
  's_13': 1,
  's_130': 0,
  's_131': 0,
  's_132': 1,
  's_133': 0,
  's_134': 1,
  's_135': 0,
  's_136': 0,
  's_137': 1,
  's_138': 1,
  's_139': 1,
  's_14': 1,
  's_140': 0,
  's_141': 1,
  's_142': 0,
  's_143': 1,
  's_144': 1,
  's_145': 0,
  's_146': 1,
  's_15': 1,
  's_16': 0,
  's_17': 1,
  's_18': 1,
  's_19': 0,
  's_2': 1,
  's_20': 1,
  's_21': 0,
  's_22': 0,
  's_23': 1,
  's_24': 1,
  's_25': 0,
  's_26': 0,
  's_27': 1,
  's_28': 1,
  's_29': 0,
  's_3': 0,
  's_30': 1,
  's_31': 1,
  's_32': 0,
  's_33': 0,
  's_34': 0,
  's_35': 1,
  's_36': 1,
  's_37': 0,
  's_38': 1,
  's_39': 0,
  's_4': 0,
  's_40': 1,
  's_41': 1,
  's_42': 1,
  's_43': 1,
  's_44': 1,
  's_45': 0,
  's_46': 1,
  's_47': 1,
  's_48': 0,
  's_49': 0,
  's_5': 1,
  's_50': 1,
  's_51': 1,
  's_52': 1,
  's_53': 1,
  's_54': 1,
  's_55': 0,
  's_56': 1,
  's_57': 0,
  's_58': 0,
  's_59': 0,
  's_6': 1,
  's_60': 1,
  's_61': 1,
  's_62': 0,
  's_63': 0,
  's_64': 1,
  's_65': 0,
  's_66': 0,
  's_67': 1,
  's_68': 0,
  's_69': 0,
  's_7': 1,
  's_70': 0,
  's_71': 0,
  's_72': 1,
  's_73': 1,
  's_74': 1,
  's_75': 0,
  's_76': 1,
  's_77': 0,
  's_78': 1,
  's_79': 1,
  's_8': 1,
  's_80': 1,
  's_81': 1,
  's_82': 0,
  's_83': 0,
  's_84': 0,
  's_85': 0,
  's_86': 1,
  's_87': 1,
  's_88': 1,
  's_89': 1,
  's_9': 0,
  's_90': 1,
  's_91': 1,
  's_92': 0,
  's_93': 0,
  's_94': 0,
  's_95': 0,
  's_96': 0,
  's_97': 1,
  's_98': 1,
  's_99': 1,
  'x': 85,
})

[2024-09-11 08:09:52,366][basic_search][INFO][generic_smbo.py:310] Iter 14, objectives: [inf].
[2024-09-11 08:09:52,370][basic_search][ERROR][generic_smbo.py:290] Exception in objective function:
Traceback (most recent call last):
  File "/gyc_data/fray_data/py38hwvenv/lib/python3.8/site-packages/openbox/utils/limit.py", line 62, in run_without_time_limit
    ret = obj_func(*obj_args, **obj_kwargs)
  File "/gyc_data/fray_data/project_hw/BO_partition3.py", line 99, in obj_func
    cost = self.black_box.get_cost_from_partitions(partitions, scan_method)
  File "/gyc_data/fray_data/project_hw/BO_partition3.py", line 60, in get_cost_from_partitions
    scan_method_cpp[i] = scan_method[i]
IndexError: list index out of range

config: Configuration(values={
  's_0': 1,
  's_1': 0,
  's_10': 1,
  's_100': 0,
  's_101': 1,
  's_102': 0,
  's_103': 1,
  's_104': 0,
  's_105': 0,
  's_106': 0,
  's_107': 0,
  's_108': 1,
  's_109': 1,
  's_11': 0,
  's_110': 1,
  's_111': 1,
  's_112': 1,
  's_113': 1,
  's_114': 0,
  's_115': 1,
  's_116': 1,
  's_117': 1,
  's_118': 0,
  's_119': 1,
  's_12': 0,
  's_120': 0,
  's_121': 1,
  's_122': 1,
  's_123': 1,
  's_124': 0,
  's_125': 0,
  's_126': 0,
  's_127': 0,
  's_128': 1,
  's_129': 1,
  's_13': 1,
  's_130': 1,
  's_131': 0,
  's_132': 1,
  's_133': 1,
  's_134': 1,
  's_135': 0,
  's_136': 1,
  's_137': 0,
  's_138': 0,
  's_139': 0,
  's_14': 1,
  's_140': 0,
  's_141': 0,
  's_142': 1,
  's_143': 1,
  's_144': 1,
  's_145': 0,
  's_146': 1,
  's_15': 0,
  's_16': 0,
  's_17': 0,
  's_18': 0,
  's_19': 1,
  's_2': 0,
  's_20': 0,
  's_21': 1,
  's_22': 1,
  's_23': 0,
  's_24': 1,
  's_25': 1,
  's_26': 0,
  's_27': 1,
  's_28': 0,
  's_29': 1,
  's_3': 1,
  's_30': 0,
  's_31': 1,
  's_32': 0,
  's_33': 0,
  's_34': 0,
  's_35': 0,
  's_36': 0,
  's_37': 1,
  's_38': 0,
  's_39': 0,
  's_4': 1,
  's_40': 1,
  's_41': 1,
  's_42': 0,
  's_43': 0,
  's_44': 1,
  's_45': 0,
  's_46': 1,
  's_47': 1,
  's_48': 0,
  's_49': 0,
  's_5': 0,
  's_50': 0,
  's_51': 0,
  's_52': 0,
  's_53': 1,
  's_54': 1,
  's_55': 0,
  's_56': 1,
  's_57': 0,
  's_58': 1,
  's_59': 0,
  's_6': 1,
  's_60': 1,
  's_61': 1,
  's_62': 1,
  's_63': 1,
  's_64': 0,
  's_65': 1,
  's_66': 1,
  's_67': 1,
  's_68': 0,
  's_69': 0,
  's_7': 1,
  's_70': 1,
  's_71': 0,
  's_72': 0,
  's_73': 0,
  's_74': 1,
  's_75': 0,
  's_76': 0,
  's_77': 1,
  's_78': 0,
  's_79': 0,
  's_8': 1,
  's_80': 0,
  's_81': 0,
  's_82': 0,
  's_83': 1,
  's_84': 0,
  's_85': 1,
  's_86': 0,
  's_87': 1,
  's_88': 0,
  's_89': 0,
  's_9': 1,
  's_90': 1,
  's_91': 1,
  's_92': 1,
  's_93': 0,
  's_94': 1,
  's_95': 0,
  's_96': 1,
  's_97': 1,
  's_98': 1,
  's_99': 1,
  'x': 202,
})

[2024-09-11 08:09:52,370][basic_search][INFO][generic_smbo.py:310] Iter 15, objectives: [inf].
[2024-09-11 08:09:52,375][basic_search][ERROR][generic_smbo.py:290] Exception in objective function:
Traceback (most recent call last):
  File "/gyc_data/fray_data/py38hwvenv/lib/python3.8/site-packages/openbox/utils/limit.py", line 62, in run_without_time_limit
    ret = obj_func(*obj_args, **obj_kwargs)
  File "/gyc_data/fray_data/project_hw/BO_partition3.py", line 99, in obj_func
    cost = self.black_box.get_cost_from_partitions(partitions, scan_method)
  File "/gyc_data/fray_data/project_hw/BO_partition3.py", line 60, in get_cost_from_partitions
    scan_method_cpp[i] = scan_method[i]
IndexError: list index out of range

config: Configuration(values={
  's_0': 0,
  's_1': 1,
  's_10': 0,
  's_100': 1,
  's_101': 1,
  's_102': 1,
  's_103': 0,
  's_104': 1,
  's_105': 1,
  's_106': 0,
  's_107': 0,
  's_108': 0,
  's_109': 1,
  's_11': 0,
  's_110': 0,
  's_111': 1,
  's_112': 1,
  's_113': 1,
  's_114': 1,
  's_115': 0,
  's_116': 0,
  's_117': 1,
  's_118': 1,
  's_119': 1,
  's_12': 0,
  's_120': 0,
  's_121': 0,
  's_122': 1,
  's_123': 0,
  's_124': 0,
  's_125': 0,
  's_126': 0,
  's_127': 1,
  's_128': 1,
  's_129': 0,
  's_13': 1,
  's_130': 0,
  's_131': 1,
  's_132': 1,
  's_133': 0,
  's_134': 0,
  's_135': 1,
  's_136': 1,
  's_137': 1,
  's_138': 1,
  's_139': 1,
  's_14': 0,
  's_140': 0,
  's_141': 1,
  's_142': 1,
  's_143': 0,
  's_144': 0,
  's_145': 0,
  's_146': 1,
  's_15': 0,
  's_16': 0,
  's_17': 0,
  's_18': 1,
  's_19': 0,
  's_2': 1,
  's_20': 1,
  's_21': 0,
  's_22': 1,
  's_23': 0,
  's_24': 0,
  's_25': 1,
  's_26': 1,
  's_27': 1,
  's_28': 1,
  's_29': 1,
  's_3': 1,
  's_30': 0,
  's_31': 1,
  's_32': 1,
  's_33': 0,
  's_34': 1,
  's_35': 1,
  's_36': 0,
  's_37': 0,
  's_38': 0,
  's_39': 0,
  's_4': 1,
  's_40': 1,
  's_41': 0,
  's_42': 0,
  's_43': 0,
  's_44': 1,
  's_45': 0,
  's_46': 1,
  's_47': 1,
  's_48': 1,
  's_49': 1,
  's_5': 1,
  's_50': 1,
  's_51': 1,
  's_52': 1,
  's_53': 0,
  's_54': 1,
  's_55': 1,
  's_56': 0,
  's_57': 0,
  's_58': 0,
  's_59': 1,
  's_6': 0,
  's_60': 1,
  's_61': 0,
  's_62': 1,
  's_63': 0,
  's_64': 1,
  's_65': 0,
  's_66': 1,
  's_67': 0,
  's_68': 1,
  's_69': 0,
  's_7': 1,
  's_70': 1,
  's_71': 0,
  's_72': 1,
  's_73': 0,
  's_74': 0,
  's_75': 0,
  's_76': 1,
  's_77': 1,
  's_78': 0,
  's_79': 1,
  's_8': 1,
  's_80': 0,
  's_81': 1,
  's_82': 0,
  's_83': 0,
  's_84': 0,
  's_85': 1,
  's_86': 1,
  's_87': 1,
  's_88': 1,
  's_89': 1,
  's_9': 1,
  's_90': 0,
  's_91': 1,
  's_92': 0,
  's_93': 0,
  's_94': 1,
  's_95': 0,
  's_96': 0,
  's_97': 1,
  's_98': 1,
  's_99': 0,
  'x': 32,
})

[2024-09-11 08:09:52,375][basic_search][INFO][generic_smbo.py:310] Iter 16, objectives: [inf].
[2024-09-11 08:09:52,380][basic_search][ERROR][generic_smbo.py:290] Exception in objective function:
Traceback (most recent call last):
  File "/gyc_data/fray_data/py38hwvenv/lib/python3.8/site-packages/openbox/utils/limit.py", line 62, in run_without_time_limit
    ret = obj_func(*obj_args, **obj_kwargs)
  File "/gyc_data/fray_data/project_hw/BO_partition3.py", line 99, in obj_func
    cost = self.black_box.get_cost_from_partitions(partitions, scan_method)
  File "/gyc_data/fray_data/project_hw/BO_partition3.py", line 60, in get_cost_from_partitions
    scan_method_cpp[i] = scan_method[i]
IndexError: list index out of range

config: Configuration(values={
  's_0': 0,
  's_1': 0,
  's_10': 1,
  's_100': 1,
  's_101': 0,
  's_102': 0,
  's_103': 1,
  's_104': 0,
  's_105': 0,
  's_106': 0,
  's_107': 0,
  's_108': 1,
  's_109': 1,
  's_11': 1,
  's_110': 1,
  's_111': 0,
  's_112': 0,
  's_113': 1,
  's_114': 1,
  's_115': 1,
  's_116': 1,
  's_117': 1,
  's_118': 0,
  's_119': 1,
  's_12': 0,
  's_120': 0,
  's_121': 1,
  's_122': 1,
  's_123': 0,
  's_124': 0,
  's_125': 0,
  's_126': 0,
  's_127': 1,
  's_128': 0,
  's_129': 0,
  's_13': 0,
  's_130': 1,
  's_131': 0,
  's_132': 1,
  's_133': 0,
  's_134': 0,
  's_135': 1,
  's_136': 0,
  's_137': 0,
  's_138': 1,
  's_139': 0,
  's_14': 0,
  's_140': 1,
  's_141': 1,
  's_142': 0,
  's_143': 0,
  's_144': 1,
  's_145': 1,
  's_146': 1,
  's_15': 1,
  's_16': 1,
  's_17': 0,
  's_18': 1,
  's_19': 0,
  's_2': 1,
  's_20': 0,
  's_21': 0,
  's_22': 1,
  's_23': 0,
  's_24': 1,
  's_25': 0,
  's_26': 1,
  's_27': 1,
  's_28': 1,
  's_29': 0,
  's_3': 0,
  's_30': 1,
  's_31': 0,
  's_32': 0,
  's_33': 0,
  's_34': 0,
  's_35': 0,
  's_36': 0,
  's_37': 1,
  's_38': 0,
  's_39': 1,
  's_4': 1,
  's_40': 1,
  's_41': 0,
  's_42': 0,
  's_43': 0,
  's_44': 0,
  's_45': 0,
  's_46': 0,
  's_47': 0,
  's_48': 1,
  's_49': 0,
  's_5': 1,
  's_50': 1,
  's_51': 1,
  's_52': 1,
  's_53': 0,
  's_54': 1,
  's_55': 0,
  's_56': 1,
  's_57': 0,
  's_58': 1,
  's_59': 0,
  's_6': 0,
  's_60': 0,
  's_61': 1,
  's_62': 1,
  's_63': 0,
  's_64': 1,
  's_65': 1,
  's_66': 1,
  's_67': 0,
  's_68': 1,
  's_69': 0,
  's_7': 0,
  's_70': 0,
  's_71': 0,
  's_72': 1,
  's_73': 0,
  's_74': 1,
  's_75': 0,
  's_76': 0,
  's_77': 1,
  's_78': 0,
  's_79': 1,
  's_8': 1,
  's_80': 1,
  's_81': 1,
  's_82': 0,
  's_83': 0,
  's_84': 1,
  's_85': 0,
  's_86': 1,
  's_87': 0,
  's_88': 1,
  's_89': 0,
  's_9': 1,
  's_90': 0,
  's_91': 0,
  's_92': 1,
  's_93': 0,
  's_94': 0,
  's_95': 1,
  's_96': 1,
  's_97': 0,
  's_98': 1,
  's_99': 1,
  'x': 289,
})

[2024-09-11 08:09:52,381][basic_search][INFO][generic_smbo.py:310] Iter 17, objectives: [inf].
[2024-09-11 08:09:52,386][basic_search][ERROR][generic_smbo.py:290] Exception in objective function:
Traceback (most recent call last):
  File "/gyc_data/fray_data/py38hwvenv/lib/python3.8/site-packages/openbox/utils/limit.py", line 62, in run_without_time_limit
    ret = obj_func(*obj_args, **obj_kwargs)
  File "/gyc_data/fray_data/project_hw/BO_partition3.py", line 99, in obj_func
    cost = self.black_box.get_cost_from_partitions(partitions, scan_method)
  File "/gyc_data/fray_data/project_hw/BO_partition3.py", line 60, in get_cost_from_partitions
    scan_method_cpp[i] = scan_method[i]
IndexError: list index out of range

config: Configuration(values={
  's_0': 1,
  's_1': 0,
  's_10': 1,
  's_100': 0,
  's_101': 1,
  's_102': 1,
  's_103': 1,
  's_104': 0,
  's_105': 1,
  's_106': 0,
  's_107': 0,
  's_108': 0,
  's_109': 1,
  's_11': 0,
  's_110': 0,
  's_111': 1,
  's_112': 0,
  's_113': 1,
  's_114': 1,
  's_115': 0,
  's_116': 0,
  's_117': 0,
  's_118': 0,
  's_119': 1,
  's_12': 0,
  's_120': 0,
  's_121': 1,
  's_122': 0,
  's_123': 0,
  's_124': 1,
  's_125': 1,
  's_126': 1,
  's_127': 0,
  's_128': 0,
  's_129': 1,
  's_13': 1,
  's_130': 0,
  's_131': 1,
  's_132': 0,
  's_133': 0,
  's_134': 1,
  's_135': 0,
  's_136': 0,
  's_137': 0,
  's_138': 0,
  's_139': 0,
  's_14': 1,
  's_140': 1,
  's_141': 0,
  's_142': 0,
  's_143': 1,
  's_144': 1,
  's_145': 0,
  's_146': 0,
  's_15': 0,
  's_16': 1,
  's_17': 0,
  's_18': 1,
  's_19': 1,
  's_2': 0,
  's_20': 0,
  's_21': 0,
  's_22': 0,
  's_23': 1,
  's_24': 0,
  's_25': 0,
  's_26': 0,
  's_27': 0,
  's_28': 1,
  's_29': 0,
  's_3': 0,
  's_30': 0,
  's_31': 1,
  's_32': 0,
  's_33': 1,
  's_34': 1,
  's_35': 0,
  's_36': 1,
  's_37': 1,
  's_38': 1,
  's_39': 0,
  's_4': 1,
  's_40': 0,
  's_41': 0,
  's_42': 0,
  's_43': 0,
  's_44': 0,
  's_45': 0,
  's_46': 0,
  's_47': 1,
  's_48': 0,
  's_49': 1,
  's_5': 0,
  's_50': 0,
  's_51': 1,
  's_52': 0,
  's_53': 1,
  's_54': 0,
  's_55': 0,
  's_56': 1,
  's_57': 0,
  's_58': 0,
  's_59': 0,
  's_6': 1,
  's_60': 1,
  's_61': 0,
  's_62': 0,
  's_63': 0,
  's_64': 1,
  's_65': 1,
  's_66': 0,
  's_67': 0,
  's_68': 1,
  's_69': 1,
  's_7': 0,
  's_70': 1,
  's_71': 1,
  's_72': 1,
  's_73': 0,
  's_74': 0,
  's_75': 1,
  's_76': 1,
  's_77': 0,
  's_78': 0,
  's_79': 1,
  's_8': 1,
  's_80': 1,
  's_81': 0,
  's_82': 1,
  's_83': 0,
  's_84': 1,
  's_85': 1,
  's_86': 1,
  's_87': 1,
  's_88': 1,
  's_89': 1,
  's_9': 0,
  's_90': 0,
  's_91': 0,
  's_92': 1,
  's_93': 1,
  's_94': 0,
  's_95': 1,
  's_96': 1,
  's_97': 0,
  's_98': 1,
  's_99': 1,
  'x': 271,
})

[2024-09-11 08:09:52,386][basic_search][INFO][generic_smbo.py:310] Iter 18, objectives: [inf].
[2024-09-11 08:09:52,391][basic_search][ERROR][generic_smbo.py:290] Exception in objective function:
Traceback (most recent call last):
  File "/gyc_data/fray_data/py38hwvenv/lib/python3.8/site-packages/openbox/utils/limit.py", line 62, in run_without_time_limit
    ret = obj_func(*obj_args, **obj_kwargs)
  File "/gyc_data/fray_data/project_hw/BO_partition3.py", line 99, in obj_func
    cost = self.black_box.get_cost_from_partitions(partitions, scan_method)
  File "/gyc_data/fray_data/project_hw/BO_partition3.py", line 60, in get_cost_from_partitions
    scan_method_cpp[i] = scan_method[i]
IndexError: list index out of range

config: Configuration(values={
  's_0': 1,
  's_1': 1,
  's_10': 1,
  's_100': 1,
  's_101': 0,
  's_102': 0,
  's_103': 0,
  's_104': 0,
  's_105': 1,
  's_106': 1,
  's_107': 1,
  's_108': 1,
  's_109': 0,
  's_11': 0,
  's_110': 0,
  's_111': 1,
  's_112': 1,
  's_113': 0,
  's_114': 1,
  's_115': 0,
  's_116': 0,
  's_117': 1,
  's_118': 1,
  's_119': 0,
  's_12': 0,
  's_120': 1,
  's_121': 1,
  's_122': 1,
  's_123': 1,
  's_124': 0,
  's_125': 1,
  's_126': 1,
  's_127': 0,
  's_128': 0,
  's_129': 0,
  's_13': 0,
  's_130': 0,
  's_131': 0,
  's_132': 0,
  's_133': 0,
  's_134': 0,
  's_135': 0,
  's_136': 1,
  's_137': 0,
  's_138': 0,
  's_139': 1,
  's_14': 1,
  's_140': 0,
  's_141': 0,
  's_142': 0,
  's_143': 0,
  's_144': 1,
  's_145': 1,
  's_146': 0,
  's_15': 0,
  's_16': 0,
  's_17': 1,
  's_18': 1,
  's_19': 0,
  's_2': 0,
  's_20': 0,
  's_21': 1,
  's_22': 0,
  's_23': 1,
  's_24': 0,
  's_25': 1,
  's_26': 1,
  's_27': 1,
  's_28': 0,
  's_29': 0,
  's_3': 0,
  's_30': 1,
  's_31': 1,
  's_32': 1,
  's_33': 1,
  's_34': 1,
  's_35': 1,
  's_36': 1,
  's_37': 1,
  's_38': 0,
  's_39': 1,
  's_4': 1,
  's_40': 1,
  's_41': 0,
  's_42': 0,
  's_43': 0,
  's_44': 0,
  's_45': 1,
  's_46': 0,
  's_47': 1,
  's_48': 1,
  's_49': 1,
  's_5': 1,
  's_50': 1,
  's_51': 0,
  's_52': 1,
  's_53': 0,
  's_54': 1,
  's_55': 0,
  's_56': 0,
  's_57': 0,
  's_58': 1,
  's_59': 0,
  's_6': 0,
  's_60': 0,
  's_61': 0,
  's_62': 1,
  's_63': 0,
  's_64': 1,
  's_65': 0,
  's_66': 1,
  's_67': 1,
  's_68': 0,
  's_69': 0,
  's_7': 0,
  's_70': 0,
  's_71': 1,
  's_72': 0,
  's_73': 0,
  's_74': 1,
  's_75': 1,
  's_76': 1,
  's_77': 0,
  's_78': 0,
  's_79': 1,
  's_8': 0,
  's_80': 0,
  's_81': 0,
  's_82': 0,
  's_83': 1,
  's_84': 0,
  's_85': 0,
  's_86': 0,
  's_87': 1,
  's_88': 1,
  's_89': 1,
  's_9': 0,
  's_90': 1,
  's_91': 0,
  's_92': 0,
  's_93': 1,
  's_94': 1,
  's_95': 0,
  's_96': 1,
  's_97': 0,
  's_98': 0,
  's_99': 1,
  'x': 163,
})

[2024-09-11 08:09:52,392][basic_search][INFO][generic_smbo.py:310] Iter 19, objectives: [inf].
[2024-09-11 08:09:52,397][basic_search][ERROR][generic_smbo.py:290] Exception in objective function:
Traceback (most recent call last):
  File "/gyc_data/fray_data/py38hwvenv/lib/python3.8/site-packages/openbox/utils/limit.py", line 62, in run_without_time_limit
    ret = obj_func(*obj_args, **obj_kwargs)
  File "/gyc_data/fray_data/project_hw/BO_partition3.py", line 99, in obj_func
    cost = self.black_box.get_cost_from_partitions(partitions, scan_method)
  File "/gyc_data/fray_data/project_hw/BO_partition3.py", line 60, in get_cost_from_partitions
    scan_method_cpp[i] = scan_method[i]
IndexError: list index out of range

config: Configuration(values={
  's_0': 0,
  's_1': 0,
  's_10': 0,
  's_100': 0,
  's_101': 0,
  's_102': 1,
  's_103': 1,
  's_104': 1,
  's_105': 1,
  's_106': 1,
  's_107': 1,
  's_108': 1,
  's_109': 0,
  's_11': 0,
  's_110': 0,
  's_111': 1,
  's_112': 1,
  's_113': 1,
  's_114': 0,
  's_115': 0,
  's_116': 0,
  's_117': 1,
  's_118': 0,
  's_119': 1,
  's_12': 1,
  's_120': 0,
  's_121': 1,
  's_122': 0,
  's_123': 1,
  's_124': 0,
  's_125': 0,
  's_126': 0,
  's_127': 0,
  's_128': 0,
  's_129': 0,
  's_13': 0,
  's_130': 1,
  's_131': 1,
  's_132': 1,
  's_133': 1,
  's_134': 1,
  's_135': 0,
  's_136': 0,
  's_137': 0,
  's_138': 0,
  's_139': 1,
  's_14': 1,
  's_140': 0,
  's_141': 0,
  's_142': 1,
  's_143': 1,
  's_144': 1,
  's_145': 1,
  's_146': 1,
  's_15': 0,
  's_16': 0,
  's_17': 0,
  's_18': 0,
  's_19': 0,
  's_2': 1,
  's_20': 0,
  's_21': 1,
  's_22': 1,
  's_23': 0,
  's_24': 0,
  's_25': 0,
  's_26': 0,
  's_27': 1,
  's_28': 0,
  's_29': 0,
  's_3': 1,
  's_30': 0,
  's_31': 0,
  's_32': 0,
  's_33': 0,
  's_34': 1,
  's_35': 0,
  's_36': 1,
  's_37': 1,
  's_38': 1,
  's_39': 1,
  's_4': 0,
  's_40': 1,
  's_41': 0,
  's_42': 1,
  's_43': 0,
  's_44': 0,
  's_45': 0,
  's_46': 1,
  's_47': 0,
  's_48': 1,
  's_49': 0,
  's_5': 1,
  's_50': 0,
  's_51': 1,
  's_52': 0,
  's_53': 0,
  's_54': 0,
  's_55': 1,
  's_56': 0,
  's_57': 1,
  's_58': 1,
  's_59': 1,
  's_6': 1,
  's_60': 0,
  's_61': 0,
  's_62': 0,
  's_63': 1,
  's_64': 1,
  's_65': 0,
  's_66': 1,
  's_67': 0,
  's_68': 0,
  's_69': 1,
  's_7': 1,
  's_70': 0,
  's_71': 0,
  's_72': 0,
  's_73': 0,
  's_74': 0,
  's_75': 0,
  's_76': 1,
  's_77': 0,
  's_78': 1,
  's_79': 1,
  's_8': 0,
  's_80': 1,
  's_81': 1,
  's_82': 1,
  's_83': 1,
  's_84': 0,
  's_85': 0,
  's_86': 1,
  's_87': 0,
  's_88': 1,
  's_89': 0,
  's_9': 1,
  's_90': 1,
  's_91': 0,
  's_92': 1,
  's_93': 1,
  's_94': 0,
  's_95': 0,
  's_96': 0,
  's_97': 1,
  's_98': 0,
  's_99': 1,
  'x': 72,
})

[2024-09-11 08:09:52,398][basic_search][INFO][generic_smbo.py:310] Iter 20, objectives: [inf].
[2024-09-11 08:09:52,404][basic_search][WARNING][generic_advisor.py:467] No enough successful initial trials! Sample random configuration.
[2024-09-11 08:09:52,408][basic_search][ERROR][generic_smbo.py:290] Exception in objective function:
Traceback (most recent call last):
  File "/gyc_data/fray_data/py38hwvenv/lib/python3.8/site-packages/openbox/utils/limit.py", line 62, in run_without_time_limit
    ret = obj_func(*obj_args, **obj_kwargs)
  File "/gyc_data/fray_data/project_hw/BO_partition3.py", line 99, in obj_func
    cost = self.black_box.get_cost_from_partitions(partitions, scan_method)
  File "/gyc_data/fray_data/project_hw/BO_partition3.py", line 60, in get_cost_from_partitions
    scan_method_cpp[i] = scan_method[i]
IndexError: list index out of range

config: Configuration(values={
  's_0': 0,
  's_1': 1,
  's_10': 0,
  's_100': 0,
  's_101': 0,
  's_102': 0,
  's_103': 0,
  's_104': 0,
  's_105': 0,
  's_106': 0,
  's_107': 1,
  's_108': 1,
  's_109': 1,
  's_11': 0,
  's_110': 1,
  's_111': 1,
  's_112': 0,
  's_113': 0,
  's_114': 0,
  's_115': 0,
  's_116': 0,
  's_117': 1,
  's_118': 0,
  's_119': 1,
  's_12': 0,
  's_120': 1,
  's_121': 0,
  's_122': 1,
  's_123': 0,
  's_124': 0,
  's_125': 1,
  's_126': 0,
  's_127': 0,
  's_128': 0,
  's_129': 0,
  's_13': 0,
  's_130': 1,
  's_131': 0,
  's_132': 1,
  's_133': 1,
  's_134': 0,
  's_135': 0,
  's_136': 1,
  's_137': 0,
  's_138': 1,
  's_139': 1,
  's_14': 0,
  's_140': 1,
  's_141': 0,
  's_142': 1,
  's_143': 1,
  's_144': 1,
  's_145': 0,
  's_146': 0,
  's_15': 0,
  's_16': 1,
  's_17': 0,
  's_18': 0,
  's_19': 1,
  's_2': 1,
  's_20': 1,
  's_21': 0,
  's_22': 1,
  's_23': 1,
  's_24': 0,
  's_25': 1,
  's_26': 0,
  's_27': 1,
  's_28': 0,
  's_29': 0,
  's_3': 1,
  's_30': 0,
  's_31': 1,
  's_32': 1,
  's_33': 1,
  's_34': 0,
  's_35': 1,
  's_36': 1,
  's_37': 1,
  's_38': 1,
  's_39': 1,
  's_4': 0,
  's_40': 1,
  's_41': 0,
  's_42': 1,
  's_43': 0,
  's_44': 1,
  's_45': 0,
  's_46': 0,
  's_47': 1,
  's_48': 1,
  's_49': 0,
  's_5': 1,
  's_50': 0,
  's_51': 1,
  's_52': 1,
  's_53': 1,
  's_54': 0,
  's_55': 0,
  's_56': 1,
  's_57': 0,
  's_58': 0,
  's_59': 0,
  's_6': 1,
  's_60': 0,
  's_61': 0,
  's_62': 1,
  's_63': 0,
  's_64': 0,
  's_65': 0,
  's_66': 1,
  's_67': 0,
  's_68': 0,
  's_69': 1,
  's_7': 1,
  's_70': 0,
  's_71': 1,
  's_72': 1,
  's_73': 0,
  's_74': 0,
  's_75': 0,
  's_76': 0,
  's_77': 1,
  's_78': 0,
  's_79': 1,
  's_8': 1,
  's_80': 0,
  's_81': 0,
  's_82': 0,
  's_83': 1,
  's_84': 1,
  's_85': 0,
  's_86': 0,
  's_87': 0,
  's_88': 1,
  's_89': 0,
  's_9': 1,
  's_90': 0,
  's_91': 0,
  's_92': 0,
  's_93': 0,
  's_94': 1,
  's_95': 0,
  's_96': 1,
  's_97': 0,
  's_98': 0,
  's_99': 0,
  'x': 153,
})

[2024-09-11 08:09:52,409][basic_search][INFO][generic_smbo.py:310] Iter 21, objectives: [inf].
[2024-09-11 08:09:52,415][basic_search][WARNING][generic_advisor.py:467] No enough successful initial trials! Sample random configuration.
[2024-09-11 08:09:52,419][basic_search][ERROR][generic_smbo.py:290] Exception in objective function:
Traceback (most recent call last):
  File "/gyc_data/fray_data/py38hwvenv/lib/python3.8/site-packages/openbox/utils/limit.py", line 62, in run_without_time_limit
    ret = obj_func(*obj_args, **obj_kwargs)
  File "/gyc_data/fray_data/project_hw/BO_partition3.py", line 99, in obj_func
    cost = self.black_box.get_cost_from_partitions(partitions, scan_method)
  File "/gyc_data/fray_data/project_hw/BO_partition3.py", line 60, in get_cost_from_partitions
    scan_method_cpp[i] = scan_method[i]
IndexError: list index out of range

config: Configuration(values={
  's_0': 1,
  's_1': 0,
  's_10': 0,
  's_100': 1,
  's_101': 0,
  's_102': 0,
  's_103': 1,
  's_104': 1,
  's_105': 1,
  's_106': 1,
  's_107': 0,
  's_108': 1,
  's_109': 0,
  's_11': 0,
  's_110': 1,
  's_111': 0,
  's_112': 0,
  's_113': 1,
  's_114': 0,
  's_115': 0,
  's_116': 1,
  's_117': 0,
  's_118': 0,
  's_119': 0,
  's_12': 1,
  's_120': 1,
  's_121': 0,
  's_122': 1,
  's_123': 0,
  's_124': 0,
  's_125': 0,
  's_126': 1,
  's_127': 1,
  's_128': 1,
  's_129': 0,
  's_13': 0,
  's_130': 0,
  's_131': 1,
  's_132': 0,
  's_133': 1,
  's_134': 1,
  's_135': 0,
  's_136': 0,
  's_137': 0,
  's_138': 0,
  's_139': 0,
  's_14': 1,
  's_140': 1,
  's_141': 0,
  's_142': 1,
  's_143': 1,
  's_144': 1,
  's_145': 1,
  's_146': 0,
  's_15': 0,
  's_16': 0,
  's_17': 1,
  's_18': 0,
  's_19': 0,
  's_2': 0,
  's_20': 1,
  's_21': 1,
  's_22': 1,
  's_23': 0,
  's_24': 1,
  's_25': 0,
  's_26': 0,
  's_27': 0,
  's_28': 1,
  's_29': 0,
  's_3': 1,
  's_30': 0,
  's_31': 0,
  's_32': 1,
  's_33': 0,
  's_34': 1,
  's_35': 0,
  's_36': 1,
  's_37': 0,
  's_38': 0,
  's_39': 0,
  's_4': 0,
  's_40': 1,
  's_41': 0,
  's_42': 0,
  's_43': 1,
  's_44': 1,
  's_45': 1,
  's_46': 0,
  's_47': 0,
  's_48': 0,
  's_49': 1,
  's_5': 0,
  's_50': 0,
  's_51': 1,
  's_52': 1,
  's_53': 0,
  's_54': 0,
  's_55': 0,
  's_56': 0,
  's_57': 1,
  's_58': 1,
  's_59': 1,
  's_6': 1,
  's_60': 1,
  's_61': 0,
  's_62': 0,
  's_63': 0,
  's_64': 0,
  's_65': 1,
  's_66': 0,
  's_67': 1,
  's_68': 1,
  's_69': 1,
  's_7': 0,
  's_70': 0,
  's_71': 0,
  's_72': 0,
  's_73': 0,
  's_74': 1,
  's_75': 0,
  's_76': 1,
  's_77': 0,
  's_78': 1,
  's_79': 1,
  's_8': 0,
  's_80': 1,
  's_81': 0,
  's_82': 1,
  's_83': 0,
  's_84': 0,
  's_85': 0,
  's_86': 1,
  's_87': 0,
  's_88': 1,
  's_89': 0,
  's_9': 0,
  's_90': 1,
  's_91': 0,
  's_92': 0,
  's_93': 1,
  's_94': 0,
  's_95': 1,
  's_96': 1,
  's_97': 0,
  's_98': 1,
  's_99': 0,
  'x': 41,
})

[2024-09-11 08:09:52,419][basic_search][INFO][generic_smbo.py:310] Iter 22, objectives: [inf].
[2024-09-11 08:09:52,426][basic_search][WARNING][generic_advisor.py:467] No enough successful initial trials! Sample random configuration.
[2024-09-11 08:09:52,430][basic_search][ERROR][generic_smbo.py:290] Exception in objective function:
Traceback (most recent call last):
  File "/gyc_data/fray_data/py38hwvenv/lib/python3.8/site-packages/openbox/utils/limit.py", line 62, in run_without_time_limit
    ret = obj_func(*obj_args, **obj_kwargs)
  File "/gyc_data/fray_data/project_hw/BO_partition3.py", line 99, in obj_func
    cost = self.black_box.get_cost_from_partitions(partitions, scan_method)
  File "/gyc_data/fray_data/project_hw/BO_partition3.py", line 60, in get_cost_from_partitions
    scan_method_cpp[i] = scan_method[i]
IndexError: list index out of range

config: Configuration(values={
  's_0': 0,
  's_1': 1,
  's_10': 0,
  's_100': 0,
  's_101': 1,
  's_102': 1,
  's_103': 0,
  's_104': 0,
  's_105': 0,
  's_106': 0,
  's_107': 1,
  's_108': 1,
  's_109': 0,
  's_11': 1,
  's_110': 1,
  's_111': 0,
  's_112': 1,
  's_113': 1,
  's_114': 1,
  's_115': 1,
  's_116': 1,
  's_117': 0,
  's_118': 1,
  's_119': 0,
  's_12': 1,
  's_120': 0,
  's_121': 1,
  's_122': 1,
  's_123': 0,
  's_124': 1,
  's_125': 0,
  's_126': 1,
  's_127': 1,
  's_128': 0,
  's_129': 0,
  's_13': 1,
  's_130': 0,
  's_131': 1,
  's_132': 0,
  's_133': 0,
  's_134': 0,
  's_135': 1,
  's_136': 1,
  's_137': 0,
  's_138': 0,
  's_139': 0,
  's_14': 0,
  's_140': 0,
  's_141': 0,
  's_142': 0,
  's_143': 1,
  's_144': 0,
  's_145': 1,
  's_146': 0,
  's_15': 0,
  's_16': 1,
  's_17': 1,
  's_18': 1,
  's_19': 0,
  's_2': 1,
  's_20': 1,
  's_21': 1,
  's_22': 1,
  's_23': 1,
  's_24': 1,
  's_25': 1,
  's_26': 1,
  's_27': 1,
  's_28': 0,
  's_29': 1,
  's_3': 0,
  's_30': 1,
  's_31': 1,
  's_32': 1,
  's_33': 1,
  's_34': 1,
  's_35': 1,
  's_36': 0,
  's_37': 0,
  's_38': 0,
  's_39': 1,
  's_4': 0,
  's_40': 1,
  's_41': 0,
  's_42': 1,
  's_43': 1,
  's_44': 1,
  's_45': 1,
  's_46': 1,
  's_47': 1,
  's_48': 0,
  's_49': 1,
  's_5': 0,
  's_50': 0,
  's_51': 0,
  's_52': 1,
  's_53': 1,
  's_54': 0,
  's_55': 1,
  's_56': 0,
  's_57': 0,
  's_58': 1,
  's_59': 1,
  's_6': 1,
  's_60': 0,
  's_61': 0,
  's_62': 1,
  's_63': 0,
  's_64': 1,
  's_65': 1,
  's_66': 1,
  's_67': 1,
  's_68': 0,
  's_69': 1,
  's_7': 0,
  's_70': 1,
  's_71': 0,
  's_72': 1,
  's_73': 1,
  's_74': 1,
  's_75': 1,
  's_76': 0,
  's_77': 1,
  's_78': 0,
  's_79': 1,
  's_8': 0,
  's_80': 1,
  's_81': 1,
  's_82': 0,
  's_83': 0,
  's_84': 0,
  's_85': 1,
  's_86': 1,
  's_87': 0,
  's_88': 1,
  's_89': 1,
  's_9': 1,
  's_90': 0,
  's_91': 0,
  's_92': 0,
  's_93': 0,
  's_94': 1,
  's_95': 1,
  's_96': 0,
  's_97': 0,
  's_98': 0,
  's_99': 0,
  'x': 220,
})

[2024-09-11 08:09:52,430][basic_search][INFO][generic_smbo.py:310] Iter 23, objectives: [inf].
[2024-09-11 08:09:52,438][basic_search][WARNING][generic_advisor.py:467] No enough successful initial trials! Sample random configuration.
[2024-09-11 08:09:52,441][basic_search][ERROR][generic_smbo.py:290] Exception in objective function:
Traceback (most recent call last):
  File "/gyc_data/fray_data/py38hwvenv/lib/python3.8/site-packages/openbox/utils/limit.py", line 62, in run_without_time_limit
    ret = obj_func(*obj_args, **obj_kwargs)
  File "/gyc_data/fray_data/project_hw/BO_partition3.py", line 99, in obj_func
    cost = self.black_box.get_cost_from_partitions(partitions, scan_method)
  File "/gyc_data/fray_data/project_hw/BO_partition3.py", line 60, in get_cost_from_partitions
    scan_method_cpp[i] = scan_method[i]
IndexError: list index out of range

config: Configuration(values={
  's_0': 1,
  's_1': 0,
  's_10': 1,
  's_100': 0,
  's_101': 0,
  's_102': 0,
  's_103': 0,
  's_104': 1,
  's_105': 1,
  's_106': 1,
  's_107': 0,
  's_108': 1,
  's_109': 0,
  's_11': 1,
  's_110': 1,
  's_111': 0,
  's_112': 0,
  's_113': 1,
  's_114': 0,
  's_115': 0,
  's_116': 1,
  's_117': 1,
  's_118': 1,
  's_119': 1,
  's_12': 1,
  's_120': 1,
  's_121': 0,
  's_122': 1,
  's_123': 0,
  's_124': 0,
  's_125': 0,
  's_126': 0,
  's_127': 1,
  's_128': 0,
  's_129': 0,
  's_13': 1,
  's_130': 0,
  's_131': 0,
  's_132': 1,
  's_133': 0,
  's_134': 1,
  's_135': 1,
  's_136': 1,
  's_137': 1,
  's_138': 0,
  's_139': 1,
  's_14': 1,
  's_140': 0,
  's_141': 1,
  's_142': 0,
  's_143': 0,
  's_144': 0,
  's_145': 1,
  's_146': 1,
  's_15': 0,
  's_16': 0,
  's_17': 1,
  's_18': 1,
  's_19': 0,
  's_2': 0,
  's_20': 1,
  's_21': 1,
  's_22': 1,
  's_23': 1,
  's_24': 0,
  's_25': 0,
  's_26': 1,
  's_27': 0,
  's_28': 0,
  's_29': 0,
  's_3': 0,
  's_30': 1,
  's_31': 0,
  's_32': 1,
  's_33': 1,
  's_34': 0,
  's_35': 0,
  's_36': 0,
  's_37': 0,
  's_38': 1,
  's_39': 1,
  's_4': 1,
  's_40': 0,
  's_41': 0,
  's_42': 0,
  's_43': 0,
  's_44': 1,
  's_45': 0,
  's_46': 0,
  's_47': 1,
  's_48': 0,
  's_49': 1,
  's_5': 1,
  's_50': 1,
  's_51': 0,
  's_52': 1,
  's_53': 1,
  's_54': 0,
  's_55': 0,
  's_56': 1,
  's_57': 1,
  's_58': 1,
  's_59': 1,
  's_6': 1,
  's_60': 0,
  's_61': 0,
  's_62': 0,
  's_63': 1,
  's_64': 0,
  's_65': 1,
  's_66': 1,
  's_67': 1,
  's_68': 0,
  's_69': 1,
  's_7': 0,
  's_70': 1,
  's_71': 0,
  's_72': 0,
  's_73': 0,
  's_74': 0,
  's_75': 1,
  's_76': 0,
  's_77': 0,
  's_78': 1,
  's_79': 0,
  's_8': 1,
  's_80': 0,
  's_81': 1,
  's_82': 1,
  's_83': 0,
  's_84': 1,
  's_85': 1,
  's_86': 0,
  's_87': 0,
  's_88': 0,
  's_89': 1,
  's_9': 0,
  's_90': 0,
  's_91': 1,
  's_92': 1,
  's_93': 0,
  's_94': 1,
  's_95': 0,
  's_96': 0,
  's_97': 0,
  's_98': 1,
  's_99': 1,
  'x': 97,
})

[2024-09-11 08:09:52,442][basic_search][INFO][generic_smbo.py:310] Iter 24, objectives: [inf].
[2024-09-11 08:09:52,449][basic_search][WARNING][generic_advisor.py:467] No enough successful initial trials! Sample random configuration.
[2024-09-11 08:09:52,453][basic_search][ERROR][generic_smbo.py:290] Exception in objective function:
Traceback (most recent call last):
  File "/gyc_data/fray_data/py38hwvenv/lib/python3.8/site-packages/openbox/utils/limit.py", line 62, in run_without_time_limit
    ret = obj_func(*obj_args, **obj_kwargs)
  File "/gyc_data/fray_data/project_hw/BO_partition3.py", line 99, in obj_func
    cost = self.black_box.get_cost_from_partitions(partitions, scan_method)
  File "/gyc_data/fray_data/project_hw/BO_partition3.py", line 60, in get_cost_from_partitions
    scan_method_cpp[i] = scan_method[i]
IndexError: list index out of range

config: Configuration(values={
  's_0': 1,
  's_1': 0,
  's_10': 1,
  's_100': 1,
  's_101': 0,
  's_102': 0,
  's_103': 1,
  's_104': 0,
  's_105': 0,
  's_106': 0,
  's_107': 0,
  's_108': 0,
  's_109': 0,
  's_11': 0,
  's_110': 1,
  's_111': 0,
  's_112': 0,
  's_113': 1,
  's_114': 1,
  's_115': 0,
  's_116': 0,
  's_117': 1,
  's_118': 1,
  's_119': 0,
  's_12': 0,
  's_120': 1,
  's_121': 0,
  's_122': 0,
  's_123': 1,
  's_124': 0,
  's_125': 0,
  's_126': 1,
  's_127': 1,
  's_128': 1,
  's_129': 1,
  's_13': 0,
  's_130': 1,
  's_131': 1,
  's_132': 1,
  's_133': 0,
  's_134': 0,
  's_135': 0,
  's_136': 0,
  's_137': 1,
  's_138': 1,
  's_139': 1,
  's_14': 1,
  's_140': 1,
  's_141': 0,
  's_142': 0,
  's_143': 0,
  's_144': 1,
  's_145': 0,
  's_146': 0,
  's_15': 0,
  's_16': 0,
  's_17': 0,
  's_18': 1,
  's_19': 1,
  's_2': 1,
  's_20': 1,
  's_21': 1,
  's_22': 0,
  's_23': 0,
  's_24': 1,
  's_25': 1,
  's_26': 1,
  's_27': 1,
  's_28': 1,
  's_29': 1,
  's_3': 1,
  's_30': 0,
  's_31': 1,
  's_32': 0,
  's_33': 1,
  's_34': 0,
  's_35': 0,
  's_36': 1,
  's_37': 0,
  's_38': 1,
  's_39': 1,
  's_4': 0,
  's_40': 1,
  's_41': 1,
  's_42': 1,
  's_43': 1,
  's_44': 0,
  's_45': 0,
  's_46': 1,
  's_47': 0,
  's_48': 0,
  's_49': 0,
  's_5': 1,
  's_50': 0,
  's_51': 0,
  's_52': 0,
  's_53': 0,
  's_54': 0,
  's_55': 0,
  's_56': 0,
  's_57': 1,
  's_58': 1,
  's_59': 0,
  's_6': 0,
  's_60': 0,
  's_61': 0,
  's_62': 1,
  's_63': 0,
  's_64': 0,
  's_65': 1,
  's_66': 0,
  's_67': 1,
  's_68': 1,
  's_69': 1,
  's_7': 0,
  's_70': 0,
  's_71': 1,
  's_72': 1,
  's_73': 0,
  's_74': 0,
  's_75': 0,
  's_76': 0,
  's_77': 1,
  's_78': 0,
  's_79': 1,
  's_8': 0,
  's_80': 1,
  's_81': 0,
  's_82': 1,
  's_83': 1,
  's_84': 1,
  's_85': 0,
  's_86': 0,
  's_87': 0,
  's_88': 1,
  's_89': 0,
  's_9': 1,
  's_90': 0,
  's_91': 0,
  's_92': 0,
  's_93': 0,
  's_94': 1,
  's_95': 1,
  's_96': 1,
  's_97': 1,
  's_98': 1,
  's_99': 1,
  'x': 4,
})

[2024-09-11 08:09:52,453][basic_search][INFO][generic_smbo.py:310] Iter 25, objectives: [inf].
[2024-09-11 08:09:52,461][basic_search][WARNING][generic_advisor.py:467] No enough successful initial trials! Sample random configuration.
[2024-09-11 08:09:52,465][basic_search][ERROR][generic_smbo.py:290] Exception in objective function:
Traceback (most recent call last):
  File "/gyc_data/fray_data/py38hwvenv/lib/python3.8/site-packages/openbox/utils/limit.py", line 62, in run_without_time_limit
    ret = obj_func(*obj_args, **obj_kwargs)
  File "/gyc_data/fray_data/project_hw/BO_partition3.py", line 99, in obj_func
    cost = self.black_box.get_cost_from_partitions(partitions, scan_method)
  File "/gyc_data/fray_data/project_hw/BO_partition3.py", line 60, in get_cost_from_partitions
    scan_method_cpp[i] = scan_method[i]
IndexError: list index out of range

config: Configuration(values={
  's_0': 1,
  's_1': 0,
  's_10': 0,
  's_100': 1,
  's_101': 1,
  's_102': 0,
  's_103': 0,
  's_104': 0,
  's_105': 0,
  's_106': 1,
  's_107': 0,
  's_108': 1,
  's_109': 0,
  's_11': 1,
  's_110': 0,
  's_111': 1,
  's_112': 1,
  's_113': 1,
  's_114': 1,
  's_115': 0,
  's_116': 0,
  's_117': 0,
  's_118': 0,
  's_119': 0,
  's_12': 0,
  's_120': 1,
  's_121': 1,
  's_122': 1,
  's_123': 1,
  's_124': 0,
  's_125': 0,
  's_126': 1,
  's_127': 1,
  's_128': 0,
  's_129': 0,
  's_13': 0,
  's_130': 1,
  's_131': 1,
  's_132': 1,
  's_133': 1,
  's_134': 1,
  's_135': 0,
  's_136': 0,
  's_137': 1,
  's_138': 0,
  's_139': 0,
  's_14': 0,
  's_140': 1,
  's_141': 0,
  's_142': 0,
  's_143': 0,
  's_144': 1,
  's_145': 1,
  's_146': 0,
  's_15': 1,
  's_16': 0,
  's_17': 1,
  's_18': 1,
  's_19': 0,
  's_2': 0,
  's_20': 1,
  's_21': 0,
  's_22': 1,
  's_23': 1,
  's_24': 1,
  's_25': 0,
  's_26': 0,
  's_27': 1,
  's_28': 0,
  's_29': 0,
  's_3': 0,
  's_30': 1,
  's_31': 1,
  's_32': 1,
  's_33': 0,
  's_34': 0,
  's_35': 0,
  's_36': 1,
  's_37': 0,
  's_38': 1,
  's_39': 1,
  's_4': 1,
  's_40': 1,
  's_41': 1,
  's_42': 1,
  's_43': 1,
  's_44': 0,
  's_45': 1,
  's_46': 1,
  's_47': 0,
  's_48': 0,
  's_49': 1,
  's_5': 0,
  's_50': 1,
  's_51': 1,
  's_52': 1,
  's_53': 0,
  's_54': 0,
  's_55': 1,
  's_56': 0,
  's_57': 0,
  's_58': 1,
  's_59': 1,
  's_6': 0,
  's_60': 0,
  's_61': 1,
  's_62': 1,
  's_63': 0,
  's_64': 1,
  's_65': 0,
  's_66': 1,
  's_67': 1,
  's_68': 0,
  's_69': 1,
  's_7': 0,
  's_70': 0,
  's_71': 0,
  's_72': 1,
  's_73': 1,
  's_74': 0,
  's_75': 0,
  's_76': 1,
  's_77': 0,
  's_78': 1,
  's_79': 1,
  's_8': 0,
  's_80': 1,
  's_81': 0,
  's_82': 1,
  's_83': 0,
  's_84': 0,
  's_85': 0,
  's_86': 1,
  's_87': 0,
  's_88': 1,
  's_89': 0,
  's_9': 0,
  's_90': 0,
  's_91': 1,
  's_92': 0,
  's_93': 1,
  's_94': 0,
  's_95': 1,
  's_96': 1,
  's_97': 0,
  's_98': 1,
  's_99': 0,
  'x': 25,
})

[2024-09-11 08:09:52,465][basic_search][INFO][generic_smbo.py:310] Iter 26, objectives: [inf].
[2024-09-11 08:09:52,473][basic_search][WARNING][generic_advisor.py:467] No enough successful initial trials! Sample random configuration.
[2024-09-11 08:09:52,477][basic_search][ERROR][generic_smbo.py:290] Exception in objective function:
Traceback (most recent call last):
  File "/gyc_data/fray_data/py38hwvenv/lib/python3.8/site-packages/openbox/utils/limit.py", line 62, in run_without_time_limit
    ret = obj_func(*obj_args, **obj_kwargs)
  File "/gyc_data/fray_data/project_hw/BO_partition3.py", line 99, in obj_func
    cost = self.black_box.get_cost_from_partitions(partitions, scan_method)
  File "/gyc_data/fray_data/project_hw/BO_partition3.py", line 60, in get_cost_from_partitions
    scan_method_cpp[i] = scan_method[i]
IndexError: list index out of range

config: Configuration(values={
  's_0': 0,
  's_1': 0,
  's_10': 1,
  's_100': 1,
  's_101': 0,
  's_102': 1,
  's_103': 1,
  's_104': 0,
  's_105': 0,
  's_106': 1,
  's_107': 1,
  's_108': 0,
  's_109': 1,
  's_11': 1,
  's_110': 0,
  's_111': 0,
  's_112': 1,
  's_113': 1,
  's_114': 0,
  's_115': 0,
  's_116': 1,
  's_117': 0,
  's_118': 1,
  's_119': 1,
  's_12': 0,
  's_120': 0,
  's_121': 0,
  's_122': 1,
  's_123': 0,
  's_124': 0,
  's_125': 1,
  's_126': 1,
  's_127': 0,
  's_128': 0,
  's_129': 0,
  's_13': 1,
  's_130': 0,
  's_131': 0,
  's_132': 0,
  's_133': 0,
  's_134': 1,
  's_135': 0,
  's_136': 0,
  's_137': 0,
  's_138': 0,
  's_139': 1,
  's_14': 1,
  's_140': 0,
  's_141': 0,
  's_142': 1,
  's_143': 1,
  's_144': 1,
  's_145': 0,
  's_146': 0,
  's_15': 0,
  's_16': 1,
  's_17': 0,
  's_18': 0,
  's_19': 0,
  's_2': 0,
  's_20': 0,
  's_21': 1,
  's_22': 0,
  's_23': 0,
  's_24': 1,
  's_25': 1,
  's_26': 0,
  's_27': 1,
  's_28': 1,
  's_29': 1,
  's_3': 0,
  's_30': 1,
  's_31': 0,
  's_32': 1,
  's_33': 0,
  's_34': 1,
  's_35': 0,
  's_36': 1,
  's_37': 0,
  's_38': 1,
  's_39': 1,
  's_4': 1,
  's_40': 0,
  's_41': 1,
  's_42': 1,
  's_43': 0,
  's_44': 0,
  's_45': 0,
  's_46': 1,
  's_47': 1,
  's_48': 0,
  's_49': 0,
  's_5': 0,
  's_50': 1,
  's_51': 1,
  's_52': 1,
  's_53': 0,
  's_54': 0,
  's_55': 0,
  's_56': 0,
  's_57': 0,
  's_58': 0,
  's_59': 0,
  's_6': 1,
  's_60': 0,
  's_61': 1,
  's_62': 0,
  's_63': 0,
  's_64': 0,
  's_65': 0,
  's_66': 0,
  's_67': 0,
  's_68': 1,
  's_69': 1,
  's_7': 0,
  's_70': 1,
  's_71': 1,
  's_72': 0,
  's_73': 1,
  's_74': 0,
  's_75': 0,
  's_76': 0,
  's_77': 0,
  's_78': 1,
  's_79': 0,
  's_8': 1,
  's_80': 1,
  's_81': 1,
  's_82': 1,
  's_83': 0,
  's_84': 0,
  's_85': 1,
  's_86': 1,
  's_87': 0,
  's_88': 1,
  's_89': 1,
  's_9': 0,
  's_90': 1,
  's_91': 1,
  's_92': 0,
  's_93': 1,
  's_94': 1,
  's_95': 0,
  's_96': 1,
  's_97': 0,
  's_98': 0,
  's_99': 1,
  'x': 152,
})

[2024-09-11 08:09:52,477][basic_search][INFO][generic_smbo.py:310] Iter 27, objectives: [inf].
[2024-09-11 08:09:52,485][basic_search][WARNING][generic_advisor.py:467] No enough successful initial trials! Sample random configuration.
[2024-09-11 08:09:52,489][basic_search][ERROR][generic_smbo.py:290] Exception in objective function:
Traceback (most recent call last):
  File "/gyc_data/fray_data/py38hwvenv/lib/python3.8/site-packages/openbox/utils/limit.py", line 62, in run_without_time_limit
    ret = obj_func(*obj_args, **obj_kwargs)
  File "/gyc_data/fray_data/project_hw/BO_partition3.py", line 99, in obj_func
    cost = self.black_box.get_cost_from_partitions(partitions, scan_method)
  File "/gyc_data/fray_data/project_hw/BO_partition3.py", line 60, in get_cost_from_partitions
    scan_method_cpp[i] = scan_method[i]
IndexError: list index out of range

config: Configuration(values={
  's_0': 1,
  's_1': 1,
  's_10': 1,
  's_100': 1,
  's_101': 0,
  's_102': 0,
  's_103': 1,
  's_104': 1,
  's_105': 1,
  's_106': 0,
  's_107': 0,
  's_108': 1,
  's_109': 0,
  's_11': 0,
  's_110': 1,
  's_111': 1,
  's_112': 0,
  's_113': 1,
  's_114': 0,
  's_115': 1,
  's_116': 1,
  's_117': 1,
  's_118': 0,
  's_119': 1,
  's_12': 0,
  's_120': 0,
  's_121': 0,
  's_122': 0,
  's_123': 0,
  's_124': 1,
  's_125': 1,
  's_126': 0,
  's_127': 0,
  's_128': 0,
  's_129': 0,
  's_13': 1,
  's_130': 0,
  's_131': 0,
  's_132': 0,
  's_133': 0,
  's_134': 1,
  's_135': 0,
  's_136': 0,
  's_137': 0,
  's_138': 1,
  's_139': 1,
  's_14': 1,
  's_140': 1,
  's_141': 1,
  's_142': 1,
  's_143': 1,
  's_144': 0,
  's_145': 0,
  's_146': 0,
  's_15': 0,
  's_16': 1,
  's_17': 1,
  's_18': 1,
  's_19': 0,
  's_2': 1,
  's_20': 1,
  's_21': 0,
  's_22': 0,
  's_23': 1,
  's_24': 1,
  's_25': 1,
  's_26': 0,
  's_27': 1,
  's_28': 1,
  's_29': 0,
  's_3': 1,
  's_30': 0,
  's_31': 1,
  's_32': 0,
  's_33': 0,
  's_34': 0,
  's_35': 1,
  's_36': 0,
  's_37': 1,
  's_38': 1,
  's_39': 0,
  's_4': 0,
  's_40': 0,
  's_41': 1,
  's_42': 1,
  's_43': 0,
  's_44': 0,
  's_45': 0,
  's_46': 1,
  's_47': 0,
  's_48': 0,
  's_49': 0,
  's_5': 0,
  's_50': 0,
  's_51': 0,
  's_52': 1,
  's_53': 0,
  's_54': 1,
  's_55': 0,
  's_56': 1,
  's_57': 1,
  's_58': 1,
  's_59': 0,
  's_6': 1,
  's_60': 0,
  's_61': 0,
  's_62': 0,
  's_63': 0,
  's_64': 1,
  's_65': 0,
  's_66': 1,
  's_67': 1,
  's_68': 0,
  's_69': 0,
  's_7': 0,
  's_70': 1,
  's_71': 1,
  's_72': 1,
  's_73': 1,
  's_74': 1,
  's_75': 0,
  's_76': 0,
  's_77': 0,
  's_78': 0,
  's_79': 0,
  's_8': 0,
  's_80': 1,
  's_81': 1,
  's_82': 0,
  's_83': 1,
  's_84': 0,
  's_85': 1,
  's_86': 1,
  's_87': 0,
  's_88': 1,
  's_89': 0,
  's_9': 0,
  's_90': 1,
  's_91': 0,
  's_92': 1,
  's_93': 0,
  's_94': 0,
  's_95': 1,
  's_96': 1,
  's_97': 1,
  's_98': 0,
  's_99': 0,
  'x': 154,
})

[2024-09-11 08:09:52,489][basic_search][INFO][generic_smbo.py:310] Iter 28, objectives: [inf].
[2024-09-11 08:09:52,498][basic_search][WARNING][generic_advisor.py:467] No enough successful initial trials! Sample random configuration.
[2024-09-11 08:09:52,502][basic_search][ERROR][generic_smbo.py:290] Exception in objective function:
Traceback (most recent call last):
  File "/gyc_data/fray_data/py38hwvenv/lib/python3.8/site-packages/openbox/utils/limit.py", line 62, in run_without_time_limit
    ret = obj_func(*obj_args, **obj_kwargs)
  File "/gyc_data/fray_data/project_hw/BO_partition3.py", line 99, in obj_func
    cost = self.black_box.get_cost_from_partitions(partitions, scan_method)
  File "/gyc_data/fray_data/project_hw/BO_partition3.py", line 60, in get_cost_from_partitions
    scan_method_cpp[i] = scan_method[i]
IndexError: list index out of range

config: Configuration(values={
  's_0': 0,
  's_1': 0,
  's_10': 1,
  's_100': 0,
  's_101': 0,
  's_102': 0,
  's_103': 0,
  's_104': 0,
  's_105': 0,
  's_106': 1,
  's_107': 1,
  's_108': 1,
  's_109': 0,
  's_11': 1,
  's_110': 1,
  's_111': 1,
  's_112': 1,
  's_113': 0,
  's_114': 0,
  's_115': 0,
  's_116': 0,
  's_117': 0,
  's_118': 1,
  's_119': 0,
  's_12': 1,
  's_120': 1,
  's_121': 1,
  's_122': 1,
  's_123': 0,
  's_124': 0,
  's_125': 0,
  's_126': 1,
  's_127': 0,
  's_128': 0,
  's_129': 1,
  's_13': 0,
  's_130': 0,
  's_131': 0,
  's_132': 1,
  's_133': 1,
  's_134': 0,
  's_135': 0,
  's_136': 1,
  's_137': 0,
  's_138': 0,
  's_139': 1,
  's_14': 0,
  's_140': 0,
  's_141': 1,
  's_142': 0,
  's_143': 1,
  's_144': 1,
  's_145': 1,
  's_146': 1,
  's_15': 0,
  's_16': 1,
  's_17': 1,
  's_18': 1,
  's_19': 0,
  's_2': 1,
  's_20': 0,
  's_21': 1,
  's_22': 0,
  's_23': 0,
  's_24': 1,
  's_25': 1,
  's_26': 1,
  's_27': 1,
  's_28': 1,
  's_29': 0,
  's_3': 0,
  's_30': 1,
  's_31': 1,
  's_32': 0,
  's_33': 0,
  's_34': 0,
  's_35': 0,
  's_36': 0,
  's_37': 1,
  's_38': 0,
  's_39': 0,
  's_4': 0,
  's_40': 1,
  's_41': 1,
  's_42': 1,
  's_43': 0,
  's_44': 1,
  's_45': 0,
  's_46': 0,
  's_47': 0,
  's_48': 0,
  's_49': 0,
  's_5': 0,
  's_50': 1,
  's_51': 1,
  's_52': 1,
  's_53': 1,
  's_54': 1,
  's_55': 0,
  's_56': 0,
  's_57': 0,
  's_58': 0,
  's_59': 0,
  's_6': 1,
  's_60': 0,
  's_61': 1,
  's_62': 0,
  's_63': 0,
  's_64': 1,
  's_65': 1,
  's_66': 0,
  's_67': 1,
  's_68': 1,
  's_69': 1,
  's_7': 1,
  's_70': 0,
  's_71': 0,
  's_72': 0,
  's_73': 1,
  's_74': 0,
  's_75': 1,
  's_76': 0,
  's_77': 1,
  's_78': 0,
  's_79': 1,
  's_8': 0,
  's_80': 1,
  's_81': 1,
  's_82': 0,
  's_83': 1,
  's_84': 1,
  's_85': 1,
  's_86': 0,
  's_87': 0,
  's_88': 0,
  's_89': 0,
  's_9': 0,
  's_90': 0,
  's_91': 1,
  's_92': 1,
  's_93': 1,
  's_94': 1,
  's_95': 0,
  's_96': 1,
  's_97': 1,
  's_98': 0,
  's_99': 1,
  'x': 204,
})

[2024-09-11 08:09:52,502][basic_search][INFO][generic_smbo.py:310] Iter 29, objectives: [inf].
[2024-09-11 08:09:52,511][basic_search][WARNING][generic_advisor.py:467] No enough successful initial trials! Sample random configuration.
[2024-09-11 08:09:52,514][basic_search][ERROR][generic_smbo.py:290] Exception in objective function:
Traceback (most recent call last):
  File "/gyc_data/fray_data/py38hwvenv/lib/python3.8/site-packages/openbox/utils/limit.py", line 62, in run_without_time_limit
    ret = obj_func(*obj_args, **obj_kwargs)
  File "/gyc_data/fray_data/project_hw/BO_partition3.py", line 99, in obj_func
    cost = self.black_box.get_cost_from_partitions(partitions, scan_method)
  File "/gyc_data/fray_data/project_hw/BO_partition3.py", line 60, in get_cost_from_partitions
    scan_method_cpp[i] = scan_method[i]
IndexError: list index out of range

config: Configuration(values={
  's_0': 0,
  's_1': 1,
  's_10': 0,
  's_100': 0,
  's_101': 0,
  's_102': 1,
  's_103': 0,
  's_104': 1,
  's_105': 1,
  's_106': 0,
  's_107': 0,
  's_108': 0,
  's_109': 0,
  's_11': 0,
  's_110': 1,
  's_111': 1,
  's_112': 1,
  's_113': 0,
  's_114': 1,
  's_115': 1,
  's_116': 1,
  's_117': 0,
  's_118': 1,
  's_119': 0,
  's_12': 0,
  's_120': 1,
  's_121': 0,
  's_122': 1,
  's_123': 0,
  's_124': 1,
  's_125': 0,
  's_126': 0,
  's_127': 1,
  's_128': 0,
  's_129': 0,
  's_13': 0,
  's_130': 0,
  's_131': 1,
  's_132': 1,
  's_133': 0,
  's_134': 0,
  's_135': 1,
  's_136': 1,
  's_137': 0,
  's_138': 1,
  's_139': 0,
  's_14': 0,
  's_140': 0,
  's_141': 0,
  's_142': 0,
  's_143': 0,
  's_144': 1,
  's_145': 0,
  's_146': 1,
  's_15': 0,
  's_16': 0,
  's_17': 0,
  's_18': 0,
  's_19': 0,
  's_2': 0,
  's_20': 0,
  's_21': 1,
  's_22': 0,
  's_23': 1,
  's_24': 1,
  's_25': 0,
  's_26': 1,
  's_27': 1,
  's_28': 0,
  's_29': 1,
  's_3': 0,
  's_30': 1,
  's_31': 0,
  's_32': 0,
  's_33': 1,
  's_34': 1,
  's_35': 1,
  's_36': 1,
  's_37': 1,
  's_38': 0,
  's_39': 0,
  's_4': 1,
  's_40': 0,
  's_41': 0,
  's_42': 1,
  's_43': 0,
  's_44': 0,
  's_45': 1,
  's_46': 0,
  's_47': 1,
  's_48': 1,
  's_49': 0,
  's_5': 0,
  's_50': 1,
  's_51': 0,
  's_52': 0,
  's_53': 0,
  's_54': 0,
  's_55': 1,
  's_56': 1,
  's_57': 1,
  's_58': 0,
  's_59': 1,
  's_6': 1,
  's_60': 0,
  's_61': 0,
  's_62': 1,
  's_63': 1,
  's_64': 0,
  's_65': 0,
  's_66': 0,
  's_67': 1,
  's_68': 0,
  's_69': 1,
  's_7': 0,
  's_70': 0,
  's_71': 1,
  's_72': 1,
  's_73': 0,
  's_74': 0,
  's_75': 0,
  's_76': 1,
  's_77': 0,
  's_78': 0,
  's_79': 1,
  's_8': 0,
  's_80': 1,
  's_81': 1,
  's_82': 1,
  's_83': 0,
  's_84': 1,
  's_85': 0,
  's_86': 1,
  's_87': 0,
  's_88': 1,
  's_89': 1,
  's_9': 1,
  's_90': 0,
  's_91': 1,
  's_92': 0,
  's_93': 1,
  's_94': 0,
  's_95': 0,
  's_96': 1,
  's_97': 1,
  's_98': 1,
  's_99': 0,
  'x': 137,
})

[2024-09-11 08:09:52,515][basic_search][INFO][generic_smbo.py:310] Iter 30, objectives: [inf].
[2024-09-11 08:09:52,524][basic_search][WARNING][generic_advisor.py:467] No enough successful initial trials! Sample random configuration.
[2024-09-11 08:09:52,529][basic_search][ERROR][generic_smbo.py:290] Exception in objective function:
Traceback (most recent call last):
  File "/gyc_data/fray_data/py38hwvenv/lib/python3.8/site-packages/openbox/utils/limit.py", line 62, in run_without_time_limit
    ret = obj_func(*obj_args, **obj_kwargs)
  File "/gyc_data/fray_data/project_hw/BO_partition3.py", line 99, in obj_func
    cost = self.black_box.get_cost_from_partitions(partitions, scan_method)
  File "/gyc_data/fray_data/project_hw/BO_partition3.py", line 60, in get_cost_from_partitions
    scan_method_cpp[i] = scan_method[i]
IndexError: list index out of range

config: Configuration(values={
  's_0': 1,
  's_1': 0,
  's_10': 1,
  's_100': 1,
  's_101': 0,
  's_102': 0,
  's_103': 1,
  's_104': 1,
  's_105': 1,
  's_106': 1,
  's_107': 0,
  's_108': 0,
  's_109': 0,
  's_11': 1,
  's_110': 0,
  's_111': 1,
  's_112': 1,
  's_113': 0,
  's_114': 0,
  's_115': 1,
  's_116': 1,
  's_117': 0,
  's_118': 0,
  's_119': 0,
  's_12': 1,
  's_120': 1,
  's_121': 1,
  's_122': 0,
  's_123': 0,
  's_124': 0,
  's_125': 1,
  's_126': 1,
  's_127': 0,
  's_128': 0,
  's_129': 0,
  's_13': 1,
  's_130': 0,
  's_131': 0,
  's_132': 1,
  's_133': 1,
  's_134': 0,
  's_135': 0,
  's_136': 0,
  's_137': 1,
  's_138': 0,
  's_139': 1,
  's_14': 1,
  's_140': 0,
  's_141': 0,
  's_142': 0,
  's_143': 1,
  's_144': 0,
  's_145': 0,
  's_146': 0,
  's_15': 0,
  's_16': 0,
  's_17': 1,
  's_18': 0,
  's_19': 0,
  's_2': 1,
  's_20': 1,
  's_21': 0,
  's_22': 1,
  's_23': 1,
  's_24': 0,
  's_25': 1,
  's_26': 0,
  's_27': 0,
  's_28': 1,
  's_29': 0,
  's_3': 0,
  's_30': 0,
  's_31': 1,
  's_32': 0,
  's_33': 0,
  's_34': 1,
  's_35': 1,
  's_36': 1,
  's_37': 0,
  's_38': 1,
  's_39': 0,
  's_4': 1,
  's_40': 0,
  's_41': 1,
  's_42': 1,
  's_43': 1,
  's_44': 0,
  's_45': 1,
  's_46': 0,
  's_47': 0,
  's_48': 0,
  's_49': 0,
  's_5': 1,
  's_50': 1,
  's_51': 0,
  's_52': 1,
  's_53': 0,
  's_54': 1,
  's_55': 1,
  's_56': 1,
  's_57': 1,
  's_58': 0,
  's_59': 0,
  's_6': 1,
  's_60': 1,
  's_61': 1,
  's_62': 0,
  's_63': 0,
  's_64': 0,
  's_65': 0,
  's_66': 0,
  's_67': 0,
  's_68': 0,
  's_69': 0,
  's_7': 1,
  's_70': 0,
  's_71': 0,
  's_72': 0,
  's_73': 0,
  's_74': 1,
  's_75': 0,
  's_76': 0,
  's_77': 0,
  's_78': 1,
  's_79': 0,
  's_8': 0,
  's_80': 1,
  's_81': 0,
  's_82': 0,
  's_83': 1,
  's_84': 0,
  's_85': 1,
  's_86': 0,
  's_87': 1,
  's_88': 0,
  's_89': 0,
  's_9': 1,
  's_90': 0,
  's_91': 1,
  's_92': 0,
  's_93': 1,
  's_94': 0,
  's_95': 0,
  's_96': 1,
  's_97': 1,
  's_98': 0,
  's_99': 0,
  'x': 3,
})

[2024-09-11 08:09:52,529][basic_search][INFO][generic_smbo.py:310] Iter 31, objectives: [inf].
[2024-09-11 08:09:52,539][basic_search][WARNING][generic_advisor.py:467] No enough successful initial trials! Sample random configuration.
[2024-09-11 08:09:52,542][basic_search][ERROR][generic_smbo.py:290] Exception in objective function:
Traceback (most recent call last):
  File "/gyc_data/fray_data/py38hwvenv/lib/python3.8/site-packages/openbox/utils/limit.py", line 62, in run_without_time_limit
    ret = obj_func(*obj_args, **obj_kwargs)
  File "/gyc_data/fray_data/project_hw/BO_partition3.py", line 99, in obj_func
    cost = self.black_box.get_cost_from_partitions(partitions, scan_method)
  File "/gyc_data/fray_data/project_hw/BO_partition3.py", line 60, in get_cost_from_partitions
    scan_method_cpp[i] = scan_method[i]
IndexError: list index out of range

config: Configuration(values={
  's_0': 0,
  's_1': 0,
  's_10': 1,
  's_100': 0,
  's_101': 1,
  's_102': 1,
  's_103': 0,
  's_104': 1,
  's_105': 1,
  's_106': 0,
  's_107': 0,
  's_108': 0,
  's_109': 1,
  's_11': 0,
  's_110': 1,
  's_111': 0,
  's_112': 0,
  's_113': 0,
  's_114': 1,
  's_115': 0,
  's_116': 1,
  's_117': 0,
  's_118': 1,
  's_119': 1,
  's_12': 1,
  's_120': 1,
  's_121': 1,
  's_122': 0,
  's_123': 0,
  's_124': 0,
  's_125': 0,
  's_126': 0,
  's_127': 1,
  's_128': 0,
  's_129': 0,
  's_13': 0,
  's_130': 0,
  's_131': 1,
  's_132': 0,
  's_133': 1,
  's_134': 1,
  's_135': 0,
  's_136': 1,
  's_137': 1,
  's_138': 1,
  's_139': 1,
  's_14': 1,
  's_140': 1,
  's_141': 1,
  's_142': 0,
  's_143': 1,
  's_144': 1,
  's_145': 1,
  's_146': 0,
  's_15': 0,
  's_16': 0,
  's_17': 1,
  's_18': 1,
  's_19': 1,
  's_2': 0,
  's_20': 0,
  's_21': 0,
  's_22': 1,
  's_23': 0,
  's_24': 1,
  's_25': 0,
  's_26': 1,
  's_27': 1,
  's_28': 0,
  's_29': 1,
  's_3': 1,
  's_30': 0,
  's_31': 0,
  's_32': 1,
  's_33': 1,
  's_34': 0,
  's_35': 0,
  's_36': 1,
  's_37': 1,
  's_38': 1,
  's_39': 0,
  's_4': 0,
  's_40': 1,
  's_41': 0,
  's_42': 1,
  's_43': 0,
  's_44': 0,
  's_45': 1,
  's_46': 1,
  's_47': 1,
  's_48': 0,
  's_49': 0,
  's_5': 1,
  's_50': 1,
  's_51': 1,
  's_52': 0,
  's_53': 1,
  's_54': 1,
  's_55': 1,
  's_56': 0,
  's_57': 1,
  's_58': 0,
  's_59': 0,
  's_6': 1,
  's_60': 1,
  's_61': 0,
  's_62': 0,
  's_63': 0,
  's_64': 1,
  's_65': 0,
  's_66': 1,
  's_67': 1,
  's_68': 0,
  's_69': 0,
  's_7': 0,
  's_70': 1,
  's_71': 0,
  's_72': 0,
  's_73': 1,
  's_74': 1,
  's_75': 0,
  's_76': 0,
  's_77': 0,
  's_78': 1,
  's_79': 1,
  's_8': 1,
  's_80': 0,
  's_81': 0,
  's_82': 1,
  's_83': 0,
  's_84': 1,
  's_85': 0,
  's_86': 0,
  's_87': 1,
  's_88': 0,
  's_89': 0,
  's_9': 1,
  's_90': 1,
  's_91': 1,
  's_92': 0,
  's_93': 1,
  's_94': 0,
  's_95': 1,
  's_96': 1,
  's_97': 1,
  's_98': 0,
  's_99': 0,
  'x': 253,
})

[2024-09-11 08:09:52,543][basic_search][INFO][generic_smbo.py:310] Iter 32, objectives: [inf].
[2024-09-11 08:09:52,552][basic_search][WARNING][generic_advisor.py:467] No enough successful initial trials! Sample random configuration.
[2024-09-11 08:09:52,556][basic_search][ERROR][generic_smbo.py:290] Exception in objective function:
Traceback (most recent call last):
  File "/gyc_data/fray_data/py38hwvenv/lib/python3.8/site-packages/openbox/utils/limit.py", line 62, in run_without_time_limit
    ret = obj_func(*obj_args, **obj_kwargs)
  File "/gyc_data/fray_data/project_hw/BO_partition3.py", line 99, in obj_func
    cost = self.black_box.get_cost_from_partitions(partitions, scan_method)
  File "/gyc_data/fray_data/project_hw/BO_partition3.py", line 60, in get_cost_from_partitions
    scan_method_cpp[i] = scan_method[i]
IndexError: list index out of range

config: Configuration(values={
  's_0': 0,
  's_1': 1,
  's_10': 1,
  's_100': 0,
  's_101': 0,
  's_102': 1,
  's_103': 1,
  's_104': 0,
  's_105': 0,
  's_106': 0,
  's_107': 1,
  's_108': 0,
  's_109': 0,
  's_11': 0,
  's_110': 1,
  's_111': 1,
  's_112': 1,
  's_113': 1,
  's_114': 0,
  's_115': 1,
  's_116': 1,
  's_117': 0,
  's_118': 0,
  's_119': 1,
  's_12': 0,
  's_120': 0,
  's_121': 1,
  's_122': 1,
  's_123': 0,
  's_124': 1,
  's_125': 1,
  's_126': 0,
  's_127': 0,
  's_128': 1,
  's_129': 0,
  's_13': 0,
  's_130': 1,
  's_131': 1,
  's_132': 0,
  's_133': 0,
  's_134': 0,
  's_135': 0,
  's_136': 1,
  's_137': 1,
  's_138': 0,
  's_139': 1,
  's_14': 1,
  's_140': 0,
  's_141': 0,
  's_142': 1,
  's_143': 1,
  's_144': 1,
  's_145': 1,
  's_146': 1,
  's_15': 1,
  's_16': 0,
  's_17': 0,
  's_18': 0,
  's_19': 1,
  's_2': 1,
  's_20': 1,
  's_21': 1,
  's_22': 1,
  's_23': 1,
  's_24': 0,
  's_25': 1,
  's_26': 0,
  's_27': 0,
  's_28': 1,
  's_29': 1,
  's_3': 1,
  's_30': 0,
  's_31': 0,
  's_32': 1,
  's_33': 0,
  's_34': 1,
  's_35': 1,
  's_36': 0,
  's_37': 1,
  's_38': 0,
  's_39': 1,
  's_4': 0,
  's_40': 1,
  's_41': 1,
  's_42': 0,
  's_43': 1,
  's_44': 1,
  's_45': 1,
  's_46': 1,
  's_47': 1,
  's_48': 0,
  's_49': 1,
  's_5': 1,
  's_50': 1,
  's_51': 1,
  's_52': 0,
  's_53': 0,
  's_54': 0,
  's_55': 1,
  's_56': 0,
  's_57': 0,
  's_58': 0,
  's_59': 0,
  's_6': 0,
  's_60': 1,
  's_61': 1,
  's_62': 0,
  's_63': 0,
  's_64': 0,
  's_65': 1,
  's_66': 0,
  's_67': 0,
  's_68': 1,
  's_69': 1,
  's_7': 1,
  's_70': 1,
  's_71': 0,
  's_72': 0,
  's_73': 1,
  's_74': 1,
  's_75': 1,
  's_76': 1,
  's_77': 1,
  's_78': 1,
  's_79': 1,
  's_8': 0,
  's_80': 1,
  's_81': 0,
  's_82': 1,
  's_83': 1,
  's_84': 0,
  's_85': 0,
  's_86': 1,
  's_87': 0,
  's_88': 0,
  's_89': 1,
  's_9': 1,
  's_90': 1,
  's_91': 1,
  's_92': 0,
  's_93': 0,
  's_94': 0,
  's_95': 1,
  's_96': 1,
  's_97': 0,
  's_98': 0,
  's_99': 0,
  'x': 213,
})

[2024-09-11 08:09:52,556][basic_search][INFO][generic_smbo.py:310] Iter 33, objectives: [inf].
[2024-09-11 08:09:52,566][basic_search][WARNING][generic_advisor.py:467] No enough successful initial trials! Sample random configuration.
[2024-09-11 08:09:52,570][basic_search][ERROR][generic_smbo.py:290] Exception in objective function:
Traceback (most recent call last):
  File "/gyc_data/fray_data/py38hwvenv/lib/python3.8/site-packages/openbox/utils/limit.py", line 62, in run_without_time_limit
    ret = obj_func(*obj_args, **obj_kwargs)
  File "/gyc_data/fray_data/project_hw/BO_partition3.py", line 99, in obj_func
    cost = self.black_box.get_cost_from_partitions(partitions, scan_method)
  File "/gyc_data/fray_data/project_hw/BO_partition3.py", line 60, in get_cost_from_partitions
    scan_method_cpp[i] = scan_method[i]
IndexError: list index out of range

config: Configuration(values={
  's_0': 0,
  's_1': 1,
  's_10': 1,
  's_100': 0,
  's_101': 1,
  's_102': 0,
  's_103': 0,
  's_104': 1,
  's_105': 0,
  's_106': 0,
  's_107': 1,
  's_108': 1,
  's_109': 0,
  's_11': 0,
  's_110': 1,
  's_111': 1,
  's_112': 1,
  's_113': 1,
  's_114': 0,
  's_115': 1,
  's_116': 1,
  's_117': 1,
  's_118': 0,
  's_119': 0,
  's_12': 1,
  's_120': 1,
  's_121': 0,
  's_122': 1,
  's_123': 0,
  's_124': 1,
  's_125': 1,
  's_126': 1,
  's_127': 0,
  's_128': 1,
  's_129': 0,
  's_13': 0,
  's_130': 1,
  's_131': 1,
  's_132': 0,
  's_133': 0,
  's_134': 1,
  's_135': 1,
  's_136': 0,
  's_137': 1,
  's_138': 1,
  's_139': 0,
  's_14': 1,
  's_140': 0,
  's_141': 1,
  's_142': 0,
  's_143': 0,
  's_144': 0,
  's_145': 1,
  's_146': 1,
  's_15': 1,
  's_16': 0,
  's_17': 0,
  's_18': 1,
  's_19': 0,
  's_2': 0,
  's_20': 0,
  's_21': 0,
  's_22': 1,
  's_23': 1,
  's_24': 0,
  's_25': 0,
  's_26': 0,
  's_27': 1,
  's_28': 1,
  's_29': 0,
  's_3': 0,
  's_30': 1,
  's_31': 1,
  's_32': 1,
  's_33': 1,
  's_34': 1,
  's_35': 1,
  's_36': 0,
  's_37': 0,
  's_38': 0,
  's_39': 1,
  's_4': 0,
  's_40': 1,
  's_41': 0,
  's_42': 0,
  's_43': 1,
  's_44': 0,
  's_45': 0,
  's_46': 1,
  's_47': 0,
  's_48': 0,
  's_49': 1,
  's_5': 1,
  's_50': 0,
  's_51': 1,
  's_52': 0,
  's_53': 1,
  's_54': 0,
  's_55': 1,
  's_56': 1,
  's_57': 0,
  's_58': 1,
  's_59': 0,
  's_6': 0,
  's_60': 0,
  's_61': 1,
  's_62': 0,
  's_63': 0,
  's_64': 0,
  's_65': 0,
  's_66': 1,
  's_67': 1,
  's_68': 1,
  's_69': 0,
  's_7': 1,
  's_70': 0,
  's_71': 1,
  's_72': 1,
  's_73': 1,
  's_74': 0,
  's_75': 1,
  's_76': 1,
  's_77': 1,
  's_78': 0,
  's_79': 0,
  's_8': 0,
  's_80': 1,
  's_81': 0,
  's_82': 0,
  's_83': 1,
  's_84': 0,
  's_85': 1,
  's_86': 1,
  's_87': 0,
  's_88': 1,
  's_89': 1,
  's_9': 1,
  's_90': 1,
  's_91': 1,
  's_92': 0,
  's_93': 0,
  's_94': 0,
  's_95': 0,
  's_96': 0,
  's_97': 1,
  's_98': 1,
  's_99': 1,
  'x': 102,
})

[2024-09-11 08:09:52,570][basic_search][INFO][generic_smbo.py:310] Iter 34, objectives: [inf].
[2024-09-11 08:09:52,580][basic_search][WARNING][generic_advisor.py:467] No enough successful initial trials! Sample random configuration.
[2024-09-11 08:09:52,584][basic_search][ERROR][generic_smbo.py:290] Exception in objective function:
Traceback (most recent call last):
  File "/gyc_data/fray_data/py38hwvenv/lib/python3.8/site-packages/openbox/utils/limit.py", line 62, in run_without_time_limit
    ret = obj_func(*obj_args, **obj_kwargs)
  File "/gyc_data/fray_data/project_hw/BO_partition3.py", line 99, in obj_func
    cost = self.black_box.get_cost_from_partitions(partitions, scan_method)
  File "/gyc_data/fray_data/project_hw/BO_partition3.py", line 60, in get_cost_from_partitions
    scan_method_cpp[i] = scan_method[i]
IndexError: list index out of range

config: Configuration(values={
  's_0': 1,
  's_1': 1,
  's_10': 0,
  's_100': 1,
  's_101': 0,
  's_102': 0,
  's_103': 0,
  's_104': 1,
  's_105': 0,
  's_106': 0,
  's_107': 1,
  's_108': 1,
  's_109': 0,
  's_11': 1,
  's_110': 0,
  's_111': 1,
  's_112': 0,
  's_113': 0,
  's_114': 0,
  's_115': 1,
  's_116': 0,
  's_117': 1,
  's_118': 1,
  's_119': 0,
  's_12': 0,
  's_120': 0,
  's_121': 1,
  's_122': 1,
  's_123': 1,
  's_124': 0,
  's_125': 1,
  's_126': 0,
  's_127': 1,
  's_128': 1,
  's_129': 0,
  's_13': 0,
  's_130': 0,
  's_131': 0,
  's_132': 1,
  's_133': 0,
  's_134': 1,
  's_135': 0,
  's_136': 0,
  's_137': 0,
  's_138': 0,
  's_139': 0,
  's_14': 1,
  's_140': 0,
  's_141': 0,
  's_142': 1,
  's_143': 0,
  's_144': 1,
  's_145': 1,
  's_146': 1,
  's_15': 0,
  's_16': 0,
  's_17': 0,
  's_18': 0,
  's_19': 0,
  's_2': 1,
  's_20': 1,
  's_21': 1,
  's_22': 0,
  's_23': 1,
  's_24': 0,
  's_25': 1,
  's_26': 0,
  's_27': 0,
  's_28': 1,
  's_29': 0,
  's_3': 1,
  's_30': 1,
  's_31': 1,
  's_32': 0,
  's_33': 0,
  's_34': 0,
  's_35': 1,
  's_36': 1,
  's_37': 1,
  's_38': 1,
  's_39': 1,
  's_4': 0,
  's_40': 0,
  's_41': 0,
  's_42': 0,
  's_43': 1,
  's_44': 1,
  's_45': 1,
  's_46': 1,
  's_47': 1,
  's_48': 1,
  's_49': 0,
  's_5': 0,
  's_50': 0,
  's_51': 0,
  's_52': 1,
  's_53': 0,
  's_54': 0,
  's_55': 0,
  's_56': 1,
  's_57': 0,
  's_58': 1,
  's_59': 1,
  's_6': 1,
  's_60': 1,
  's_61': 0,
  's_62': 1,
  's_63': 0,
  's_64': 0,
  's_65': 1,
  's_66': 0,
  's_67': 0,
  's_68': 0,
  's_69': 1,
  's_7': 0,
  's_70': 1,
  's_71': 1,
  's_72': 1,
  's_73': 1,
  's_74': 0,
  's_75': 1,
  's_76': 1,
  's_77': 1,
  's_78': 1,
  's_79': 0,
  's_8': 0,
  's_80': 1,
  's_81': 0,
  's_82': 0,
  's_83': 1,
  's_84': 0,
  's_85': 0,
  's_86': 0,
  's_87': 1,
  's_88': 1,
  's_89': 0,
  's_9': 0,
  's_90': 0,
  's_91': 1,
  's_92': 1,
  's_93': 1,
  's_94': 1,
  's_95': 1,
  's_96': 1,
  's_97': 1,
  's_98': 1,
  's_99': 1,
  'x': 205,
})

[2024-09-11 08:09:52,584][basic_search][INFO][generic_smbo.py:310] Iter 35, objectives: [inf].
[2024-09-11 08:09:52,594][basic_search][WARNING][generic_advisor.py:467] No enough successful initial trials! Sample random configuration.
[2024-09-11 08:09:52,598][basic_search][ERROR][generic_smbo.py:290] Exception in objective function:
Traceback (most recent call last):
  File "/gyc_data/fray_data/py38hwvenv/lib/python3.8/site-packages/openbox/utils/limit.py", line 62, in run_without_time_limit
    ret = obj_func(*obj_args, **obj_kwargs)
  File "/gyc_data/fray_data/project_hw/BO_partition3.py", line 99, in obj_func
    cost = self.black_box.get_cost_from_partitions(partitions, scan_method)
  File "/gyc_data/fray_data/project_hw/BO_partition3.py", line 60, in get_cost_from_partitions
    scan_method_cpp[i] = scan_method[i]
IndexError: list index out of range

config: Configuration(values={
  's_0': 0,
  's_1': 1,
  's_10': 0,
  's_100': 0,
  's_101': 0,
  's_102': 1,
  's_103': 0,
  's_104': 1,
  's_105': 1,
  's_106': 1,
  's_107': 1,
  's_108': 0,
  's_109': 1,
  's_11': 0,
  's_110': 0,
  's_111': 0,
  's_112': 1,
  's_113': 0,
  's_114': 1,
  's_115': 1,
  's_116': 1,
  's_117': 1,
  's_118': 0,
  's_119': 1,
  's_12': 0,
  's_120': 1,
  's_121': 1,
  's_122': 0,
  's_123': 1,
  's_124': 0,
  's_125': 0,
  's_126': 1,
  's_127': 0,
  's_128': 1,
  's_129': 1,
  's_13': 0,
  's_130': 1,
  's_131': 0,
  's_132': 1,
  's_133': 1,
  's_134': 0,
  's_135': 1,
  's_136': 0,
  's_137': 1,
  's_138': 1,
  's_139': 1,
  's_14': 0,
  's_140': 1,
  's_141': 1,
  's_142': 1,
  's_143': 0,
  's_144': 1,
  's_145': 1,
  's_146': 0,
  's_15': 1,
  's_16': 1,
  's_17': 1,
  's_18': 1,
  's_19': 1,
  's_2': 0,
  's_20': 1,
  's_21': 1,
  's_22': 1,
  's_23': 0,
  's_24': 0,
  's_25': 1,
  's_26': 0,
  's_27': 1,
  's_28': 0,
  's_29': 1,
  's_3': 0,
  's_30': 0,
  's_31': 0,
  's_32': 1,
  's_33': 0,
  's_34': 1,
  's_35': 0,
  's_36': 0,
  's_37': 0,
  's_38': 1,
  's_39': 1,
  's_4': 0,
  's_40': 1,
  's_41': 1,
  's_42': 0,
  's_43': 1,
  's_44': 1,
  's_45': 1,
  's_46': 1,
  's_47': 1,
  's_48': 0,
  's_49': 0,
  's_5': 1,
  's_50': 0,
  's_51': 0,
  's_52': 1,
  's_53': 1,
  's_54': 0,
  's_55': 1,
  's_56': 0,
  's_57': 0,
  's_58': 1,
  's_59': 0,
  's_6': 1,
  's_60': 1,
  's_61': 1,
  's_62': 1,
  's_63': 1,
  's_64': 0,
  's_65': 0,
  's_66': 0,
  's_67': 0,
  's_68': 0,
  's_69': 0,
  's_7': 1,
  's_70': 1,
  's_71': 0,
  's_72': 0,
  's_73': 0,
  's_74': 0,
  's_75': 0,
  's_76': 0,
  's_77': 0,
  's_78': 0,
  's_79': 1,
  's_8': 1,
  's_80': 0,
  's_81': 0,
  's_82': 0,
  's_83': 0,
  's_84': 1,
  's_85': 0,
  's_86': 0,
  's_87': 0,
  's_88': 0,
  's_89': 1,
  's_9': 1,
  's_90': 1,
  's_91': 0,
  's_92': 0,
  's_93': 1,
  's_94': 1,
  's_95': 1,
  's_96': 0,
  's_97': 0,
  's_98': 1,
  's_99': 0,
  'x': 134,
})

[2024-09-11 08:09:52,598][basic_search][INFO][generic_smbo.py:310] Iter 36, objectives: [inf].
[2024-09-11 08:09:52,609][basic_search][WARNING][generic_advisor.py:467] No enough successful initial trials! Sample random configuration.
[2024-09-11 08:09:52,613][basic_search][ERROR][generic_smbo.py:290] Exception in objective function:
Traceback (most recent call last):
  File "/gyc_data/fray_data/py38hwvenv/lib/python3.8/site-packages/openbox/utils/limit.py", line 62, in run_without_time_limit
    ret = obj_func(*obj_args, **obj_kwargs)
  File "/gyc_data/fray_data/project_hw/BO_partition3.py", line 99, in obj_func
    cost = self.black_box.get_cost_from_partitions(partitions, scan_method)
  File "/gyc_data/fray_data/project_hw/BO_partition3.py", line 60, in get_cost_from_partitions
    scan_method_cpp[i] = scan_method[i]
IndexError: list index out of range

config: Configuration(values={
  's_0': 0,
  's_1': 1,
  's_10': 1,
  's_100': 0,
  's_101': 1,
  's_102': 1,
  's_103': 1,
  's_104': 1,
  's_105': 1,
  's_106': 0,
  's_107': 0,
  's_108': 0,
  's_109': 1,
  's_11': 0,
  's_110': 0,
  's_111': 1,
  's_112': 0,
  's_113': 1,
  's_114': 0,
  's_115': 1,
  's_116': 0,
  's_117': 0,
  's_118': 0,
  's_119': 1,
  's_12': 1,
  's_120': 1,
  's_121': 1,
  's_122': 0,
  's_123': 0,
  's_124': 1,
  's_125': 1,
  's_126': 1,
  's_127': 1,
  's_128': 1,
  's_129': 0,
  's_13': 0,
  's_130': 1,
  's_131': 1,
  's_132': 0,
  's_133': 1,
  's_134': 1,
  's_135': 0,
  's_136': 1,
  's_137': 0,
  's_138': 0,
  's_139': 0,
  's_14': 1,
  's_140': 0,
  's_141': 1,
  's_142': 1,
  's_143': 0,
  's_144': 1,
  's_145': 0,
  's_146': 1,
  's_15': 0,
  's_16': 0,
  's_17': 1,
  's_18': 0,
  's_19': 0,
  's_2': 0,
  's_20': 1,
  's_21': 0,
  's_22': 0,
  's_23': 0,
  's_24': 0,
  's_25': 1,
  's_26': 0,
  's_27': 0,
  's_28': 0,
  's_29': 0,
  's_3': 0,
  's_30': 0,
  's_31': 0,
  's_32': 0,
  's_33': 0,
  's_34': 0,
  's_35': 1,
  's_36': 1,
  's_37': 0,
  's_38': 1,
  's_39': 0,
  's_4': 0,
  's_40': 0,
  's_41': 0,
  's_42': 0,
  's_43': 0,
  's_44': 1,
  's_45': 0,
  's_46': 1,
  's_47': 0,
  's_48': 0,
  's_49': 1,
  's_5': 0,
  's_50': 1,
  's_51': 0,
  's_52': 1,
  's_53': 1,
  's_54': 0,
  's_55': 1,
  's_56': 1,
  's_57': 0,
  's_58': 0,
  's_59': 1,
  's_6': 0,
  's_60': 1,
  's_61': 0,
  's_62': 1,
  's_63': 0,
  's_64': 0,
  's_65': 1,
  's_66': 1,
  's_67': 0,
  's_68': 0,
  's_69': 0,
  's_7': 0,
  's_70': 1,
  's_71': 0,
  's_72': 1,
  's_73': 0,
  's_74': 0,
  's_75': 0,
  's_76': 0,
  's_77': 0,
  's_78': 0,
  's_79': 1,
  's_8': 1,
  's_80': 1,
  's_81': 1,
  's_82': 1,
  's_83': 0,
  's_84': 0,
  's_85': 0,
  's_86': 0,
  's_87': 1,
  's_88': 1,
  's_89': 0,
  's_9': 1,
  's_90': 0,
  's_91': 1,
  's_92': 0,
  's_93': 1,
  's_94': 1,
  's_95': 0,
  's_96': 1,
  's_97': 0,
  's_98': 0,
  's_99': 0,
  'x': 258,
})

[2024-09-11 08:09:52,613][basic_search][INFO][generic_smbo.py:310] Iter 37, objectives: [inf].
[2024-09-11 08:09:52,624][basic_search][WARNING][generic_advisor.py:467] No enough successful initial trials! Sample random configuration.
[2024-09-11 08:09:52,627][basic_search][ERROR][generic_smbo.py:290] Exception in objective function:
Traceback (most recent call last):
  File "/gyc_data/fray_data/py38hwvenv/lib/python3.8/site-packages/openbox/utils/limit.py", line 62, in run_without_time_limit
    ret = obj_func(*obj_args, **obj_kwargs)
  File "/gyc_data/fray_data/project_hw/BO_partition3.py", line 99, in obj_func
    cost = self.black_box.get_cost_from_partitions(partitions, scan_method)
  File "/gyc_data/fray_data/project_hw/BO_partition3.py", line 60, in get_cost_from_partitions
    scan_method_cpp[i] = scan_method[i]
IndexError: list index out of range

config: Configuration(values={
  's_0': 0,
  's_1': 1,
  's_10': 0,
  's_100': 0,
  's_101': 0,
  's_102': 0,
  's_103': 1,
  's_104': 1,
  's_105': 1,
  's_106': 0,
  's_107': 0,
  's_108': 0,
  's_109': 0,
  's_11': 0,
  's_110': 1,
  's_111': 1,
  's_112': 0,
  's_113': 0,
  's_114': 1,
  's_115': 1,
  's_116': 1,
  's_117': 1,
  's_118': 0,
  's_119': 1,
  's_12': 1,
  's_120': 0,
  's_121': 0,
  's_122': 1,
  's_123': 0,
  's_124': 1,
  's_125': 1,
  's_126': 0,
  's_127': 1,
  's_128': 0,
  's_129': 1,
  's_13': 1,
  's_130': 0,
  's_131': 0,
  's_132': 0,
  's_133': 1,
  's_134': 0,
  's_135': 1,
  's_136': 1,
  's_137': 0,
  's_138': 1,
  's_139': 1,
  's_14': 0,
  's_140': 0,
  's_141': 1,
  's_142': 1,
  's_143': 0,
  's_144': 1,
  's_145': 1,
  's_146': 1,
  's_15': 1,
  's_16': 0,
  's_17': 0,
  's_18': 0,
  's_19': 0,
  's_2': 1,
  's_20': 1,
  's_21': 0,
  's_22': 1,
  's_23': 1,
  's_24': 0,
  's_25': 0,
  's_26': 0,
  's_27': 1,
  's_28': 1,
  's_29': 1,
  's_3': 1,
  's_30': 1,
  's_31': 1,
  's_32': 0,
  's_33': 0,
  's_34': 0,
  's_35': 0,
  's_36': 1,
  's_37': 1,
  's_38': 1,
  's_39': 1,
  's_4': 0,
  's_40': 0,
  's_41': 1,
  's_42': 1,
  's_43': 1,
  's_44': 1,
  's_45': 1,
  's_46': 1,
  's_47': 0,
  's_48': 1,
  's_49': 0,
  's_5': 1,
  's_50': 1,
  's_51': 0,
  's_52': 0,
  's_53': 0,
  's_54': 1,
  's_55': 1,
  's_56': 1,
  's_57': 0,
  's_58': 1,
  's_59': 0,
  's_6': 1,
  's_60': 0,
  's_61': 1,
  's_62': 1,
  's_63': 0,
  's_64': 1,
  's_65': 0,
  's_66': 1,
  's_67': 1,
  's_68': 1,
  's_69': 0,
  's_7': 0,
  's_70': 0,
  's_71': 1,
  's_72': 1,
  's_73': 1,
  's_74': 0,
  's_75': 0,
  's_76': 0,
  's_77': 1,
  's_78': 0,
  's_79': 1,
  's_8': 0,
  's_80': 0,
  's_81': 0,
  's_82': 0,
  's_83': 0,
  's_84': 0,
  's_85': 0,
  's_86': 0,
  's_87': 0,
  's_88': 0,
  's_89': 0,
  's_9': 1,
  's_90': 1,
  's_91': 1,
  's_92': 0,
  's_93': 0,
  's_94': 1,
  's_95': 1,
  's_96': 1,
  's_97': 0,
  's_98': 0,
  's_99': 1,
  'x': 59,
})

[2024-09-11 08:09:52,628][basic_search][INFO][generic_smbo.py:310] Iter 38, objectives: [inf].
[2024-09-11 08:09:52,639][basic_search][WARNING][generic_advisor.py:467] No enough successful initial trials! Sample random configuration.
[2024-09-11 08:09:52,643][basic_search][ERROR][generic_smbo.py:290] Exception in objective function:
Traceback (most recent call last):
  File "/gyc_data/fray_data/py38hwvenv/lib/python3.8/site-packages/openbox/utils/limit.py", line 62, in run_without_time_limit
    ret = obj_func(*obj_args, **obj_kwargs)
  File "/gyc_data/fray_data/project_hw/BO_partition3.py", line 99, in obj_func
    cost = self.black_box.get_cost_from_partitions(partitions, scan_method)
  File "/gyc_data/fray_data/project_hw/BO_partition3.py", line 60, in get_cost_from_partitions
    scan_method_cpp[i] = scan_method[i]
IndexError: list index out of range

config: Configuration(values={
  's_0': 0,
  's_1': 1,
  's_10': 0,
  's_100': 0,
  's_101': 0,
  's_102': 0,
  's_103': 1,
  's_104': 0,
  's_105': 1,
  's_106': 1,
  's_107': 1,
  's_108': 1,
  's_109': 1,
  's_11': 0,
  's_110': 0,
  's_111': 0,
  's_112': 0,
  's_113': 1,
  's_114': 0,
  's_115': 1,
  's_116': 1,
  's_117': 1,
  's_118': 0,
  's_119': 1,
  's_12': 1,
  's_120': 1,
  's_121': 1,
  's_122': 0,
  's_123': 0,
  's_124': 1,
  's_125': 0,
  's_126': 1,
  's_127': 0,
  's_128': 0,
  's_129': 1,
  's_13': 0,
  's_130': 1,
  's_131': 0,
  's_132': 1,
  's_133': 1,
  's_134': 1,
  's_135': 0,
  's_136': 1,
  's_137': 1,
  's_138': 1,
  's_139': 1,
  's_14': 0,
  's_140': 1,
  's_141': 1,
  's_142': 0,
  's_143': 1,
  's_144': 1,
  's_145': 1,
  's_146': 1,
  's_15': 0,
  's_16': 0,
  's_17': 0,
  's_18': 1,
  's_19': 1,
  's_2': 1,
  's_20': 0,
  's_21': 0,
  's_22': 1,
  's_23': 0,
  's_24': 1,
  's_25': 1,
  's_26': 0,
  's_27': 0,
  's_28': 0,
  's_29': 1,
  's_3': 1,
  's_30': 1,
  's_31': 0,
  's_32': 0,
  's_33': 1,
  's_34': 0,
  's_35': 1,
  's_36': 1,
  's_37': 1,
  's_38': 0,
  's_39': 0,
  's_4': 1,
  's_40': 1,
  's_41': 1,
  's_42': 1,
  's_43': 1,
  's_44': 1,
  's_45': 1,
  's_46': 1,
  's_47': 0,
  's_48': 0,
  's_49': 1,
  's_5': 0,
  's_50': 0,
  's_51': 1,
  's_52': 1,
  's_53': 0,
  's_54': 0,
  's_55': 1,
  's_56': 1,
  's_57': 0,
  's_58': 0,
  's_59': 0,
  's_6': 1,
  's_60': 0,
  's_61': 0,
  's_62': 0,
  's_63': 0,
  's_64': 0,
  's_65': 0,
  's_66': 0,
  's_67': 0,
  's_68': 0,
  's_69': 1,
  's_7': 0,
  's_70': 1,
  's_71': 0,
  's_72': 0,
  's_73': 0,
  's_74': 0,
  's_75': 1,
  's_76': 0,
  's_77': 1,
  's_78': 0,
  's_79': 1,
  's_8': 1,
  's_80': 0,
  's_81': 1,
  's_82': 0,
  's_83': 0,
  's_84': 0,
  's_85': 0,
  's_86': 0,
  's_87': 0,
  's_88': 1,
  's_89': 0,
  's_9': 1,
  's_90': 1,
  's_91': 1,
  's_92': 0,
  's_93': 0,
  's_94': 0,
  's_95': 1,
  's_96': 1,
  's_97': 1,
  's_98': 1,
  's_99': 1,
  'x': 79,
})

[2024-09-11 08:09:52,643][basic_search][INFO][generic_smbo.py:310] Iter 39, objectives: [inf].
[2024-09-11 08:09:52,654][basic_search][WARNING][generic_advisor.py:467] No enough successful initial trials! Sample random configuration.
[2024-09-11 08:09:52,658][basic_search][ERROR][generic_smbo.py:290] Exception in objective function:
Traceback (most recent call last):
  File "/gyc_data/fray_data/py38hwvenv/lib/python3.8/site-packages/openbox/utils/limit.py", line 62, in run_without_time_limit
    ret = obj_func(*obj_args, **obj_kwargs)
  File "/gyc_data/fray_data/project_hw/BO_partition3.py", line 99, in obj_func
    cost = self.black_box.get_cost_from_partitions(partitions, scan_method)
  File "/gyc_data/fray_data/project_hw/BO_partition3.py", line 60, in get_cost_from_partitions
    scan_method_cpp[i] = scan_method[i]
IndexError: list index out of range

config: Configuration(values={
  's_0': 0,
  's_1': 1,
  's_10': 1,
  's_100': 0,
  's_101': 0,
  's_102': 0,
  's_103': 0,
  's_104': 1,
  's_105': 0,
  's_106': 1,
  's_107': 0,
  's_108': 1,
  's_109': 0,
  's_11': 0,
  's_110': 1,
  's_111': 1,
  's_112': 1,
  's_113': 1,
  's_114': 1,
  's_115': 0,
  's_116': 1,
  's_117': 1,
  's_118': 1,
  's_119': 1,
  's_12': 1,
  's_120': 1,
  's_121': 0,
  's_122': 1,
  's_123': 0,
  's_124': 1,
  's_125': 1,
  's_126': 1,
  's_127': 0,
  's_128': 0,
  's_129': 0,
  's_13': 0,
  's_130': 1,
  's_131': 1,
  's_132': 0,
  's_133': 1,
  's_134': 0,
  's_135': 0,
  's_136': 0,
  's_137': 0,
  's_138': 0,
  's_139': 1,
  's_14': 1,
  's_140': 1,
  's_141': 0,
  's_142': 0,
  's_143': 1,
  's_144': 0,
  's_145': 0,
  's_146': 0,
  's_15': 0,
  's_16': 0,
  's_17': 1,
  's_18': 0,
  's_19': 0,
  's_2': 1,
  's_20': 1,
  's_21': 1,
  's_22': 1,
  's_23': 1,
  's_24': 0,
  's_25': 0,
  's_26': 0,
  's_27': 1,
  's_28': 0,
  's_29': 1,
  's_3': 1,
  's_30': 0,
  's_31': 1,
  's_32': 0,
  's_33': 0,
  's_34': 1,
  's_35': 0,
  's_36': 1,
  's_37': 0,
  's_38': 1,
  's_39': 1,
  's_4': 0,
  's_40': 0,
  's_41': 0,
  's_42': 0,
  's_43': 1,
  's_44': 1,
  's_45': 1,
  's_46': 0,
  's_47': 1,
  's_48': 1,
  's_49': 0,
  's_5': 0,
  's_50': 1,
  's_51': 0,
  's_52': 1,
  's_53': 1,
  's_54': 0,
  's_55': 1,
  's_56': 1,
  's_57': 1,
  's_58': 0,
  's_59': 0,
  's_6': 0,
  's_60': 1,
  's_61': 0,
  's_62': 0,
  's_63': 0,
  's_64': 0,
  's_65': 0,
  's_66': 1,
  's_67': 0,
  's_68': 1,
  's_69': 0,
  's_7': 1,
  's_70': 1,
  's_71': 0,
  's_72': 1,
  's_73': 0,
  's_74': 1,
  's_75': 0,
  's_76': 1,
  's_77': 0,
  's_78': 0,
  's_79': 1,
  's_8': 1,
  's_80': 1,
  's_81': 1,
  's_82': 0,
  's_83': 1,
  's_84': 0,
  's_85': 0,
  's_86': 1,
  's_87': 1,
  's_88': 0,
  's_89': 1,
  's_9': 1,
  's_90': 1,
  's_91': 0,
  's_92': 1,
  's_93': 1,
  's_94': 1,
  's_95': 0,
  's_96': 0,
  's_97': 0,
  's_98': 1,
  's_99': 0,
  'x': 126,
})

[2024-09-11 08:09:52,658][basic_search][INFO][generic_smbo.py:310] Iter 40, objectives: [inf].
[2024-09-11 08:09:52,670][basic_search][WARNING][generic_advisor.py:467] No enough successful initial trials! Sample random configuration.
[2024-09-11 08:09:52,674][basic_search][ERROR][generic_smbo.py:290] Exception in objective function:
Traceback (most recent call last):
  File "/gyc_data/fray_data/py38hwvenv/lib/python3.8/site-packages/openbox/utils/limit.py", line 62, in run_without_time_limit
    ret = obj_func(*obj_args, **obj_kwargs)
  File "/gyc_data/fray_data/project_hw/BO_partition3.py", line 99, in obj_func
    cost = self.black_box.get_cost_from_partitions(partitions, scan_method)
  File "/gyc_data/fray_data/project_hw/BO_partition3.py", line 60, in get_cost_from_partitions
    scan_method_cpp[i] = scan_method[i]
IndexError: list index out of range

config: Configuration(values={
  's_0': 1,
  's_1': 1,
  's_10': 0,
  's_100': 1,
  's_101': 0,
  's_102': 1,
  's_103': 1,
  's_104': 1,
  's_105': 0,
  's_106': 1,
  's_107': 0,
  's_108': 1,
  's_109': 0,
  's_11': 1,
  's_110': 1,
  's_111': 1,
  's_112': 1,
  's_113': 1,
  's_114': 1,
  's_115': 0,
  's_116': 0,
  's_117': 1,
  's_118': 0,
  's_119': 1,
  's_12': 0,
  's_120': 1,
  's_121': 1,
  's_122': 1,
  's_123': 0,
  's_124': 0,
  's_125': 1,
  's_126': 1,
  's_127': 1,
  's_128': 0,
  's_129': 0,
  's_13': 0,
  's_130': 0,
  's_131': 0,
  's_132': 0,
  's_133': 0,
  's_134': 1,
  's_135': 0,
  's_136': 0,
  's_137': 0,
  's_138': 1,
  's_139': 1,
  's_14': 1,
  's_140': 1,
  's_141': 1,
  's_142': 0,
  's_143': 0,
  's_144': 1,
  's_145': 0,
  's_146': 0,
  's_15': 0,
  's_16': 1,
  's_17': 1,
  's_18': 0,
  's_19': 0,
  's_2': 1,
  's_20': 0,
  's_21': 0,
  's_22': 0,
  's_23': 1,
  's_24': 0,
  's_25': 1,
  's_26': 0,
  's_27': 1,
  's_28': 1,
  's_29': 1,
  's_3': 0,
  's_30': 0,
  's_31': 1,
  's_32': 1,
  's_33': 0,
  's_34': 0,
  's_35': 0,
  's_36': 0,
  's_37': 1,
  's_38': 0,
  's_39': 1,
  's_4': 0,
  's_40': 1,
  's_41': 1,
  's_42': 1,
  's_43': 1,
  's_44': 1,
  's_45': 0,
  's_46': 0,
  's_47': 1,
  's_48': 0,
  's_49': 0,
  's_5': 1,
  's_50': 1,
  's_51': 1,
  's_52': 0,
  's_53': 1,
  's_54': 1,
  's_55': 1,
  's_56': 0,
  's_57': 1,
  's_58': 0,
  's_59': 1,
  's_6': 1,
  's_60': 1,
  's_61': 0,
  's_62': 0,
  's_63': 0,
  's_64': 0,
  's_65': 0,
  's_66': 1,
  's_67': 0,
  's_68': 0,
  's_69': 0,
  's_7': 0,
  's_70': 1,
  's_71': 1,
  's_72': 1,
  's_73': 1,
  's_74': 1,
  's_75': 1,
  's_76': 1,
  's_77': 1,
  's_78': 0,
  's_79': 1,
  's_8': 0,
  's_80': 1,
  's_81': 1,
  's_82': 0,
  's_83': 1,
  's_84': 1,
  's_85': 1,
  's_86': 1,
  's_87': 0,
  's_88': 0,
  's_89': 0,
  's_9': 1,
  's_90': 1,
  's_91': 0,
  's_92': 1,
  's_93': 1,
  's_94': 0,
  's_95': 1,
  's_96': 1,
  's_97': 1,
  's_98': 1,
  's_99': 0,
  'x': 12,
})

[2024-09-11 08:09:52,674][basic_search][INFO][generic_smbo.py:310] Iter 41, objectives: [inf].
[2024-09-11 08:09:52,686][basic_search][WARNING][generic_advisor.py:467] No enough successful initial trials! Sample random configuration.
[2024-09-11 08:09:52,690][basic_search][ERROR][generic_smbo.py:290] Exception in objective function:
Traceback (most recent call last):
  File "/gyc_data/fray_data/py38hwvenv/lib/python3.8/site-packages/openbox/utils/limit.py", line 62, in run_without_time_limit
    ret = obj_func(*obj_args, **obj_kwargs)
  File "/gyc_data/fray_data/project_hw/BO_partition3.py", line 99, in obj_func
    cost = self.black_box.get_cost_from_partitions(partitions, scan_method)
  File "/gyc_data/fray_data/project_hw/BO_partition3.py", line 60, in get_cost_from_partitions
    scan_method_cpp[i] = scan_method[i]
IndexError: list index out of range

config: Configuration(values={
  's_0': 1,
  's_1': 1,
  's_10': 0,
  's_100': 0,
  's_101': 1,
  's_102': 0,
  's_103': 1,
  's_104': 0,
  's_105': 0,
  's_106': 0,
  's_107': 0,
  's_108': 1,
  's_109': 0,
  's_11': 1,
  's_110': 1,
  's_111': 0,
  's_112': 1,
  's_113': 1,
  's_114': 0,
  's_115': 0,
  's_116': 1,
  's_117': 1,
  's_118': 1,
  's_119': 1,
  's_12': 1,
  's_120': 1,
  's_121': 1,
  's_122': 1,
  's_123': 0,
  's_124': 0,
  's_125': 0,
  's_126': 0,
  's_127': 0,
  's_128': 1,
  's_129': 1,
  's_13': 0,
  's_130': 0,
  's_131': 1,
  's_132': 1,
  's_133': 0,
  's_134': 1,
  's_135': 1,
  's_136': 1,
  's_137': 1,
  's_138': 1,
  's_139': 0,
  's_14': 1,
  's_140': 1,
  's_141': 0,
  's_142': 1,
  's_143': 1,
  's_144': 1,
  's_145': 1,
  's_146': 0,
  's_15': 0,
  's_16': 0,
  's_17': 0,
  's_18': 0,
  's_19': 0,
  's_2': 1,
  's_20': 1,
  's_21': 1,
  's_22': 0,
  's_23': 1,
  's_24': 1,
  's_25': 1,
  's_26': 1,
  's_27': 0,
  's_28': 1,
  's_29': 1,
  's_3': 0,
  's_30': 0,
  's_31': 0,
  's_32': 1,
  's_33': 1,
  's_34': 1,
  's_35': 1,
  's_36': 1,
  's_37': 0,
  's_38': 1,
  's_39': 0,
  's_4': 0,
  's_40': 1,
  's_41': 0,
  's_42': 0,
  's_43': 1,
  's_44': 0,
  's_45': 0,
  's_46': 0,
  's_47': 1,
  's_48': 0,
  's_49': 1,
  's_5': 1,
  's_50': 0,
  's_51': 0,
  's_52': 1,
  's_53': 0,
  's_54': 1,
  's_55': 0,
  's_56': 0,
  's_57': 1,
  's_58': 0,
  's_59': 1,
  's_6': 1,
  's_60': 0,
  's_61': 1,
  's_62': 1,
  's_63': 1,
  's_64': 0,
  's_65': 1,
  's_66': 0,
  's_67': 0,
  's_68': 1,
  's_69': 0,
  's_7': 1,
  's_70': 1,
  's_71': 0,
  's_72': 1,
  's_73': 0,
  's_74': 0,
  's_75': 1,
  's_76': 1,
  's_77': 0,
  's_78': 1,
  's_79': 1,
  's_8': 1,
  's_80': 0,
  's_81': 1,
  's_82': 0,
  's_83': 1,
  's_84': 1,
  's_85': 0,
  's_86': 0,
  's_87': 0,
  's_88': 0,
  's_89': 1,
  's_9': 1,
  's_90': 0,
  's_91': 0,
  's_92': 0,
  's_93': 0,
  's_94': 0,
  's_95': 1,
  's_96': 0,
  's_97': 1,
  's_98': 0,
  's_99': 0,
  'x': 235,
})

[2024-09-11 08:09:52,690][basic_search][INFO][generic_smbo.py:310] Iter 42, objectives: [inf].
[2024-09-11 08:09:52,702][basic_search][WARNING][generic_advisor.py:467] No enough successful initial trials! Sample random configuration.
[2024-09-11 08:09:52,706][basic_search][ERROR][generic_smbo.py:290] Exception in objective function:
Traceback (most recent call last):
  File "/gyc_data/fray_data/py38hwvenv/lib/python3.8/site-packages/openbox/utils/limit.py", line 62, in run_without_time_limit
    ret = obj_func(*obj_args, **obj_kwargs)
  File "/gyc_data/fray_data/project_hw/BO_partition3.py", line 99, in obj_func
    cost = self.black_box.get_cost_from_partitions(partitions, scan_method)
  File "/gyc_data/fray_data/project_hw/BO_partition3.py", line 60, in get_cost_from_partitions
    scan_method_cpp[i] = scan_method[i]
IndexError: list index out of range

config: Configuration(values={
  's_0': 0,
  's_1': 0,
  's_10': 1,
  's_100': 0,
  's_101': 0,
  's_102': 1,
  's_103': 0,
  's_104': 1,
  's_105': 0,
  's_106': 0,
  's_107': 1,
  's_108': 1,
  's_109': 1,
  's_11': 0,
  's_110': 0,
  's_111': 0,
  's_112': 0,
  's_113': 0,
  's_114': 1,
  's_115': 0,
  's_116': 0,
  's_117': 0,
  's_118': 1,
  's_119': 1,
  's_12': 1,
  's_120': 0,
  's_121': 1,
  's_122': 1,
  's_123': 0,
  's_124': 1,
  's_125': 1,
  's_126': 0,
  's_127': 0,
  's_128': 1,
  's_129': 1,
  's_13': 0,
  's_130': 1,
  's_131': 1,
  's_132': 1,
  's_133': 0,
  's_134': 1,
  's_135': 1,
  's_136': 1,
  's_137': 0,
  's_138': 0,
  's_139': 0,
  's_14': 0,
  's_140': 1,
  's_141': 0,
  's_142': 0,
  's_143': 1,
  's_144': 1,
  's_145': 1,
  's_146': 1,
  's_15': 0,
  's_16': 0,
  's_17': 0,
  's_18': 1,
  's_19': 0,
  's_2': 1,
  's_20': 1,
  's_21': 1,
  's_22': 0,
  's_23': 0,
  's_24': 0,
  's_25': 0,
  's_26': 1,
  's_27': 0,
  's_28': 1,
  's_29': 0,
  's_3': 0,
  's_30': 0,
  's_31': 0,
  's_32': 1,
  's_33': 1,
  's_34': 1,
  's_35': 0,
  's_36': 0,
  's_37': 1,
  's_38': 0,
  's_39': 0,
  's_4': 1,
  's_40': 1,
  's_41': 0,
  's_42': 1,
  's_43': 0,
  's_44': 0,
  's_45': 1,
  's_46': 1,
  's_47': 1,
  's_48': 0,
  's_49': 0,
  's_5': 0,
  's_50': 0,
  's_51': 0,
  's_52': 1,
  's_53': 0,
  's_54': 1,
  's_55': 0,
  's_56': 1,
  's_57': 1,
  's_58': 0,
  's_59': 1,
  's_6': 0,
  's_60': 1,
  's_61': 1,
  's_62': 0,
  's_63': 1,
  's_64': 0,
  's_65': 0,
  's_66': 0,
  's_67': 0,
  's_68': 1,
  's_69': 0,
  's_7': 0,
  's_70': 1,
  's_71': 0,
  's_72': 0,
  's_73': 0,
  's_74': 0,
  's_75': 1,
  's_76': 1,
  's_77': 0,
  's_78': 1,
  's_79': 0,
  's_8': 1,
  's_80': 0,
  's_81': 0,
  's_82': 1,
  's_83': 0,
  's_84': 1,
  's_85': 1,
  's_86': 0,
  's_87': 0,
  's_88': 1,
  's_89': 0,
  's_9': 1,
  's_90': 1,
  's_91': 1,
  's_92': 1,
  's_93': 1,
  's_94': 0,
  's_95': 1,
  's_96': 0,
  's_97': 1,
  's_98': 0,
  's_99': 1,
  'x': 46,
})

[2024-09-11 08:09:52,706][basic_search][INFO][generic_smbo.py:310] Iter 43, objectives: [inf].
[2024-09-11 08:09:52,719][basic_search][WARNING][generic_advisor.py:467] No enough successful initial trials! Sample random configuration.
[2024-09-11 08:09:52,722][basic_search][ERROR][generic_smbo.py:290] Exception in objective function:
Traceback (most recent call last):
  File "/gyc_data/fray_data/py38hwvenv/lib/python3.8/site-packages/openbox/utils/limit.py", line 62, in run_without_time_limit
    ret = obj_func(*obj_args, **obj_kwargs)
  File "/gyc_data/fray_data/project_hw/BO_partition3.py", line 99, in obj_func
    cost = self.black_box.get_cost_from_partitions(partitions, scan_method)
  File "/gyc_data/fray_data/project_hw/BO_partition3.py", line 60, in get_cost_from_partitions
    scan_method_cpp[i] = scan_method[i]
IndexError: list index out of range

config: Configuration(values={
  's_0': 0,
  's_1': 1,
  's_10': 0,
  's_100': 0,
  's_101': 0,
  's_102': 0,
  's_103': 1,
  's_104': 0,
  's_105': 0,
  's_106': 0,
  's_107': 0,
  's_108': 1,
  's_109': 0,
  's_11': 1,
  's_110': 0,
  's_111': 0,
  's_112': 0,
  's_113': 1,
  's_114': 1,
  's_115': 1,
  's_116': 1,
  's_117': 0,
  's_118': 1,
  's_119': 0,
  's_12': 0,
  's_120': 0,
  's_121': 0,
  's_122': 0,
  's_123': 0,
  's_124': 0,
  's_125': 1,
  's_126': 0,
  's_127': 1,
  's_128': 0,
  's_129': 1,
  's_13': 0,
  's_130': 0,
  's_131': 1,
  's_132': 1,
  's_133': 0,
  's_134': 0,
  's_135': 1,
  's_136': 1,
  's_137': 1,
  's_138': 1,
  's_139': 0,
  's_14': 1,
  's_140': 1,
  's_141': 0,
  's_142': 1,
  's_143': 0,
  's_144': 0,
  's_145': 1,
  's_146': 1,
  's_15': 0,
  's_16': 0,
  's_17': 0,
  's_18': 0,
  's_19': 0,
  's_2': 0,
  's_20': 0,
  's_21': 1,
  's_22': 0,
  's_23': 1,
  's_24': 1,
  's_25': 1,
  's_26': 1,
  's_27': 1,
  's_28': 1,
  's_29': 0,
  's_3': 0,
  's_30': 1,
  's_31': 1,
  's_32': 1,
  's_33': 0,
  's_34': 0,
  's_35': 1,
  's_36': 1,
  's_37': 0,
  's_38': 0,
  's_39': 1,
  's_4': 1,
  's_40': 0,
  's_41': 1,
  's_42': 0,
  's_43': 1,
  's_44': 1,
  's_45': 0,
  's_46': 1,
  's_47': 0,
  's_48': 1,
  's_49': 1,
  's_5': 0,
  's_50': 0,
  's_51': 0,
  's_52': 0,
  's_53': 1,
  's_54': 0,
  's_55': 0,
  's_56': 0,
  's_57': 0,
  's_58': 1,
  's_59': 1,
  's_6': 1,
  's_60': 1,
  's_61': 0,
  's_62': 1,
  's_63': 0,
  's_64': 0,
  's_65': 1,
  's_66': 0,
  's_67': 0,
  's_68': 1,
  's_69': 1,
  's_7': 0,
  's_70': 0,
  's_71': 0,
  's_72': 1,
  's_73': 1,
  's_74': 0,
  's_75': 0,
  's_76': 1,
  's_77': 1,
  's_78': 1,
  's_79': 1,
  's_8': 1,
  's_80': 0,
  's_81': 0,
  's_82': 0,
  's_83': 0,
  's_84': 0,
  's_85': 0,
  's_86': 0,
  's_87': 0,
  's_88': 0,
  's_89': 0,
  's_9': 0,
  's_90': 1,
  's_91': 1,
  's_92': 0,
  's_93': 1,
  's_94': 0,
  's_95': 1,
  's_96': 1,
  's_97': 0,
  's_98': 0,
  's_99': 0,
  'x': 229,
})

[2024-09-11 08:09:52,723][basic_search][INFO][generic_smbo.py:310] Iter 44, objectives: [inf].
[2024-09-11 08:09:52,735][basic_search][WARNING][generic_advisor.py:467] No enough successful initial trials! Sample random configuration.
[2024-09-11 08:09:52,739][basic_search][ERROR][generic_smbo.py:290] Exception in objective function:
Traceback (most recent call last):
  File "/gyc_data/fray_data/py38hwvenv/lib/python3.8/site-packages/openbox/utils/limit.py", line 62, in run_without_time_limit
    ret = obj_func(*obj_args, **obj_kwargs)
  File "/gyc_data/fray_data/project_hw/BO_partition3.py", line 99, in obj_func
    cost = self.black_box.get_cost_from_partitions(partitions, scan_method)
  File "/gyc_data/fray_data/project_hw/BO_partition3.py", line 60, in get_cost_from_partitions
    scan_method_cpp[i] = scan_method[i]
IndexError: list index out of range

config: Configuration(values={
  's_0': 1,
  's_1': 1,
  's_10': 0,
  's_100': 1,
  's_101': 1,
  's_102': 0,
  's_103': 1,
  's_104': 0,
  's_105': 0,
  's_106': 0,
  's_107': 1,
  's_108': 1,
  's_109': 0,
  's_11': 0,
  's_110': 0,
  's_111': 1,
  's_112': 0,
  's_113': 1,
  's_114': 1,
  's_115': 0,
  's_116': 0,
  's_117': 1,
  's_118': 0,
  's_119': 0,
  's_12': 1,
  's_120': 0,
  's_121': 0,
  's_122': 1,
  's_123': 0,
  's_124': 1,
  's_125': 0,
  's_126': 0,
  's_127': 1,
  's_128': 1,
  's_129': 0,
  's_13': 1,
  's_130': 0,
  's_131': 1,
  's_132': 1,
  's_133': 1,
  's_134': 1,
  's_135': 0,
  's_136': 1,
  's_137': 0,
  's_138': 0,
  's_139': 0,
  's_14': 1,
  's_140': 1,
  's_141': 0,
  's_142': 1,
  's_143': 0,
  's_144': 1,
  's_145': 0,
  's_146': 1,
  's_15': 0,
  's_16': 0,
  's_17': 1,
  's_18': 1,
  's_19': 1,
  's_2': 1,
  's_20': 0,
  's_21': 0,
  's_22': 1,
  's_23': 0,
  's_24': 1,
  's_25': 0,
  's_26': 0,
  's_27': 0,
  's_28': 1,
  's_29': 1,
  's_3': 0,
  's_30': 0,
  's_31': 0,
  's_32': 1,
  's_33': 0,
  's_34': 0,
  's_35': 1,
  's_36': 1,
  's_37': 0,
  's_38': 0,
  's_39': 0,
  's_4': 0,
  's_40': 0,
  's_41': 1,
  's_42': 0,
  's_43': 1,
  's_44': 1,
  's_45': 1,
  's_46': 1,
  's_47': 1,
  's_48': 0,
  's_49': 1,
  's_5': 1,
  's_50': 1,
  's_51': 1,
  's_52': 0,
  's_53': 0,
  's_54': 1,
  's_55': 1,
  's_56': 0,
  's_57': 0,
  's_58': 1,
  's_59': 1,
  's_6': 1,
  's_60': 0,
  's_61': 0,
  's_62': 0,
  's_63': 0,
  's_64': 0,
  's_65': 1,
  's_66': 0,
  's_67': 0,
  's_68': 0,
  's_69': 0,
  's_7': 0,
  's_70': 0,
  's_71': 1,
  's_72': 0,
  's_73': 1,
  's_74': 0,
  's_75': 1,
  's_76': 0,
  's_77': 1,
  's_78': 0,
  's_79': 1,
  's_8': 0,
  's_80': 1,
  's_81': 0,
  's_82': 0,
  's_83': 1,
  's_84': 1,
  's_85': 0,
  's_86': 1,
  's_87': 0,
  's_88': 0,
  's_89': 0,
  's_9': 1,
  's_90': 1,
  's_91': 0,
  's_92': 0,
  's_93': 0,
  's_94': 0,
  's_95': 1,
  's_96': 0,
  's_97': 0,
  's_98': 0,
  's_99': 1,
  'x': 196,
})

[2024-09-11 08:09:52,739][basic_search][INFO][generic_smbo.py:310] Iter 45, objectives: [inf].
[2024-09-11 08:09:52,753][basic_search][WARNING][generic_advisor.py:467] No enough successful initial trials! Sample random configuration.
[2024-09-11 08:09:52,756][basic_search][ERROR][generic_smbo.py:290] Exception in objective function:
Traceback (most recent call last):
  File "/gyc_data/fray_data/py38hwvenv/lib/python3.8/site-packages/openbox/utils/limit.py", line 62, in run_without_time_limit
    ret = obj_func(*obj_args, **obj_kwargs)
  File "/gyc_data/fray_data/project_hw/BO_partition3.py", line 99, in obj_func
    cost = self.black_box.get_cost_from_partitions(partitions, scan_method)
  File "/gyc_data/fray_data/project_hw/BO_partition3.py", line 60, in get_cost_from_partitions
    scan_method_cpp[i] = scan_method[i]
IndexError: list index out of range

config: Configuration(values={
  's_0': 0,
  's_1': 1,
  's_10': 1,
  's_100': 0,
  's_101': 0,
  's_102': 0,
  's_103': 1,
  's_104': 1,
  's_105': 1,
  's_106': 1,
  's_107': 1,
  's_108': 1,
  's_109': 1,
  's_11': 1,
  's_110': 0,
  's_111': 0,
  's_112': 1,
  's_113': 0,
  's_114': 0,
  's_115': 0,
  's_116': 0,
  's_117': 0,
  's_118': 0,
  's_119': 1,
  's_12': 0,
  's_120': 1,
  's_121': 1,
  's_122': 1,
  's_123': 1,
  's_124': 0,
  's_125': 0,
  's_126': 0,
  's_127': 1,
  's_128': 1,
  's_129': 1,
  's_13': 0,
  's_130': 1,
  's_131': 1,
  's_132': 1,
  's_133': 0,
  's_134': 0,
  's_135': 1,
  's_136': 1,
  's_137': 1,
  's_138': 1,
  's_139': 0,
  's_14': 0,
  's_140': 0,
  's_141': 0,
  's_142': 1,
  's_143': 1,
  's_144': 0,
  's_145': 0,
  's_146': 1,
  's_15': 1,
  's_16': 1,
  's_17': 0,
  's_18': 1,
  's_19': 0,
  's_2': 0,
  's_20': 1,
  's_21': 1,
  's_22': 0,
  's_23': 1,
  's_24': 1,
  's_25': 0,
  's_26': 0,
  's_27': 1,
  's_28': 1,
  's_29': 0,
  's_3': 1,
  's_30': 1,
  's_31': 1,
  's_32': 1,
  's_33': 1,
  's_34': 0,
  's_35': 1,
  's_36': 1,
  's_37': 1,
  's_38': 1,
  's_39': 0,
  's_4': 0,
  's_40': 0,
  's_41': 1,
  's_42': 0,
  's_43': 0,
  's_44': 0,
  's_45': 1,
  's_46': 1,
  's_47': 0,
  's_48': 0,
  's_49': 0,
  's_5': 1,
  's_50': 0,
  's_51': 1,
  's_52': 0,
  's_53': 0,
  's_54': 0,
  's_55': 1,
  's_56': 0,
  's_57': 0,
  's_58': 1,
  's_59': 0,
  's_6': 0,
  's_60': 0,
  's_61': 1,
  's_62': 0,
  's_63': 0,
  's_64': 0,
  's_65': 0,
  's_66': 1,
  's_67': 1,
  's_68': 0,
  's_69': 1,
  's_7': 1,
  's_70': 1,
  's_71': 1,
  's_72': 0,
  's_73': 0,
  's_74': 0,
  's_75': 1,
  's_76': 0,
  's_77': 0,
  's_78': 0,
  's_79': 1,
  's_8': 1,
  's_80': 1,
  's_81': 1,
  's_82': 1,
  's_83': 0,
  's_84': 0,
  's_85': 0,
  's_86': 1,
  's_87': 0,
  's_88': 0,
  's_89': 0,
  's_9': 1,
  's_90': 1,
  's_91': 0,
  's_92': 0,
  's_93': 0,
  's_94': 0,
  's_95': 1,
  's_96': 0,
  's_97': 0,
  's_98': 0,
  's_99': 1,
  'x': 154,
})

[2024-09-11 08:09:52,757][basic_search][INFO][generic_smbo.py:310] Iter 46, objectives: [inf].
[2024-09-11 08:09:52,770][basic_search][WARNING][generic_advisor.py:467] No enough successful initial trials! Sample random configuration.
[2024-09-11 08:09:52,774][basic_search][ERROR][generic_smbo.py:290] Exception in objective function:
Traceback (most recent call last):
  File "/gyc_data/fray_data/py38hwvenv/lib/python3.8/site-packages/openbox/utils/limit.py", line 62, in run_without_time_limit
    ret = obj_func(*obj_args, **obj_kwargs)
  File "/gyc_data/fray_data/project_hw/BO_partition3.py", line 99, in obj_func
    cost = self.black_box.get_cost_from_partitions(partitions, scan_method)
  File "/gyc_data/fray_data/project_hw/BO_partition3.py", line 60, in get_cost_from_partitions
    scan_method_cpp[i] = scan_method[i]
IndexError: list index out of range

config: Configuration(values={
  's_0': 0,
  's_1': 0,
  's_10': 1,
  's_100': 0,
  's_101': 1,
  's_102': 1,
  's_103': 1,
  's_104': 1,
  's_105': 1,
  's_106': 1,
  's_107': 0,
  's_108': 1,
  's_109': 1,
  's_11': 0,
  's_110': 1,
  's_111': 0,
  's_112': 0,
  's_113': 0,
  's_114': 0,
  's_115': 0,
  's_116': 1,
  's_117': 1,
  's_118': 0,
  's_119': 1,
  's_12': 1,
  's_120': 1,
  's_121': 1,
  's_122': 0,
  's_123': 1,
  's_124': 1,
  's_125': 0,
  's_126': 0,
  's_127': 0,
  's_128': 1,
  's_129': 0,
  's_13': 1,
  's_130': 1,
  's_131': 0,
  's_132': 1,
  's_133': 1,
  's_134': 0,
  's_135': 0,
  's_136': 1,
  's_137': 0,
  's_138': 1,
  's_139': 0,
  's_14': 1,
  's_140': 1,
  's_141': 1,
  's_142': 1,
  's_143': 1,
  's_144': 0,
  's_145': 0,
  's_146': 0,
  's_15': 0,
  's_16': 0,
  's_17': 0,
  's_18': 0,
  's_19': 0,
  's_2': 0,
  's_20': 0,
  's_21': 0,
  's_22': 1,
  's_23': 1,
  's_24': 1,
  's_25': 0,
  's_26': 0,
  's_27': 1,
  's_28': 0,
  's_29': 0,
  's_3': 1,
  's_30': 0,
  's_31': 0,
  's_32': 0,
  's_33': 1,
  's_34': 0,
  's_35': 1,
  's_36': 1,
  's_37': 1,
  's_38': 1,
  's_39': 1,
  's_4': 0,
  's_40': 0,
  's_41': 1,
  's_42': 1,
  's_43': 0,
  's_44': 1,
  's_45': 1,
  's_46': 1,
  's_47': 0,
  's_48': 1,
  's_49': 0,
  's_5': 0,
  's_50': 0,
  's_51': 1,
  's_52': 1,
  's_53': 1,
  's_54': 0,
  's_55': 0,
  's_56': 1,
  's_57': 0,
  's_58': 0,
  's_59': 1,
  's_6': 1,
  's_60': 1,
  's_61': 1,
  's_62': 0,
  's_63': 1,
  's_64': 0,
  's_65': 1,
  's_66': 0,
  's_67': 1,
  's_68': 1,
  's_69': 1,
  's_7': 0,
  's_70': 1,
  's_71': 0,
  's_72': 1,
  's_73': 0,
  's_74': 0,
  's_75': 0,
  's_76': 1,
  's_77': 1,
  's_78': 1,
  's_79': 1,
  's_8': 0,
  's_80': 1,
  's_81': 0,
  's_82': 1,
  's_83': 1,
  's_84': 0,
  's_85': 1,
  's_86': 0,
  's_87': 0,
  's_88': 0,
  's_89': 0,
  's_9': 0,
  's_90': 0,
  's_91': 1,
  's_92': 1,
  's_93': 1,
  's_94': 1,
  's_95': 1,
  's_96': 0,
  's_97': 1,
  's_98': 0,
  's_99': 0,
  'x': 202,
})

[2024-09-11 08:09:52,774][basic_search][INFO][generic_smbo.py:310] Iter 47, objectives: [inf].
[2024-09-11 08:09:52,788][basic_search][WARNING][generic_advisor.py:467] No enough successful initial trials! Sample random configuration.
[2024-09-11 08:09:52,792][basic_search][ERROR][generic_smbo.py:290] Exception in objective function:
Traceback (most recent call last):
  File "/gyc_data/fray_data/py38hwvenv/lib/python3.8/site-packages/openbox/utils/limit.py", line 62, in run_without_time_limit
    ret = obj_func(*obj_args, **obj_kwargs)
  File "/gyc_data/fray_data/project_hw/BO_partition3.py", line 99, in obj_func
    cost = self.black_box.get_cost_from_partitions(partitions, scan_method)
  File "/gyc_data/fray_data/project_hw/BO_partition3.py", line 60, in get_cost_from_partitions
    scan_method_cpp[i] = scan_method[i]
IndexError: list index out of range

config: Configuration(values={
  's_0': 1,
  's_1': 1,
  's_10': 0,
  's_100': 1,
  's_101': 0,
  's_102': 0,
  's_103': 0,
  's_104': 0,
  's_105': 0,
  's_106': 1,
  's_107': 1,
  's_108': 0,
  's_109': 0,
  's_11': 1,
  's_110': 1,
  's_111': 1,
  's_112': 1,
  's_113': 1,
  's_114': 0,
  's_115': 0,
  's_116': 1,
  's_117': 1,
  's_118': 0,
  's_119': 0,
  's_12': 1,
  's_120': 1,
  's_121': 1,
  's_122': 0,
  's_123': 1,
  's_124': 1,
  's_125': 0,
  's_126': 0,
  's_127': 0,
  's_128': 1,
  's_129': 0,
  's_13': 1,
  's_130': 0,
  's_131': 0,
  's_132': 0,
  's_133': 0,
  's_134': 0,
  's_135': 0,
  's_136': 1,
  's_137': 0,
  's_138': 0,
  's_139': 0,
  's_14': 0,
  's_140': 1,
  's_141': 1,
  's_142': 0,
  's_143': 1,
  's_144': 0,
  's_145': 1,
  's_146': 0,
  's_15': 0,
  's_16': 1,
  's_17': 1,
  's_18': 1,
  's_19': 1,
  's_2': 0,
  's_20': 1,
  's_21': 0,
  's_22': 0,
  's_23': 0,
  's_24': 1,
  's_25': 1,
  's_26': 0,
  's_27': 0,
  's_28': 0,
  's_29': 0,
  's_3': 1,
  's_30': 0,
  's_31': 0,
  's_32': 1,
  's_33': 0,
  's_34': 1,
  's_35': 1,
  's_36': 1,
  's_37': 1,
  's_38': 1,
  's_39': 1,
  's_4': 1,
  's_40': 0,
  's_41': 0,
  's_42': 1,
  's_43': 0,
  's_44': 0,
  's_45': 1,
  's_46': 1,
  's_47': 0,
  's_48': 0,
  's_49': 0,
  's_5': 1,
  's_50': 0,
  's_51': 0,
  's_52': 0,
  's_53': 1,
  's_54': 0,
  's_55': 1,
  's_56': 0,
  's_57': 0,
  's_58': 1,
  's_59': 0,
  's_6': 0,
  's_60': 1,
  's_61': 0,
  's_62': 1,
  's_63': 0,
  's_64': 1,
  's_65': 1,
  's_66': 1,
  's_67': 0,
  's_68': 0,
  's_69': 1,
  's_7': 0,
  's_70': 0,
  's_71': 1,
  's_72': 1,
  's_73': 0,
  's_74': 0,
  's_75': 0,
  's_76': 0,
  's_77': 1,
  's_78': 0,
  's_79': 1,
  's_8': 0,
  's_80': 0,
  's_81': 0,
  's_82': 0,
  's_83': 1,
  's_84': 0,
  's_85': 1,
  's_86': 1,
  's_87': 0,
  's_88': 1,
  's_89': 1,
  's_9': 1,
  's_90': 1,
  's_91': 0,
  's_92': 1,
  's_93': 1,
  's_94': 1,
  's_95': 1,
  's_96': 1,
  's_97': 1,
  's_98': 0,
  's_99': 0,
  'x': 27,
})

[2024-09-11 08:09:52,792][basic_search][INFO][generic_smbo.py:310] Iter 48, objectives: [inf].
[2024-09-11 08:09:52,805][basic_search][WARNING][generic_advisor.py:467] No enough successful initial trials! Sample random configuration.
[2024-09-11 08:09:52,814][basic_search][ERROR][generic_smbo.py:290] Exception in objective function:
Traceback (most recent call last):
  File "/gyc_data/fray_data/py38hwvenv/lib/python3.8/site-packages/openbox/utils/limit.py", line 62, in run_without_time_limit
    ret = obj_func(*obj_args, **obj_kwargs)
  File "/gyc_data/fray_data/project_hw/BO_partition3.py", line 99, in obj_func
    cost = self.black_box.get_cost_from_partitions(partitions, scan_method)
  File "/gyc_data/fray_data/project_hw/BO_partition3.py", line 60, in get_cost_from_partitions
    scan_method_cpp[i] = scan_method[i]
IndexError: list index out of range

config: Configuration(values={
  's_0': 0,
  's_1': 0,
  's_10': 1,
  's_100': 1,
  's_101': 1,
  's_102': 0,
  's_103': 0,
  's_104': 0,
  's_105': 0,
  's_106': 0,
  's_107': 1,
  's_108': 1,
  's_109': 1,
  's_11': 0,
  's_110': 0,
  's_111': 1,
  's_112': 0,
  's_113': 1,
  's_114': 0,
  's_115': 0,
  's_116': 1,
  's_117': 1,
  's_118': 1,
  's_119': 1,
  's_12': 0,
  's_120': 0,
  's_121': 0,
  's_122': 0,
  's_123': 1,
  's_124': 1,
  's_125': 0,
  's_126': 0,
  's_127': 1,
  's_128': 0,
  's_129': 1,
  's_13': 1,
  's_130': 1,
  's_131': 0,
  's_132': 0,
  's_133': 0,
  's_134': 0,
  's_135': 1,
  's_136': 0,
  's_137': 1,
  's_138': 1,
  's_139': 1,
  's_14': 0,
  's_140': 0,
  's_141': 1,
  's_142': 1,
  's_143': 0,
  's_144': 0,
  's_145': 1,
  's_146': 1,
  's_15': 0,
  's_16': 1,
  's_17': 1,
  's_18': 0,
  's_19': 0,
  's_2': 1,
  's_20': 0,
  's_21': 0,
  's_22': 0,
  's_23': 0,
  's_24': 1,
  's_25': 1,
  's_26': 0,
  's_27': 1,
  's_28': 1,
  's_29': 1,
  's_3': 1,
  's_30': 0,
  's_31': 0,
  's_32': 1,
  's_33': 1,
  's_34': 0,
  's_35': 1,
  's_36': 1,
  's_37': 1,
  's_38': 0,
  's_39': 0,
  's_4': 1,
  's_40': 1,
  's_41': 0,
  's_42': 1,
  's_43': 1,
  's_44': 0,
  's_45': 1,
  's_46': 1,
  's_47': 0,
  's_48': 0,
  's_49': 0,
  's_5': 1,
  's_50': 0,
  's_51': 1,
  's_52': 0,
  's_53': 0,
  's_54': 0,
  's_55': 1,
  's_56': 0,
  's_57': 0,
  's_58': 1,
  's_59': 0,
  's_6': 0,
  's_60': 0,
  's_61': 1,
  's_62': 0,
  's_63': 0,
  's_64': 0,
  's_65': 1,
  's_66': 0,
  's_67': 0,
  's_68': 0,
  's_69': 0,
  's_7': 0,
  's_70': 1,
  's_71': 1,
  's_72': 1,
  's_73': 0,
  's_74': 0,
  's_75': 0,
  's_76': 0,
  's_77': 1,
  's_78': 1,
  's_79': 0,
  's_8': 0,
  's_80': 0,
  's_81': 0,
  's_82': 1,
  's_83': 1,
  's_84': 0,
  's_85': 1,
  's_86': 1,
  's_87': 0,
  's_88': 1,
  's_89': 0,
  's_9': 0,
  's_90': 0,
  's_91': 1,
  's_92': 1,
  's_93': 1,
  's_94': 0,
  's_95': 1,
  's_96': 0,
  's_97': 1,
  's_98': 1,
  's_99': 1,
  'x': 71,
})

[2024-09-11 08:09:52,814][basic_search][INFO][generic_smbo.py:310] Iter 49, objectives: [inf].
[2024-09-11 08:09:52,829][basic_search][WARNING][generic_advisor.py:467] No enough successful initial trials! Sample random configuration.
[2024-09-11 08:09:52,834][basic_search][ERROR][generic_smbo.py:290] Exception in objective function:
Traceback (most recent call last):
  File "/gyc_data/fray_data/py38hwvenv/lib/python3.8/site-packages/openbox/utils/limit.py", line 62, in run_without_time_limit
    ret = obj_func(*obj_args, **obj_kwargs)
  File "/gyc_data/fray_data/project_hw/BO_partition3.py", line 99, in obj_func
    cost = self.black_box.get_cost_from_partitions(partitions, scan_method)
  File "/gyc_data/fray_data/project_hw/BO_partition3.py", line 60, in get_cost_from_partitions
    scan_method_cpp[i] = scan_method[i]
IndexError: list index out of range

config: Configuration(values={
  's_0': 1,
  's_1': 1,
  's_10': 0,
  's_100': 0,
  's_101': 0,
  's_102': 0,
  's_103': 0,
  's_104': 0,
  's_105': 0,
  's_106': 0,
  's_107': 1,
  's_108': 1,
  's_109': 1,
  's_11': 1,
  's_110': 0,
  's_111': 0,
  's_112': 1,
  's_113': 0,
  's_114': 0,
  's_115': 1,
  's_116': 0,
  's_117': 1,
  's_118': 1,
  's_119': 0,
  's_12': 0,
  's_120': 1,
  's_121': 1,
  's_122': 1,
  's_123': 0,
  's_124': 1,
  's_125': 1,
  's_126': 1,
  's_127': 0,
  's_128': 0,
  's_129': 1,
  's_13': 1,
  's_130': 1,
  's_131': 1,
  's_132': 1,
  's_133': 1,
  's_134': 0,
  's_135': 1,
  's_136': 1,
  's_137': 1,
  's_138': 1,
  's_139': 0,
  's_14': 0,
  's_140': 0,
  's_141': 1,
  's_142': 0,
  's_143': 1,
  's_144': 1,
  's_145': 1,
  's_146': 0,
  's_15': 1,
  's_16': 0,
  's_17': 1,
  's_18': 1,
  's_19': 1,
  's_2': 0,
  's_20': 0,
  's_21': 1,
  's_22': 1,
  's_23': 0,
  's_24': 0,
  's_25': 1,
  's_26': 0,
  's_27': 1,
  's_28': 1,
  's_29': 0,
  's_3': 0,
  's_30': 1,
  's_31': 1,
  's_32': 1,
  's_33': 1,
  's_34': 1,
  's_35': 0,
  's_36': 1,
  's_37': 0,
  's_38': 0,
  's_39': 0,
  's_4': 0,
  's_40': 0,
  's_41': 0,
  's_42': 0,
  's_43': 1,
  's_44': 0,
  's_45': 0,
  's_46': 1,
  's_47': 0,
  's_48': 1,
  's_49': 0,
  's_5': 0,
  's_50': 1,
  's_51': 0,
  's_52': 0,
  's_53': 1,
  's_54': 1,
  's_55': 1,
  's_56': 1,
  's_57': 0,
  's_58': 1,
  's_59': 1,
  's_6': 1,
  's_60': 0,
  's_61': 1,
  's_62': 0,
  's_63': 0,
  's_64': 1,
  's_65': 1,
  's_66': 0,
  's_67': 0,
  's_68': 0,
  's_69': 0,
  's_7': 1,
  's_70': 1,
  's_71': 1,
  's_72': 0,
  's_73': 1,
  's_74': 0,
  's_75': 1,
  's_76': 1,
  's_77': 1,
  's_78': 0,
  's_79': 0,
  's_8': 0,
  's_80': 0,
  's_81': 0,
  's_82': 0,
  's_83': 1,
  's_84': 1,
  's_85': 1,
  's_86': 0,
  's_87': 1,
  's_88': 0,
  's_89': 1,
  's_9': 1,
  's_90': 0,
  's_91': 1,
  's_92': 0,
  's_93': 0,
  's_94': 1,
  's_95': 1,
  's_96': 1,
  's_97': 1,
  's_98': 0,
  's_99': 0,
  'x': 210,
})

[2024-09-11 08:09:52,834][basic_search][INFO][generic_smbo.py:310] Iter 50, objectives: [inf].
[2024-09-11 08:09:52,848][basic_search][INFO][html_visualizer.py:96] Please open the html file to view visualization result: file:///gyc_data/fray_data/project_hw/logs_gray_clapboard_search/history/basic_search/basic_search_2024-09-11-08-09-52-326212.html
[2024-09-11 08:09:52,855][basic_search][WARNING][history.py:559] No feasible incumbent observations returned!
