[2024-09-05 06:43:26,297][basic_search][INFO][color_logger.py:203] Logfile: /gyc_data/fray_data/project_hw/logs_gray_clapboard_search/basic_search_2024-09-05-06-43-26-297662.log
[2024-09-05 06:43:26,655][basic_search][INFO][generic_advisor.py:231] [BO auto selection]  acq_type: ei. acq_optimizer_type: local_random.
[2024-09-05 06:43:26,660][basic_search][INFO][html_visualizer.py:462] Please open the html file to view visualization result: file:///gyc_data/fray_data/project_hw/logs_gray_clapboard_search/history/basic_search/basic_search_2024-09-05-06-43-26-658599.html
[2024-09-05 06:43:26,661][basic_search][ERROR][generic_smbo.py:290] Exception in objective function:
Traceback (most recent call last):
  File "/gyc_data/fray_data/py38hwvenv/lib/python3.8/site-packages/openbox/utils/limit.py", line 62, in run_without_time_limit
    ret = obj_func(*obj_args, **obj_kwargs)
  File "BO_partition.py", line 72, in obj_func
    cost = self.black_box.get_cost_from_partitions(partitions)
  File "BO_partition.py", line 34, in get_cost_from_partitions
    partitions_cpp[i]=partitions[i]
IndexError: list index out of range

config: Configuration(values={
  'x0': 0,
  'x1': 0,
  'x10': 0,
  'x100': 0,
  'x101': 0,
  'x102': 0,
  'x103': 0,
  'x104': 0,
  'x105': 0,
  'x106': 0,
  'x107': 0,
  'x108': 0,
  'x109': 0,
  'x11': 0,
  'x110': 0,
  'x111': 0,
  'x112': 0,
  'x113': 0,
  'x114': 0,
  'x115': 0,
  'x116': 0,
  'x117': 0,
  'x118': 0,
  'x119': 0,
  'x12': 0,
  'x120': 0,
  'x121': 0,
  'x122': 0,
  'x123': 0,
  'x124': 0,
  'x125': 0,
  'x126': 0,
  'x127': 0,
  'x128': 0,
  'x129': 0,
  'x13': 0,
  'x130': 0,
  'x131': 0,
  'x132': 0,
  'x133': 0,
  'x134': 0,
  'x135': 0,
  'x136': 0,
  'x137': 0,
  'x138': 0,
  'x139': 0,
  'x14': 0,
  'x140': 0,
  'x141': 0,
  'x142': 0,
  'x143': 0,
  'x144': 0,
  'x145': 0,
  'x15': 0,
  'x16': 0,
  'x17': 0,
  'x18': 0,
  'x19': 0,
  'x2': 0,
  'x20': 0,
  'x21': 0,
  'x22': 0,
  'x23': 0,
  'x24': 0,
  'x25': 0,
  'x26': 0,
  'x27': 0,
  'x28': 0,
  'x29': 0,
  'x3': 0,
  'x30': 0,
  'x31': 0,
  'x32': 0,
  'x33': 0,
  'x34': 0,
  'x35': 0,
  'x36': 0,
  'x37': 0,
  'x38': 0,
  'x39': 0,
  'x4': 0,
  'x40': 0,
  'x41': 0,
  'x42': 0,
  'x43': 0,
  'x44': 0,
  'x45': 0,
  'x46': 0,
  'x47': 0,
  'x48': 0,
  'x49': 0,
  'x5': 0,
  'x50': 0,
  'x51': 0,
  'x52': 0,
  'x53': 0,
  'x54': 0,
  'x55': 0,
  'x56': 0,
  'x57': 0,
  'x58': 0,
  'x59': 0,
  'x6': 0,
  'x60': 0,
  'x61': 0,
  'x62': 0,
  'x63': 0,
  'x64': 0,
  'x65': 0,
  'x66': 0,
  'x67': 0,
  'x68': 0,
  'x69': 0,
  'x7': 0,
  'x70': 0,
  'x71': 0,
  'x72': 0,
  'x73': 0,
  'x74': 0,
  'x75': 0,
  'x76': 0,
  'x77': 0,
  'x78': 0,
  'x79': 0,
  'x8': 0,
  'x80': 0,
  'x81': 0,
  'x82': 0,
  'x83': 0,
  'x84': 0,
  'x85': 0,
  'x86': 0,
  'x87': 0,
  'x88': 0,
  'x89': 0,
  'x9': 0,
  'x90': 0,
  'x91': 0,
  'x92': 0,
  'x93': 0,
  'x94': 0,
  'x95': 0,
  'x96': 0,
  'x97': 0,
  'x98': 0,
  'x99': 0,
})

[2024-09-05 06:43:26,662][basic_search][INFO][generic_smbo.py:310] Iter 1, objectives: [inf].
[2024-09-05 06:43:26,663][basic_search][ERROR][generic_smbo.py:290] Exception in objective function:
Traceback (most recent call last):
  File "/gyc_data/fray_data/py38hwvenv/lib/python3.8/site-packages/openbox/utils/limit.py", line 62, in run_without_time_limit
    ret = obj_func(*obj_args, **obj_kwargs)
  File "BO_partition.py", line 72, in obj_func
    cost = self.black_box.get_cost_from_partitions(partitions)
  File "BO_partition.py", line 34, in get_cost_from_partitions
    partitions_cpp[i]=partitions[i]
IndexError: list index out of range

config: Configuration(values={
  'x0': 0,
  'x1': 0,
  'x10': 0,
  'x100': 1,
  'x101': 0,
  'x102': 1,
  'x103': 1,
  'x104': 1,
  'x105': 0,
  'x106': 0,
  'x107': 0,
  'x108': 1,
  'x109': 0,
  'x11': 0,
  'x110': 1,
  'x111': 0,
  'x112': 1,
  'x113': 1,
  'x114': 1,
  'x115': 0,
  'x116': 0,
  'x117': 0,
  'x118': 0,
  'x119': 0,
  'x12': 1,
  'x120': 0,
  'x121': 1,
  'x122': 1,
  'x123': 0,
  'x124': 0,
  'x125': 1,
  'x126': 1,
  'x127': 1,
  'x128': 1,
  'x129': 1,
  'x13': 0,
  'x130': 1,
  'x131': 1,
  'x132': 1,
  'x133': 0,
  'x134': 1,
  'x135': 1,
  'x136': 0,
  'x137': 0,
  'x138': 1,
  'x139': 1,
  'x14': 0,
  'x140': 0,
  'x141': 1,
  'x142': 1,
  'x143': 1,
  'x144': 0,
  'x145': 1,
  'x15': 1,
  'x16': 1,
  'x17': 1,
  'x18': 1,
  'x19': 1,
  'x2': 1,
  'x20': 1,
  'x21': 1,
  'x22': 0,
  'x23': 1,
  'x24': 0,
  'x25': 1,
  'x26': 1,
  'x27': 0,
  'x28': 1,
  'x29': 0,
  'x3': 0,
  'x30': 1,
  'x31': 0,
  'x32': 1,
  'x33': 1,
  'x34': 1,
  'x35': 1,
  'x36': 0,
  'x37': 1,
  'x38': 0,
  'x39': 1,
  'x4': 0,
  'x40': 0,
  'x41': 1,
  'x42': 0,
  'x43': 0,
  'x44': 1,
  'x45': 1,
  'x46': 0,
  'x47': 1,
  'x48': 1,
  'x49': 0,
  'x5': 0,
  'x50': 1,
  'x51': 1,
  'x52': 1,
  'x53': 0,
  'x54': 1,
  'x55': 0,
  'x56': 1,
  'x57': 0,
  'x58': 0,
  'x59': 0,
  'x6': 0,
  'x60': 1,
  'x61': 1,
  'x62': 0,
  'x63': 0,
  'x64': 1,
  'x65': 0,
  'x66': 0,
  'x67': 1,
  'x68': 1,
  'x69': 1,
  'x7': 1,
  'x70': 1,
  'x71': 1,
  'x72': 1,
  'x73': 1,
  'x74': 1,
  'x75': 1,
  'x76': 1,
  'x77': 1,
  'x78': 0,
  'x79': 1,
  'x8': 1,
  'x80': 1,
  'x81': 1,
  'x82': 1,
  'x83': 0,
  'x84': 0,
  'x85': 1,
  'x86': 1,
  'x87': 0,
  'x88': 1,
  'x89': 1,
  'x9': 1,
  'x90': 1,
  'x91': 1,
  'x92': 1,
  'x93': 0,
  'x94': 1,
  'x95': 0,
  'x96': 0,
  'x97': 0,
  'x98': 1,
  'x99': 1,
})

[2024-09-05 06:43:26,663][basic_search][INFO][generic_smbo.py:310] Iter 2, objectives: [inf].
[2024-09-05 06:43:26,664][basic_search][ERROR][generic_smbo.py:290] Exception in objective function:
Traceback (most recent call last):
  File "/gyc_data/fray_data/py38hwvenv/lib/python3.8/site-packages/openbox/utils/limit.py", line 62, in run_without_time_limit
    ret = obj_func(*obj_args, **obj_kwargs)
  File "BO_partition.py", line 72, in obj_func
    cost = self.black_box.get_cost_from_partitions(partitions)
  File "BO_partition.py", line 34, in get_cost_from_partitions
    partitions_cpp[i]=partitions[i]
IndexError: list index out of range

config: Configuration(values={
  'x0': 1,
  'x1': 0,
  'x10': 1,
  'x100': 0,
  'x101': 1,
  'x102': 1,
  'x103': 1,
  'x104': 0,
  'x105': 1,
  'x106': 1,
  'x107': 1,
  'x108': 0,
  'x109': 1,
  'x11': 1,
  'x110': 1,
  'x111': 0,
  'x112': 1,
  'x113': 0,
  'x114': 1,
  'x115': 1,
  'x116': 0,
  'x117': 1,
  'x118': 1,
  'x119': 0,
  'x12': 1,
  'x120': 1,
  'x121': 0,
  'x122': 0,
  'x123': 1,
  'x124': 1,
  'x125': 0,
  'x126': 0,
  'x127': 0,
  'x128': 1,
  'x129': 1,
  'x13': 0,
  'x130': 1,
  'x131': 1,
  'x132': 0,
  'x133': 0,
  'x134': 1,
  'x135': 0,
  'x136': 0,
  'x137': 1,
  'x138': 1,
  'x139': 1,
  'x14': 0,
  'x140': 0,
  'x141': 0,
  'x142': 0,
  'x143': 0,
  'x144': 0,
  'x145': 0,
  'x15': 1,
  'x16': 1,
  'x17': 0,
  'x18': 0,
  'x19': 0,
  'x2': 1,
  'x20': 0,
  'x21': 1,
  'x22': 1,
  'x23': 0,
  'x24': 1,
  'x25': 0,
  'x26': 1,
  'x27': 1,
  'x28': 0,
  'x29': 0,
  'x3': 0,
  'x30': 0,
  'x31': 0,
  'x32': 0,
  'x33': 0,
  'x34': 0,
  'x35': 0,
  'x36': 1,
  'x37': 0,
  'x38': 0,
  'x39': 1,
  'x4': 0,
  'x40': 0,
  'x41': 0,
  'x42': 1,
  'x43': 1,
  'x44': 1,
  'x45': 1,
  'x46': 0,
  'x47': 1,
  'x48': 0,
  'x49': 1,
  'x5': 1,
  'x50': 1,
  'x51': 1,
  'x52': 1,
  'x53': 1,
  'x54': 0,
  'x55': 1,
  'x56': 1,
  'x57': 0,
  'x58': 1,
  'x59': 1,
  'x6': 1,
  'x60': 1,
  'x61': 1,
  'x62': 1,
  'x63': 1,
  'x64': 1,
  'x65': 1,
  'x66': 0,
  'x67': 0,
  'x68': 1,
  'x69': 0,
  'x7': 1,
  'x70': 0,
  'x71': 1,
  'x72': 1,
  'x73': 0,
  'x74': 0,
  'x75': 1,
  'x76': 1,
  'x77': 0,
  'x78': 1,
  'x79': 0,
  'x8': 1,
  'x80': 1,
  'x81': 1,
  'x82': 0,
  'x83': 1,
  'x84': 1,
  'x85': 1,
  'x86': 0,
  'x87': 0,
  'x88': 1,
  'x89': 0,
  'x9': 0,
  'x90': 1,
  'x91': 0,
  'x92': 1,
  'x93': 0,
  'x94': 0,
  'x95': 0,
  'x96': 0,
  'x97': 1,
  'x98': 0,
  'x99': 1,
})

[2024-09-05 06:43:26,664][basic_search][INFO][generic_smbo.py:310] Iter 3, objectives: [inf].
[2024-09-05 06:43:26,668][basic_search][ERROR][generic_smbo.py:290] Exception in objective function:
Traceback (most recent call last):
  File "/gyc_data/fray_data/py38hwvenv/lib/python3.8/site-packages/openbox/utils/limit.py", line 62, in run_without_time_limit
    ret = obj_func(*obj_args, **obj_kwargs)
  File "BO_partition.py", line 72, in obj_func
    cost = self.black_box.get_cost_from_partitions(partitions)
  File "BO_partition.py", line 34, in get_cost_from_partitions
    partitions_cpp[i]=partitions[i]
IndexError: list index out of range

config: Configuration(values={
  'x0': 1,
  'x1': 1,
  'x10': 0,
  'x100': 1,
  'x101': 1,
  'x102': 1,
  'x103': 1,
  'x104': 0,
  'x105': 1,
  'x106': 1,
  'x107': 0,
  'x108': 1,
  'x109': 1,
  'x11': 0,
  'x110': 0,
  'x111': 1,
  'x112': 1,
  'x113': 0,
  'x114': 0,
  'x115': 1,
  'x116': 1,
  'x117': 1,
  'x118': 1,
  'x119': 1,
  'x12': 1,
  'x120': 1,
  'x121': 0,
  'x122': 0,
  'x123': 1,
  'x124': 1,
  'x125': 1,
  'x126': 1,
  'x127': 0,
  'x128': 0,
  'x129': 0,
  'x13': 0,
  'x130': 0,
  'x131': 0,
  'x132': 1,
  'x133': 1,
  'x134': 0,
  'x135': 1,
  'x136': 0,
  'x137': 0,
  'x138': 0,
  'x139': 0,
  'x14': 0,
  'x140': 0,
  'x141': 0,
  'x142': 1,
  'x143': 0,
  'x144': 0,
  'x145': 1,
  'x15': 1,
  'x16': 1,
  'x17': 0,
  'x18': 1,
  'x19': 1,
  'x2': 0,
  'x20': 1,
  'x21': 0,
  'x22': 1,
  'x23': 0,
  'x24': 0,
  'x25': 0,
  'x26': 0,
  'x27': 1,
  'x28': 0,
  'x29': 0,
  'x3': 0,
  'x30': 1,
  'x31': 1,
  'x32': 1,
  'x33': 1,
  'x34': 1,
  'x35': 1,
  'x36': 0,
  'x37': 0,
  'x38': 0,
  'x39': 0,
  'x4': 1,
  'x40': 0,
  'x41': 0,
  'x42': 1,
  'x43': 1,
  'x44': 1,
  'x45': 0,
  'x46': 1,
  'x47': 0,
  'x48': 1,
  'x49': 0,
  'x5': 0,
  'x50': 0,
  'x51': 1,
  'x52': 0,
  'x53': 0,
  'x54': 1,
  'x55': 1,
  'x56': 0,
  'x57': 1,
  'x58': 0,
  'x59': 1,
  'x6': 0,
  'x60': 1,
  'x61': 1,
  'x62': 1,
  'x63': 0,
  'x64': 1,
  'x65': 0,
  'x66': 1,
  'x67': 1,
  'x68': 1,
  'x69': 1,
  'x7': 0,
  'x70': 0,
  'x71': 1,
  'x72': 0,
  'x73': 0,
  'x74': 0,
  'x75': 0,
  'x76': 0,
  'x77': 1,
  'x78': 1,
  'x79': 1,
  'x8': 1,
  'x80': 1,
  'x81': 0,
  'x82': 0,
  'x83': 1,
  'x84': 1,
  'x85': 0,
  'x86': 0,
  'x87': 1,
  'x88': 1,
  'x89': 0,
  'x9': 0,
  'x90': 1,
  'x91': 1,
  'x92': 0,
  'x93': 0,
  'x94': 0,
  'x95': 1,
  'x96': 0,
  'x97': 1,
  'x98': 1,
  'x99': 0,
})

[2024-09-05 06:43:26,668][basic_search][INFO][generic_smbo.py:310] Iter 4, objectives: [inf].
[2024-09-05 06:43:26,670][basic_search][ERROR][generic_smbo.py:290] Exception in objective function:
Traceback (most recent call last):
  File "/gyc_data/fray_data/py38hwvenv/lib/python3.8/site-packages/openbox/utils/limit.py", line 62, in run_without_time_limit
    ret = obj_func(*obj_args, **obj_kwargs)
  File "BO_partition.py", line 72, in obj_func
    cost = self.black_box.get_cost_from_partitions(partitions)
  File "BO_partition.py", line 34, in get_cost_from_partitions
    partitions_cpp[i]=partitions[i]
IndexError: list index out of range

config: Configuration(values={
  'x0': 1,
  'x1': 1,
  'x10': 1,
  'x100': 0,
  'x101': 0,
  'x102': 0,
  'x103': 0,
  'x104': 0,
  'x105': 1,
  'x106': 0,
  'x107': 0,
  'x108': 0,
  'x109': 0,
  'x11': 1,
  'x110': 1,
  'x111': 1,
  'x112': 1,
  'x113': 0,
  'x114': 0,
  'x115': 1,
  'x116': 1,
  'x117': 0,
  'x118': 0,
  'x119': 1,
  'x12': 1,
  'x120': 0,
  'x121': 1,
  'x122': 1,
  'x123': 1,
  'x124': 0,
  'x125': 1,
  'x126': 1,
  'x127': 1,
  'x128': 1,
  'x129': 0,
  'x13': 0,
  'x130': 1,
  'x131': 1,
  'x132': 0,
  'x133': 1,
  'x134': 1,
  'x135': 1,
  'x136': 0,
  'x137': 1,
  'x138': 1,
  'x139': 0,
  'x14': 1,
  'x140': 1,
  'x141': 1,
  'x142': 1,
  'x143': 1,
  'x144': 0,
  'x145': 0,
  'x15': 1,
  'x16': 1,
  'x17': 1,
  'x18': 0,
  'x19': 1,
  'x2': 0,
  'x20': 0,
  'x21': 1,
  'x22': 0,
  'x23': 0,
  'x24': 0,
  'x25': 0,
  'x26': 0,
  'x27': 1,
  'x28': 1,
  'x29': 1,
  'x3': 0,
  'x30': 1,
  'x31': 0,
  'x32': 0,
  'x33': 0,
  'x34': 0,
  'x35': 0,
  'x36': 1,
  'x37': 1,
  'x38': 1,
  'x39': 0,
  'x4': 0,
  'x40': 0,
  'x41': 0,
  'x42': 0,
  'x43': 0,
  'x44': 1,
  'x45': 1,
  'x46': 0,
  'x47': 0,
  'x48': 0,
  'x49': 1,
  'x5': 0,
  'x50': 1,
  'x51': 0,
  'x52': 1,
  'x53': 0,
  'x54': 1,
  'x55': 1,
  'x56': 1,
  'x57': 1,
  'x58': 0,
  'x59': 1,
  'x6': 1,
  'x60': 0,
  'x61': 1,
  'x62': 1,
  'x63': 0,
  'x64': 0,
  'x65': 1,
  'x66': 0,
  'x67': 1,
  'x68': 0,
  'x69': 1,
  'x7': 0,
  'x70': 0,
  'x71': 0,
  'x72': 1,
  'x73': 1,
  'x74': 1,
  'x75': 1,
  'x76': 1,
  'x77': 0,
  'x78': 1,
  'x79': 0,
  'x8': 0,
  'x80': 1,
  'x81': 0,
  'x82': 1,
  'x83': 0,
  'x84': 1,
  'x85': 0,
  'x86': 1,
  'x87': 1,
  'x88': 0,
  'x89': 1,
  'x9': 0,
  'x90': 1,
  'x91': 0,
  'x92': 0,
  'x93': 1,
  'x94': 1,
  'x95': 1,
  'x96': 1,
  'x97': 1,
  'x98': 0,
  'x99': 1,
})

[2024-09-05 06:43:26,670][basic_search][INFO][generic_smbo.py:310] Iter 5, objectives: [inf].
[2024-09-05 06:43:26,672][basic_search][ERROR][generic_smbo.py:290] Exception in objective function:
Traceback (most recent call last):
  File "/gyc_data/fray_data/py38hwvenv/lib/python3.8/site-packages/openbox/utils/limit.py", line 62, in run_without_time_limit
    ret = obj_func(*obj_args, **obj_kwargs)
  File "BO_partition.py", line 72, in obj_func
    cost = self.black_box.get_cost_from_partitions(partitions)
  File "BO_partition.py", line 34, in get_cost_from_partitions
    partitions_cpp[i]=partitions[i]
IndexError: list index out of range

config: Configuration(values={
  'x0': 1,
  'x1': 1,
  'x10': 1,
  'x100': 0,
  'x101': 1,
  'x102': 0,
  'x103': 1,
  'x104': 1,
  'x105': 0,
  'x106': 0,
  'x107': 0,
  'x108': 0,
  'x109': 0,
  'x11': 0,
  'x110': 1,
  'x111': 0,
  'x112': 0,
  'x113': 1,
  'x114': 0,
  'x115': 0,
  'x116': 0,
  'x117': 1,
  'x118': 0,
  'x119': 1,
  'x12': 0,
  'x120': 1,
  'x121': 1,
  'x122': 1,
  'x123': 0,
  'x124': 1,
  'x125': 0,
  'x126': 0,
  'x127': 1,
  'x128': 1,
  'x129': 0,
  'x13': 1,
  'x130': 0,
  'x131': 1,
  'x132': 0,
  'x133': 0,
  'x134': 0,
  'x135': 1,
  'x136': 1,
  'x137': 1,
  'x138': 0,
  'x139': 1,
  'x14': 0,
  'x140': 1,
  'x141': 1,
  'x142': 0,
  'x143': 1,
  'x144': 1,
  'x145': 0,
  'x15': 0,
  'x16': 1,
  'x17': 0,
  'x18': 0,
  'x19': 1,
  'x2': 1,
  'x20': 1,
  'x21': 0,
  'x22': 1,
  'x23': 1,
  'x24': 1,
  'x25': 1,
  'x26': 1,
  'x27': 0,
  'x28': 0,
  'x29': 1,
  'x3': 0,
  'x30': 0,
  'x31': 0,
  'x32': 1,
  'x33': 1,
  'x34': 1,
  'x35': 0,
  'x36': 1,
  'x37': 0,
  'x38': 1,
  'x39': 0,
  'x4': 1,
  'x40': 0,
  'x41': 1,
  'x42': 1,
  'x43': 1,
  'x44': 1,
  'x45': 1,
  'x46': 0,
  'x47': 1,
  'x48': 0,
  'x49': 0,
  'x5': 0,
  'x50': 0,
  'x51': 0,
  'x52': 0,
  'x53': 0,
  'x54': 1,
  'x55': 0,
  'x56': 1,
  'x57': 1,
  'x58': 1,
  'x59': 1,
  'x6': 0,
  'x60': 1,
  'x61': 1,
  'x62': 1,
  'x63': 1,
  'x64': 0,
  'x65': 0,
  'x66': 1,
  'x67': 1,
  'x68': 1,
  'x69': 0,
  'x7': 0,
  'x70': 0,
  'x71': 0,
  'x72': 0,
  'x73': 0,
  'x74': 1,
  'x75': 0,
  'x76': 0,
  'x77': 0,
  'x78': 1,
  'x79': 0,
  'x8': 0,
  'x80': 1,
  'x81': 1,
  'x82': 0,
  'x83': 1,
  'x84': 1,
  'x85': 0,
  'x86': 0,
  'x87': 1,
  'x88': 0,
  'x89': 1,
  'x9': 1,
  'x90': 0,
  'x91': 0,
  'x92': 1,
  'x93': 1,
  'x94': 1,
  'x95': 0,
  'x96': 0,
  'x97': 0,
  'x98': 1,
  'x99': 1,
})

[2024-09-05 06:43:26,672][basic_search][INFO][generic_smbo.py:310] Iter 6, objectives: [inf].
[2024-09-05 06:43:26,675][basic_search][ERROR][generic_smbo.py:290] Exception in objective function:
Traceback (most recent call last):
  File "/gyc_data/fray_data/py38hwvenv/lib/python3.8/site-packages/openbox/utils/limit.py", line 62, in run_without_time_limit
    ret = obj_func(*obj_args, **obj_kwargs)
  File "BO_partition.py", line 72, in obj_func
    cost = self.black_box.get_cost_from_partitions(partitions)
  File "BO_partition.py", line 34, in get_cost_from_partitions
    partitions_cpp[i]=partitions[i]
IndexError: list index out of range

config: Configuration(values={
  'x0': 1,
  'x1': 0,
  'x10': 1,
  'x100': 0,
  'x101': 0,
  'x102': 0,
  'x103': 0,
  'x104': 1,
  'x105': 0,
  'x106': 1,
  'x107': 0,
  'x108': 0,
  'x109': 0,
  'x11': 1,
  'x110': 0,
  'x111': 0,
  'x112': 1,
  'x113': 0,
  'x114': 1,
  'x115': 1,
  'x116': 1,
  'x117': 1,
  'x118': 0,
  'x119': 1,
  'x12': 0,
  'x120': 1,
  'x121': 0,
  'x122': 0,
  'x123': 1,
  'x124': 1,
  'x125': 1,
  'x126': 0,
  'x127': 1,
  'x128': 0,
  'x129': 0,
  'x13': 0,
  'x130': 0,
  'x131': 0,
  'x132': 1,
  'x133': 1,
  'x134': 0,
  'x135': 0,
  'x136': 0,
  'x137': 1,
  'x138': 1,
  'x139': 1,
  'x14': 0,
  'x140': 1,
  'x141': 1,
  'x142': 0,
  'x143': 0,
  'x144': 0,
  'x145': 1,
  'x15': 0,
  'x16': 1,
  'x17': 1,
  'x18': 0,
  'x19': 0,
  'x2': 0,
  'x20': 0,
  'x21': 1,
  'x22': 1,
  'x23': 0,
  'x24': 0,
  'x25': 1,
  'x26': 1,
  'x27': 1,
  'x28': 1,
  'x29': 0,
  'x3': 0,
  'x30': 0,
  'x31': 0,
  'x32': 0,
  'x33': 0,
  'x34': 1,
  'x35': 1,
  'x36': 1,
  'x37': 1,
  'x38': 1,
  'x39': 1,
  'x4': 0,
  'x40': 1,
  'x41': 1,
  'x42': 0,
  'x43': 0,
  'x44': 0,
  'x45': 0,
  'x46': 1,
  'x47': 1,
  'x48': 1,
  'x49': 0,
  'x5': 1,
  'x50': 1,
  'x51': 1,
  'x52': 0,
  'x53': 1,
  'x54': 0,
  'x55': 0,
  'x56': 1,
  'x57': 1,
  'x58': 1,
  'x59': 1,
  'x6': 0,
  'x60': 1,
  'x61': 1,
  'x62': 0,
  'x63': 0,
  'x64': 0,
  'x65': 0,
  'x66': 1,
  'x67': 1,
  'x68': 1,
  'x69': 1,
  'x7': 0,
  'x70': 1,
  'x71': 0,
  'x72': 1,
  'x73': 0,
  'x74': 0,
  'x75': 0,
  'x76': 0,
  'x77': 0,
  'x78': 1,
  'x79': 1,
  'x8': 0,
  'x80': 0,
  'x81': 1,
  'x82': 1,
  'x83': 0,
  'x84': 1,
  'x85': 1,
  'x86': 1,
  'x87': 1,
  'x88': 1,
  'x89': 0,
  'x9': 0,
  'x90': 0,
  'x91': 0,
  'x92': 1,
  'x93': 0,
  'x94': 1,
  'x95': 1,
  'x96': 1,
  'x97': 0,
  'x98': 0,
  'x99': 0,
})

[2024-09-05 06:43:26,675][basic_search][INFO][generic_smbo.py:310] Iter 7, objectives: [inf].
[2024-09-05 06:43:26,677][basic_search][ERROR][generic_smbo.py:290] Exception in objective function:
Traceback (most recent call last):
  File "/gyc_data/fray_data/py38hwvenv/lib/python3.8/site-packages/openbox/utils/limit.py", line 62, in run_without_time_limit
    ret = obj_func(*obj_args, **obj_kwargs)
  File "BO_partition.py", line 72, in obj_func
    cost = self.black_box.get_cost_from_partitions(partitions)
  File "BO_partition.py", line 34, in get_cost_from_partitions
    partitions_cpp[i]=partitions[i]
IndexError: list index out of range

config: Configuration(values={
  'x0': 0,
  'x1': 0,
  'x10': 1,
  'x100': 1,
  'x101': 1,
  'x102': 1,
  'x103': 0,
  'x104': 0,
  'x105': 1,
  'x106': 1,
  'x107': 1,
  'x108': 0,
  'x109': 0,
  'x11': 1,
  'x110': 1,
  'x111': 1,
  'x112': 1,
  'x113': 1,
  'x114': 1,
  'x115': 1,
  'x116': 1,
  'x117': 0,
  'x118': 1,
  'x119': 1,
  'x12': 0,
  'x120': 0,
  'x121': 1,
  'x122': 1,
  'x123': 1,
  'x124': 0,
  'x125': 0,
  'x126': 0,
  'x127': 1,
  'x128': 1,
  'x129': 1,
  'x13': 1,
  'x130': 0,
  'x131': 0,
  'x132': 1,
  'x133': 1,
  'x134': 0,
  'x135': 0,
  'x136': 0,
  'x137': 0,
  'x138': 0,
  'x139': 1,
  'x14': 0,
  'x140': 1,
  'x141': 1,
  'x142': 1,
  'x143': 1,
  'x144': 1,
  'x145': 1,
  'x15': 1,
  'x16': 0,
  'x17': 1,
  'x18': 0,
  'x19': 1,
  'x2': 0,
  'x20': 0,
  'x21': 1,
  'x22': 1,
  'x23': 1,
  'x24': 1,
  'x25': 0,
  'x26': 0,
  'x27': 0,
  'x28': 0,
  'x29': 1,
  'x3': 1,
  'x30': 0,
  'x31': 0,
  'x32': 0,
  'x33': 0,
  'x34': 1,
  'x35': 0,
  'x36': 1,
  'x37': 1,
  'x38': 1,
  'x39': 1,
  'x4': 1,
  'x40': 0,
  'x41': 0,
  'x42': 1,
  'x43': 0,
  'x44': 1,
  'x45': 1,
  'x46': 1,
  'x47': 0,
  'x48': 1,
  'x49': 1,
  'x5': 0,
  'x50': 0,
  'x51': 1,
  'x52': 0,
  'x53': 1,
  'x54': 0,
  'x55': 1,
  'x56': 0,
  'x57': 0,
  'x58': 1,
  'x59': 0,
  'x6': 0,
  'x60': 0,
  'x61': 0,
  'x62': 1,
  'x63': 1,
  'x64': 0,
  'x65': 1,
  'x66': 0,
  'x67': 1,
  'x68': 0,
  'x69': 1,
  'x7': 1,
  'x70': 1,
  'x71': 1,
  'x72': 0,
  'x73': 0,
  'x74': 1,
  'x75': 0,
  'x76': 0,
  'x77': 1,
  'x78': 1,
  'x79': 1,
  'x8': 1,
  'x80': 1,
  'x81': 0,
  'x82': 0,
  'x83': 1,
  'x84': 0,
  'x85': 1,
  'x86': 0,
  'x87': 0,
  'x88': 0,
  'x89': 1,
  'x9': 1,
  'x90': 1,
  'x91': 0,
  'x92': 1,
  'x93': 1,
  'x94': 1,
  'x95': 1,
  'x96': 0,
  'x97': 0,
  'x98': 0,
  'x99': 1,
})

[2024-09-05 06:43:26,678][basic_search][INFO][generic_smbo.py:310] Iter 8, objectives: [inf].
[2024-09-05 06:43:26,681][basic_search][WARNING][generic_advisor.py:467] No enough successful initial trials! Sample random configuration.
[2024-09-05 06:43:26,685][basic_search][ERROR][generic_smbo.py:290] Exception in objective function:
Traceback (most recent call last):
  File "/gyc_data/fray_data/py38hwvenv/lib/python3.8/site-packages/openbox/utils/limit.py", line 62, in run_without_time_limit
    ret = obj_func(*obj_args, **obj_kwargs)
  File "BO_partition.py", line 72, in obj_func
    cost = self.black_box.get_cost_from_partitions(partitions)
  File "BO_partition.py", line 34, in get_cost_from_partitions
    partitions_cpp[i]=partitions[i]
IndexError: list index out of range

config: Configuration(values={
  'x0': 1,
  'x1': 0,
  'x10': 1,
  'x100': 1,
  'x101': 0,
  'x102': 1,
  'x103': 1,
  'x104': 1,
  'x105': 0,
  'x106': 1,
  'x107': 1,
  'x108': 0,
  'x109': 1,
  'x11': 0,
  'x110': 1,
  'x111': 0,
  'x112': 0,
  'x113': 1,
  'x114': 0,
  'x115': 0,
  'x116': 0,
  'x117': 0,
  'x118': 1,
  'x119': 0,
  'x12': 0,
  'x120': 0,
  'x121': 1,
  'x122': 0,
  'x123': 0,
  'x124': 0,
  'x125': 1,
  'x126': 0,
  'x127': 1,
  'x128': 0,
  'x129': 0,
  'x13': 1,
  'x130': 1,
  'x131': 1,
  'x132': 1,
  'x133': 0,
  'x134': 0,
  'x135': 0,
  'x136': 0,
  'x137': 0,
  'x138': 0,
  'x139': 0,
  'x14': 1,
  'x140': 1,
  'x141': 1,
  'x142': 1,
  'x143': 1,
  'x144': 0,
  'x145': 0,
  'x15': 1,
  'x16': 0,
  'x17': 1,
  'x18': 1,
  'x19': 0,
  'x2': 0,
  'x20': 0,
  'x21': 0,
  'x22': 0,
  'x23': 0,
  'x24': 0,
  'x25': 1,
  'x26': 1,
  'x27': 1,
  'x28': 0,
  'x29': 0,
  'x3': 0,
  'x30': 0,
  'x31': 0,
  'x32': 0,
  'x33': 0,
  'x34': 1,
  'x35': 0,
  'x36': 0,
  'x37': 0,
  'x38': 0,
  'x39': 1,
  'x4': 1,
  'x40': 0,
  'x41': 0,
  'x42': 0,
  'x43': 1,
  'x44': 1,
  'x45': 0,
  'x46': 1,
  'x47': 1,
  'x48': 1,
  'x49': 0,
  'x5': 0,
  'x50': 0,
  'x51': 1,
  'x52': 1,
  'x53': 1,
  'x54': 0,
  'x55': 0,
  'x56': 0,
  'x57': 1,
  'x58': 0,
  'x59': 0,
  'x6': 0,
  'x60': 1,
  'x61': 1,
  'x62': 0,
  'x63': 0,
  'x64': 1,
  'x65': 0,
  'x66': 0,
  'x67': 0,
  'x68': 0,
  'x69': 0,
  'x7': 1,
  'x70': 0,
  'x71': 0,
  'x72': 0,
  'x73': 0,
  'x74': 1,
  'x75': 1,
  'x76': 1,
  'x77': 1,
  'x78': 0,
  'x79': 0,
  'x8': 0,
  'x80': 0,
  'x81': 0,
  'x82': 0,
  'x83': 1,
  'x84': 1,
  'x85': 1,
  'x86': 1,
  'x87': 0,
  'x88': 1,
  'x89': 1,
  'x9': 0,
  'x90': 1,
  'x91': 1,
  'x92': 0,
  'x93': 1,
  'x94': 0,
  'x95': 1,
  'x96': 1,
  'x97': 1,
  'x98': 1,
  'x99': 1,
})

[2024-09-05 06:43:26,685][basic_search][INFO][generic_smbo.py:310] Iter 9, objectives: [inf].
[2024-09-05 06:43:26,688][basic_search][WARNING][generic_advisor.py:467] No enough successful initial trials! Sample random configuration.
[2024-09-05 06:43:26,692][basic_search][ERROR][generic_smbo.py:290] Exception in objective function:
Traceback (most recent call last):
  File "/gyc_data/fray_data/py38hwvenv/lib/python3.8/site-packages/openbox/utils/limit.py", line 62, in run_without_time_limit
    ret = obj_func(*obj_args, **obj_kwargs)
  File "BO_partition.py", line 72, in obj_func
    cost = self.black_box.get_cost_from_partitions(partitions)
  File "BO_partition.py", line 34, in get_cost_from_partitions
    partitions_cpp[i]=partitions[i]
IndexError: list index out of range

config: Configuration(values={
  'x0': 1,
  'x1': 1,
  'x10': 0,
  'x100': 0,
  'x101': 1,
  'x102': 1,
  'x103': 0,
  'x104': 0,
  'x105': 0,
  'x106': 0,
  'x107': 0,
  'x108': 0,
  'x109': 0,
  'x11': 1,
  'x110': 1,
  'x111': 0,
  'x112': 0,
  'x113': 1,
  'x114': 0,
  'x115': 1,
  'x116': 0,
  'x117': 0,
  'x118': 0,
  'x119': 1,
  'x12': 1,
  'x120': 1,
  'x121': 1,
  'x122': 1,
  'x123': 0,
  'x124': 0,
  'x125': 1,
  'x126': 1,
  'x127': 1,
  'x128': 1,
  'x129': 0,
  'x13': 0,
  'x130': 0,
  'x131': 0,
  'x132': 1,
  'x133': 1,
  'x134': 1,
  'x135': 0,
  'x136': 1,
  'x137': 1,
  'x138': 1,
  'x139': 1,
  'x14': 1,
  'x140': 0,
  'x141': 0,
  'x142': 1,
  'x143': 1,
  'x144': 1,
  'x145': 0,
  'x15': 1,
  'x16': 1,
  'x17': 1,
  'x18': 1,
  'x19': 1,
  'x2': 1,
  'x20': 1,
  'x21': 0,
  'x22': 0,
  'x23': 0,
  'x24': 1,
  'x25': 0,
  'x26': 0,
  'x27': 1,
  'x28': 0,
  'x29': 1,
  'x3': 1,
  'x30': 1,
  'x31': 0,
  'x32': 0,
  'x33': 1,
  'x34': 1,
  'x35': 0,
  'x36': 1,
  'x37': 1,
  'x38': 1,
  'x39': 1,
  'x4': 0,
  'x40': 0,
  'x41': 0,
  'x42': 1,
  'x43': 1,
  'x44': 1,
  'x45': 0,
  'x46': 1,
  'x47': 1,
  'x48': 1,
  'x49': 1,
  'x5': 1,
  'x50': 1,
  'x51': 1,
  'x52': 0,
  'x53': 0,
  'x54': 1,
  'x55': 0,
  'x56': 0,
  'x57': 1,
  'x58': 1,
  'x59': 1,
  'x6': 1,
  'x60': 1,
  'x61': 1,
  'x62': 1,
  'x63': 0,
  'x64': 1,
  'x65': 1,
  'x66': 0,
  'x67': 1,
  'x68': 1,
  'x69': 0,
  'x7': 0,
  'x70': 1,
  'x71': 0,
  'x72': 1,
  'x73': 0,
  'x74': 0,
  'x75': 0,
  'x76': 1,
  'x77': 1,
  'x78': 1,
  'x79': 1,
  'x8': 1,
  'x80': 1,
  'x81': 1,
  'x82': 1,
  'x83': 0,
  'x84': 0,
  'x85': 1,
  'x86': 1,
  'x87': 0,
  'x88': 1,
  'x89': 1,
  'x9': 0,
  'x90': 0,
  'x91': 0,
  'x92': 0,
  'x93': 1,
  'x94': 0,
  'x95': 1,
  'x96': 1,
  'x97': 1,
  'x98': 0,
  'x99': 1,
})

[2024-09-05 06:43:26,692][basic_search][INFO][generic_smbo.py:310] Iter 10, objectives: [inf].
[2024-09-05 06:43:26,696][basic_search][WARNING][generic_advisor.py:467] No enough successful initial trials! Sample random configuration.
[2024-09-05 06:43:26,700][basic_search][ERROR][generic_smbo.py:290] Exception in objective function:
Traceback (most recent call last):
  File "/gyc_data/fray_data/py38hwvenv/lib/python3.8/site-packages/openbox/utils/limit.py", line 62, in run_without_time_limit
    ret = obj_func(*obj_args, **obj_kwargs)
  File "BO_partition.py", line 72, in obj_func
    cost = self.black_box.get_cost_from_partitions(partitions)
  File "BO_partition.py", line 34, in get_cost_from_partitions
    partitions_cpp[i]=partitions[i]
IndexError: list index out of range

config: Configuration(values={
  'x0': 0,
  'x1': 1,
  'x10': 1,
  'x100': 0,
  'x101': 0,
  'x102': 0,
  'x103': 1,
  'x104': 1,
  'x105': 1,
  'x106': 1,
  'x107': 0,
  'x108': 1,
  'x109': 1,
  'x11': 1,
  'x110': 1,
  'x111': 0,
  'x112': 1,
  'x113': 0,
  'x114': 1,
  'x115': 0,
  'x116': 1,
  'x117': 1,
  'x118': 1,
  'x119': 0,
  'x12': 1,
  'x120': 1,
  'x121': 1,
  'x122': 0,
  'x123': 0,
  'x124': 0,
  'x125': 0,
  'x126': 0,
  'x127': 0,
  'x128': 1,
  'x129': 1,
  'x13': 1,
  'x130': 0,
  'x131': 0,
  'x132': 1,
  'x133': 1,
  'x134': 1,
  'x135': 1,
  'x136': 0,
  'x137': 1,
  'x138': 0,
  'x139': 1,
  'x14': 1,
  'x140': 0,
  'x141': 1,
  'x142': 0,
  'x143': 0,
  'x144': 1,
  'x145': 1,
  'x15': 0,
  'x16': 0,
  'x17': 0,
  'x18': 1,
  'x19': 1,
  'x2': 0,
  'x20': 1,
  'x21': 1,
  'x22': 1,
  'x23': 1,
  'x24': 0,
  'x25': 0,
  'x26': 0,
  'x27': 1,
  'x28': 0,
  'x29': 1,
  'x3': 0,
  'x30': 1,
  'x31': 0,
  'x32': 1,
  'x33': 0,
  'x34': 1,
  'x35': 0,
  'x36': 1,
  'x37': 0,
  'x38': 1,
  'x39': 0,
  'x4': 1,
  'x40': 1,
  'x41': 1,
  'x42': 0,
  'x43': 0,
  'x44': 1,
  'x45': 0,
  'x46': 0,
  'x47': 0,
  'x48': 1,
  'x49': 1,
  'x5': 1,
  'x50': 0,
  'x51': 1,
  'x52': 1,
  'x53': 1,
  'x54': 0,
  'x55': 1,
  'x56': 0,
  'x57': 0,
  'x58': 0,
  'x59': 1,
  'x6': 1,
  'x60': 1,
  'x61': 0,
  'x62': 1,
  'x63': 0,
  'x64': 0,
  'x65': 1,
  'x66': 0,
  'x67': 0,
  'x68': 0,
  'x69': 0,
  'x7': 0,
  'x70': 1,
  'x71': 0,
  'x72': 1,
  'x73': 1,
  'x74': 0,
  'x75': 1,
  'x76': 0,
  'x77': 1,
  'x78': 0,
  'x79': 1,
  'x8': 0,
  'x80': 1,
  'x81': 1,
  'x82': 1,
  'x83': 1,
  'x84': 0,
  'x85': 1,
  'x86': 0,
  'x87': 1,
  'x88': 1,
  'x89': 1,
  'x9': 0,
  'x90': 0,
  'x91': 0,
  'x92': 0,
  'x93': 1,
  'x94': 1,
  'x95': 1,
  'x96': 1,
  'x97': 1,
  'x98': 0,
  'x99': 0,
})

[2024-09-05 06:43:26,700][basic_search][INFO][generic_smbo.py:310] Iter 11, objectives: [inf].
[2024-09-05 06:43:26,703][basic_search][INFO][generic_advisor.py:457] Sample random config. rand_prob=0.100000.
[2024-09-05 06:43:26,707][basic_search][ERROR][generic_smbo.py:290] Exception in objective function:
Traceback (most recent call last):
  File "/gyc_data/fray_data/py38hwvenv/lib/python3.8/site-packages/openbox/utils/limit.py", line 62, in run_without_time_limit
    ret = obj_func(*obj_args, **obj_kwargs)
  File "BO_partition.py", line 72, in obj_func
    cost = self.black_box.get_cost_from_partitions(partitions)
  File "BO_partition.py", line 34, in get_cost_from_partitions
    partitions_cpp[i]=partitions[i]
IndexError: list index out of range

config: Configuration(values={
  'x0': 1,
  'x1': 0,
  'x10': 0,
  'x100': 0,
  'x101': 0,
  'x102': 1,
  'x103': 1,
  'x104': 0,
  'x105': 1,
  'x106': 0,
  'x107': 1,
  'x108': 1,
  'x109': 0,
  'x11': 1,
  'x110': 1,
  'x111': 1,
  'x112': 1,
  'x113': 1,
  'x114': 1,
  'x115': 0,
  'x116': 1,
  'x117': 0,
  'x118': 1,
  'x119': 0,
  'x12': 1,
  'x120': 1,
  'x121': 0,
  'x122': 0,
  'x123': 1,
  'x124': 0,
  'x125': 0,
  'x126': 1,
  'x127': 0,
  'x128': 0,
  'x129': 1,
  'x13': 0,
  'x130': 0,
  'x131': 1,
  'x132': 0,
  'x133': 1,
  'x134': 0,
  'x135': 0,
  'x136': 1,
  'x137': 1,
  'x138': 1,
  'x139': 0,
  'x14': 1,
  'x140': 0,
  'x141': 1,
  'x142': 1,
  'x143': 0,
  'x144': 0,
  'x145': 0,
  'x15': 0,
  'x16': 0,
  'x17': 1,
  'x18': 0,
  'x19': 0,
  'x2': 1,
  'x20': 1,
  'x21': 0,
  'x22': 0,
  'x23': 0,
  'x24': 1,
  'x25': 0,
  'x26': 0,
  'x27': 1,
  'x28': 1,
  'x29': 0,
  'x3': 0,
  'x30': 0,
  'x31': 1,
  'x32': 0,
  'x33': 1,
  'x34': 1,
  'x35': 0,
  'x36': 0,
  'x37': 0,
  'x38': 1,
  'x39': 0,
  'x4': 0,
  'x40': 1,
  'x41': 0,
  'x42': 0,
  'x43': 0,
  'x44': 0,
  'x45': 0,
  'x46': 1,
  'x47': 1,
  'x48': 0,
  'x49': 1,
  'x5': 1,
  'x50': 0,
  'x51': 0,
  'x52': 1,
  'x53': 0,
  'x54': 0,
  'x55': 0,
  'x56': 1,
  'x57': 1,
  'x58': 1,
  'x59': 0,
  'x6': 1,
  'x60': 0,
  'x61': 1,
  'x62': 0,
  'x63': 1,
  'x64': 0,
  'x65': 1,
  'x66': 1,
  'x67': 1,
  'x68': 0,
  'x69': 0,
  'x7': 1,
  'x70': 0,
  'x71': 1,
  'x72': 0,
  'x73': 0,
  'x74': 1,
  'x75': 1,
  'x76': 1,
  'x77': 1,
  'x78': 0,
  'x79': 1,
  'x8': 1,
  'x80': 0,
  'x81': 0,
  'x82': 0,
  'x83': 0,
  'x84': 0,
  'x85': 1,
  'x86': 0,
  'x87': 1,
  'x88': 0,
  'x89': 1,
  'x9': 1,
  'x90': 0,
  'x91': 1,
  'x92': 0,
  'x93': 1,
  'x94': 0,
  'x95': 1,
  'x96': 0,
  'x97': 0,
  'x98': 1,
  'x99': 1,
})

[2024-09-05 06:43:26,707][basic_search][INFO][generic_smbo.py:310] Iter 12, objectives: [inf].
[2024-09-05 06:43:26,711][basic_search][WARNING][generic_advisor.py:467] No enough successful initial trials! Sample random configuration.
[2024-09-05 06:43:26,715][basic_search][ERROR][generic_smbo.py:290] Exception in objective function:
Traceback (most recent call last):
  File "/gyc_data/fray_data/py38hwvenv/lib/python3.8/site-packages/openbox/utils/limit.py", line 62, in run_without_time_limit
    ret = obj_func(*obj_args, **obj_kwargs)
  File "BO_partition.py", line 72, in obj_func
    cost = self.black_box.get_cost_from_partitions(partitions)
  File "BO_partition.py", line 34, in get_cost_from_partitions
    partitions_cpp[i]=partitions[i]
IndexError: list index out of range

config: Configuration(values={
  'x0': 0,
  'x1': 1,
  'x10': 0,
  'x100': 1,
  'x101': 1,
  'x102': 0,
  'x103': 0,
  'x104': 1,
  'x105': 0,
  'x106': 1,
  'x107': 1,
  'x108': 0,
  'x109': 1,
  'x11': 0,
  'x110': 0,
  'x111': 0,
  'x112': 1,
  'x113': 1,
  'x114': 1,
  'x115': 0,
  'x116': 1,
  'x117': 0,
  'x118': 1,
  'x119': 0,
  'x12': 1,
  'x120': 1,
  'x121': 0,
  'x122': 1,
  'x123': 1,
  'x124': 0,
  'x125': 1,
  'x126': 1,
  'x127': 0,
  'x128': 1,
  'x129': 0,
  'x13': 0,
  'x130': 0,
  'x131': 0,
  'x132': 0,
  'x133': 0,
  'x134': 0,
  'x135': 1,
  'x136': 0,
  'x137': 0,
  'x138': 1,
  'x139': 1,
  'x14': 0,
  'x140': 0,
  'x141': 1,
  'x142': 1,
  'x143': 1,
  'x144': 0,
  'x145': 0,
  'x15': 1,
  'x16': 1,
  'x17': 1,
  'x18': 0,
  'x19': 0,
  'x2': 0,
  'x20': 0,
  'x21': 1,
  'x22': 1,
  'x23': 0,
  'x24': 1,
  'x25': 0,
  'x26': 1,
  'x27': 0,
  'x28': 0,
  'x29': 0,
  'x3': 1,
  'x30': 0,
  'x31': 0,
  'x32': 0,
  'x33': 0,
  'x34': 1,
  'x35': 1,
  'x36': 1,
  'x37': 1,
  'x38': 1,
  'x39': 1,
  'x4': 1,
  'x40': 0,
  'x41': 1,
  'x42': 1,
  'x43': 0,
  'x44': 0,
  'x45': 0,
  'x46': 1,
  'x47': 0,
  'x48': 0,
  'x49': 1,
  'x5': 0,
  'x50': 1,
  'x51': 1,
  'x52': 1,
  'x53': 1,
  'x54': 1,
  'x55': 0,
  'x56': 1,
  'x57': 1,
  'x58': 0,
  'x59': 1,
  'x6': 1,
  'x60': 0,
  'x61': 1,
  'x62': 0,
  'x63': 1,
  'x64': 0,
  'x65': 0,
  'x66': 0,
  'x67': 0,
  'x68': 0,
  'x69': 0,
  'x7': 0,
  'x70': 0,
  'x71': 0,
  'x72': 1,
  'x73': 0,
  'x74': 1,
  'x75': 1,
  'x76': 1,
  'x77': 0,
  'x78': 1,
  'x79': 0,
  'x8': 0,
  'x80': 0,
  'x81': 0,
  'x82': 1,
  'x83': 0,
  'x84': 0,
  'x85': 1,
  'x86': 0,
  'x87': 0,
  'x88': 1,
  'x89': 0,
  'x9': 1,
  'x90': 0,
  'x91': 0,
  'x92': 1,
  'x93': 0,
  'x94': 0,
  'x95': 0,
  'x96': 0,
  'x97': 1,
  'x98': 0,
  'x99': 0,
})

[2024-09-05 06:43:26,716][basic_search][INFO][generic_smbo.py:310] Iter 13, objectives: [inf].
[2024-09-05 06:43:26,720][basic_search][WARNING][generic_advisor.py:467] No enough successful initial trials! Sample random configuration.
[2024-09-05 06:43:26,724][basic_search][ERROR][generic_smbo.py:290] Exception in objective function:
Traceback (most recent call last):
  File "/gyc_data/fray_data/py38hwvenv/lib/python3.8/site-packages/openbox/utils/limit.py", line 62, in run_without_time_limit
    ret = obj_func(*obj_args, **obj_kwargs)
  File "BO_partition.py", line 72, in obj_func
    cost = self.black_box.get_cost_from_partitions(partitions)
  File "BO_partition.py", line 34, in get_cost_from_partitions
    partitions_cpp[i]=partitions[i]
IndexError: list index out of range

config: Configuration(values={
  'x0': 1,
  'x1': 0,
  'x10': 1,
  'x100': 0,
  'x101': 0,
  'x102': 0,
  'x103': 0,
  'x104': 1,
  'x105': 1,
  'x106': 1,
  'x107': 0,
  'x108': 1,
  'x109': 0,
  'x11': 0,
  'x110': 1,
  'x111': 0,
  'x112': 1,
  'x113': 1,
  'x114': 0,
  'x115': 1,
  'x116': 0,
  'x117': 0,
  'x118': 0,
  'x119': 0,
  'x12': 1,
  'x120': 0,
  'x121': 0,
  'x122': 0,
  'x123': 0,
  'x124': 0,
  'x125': 0,
  'x126': 1,
  'x127': 0,
  'x128': 1,
  'x129': 0,
  'x13': 1,
  'x130': 0,
  'x131': 1,
  'x132': 0,
  'x133': 1,
  'x134': 0,
  'x135': 1,
  'x136': 1,
  'x137': 0,
  'x138': 1,
  'x139': 0,
  'x14': 0,
  'x140': 0,
  'x141': 1,
  'x142': 1,
  'x143': 0,
  'x144': 0,
  'x145': 0,
  'x15': 0,
  'x16': 0,
  'x17': 0,
  'x18': 0,
  'x19': 0,
  'x2': 0,
  'x20': 1,
  'x21': 1,
  'x22': 0,
  'x23': 1,
  'x24': 0,
  'x25': 0,
  'x26': 1,
  'x27': 0,
  'x28': 0,
  'x29': 0,
  'x3': 0,
  'x30': 0,
  'x31': 1,
  'x32': 1,
  'x33': 0,
  'x34': 0,
  'x35': 1,
  'x36': 0,
  'x37': 1,
  'x38': 1,
  'x39': 0,
  'x4': 0,
  'x40': 1,
  'x41': 1,
  'x42': 1,
  'x43': 0,
  'x44': 1,
  'x45': 0,
  'x46': 1,
  'x47': 0,
  'x48': 1,
  'x49': 0,
  'x5': 0,
  'x50': 0,
  'x51': 1,
  'x52': 0,
  'x53': 1,
  'x54': 0,
  'x55': 0,
  'x56': 1,
  'x57': 1,
  'x58': 0,
  'x59': 1,
  'x6': 0,
  'x60': 0,
  'x61': 1,
  'x62': 0,
  'x63': 1,
  'x64': 1,
  'x65': 0,
  'x66': 1,
  'x67': 1,
  'x68': 0,
  'x69': 0,
  'x7': 0,
  'x70': 0,
  'x71': 0,
  'x72': 1,
  'x73': 1,
  'x74': 0,
  'x75': 1,
  'x76': 1,
  'x77': 1,
  'x78': 0,
  'x79': 0,
  'x8': 0,
  'x80': 1,
  'x81': 1,
  'x82': 0,
  'x83': 0,
  'x84': 0,
  'x85': 1,
  'x86': 1,
  'x87': 0,
  'x88': 0,
  'x89': 1,
  'x9': 1,
  'x90': 1,
  'x91': 0,
  'x92': 0,
  'x93': 1,
  'x94': 0,
  'x95': 0,
  'x96': 0,
  'x97': 1,
  'x98': 1,
  'x99': 0,
})

[2024-09-05 06:43:26,724][basic_search][INFO][generic_smbo.py:310] Iter 14, objectives: [inf].
[2024-09-05 06:43:26,728][basic_search][WARNING][generic_advisor.py:467] No enough successful initial trials! Sample random configuration.
[2024-09-05 06:43:26,732][basic_search][ERROR][generic_smbo.py:290] Exception in objective function:
Traceback (most recent call last):
  File "/gyc_data/fray_data/py38hwvenv/lib/python3.8/site-packages/openbox/utils/limit.py", line 62, in run_without_time_limit
    ret = obj_func(*obj_args, **obj_kwargs)
  File "BO_partition.py", line 72, in obj_func
    cost = self.black_box.get_cost_from_partitions(partitions)
  File "BO_partition.py", line 34, in get_cost_from_partitions
    partitions_cpp[i]=partitions[i]
IndexError: list index out of range

config: Configuration(values={
  'x0': 1,
  'x1': 0,
  'x10': 0,
  'x100': 1,
  'x101': 1,
  'x102': 1,
  'x103': 0,
  'x104': 0,
  'x105': 1,
  'x106': 0,
  'x107': 1,
  'x108': 1,
  'x109': 0,
  'x11': 0,
  'x110': 1,
  'x111': 0,
  'x112': 1,
  'x113': 0,
  'x114': 1,
  'x115': 1,
  'x116': 1,
  'x117': 0,
  'x118': 0,
  'x119': 1,
  'x12': 1,
  'x120': 0,
  'x121': 0,
  'x122': 0,
  'x123': 0,
  'x124': 1,
  'x125': 1,
  'x126': 0,
  'x127': 1,
  'x128': 1,
  'x129': 0,
  'x13': 1,
  'x130': 0,
  'x131': 1,
  'x132': 0,
  'x133': 0,
  'x134': 0,
  'x135': 0,
  'x136': 1,
  'x137': 1,
  'x138': 1,
  'x139': 0,
  'x14': 0,
  'x140': 0,
  'x141': 0,
  'x142': 1,
  'x143': 1,
  'x144': 1,
  'x145': 1,
  'x15': 0,
  'x16': 1,
  'x17': 1,
  'x18': 0,
  'x19': 0,
  'x2': 1,
  'x20': 0,
  'x21': 0,
  'x22': 1,
  'x23': 1,
  'x24': 0,
  'x25': 1,
  'x26': 0,
  'x27': 1,
  'x28': 1,
  'x29': 1,
  'x3': 1,
  'x30': 1,
  'x31': 0,
  'x32': 1,
  'x33': 0,
  'x34': 1,
  'x35': 0,
  'x36': 0,
  'x37': 0,
  'x38': 1,
  'x39': 1,
  'x4': 0,
  'x40': 0,
  'x41': 0,
  'x42': 0,
  'x43': 0,
  'x44': 1,
  'x45': 0,
  'x46': 1,
  'x47': 0,
  'x48': 1,
  'x49': 0,
  'x5': 0,
  'x50': 0,
  'x51': 1,
  'x52': 0,
  'x53': 1,
  'x54': 1,
  'x55': 0,
  'x56': 0,
  'x57': 0,
  'x58': 1,
  'x59': 1,
  'x6': 1,
  'x60': 0,
  'x61': 0,
  'x62': 1,
  'x63': 0,
  'x64': 1,
  'x65': 1,
  'x66': 0,
  'x67': 0,
  'x68': 1,
  'x69': 1,
  'x7': 0,
  'x70': 0,
  'x71': 0,
  'x72': 1,
  'x73': 0,
  'x74': 1,
  'x75': 0,
  'x76': 1,
  'x77': 1,
  'x78': 1,
  'x79': 0,
  'x8': 1,
  'x80': 0,
  'x81': 1,
  'x82': 1,
  'x83': 1,
  'x84': 1,
  'x85': 1,
  'x86': 0,
  'x87': 1,
  'x88': 0,
  'x89': 0,
  'x9': 1,
  'x90': 1,
  'x91': 1,
  'x92': 0,
  'x93': 1,
  'x94': 1,
  'x95': 0,
  'x96': 0,
  'x97': 0,
  'x98': 0,
  'x99': 1,
})

[2024-09-05 06:43:26,732][basic_search][INFO][generic_smbo.py:310] Iter 15, objectives: [inf].
[2024-09-05 06:43:26,737][basic_search][WARNING][generic_advisor.py:467] No enough successful initial trials! Sample random configuration.
[2024-09-05 06:43:26,741][basic_search][ERROR][generic_smbo.py:290] Exception in objective function:
Traceback (most recent call last):
  File "/gyc_data/fray_data/py38hwvenv/lib/python3.8/site-packages/openbox/utils/limit.py", line 62, in run_without_time_limit
    ret = obj_func(*obj_args, **obj_kwargs)
  File "BO_partition.py", line 72, in obj_func
    cost = self.black_box.get_cost_from_partitions(partitions)
  File "BO_partition.py", line 34, in get_cost_from_partitions
    partitions_cpp[i]=partitions[i]
IndexError: list index out of range

config: Configuration(values={
  'x0': 0,
  'x1': 0,
  'x10': 0,
  'x100': 1,
  'x101': 1,
  'x102': 1,
  'x103': 0,
  'x104': 1,
  'x105': 0,
  'x106': 1,
  'x107': 0,
  'x108': 0,
  'x109': 0,
  'x11': 1,
  'x110': 0,
  'x111': 0,
  'x112': 1,
  'x113': 0,
  'x114': 1,
  'x115': 0,
  'x116': 0,
  'x117': 1,
  'x118': 0,
  'x119': 1,
  'x12': 1,
  'x120': 0,
  'x121': 0,
  'x122': 1,
  'x123': 0,
  'x124': 1,
  'x125': 1,
  'x126': 0,
  'x127': 0,
  'x128': 0,
  'x129': 1,
  'x13': 0,
  'x130': 1,
  'x131': 0,
  'x132': 0,
  'x133': 1,
  'x134': 1,
  'x135': 0,
  'x136': 0,
  'x137': 0,
  'x138': 0,
  'x139': 0,
  'x14': 0,
  'x140': 1,
  'x141': 0,
  'x142': 1,
  'x143': 1,
  'x144': 1,
  'x145': 0,
  'x15': 0,
  'x16': 1,
  'x17': 1,
  'x18': 0,
  'x19': 0,
  'x2': 1,
  'x20': 1,
  'x21': 0,
  'x22': 1,
  'x23': 0,
  'x24': 1,
  'x25': 1,
  'x26': 1,
  'x27': 1,
  'x28': 0,
  'x29': 1,
  'x3': 1,
  'x30': 1,
  'x31': 1,
  'x32': 1,
  'x33': 0,
  'x34': 0,
  'x35': 1,
  'x36': 1,
  'x37': 0,
  'x38': 0,
  'x39': 1,
  'x4': 1,
  'x40': 1,
  'x41': 1,
  'x42': 1,
  'x43': 1,
  'x44': 0,
  'x45': 0,
  'x46': 0,
  'x47': 0,
  'x48': 0,
  'x49': 0,
  'x5': 0,
  'x50': 0,
  'x51': 0,
  'x52': 0,
  'x53': 1,
  'x54': 0,
  'x55': 0,
  'x56': 0,
  'x57': 1,
  'x58': 1,
  'x59': 0,
  'x6': 0,
  'x60': 0,
  'x61': 1,
  'x62': 0,
  'x63': 1,
  'x64': 0,
  'x65': 0,
  'x66': 0,
  'x67': 1,
  'x68': 0,
  'x69': 0,
  'x7': 1,
  'x70': 0,
  'x71': 0,
  'x72': 1,
  'x73': 0,
  'x74': 1,
  'x75': 1,
  'x76': 1,
  'x77': 1,
  'x78': 1,
  'x79': 1,
  'x8': 1,
  'x80': 0,
  'x81': 0,
  'x82': 0,
  'x83': 0,
  'x84': 1,
  'x85': 1,
  'x86': 0,
  'x87': 1,
  'x88': 0,
  'x89': 0,
  'x9': 1,
  'x90': 1,
  'x91': 0,
  'x92': 0,
  'x93': 1,
  'x94': 0,
  'x95': 0,
  'x96': 0,
  'x97': 1,
  'x98': 0,
  'x99': 1,
})

[2024-09-05 06:43:26,741][basic_search][INFO][generic_smbo.py:310] Iter 16, objectives: [inf].
[2024-09-05 06:43:26,746][basic_search][WARNING][generic_advisor.py:467] No enough successful initial trials! Sample random configuration.
[2024-09-05 06:43:26,750][basic_search][ERROR][generic_smbo.py:290] Exception in objective function:
Traceback (most recent call last):
  File "/gyc_data/fray_data/py38hwvenv/lib/python3.8/site-packages/openbox/utils/limit.py", line 62, in run_without_time_limit
    ret = obj_func(*obj_args, **obj_kwargs)
  File "BO_partition.py", line 72, in obj_func
    cost = self.black_box.get_cost_from_partitions(partitions)
  File "BO_partition.py", line 34, in get_cost_from_partitions
    partitions_cpp[i]=partitions[i]
IndexError: list index out of range

config: Configuration(values={
  'x0': 0,
  'x1': 1,
  'x10': 1,
  'x100': 0,
  'x101': 1,
  'x102': 0,
  'x103': 1,
  'x104': 1,
  'x105': 1,
  'x106': 0,
  'x107': 1,
  'x108': 0,
  'x109': 1,
  'x11': 0,
  'x110': 1,
  'x111': 1,
  'x112': 0,
  'x113': 0,
  'x114': 1,
  'x115': 0,
  'x116': 1,
  'x117': 0,
  'x118': 1,
  'x119': 1,
  'x12': 0,
  'x120': 0,
  'x121': 0,
  'x122': 1,
  'x123': 1,
  'x124': 1,
  'x125': 1,
  'x126': 1,
  'x127': 0,
  'x128': 0,
  'x129': 1,
  'x13': 0,
  'x130': 1,
  'x131': 1,
  'x132': 1,
  'x133': 1,
  'x134': 1,
  'x135': 0,
  'x136': 1,
  'x137': 1,
  'x138': 0,
  'x139': 1,
  'x14': 1,
  'x140': 1,
  'x141': 1,
  'x142': 1,
  'x143': 0,
  'x144': 1,
  'x145': 0,
  'x15': 0,
  'x16': 0,
  'x17': 0,
  'x18': 1,
  'x19': 1,
  'x2': 1,
  'x20': 0,
  'x21': 0,
  'x22': 1,
  'x23': 1,
  'x24': 0,
  'x25': 1,
  'x26': 0,
  'x27': 1,
  'x28': 1,
  'x29': 1,
  'x3': 0,
  'x30': 0,
  'x31': 0,
  'x32': 0,
  'x33': 1,
  'x34': 0,
  'x35': 0,
  'x36': 1,
  'x37': 0,
  'x38': 0,
  'x39': 1,
  'x4': 1,
  'x40': 0,
  'x41': 1,
  'x42': 0,
  'x43': 0,
  'x44': 1,
  'x45': 0,
  'x46': 1,
  'x47': 1,
  'x48': 1,
  'x49': 0,
  'x5': 1,
  'x50': 1,
  'x51': 1,
  'x52': 0,
  'x53': 0,
  'x54': 1,
  'x55': 1,
  'x56': 1,
  'x57': 0,
  'x58': 0,
  'x59': 0,
  'x6': 1,
  'x60': 1,
  'x61': 1,
  'x62': 1,
  'x63': 1,
  'x64': 1,
  'x65': 0,
  'x66': 1,
  'x67': 0,
  'x68': 1,
  'x69': 1,
  'x7': 0,
  'x70': 0,
  'x71': 1,
  'x72': 1,
  'x73': 0,
  'x74': 1,
  'x75': 0,
  'x76': 1,
  'x77': 1,
  'x78': 1,
  'x79': 0,
  'x8': 0,
  'x80': 1,
  'x81': 1,
  'x82': 0,
  'x83': 1,
  'x84': 0,
  'x85': 1,
  'x86': 1,
  'x87': 0,
  'x88': 0,
  'x89': 0,
  'x9': 1,
  'x90': 0,
  'x91': 1,
  'x92': 0,
  'x93': 0,
  'x94': 1,
  'x95': 1,
  'x96': 1,
  'x97': 1,
  'x98': 1,
  'x99': 1,
})

[2024-09-05 06:43:26,750][basic_search][INFO][generic_smbo.py:310] Iter 17, objectives: [inf].
[2024-09-05 06:43:26,756][basic_search][WARNING][generic_advisor.py:467] No enough successful initial trials! Sample random configuration.
[2024-09-05 06:43:26,760][basic_search][ERROR][generic_smbo.py:290] Exception in objective function:
Traceback (most recent call last):
  File "/gyc_data/fray_data/py38hwvenv/lib/python3.8/site-packages/openbox/utils/limit.py", line 62, in run_without_time_limit
    ret = obj_func(*obj_args, **obj_kwargs)
  File "BO_partition.py", line 72, in obj_func
    cost = self.black_box.get_cost_from_partitions(partitions)
  File "BO_partition.py", line 34, in get_cost_from_partitions
    partitions_cpp[i]=partitions[i]
IndexError: list index out of range

config: Configuration(values={
  'x0': 1,
  'x1': 1,
  'x10': 1,
  'x100': 1,
  'x101': 0,
  'x102': 0,
  'x103': 0,
  'x104': 0,
  'x105': 1,
  'x106': 1,
  'x107': 1,
  'x108': 0,
  'x109': 1,
  'x11': 1,
  'x110': 0,
  'x111': 1,
  'x112': 0,
  'x113': 1,
  'x114': 0,
  'x115': 0,
  'x116': 0,
  'x117': 1,
  'x118': 1,
  'x119': 1,
  'x12': 1,
  'x120': 0,
  'x121': 1,
  'x122': 1,
  'x123': 0,
  'x124': 1,
  'x125': 0,
  'x126': 0,
  'x127': 1,
  'x128': 1,
  'x129': 1,
  'x13': 1,
  'x130': 0,
  'x131': 1,
  'x132': 1,
  'x133': 1,
  'x134': 1,
  'x135': 1,
  'x136': 1,
  'x137': 1,
  'x138': 0,
  'x139': 1,
  'x14': 0,
  'x140': 0,
  'x141': 1,
  'x142': 0,
  'x143': 1,
  'x144': 0,
  'x145': 0,
  'x15': 0,
  'x16': 1,
  'x17': 1,
  'x18': 1,
  'x19': 0,
  'x2': 0,
  'x20': 1,
  'x21': 0,
  'x22': 0,
  'x23': 0,
  'x24': 1,
  'x25': 1,
  'x26': 0,
  'x27': 1,
  'x28': 1,
  'x29': 1,
  'x3': 0,
  'x30': 1,
  'x31': 1,
  'x32': 1,
  'x33': 1,
  'x34': 0,
  'x35': 0,
  'x36': 0,
  'x37': 1,
  'x38': 1,
  'x39': 1,
  'x4': 0,
  'x40': 0,
  'x41': 0,
  'x42': 1,
  'x43': 0,
  'x44': 0,
  'x45': 1,
  'x46': 1,
  'x47': 0,
  'x48': 0,
  'x49': 0,
  'x5': 1,
  'x50': 1,
  'x51': 0,
  'x52': 0,
  'x53': 0,
  'x54': 1,
  'x55': 0,
  'x56': 0,
  'x57': 1,
  'x58': 1,
  'x59': 1,
  'x6': 0,
  'x60': 1,
  'x61': 0,
  'x62': 0,
  'x63': 1,
  'x64': 0,
  'x65': 1,
  'x66': 0,
  'x67': 1,
  'x68': 1,
  'x69': 0,
  'x7': 0,
  'x70': 0,
  'x71': 0,
  'x72': 0,
  'x73': 1,
  'x74': 0,
  'x75': 1,
  'x76': 0,
  'x77': 1,
  'x78': 0,
  'x79': 0,
  'x8': 0,
  'x80': 1,
  'x81': 1,
  'x82': 1,
  'x83': 0,
  'x84': 0,
  'x85': 1,
  'x86': 0,
  'x87': 1,
  'x88': 0,
  'x89': 1,
  'x9': 0,
  'x90': 1,
  'x91': 0,
  'x92': 0,
  'x93': 1,
  'x94': 0,
  'x95': 1,
  'x96': 1,
  'x97': 1,
  'x98': 1,
  'x99': 1,
})

[2024-09-05 06:43:26,760][basic_search][INFO][generic_smbo.py:310] Iter 18, objectives: [inf].
[2024-09-05 06:43:26,766][basic_search][WARNING][generic_advisor.py:467] No enough successful initial trials! Sample random configuration.
[2024-09-05 06:43:26,769][basic_search][ERROR][generic_smbo.py:290] Exception in objective function:
Traceback (most recent call last):
  File "/gyc_data/fray_data/py38hwvenv/lib/python3.8/site-packages/openbox/utils/limit.py", line 62, in run_without_time_limit
    ret = obj_func(*obj_args, **obj_kwargs)
  File "BO_partition.py", line 72, in obj_func
    cost = self.black_box.get_cost_from_partitions(partitions)
  File "BO_partition.py", line 34, in get_cost_from_partitions
    partitions_cpp[i]=partitions[i]
IndexError: list index out of range

config: Configuration(values={
  'x0': 1,
  'x1': 1,
  'x10': 0,
  'x100': 1,
  'x101': 1,
  'x102': 0,
  'x103': 1,
  'x104': 0,
  'x105': 0,
  'x106': 0,
  'x107': 0,
  'x108': 0,
  'x109': 0,
  'x11': 1,
  'x110': 1,
  'x111': 1,
  'x112': 0,
  'x113': 0,
  'x114': 0,
  'x115': 0,
  'x116': 1,
  'x117': 0,
  'x118': 1,
  'x119': 0,
  'x12': 0,
  'x120': 1,
  'x121': 1,
  'x122': 1,
  'x123': 0,
  'x124': 0,
  'x125': 1,
  'x126': 1,
  'x127': 1,
  'x128': 0,
  'x129': 1,
  'x13': 1,
  'x130': 1,
  'x131': 0,
  'x132': 1,
  'x133': 1,
  'x134': 0,
  'x135': 1,
  'x136': 1,
  'x137': 1,
  'x138': 1,
  'x139': 0,
  'x14': 0,
  'x140': 0,
  'x141': 1,
  'x142': 1,
  'x143': 1,
  'x144': 0,
  'x145': 0,
  'x15': 1,
  'x16': 1,
  'x17': 1,
  'x18': 1,
  'x19': 0,
  'x2': 0,
  'x20': 1,
  'x21': 1,
  'x22': 0,
  'x23': 0,
  'x24': 1,
  'x25': 1,
  'x26': 1,
  'x27': 1,
  'x28': 1,
  'x29': 0,
  'x3': 0,
  'x30': 0,
  'x31': 0,
  'x32': 1,
  'x33': 1,
  'x34': 1,
  'x35': 0,
  'x36': 1,
  'x37': 0,
  'x38': 1,
  'x39': 1,
  'x4': 0,
  'x40': 1,
  'x41': 1,
  'x42': 1,
  'x43': 0,
  'x44': 1,
  'x45': 1,
  'x46': 0,
  'x47': 1,
  'x48': 1,
  'x49': 1,
  'x5': 0,
  'x50': 0,
  'x51': 0,
  'x52': 0,
  'x53': 0,
  'x54': 1,
  'x55': 1,
  'x56': 0,
  'x57': 0,
  'x58': 1,
  'x59': 0,
  'x6': 1,
  'x60': 1,
  'x61': 0,
  'x62': 1,
  'x63': 1,
  'x64': 0,
  'x65': 1,
  'x66': 0,
  'x67': 1,
  'x68': 0,
  'x69': 0,
  'x7': 0,
  'x70': 1,
  'x71': 0,
  'x72': 0,
  'x73': 0,
  'x74': 0,
  'x75': 1,
  'x76': 1,
  'x77': 0,
  'x78': 1,
  'x79': 0,
  'x8': 0,
  'x80': 1,
  'x81': 0,
  'x82': 0,
  'x83': 1,
  'x84': 0,
  'x85': 0,
  'x86': 0,
  'x87': 0,
  'x88': 1,
  'x89': 1,
  'x9': 1,
  'x90': 0,
  'x91': 1,
  'x92': 1,
  'x93': 1,
  'x94': 1,
  'x95': 0,
  'x96': 0,
  'x97': 1,
  'x98': 0,
  'x99': 1,
})

[2024-09-05 06:43:26,770][basic_search][INFO][generic_smbo.py:310] Iter 19, objectives: [inf].
[2024-09-05 06:43:26,776][basic_search][WARNING][generic_advisor.py:467] No enough successful initial trials! Sample random configuration.
[2024-09-05 06:43:26,779][basic_search][ERROR][generic_smbo.py:290] Exception in objective function:
Traceback (most recent call last):
  File "/gyc_data/fray_data/py38hwvenv/lib/python3.8/site-packages/openbox/utils/limit.py", line 62, in run_without_time_limit
    ret = obj_func(*obj_args, **obj_kwargs)
  File "BO_partition.py", line 72, in obj_func
    cost = self.black_box.get_cost_from_partitions(partitions)
  File "BO_partition.py", line 34, in get_cost_from_partitions
    partitions_cpp[i]=partitions[i]
IndexError: list index out of range

config: Configuration(values={
  'x0': 1,
  'x1': 0,
  'x10': 1,
  'x100': 1,
  'x101': 1,
  'x102': 0,
  'x103': 0,
  'x104': 1,
  'x105': 1,
  'x106': 1,
  'x107': 1,
  'x108': 1,
  'x109': 1,
  'x11': 0,
  'x110': 1,
  'x111': 1,
  'x112': 0,
  'x113': 0,
  'x114': 0,
  'x115': 0,
  'x116': 1,
  'x117': 0,
  'x118': 0,
  'x119': 0,
  'x12': 1,
  'x120': 1,
  'x121': 0,
  'x122': 0,
  'x123': 0,
  'x124': 1,
  'x125': 1,
  'x126': 0,
  'x127': 1,
  'x128': 0,
  'x129': 1,
  'x13': 1,
  'x130': 0,
  'x131': 0,
  'x132': 1,
  'x133': 1,
  'x134': 0,
  'x135': 1,
  'x136': 1,
  'x137': 0,
  'x138': 1,
  'x139': 0,
  'x14': 0,
  'x140': 1,
  'x141': 0,
  'x142': 0,
  'x143': 0,
  'x144': 1,
  'x145': 1,
  'x15': 0,
  'x16': 1,
  'x17': 0,
  'x18': 1,
  'x19': 0,
  'x2': 1,
  'x20': 0,
  'x21': 1,
  'x22': 0,
  'x23': 0,
  'x24': 0,
  'x25': 0,
  'x26': 0,
  'x27': 1,
  'x28': 1,
  'x29': 1,
  'x3': 1,
  'x30': 1,
  'x31': 0,
  'x32': 0,
  'x33': 1,
  'x34': 1,
  'x35': 0,
  'x36': 1,
  'x37': 0,
  'x38': 1,
  'x39': 1,
  'x4': 1,
  'x40': 0,
  'x41': 1,
  'x42': 1,
  'x43': 1,
  'x44': 1,
  'x45': 1,
  'x46': 1,
  'x47': 0,
  'x48': 1,
  'x49': 0,
  'x5': 0,
  'x50': 1,
  'x51': 1,
  'x52': 0,
  'x53': 1,
  'x54': 1,
  'x55': 1,
  'x56': 1,
  'x57': 0,
  'x58': 0,
  'x59': 0,
  'x6': 1,
  'x60': 1,
  'x61': 0,
  'x62': 0,
  'x63': 1,
  'x64': 1,
  'x65': 0,
  'x66': 1,
  'x67': 1,
  'x68': 0,
  'x69': 1,
  'x7': 1,
  'x70': 0,
  'x71': 1,
  'x72': 1,
  'x73': 1,
  'x74': 0,
  'x75': 0,
  'x76': 1,
  'x77': 1,
  'x78': 0,
  'x79': 0,
  'x8': 0,
  'x80': 1,
  'x81': 0,
  'x82': 1,
  'x83': 1,
  'x84': 0,
  'x85': 0,
  'x86': 1,
  'x87': 0,
  'x88': 1,
  'x89': 0,
  'x9': 0,
  'x90': 1,
  'x91': 1,
  'x92': 1,
  'x93': 0,
  'x94': 0,
  'x95': 0,
  'x96': 0,
  'x97': 0,
  'x98': 0,
  'x99': 1,
})

[2024-09-05 06:43:26,780][basic_search][INFO][generic_smbo.py:310] Iter 20, objectives: [inf].
[2024-09-05 06:43:26,786][basic_search][WARNING][generic_advisor.py:467] No enough successful initial trials! Sample random configuration.
[2024-09-05 06:43:26,790][basic_search][ERROR][generic_smbo.py:290] Exception in objective function:
Traceback (most recent call last):
  File "/gyc_data/fray_data/py38hwvenv/lib/python3.8/site-packages/openbox/utils/limit.py", line 62, in run_without_time_limit
    ret = obj_func(*obj_args, **obj_kwargs)
  File "BO_partition.py", line 72, in obj_func
    cost = self.black_box.get_cost_from_partitions(partitions)
  File "BO_partition.py", line 34, in get_cost_from_partitions
    partitions_cpp[i]=partitions[i]
IndexError: list index out of range

config: Configuration(values={
  'x0': 1,
  'x1': 1,
  'x10': 0,
  'x100': 1,
  'x101': 1,
  'x102': 0,
  'x103': 1,
  'x104': 0,
  'x105': 1,
  'x106': 0,
  'x107': 1,
  'x108': 1,
  'x109': 0,
  'x11': 0,
  'x110': 0,
  'x111': 1,
  'x112': 0,
  'x113': 0,
  'x114': 1,
  'x115': 0,
  'x116': 0,
  'x117': 1,
  'x118': 0,
  'x119': 0,
  'x12': 1,
  'x120': 1,
  'x121': 1,
  'x122': 0,
  'x123': 0,
  'x124': 0,
  'x125': 0,
  'x126': 0,
  'x127': 1,
  'x128': 1,
  'x129': 1,
  'x13': 1,
  'x130': 1,
  'x131': 0,
  'x132': 0,
  'x133': 1,
  'x134': 1,
  'x135': 0,
  'x136': 0,
  'x137': 1,
  'x138': 1,
  'x139': 0,
  'x14': 1,
  'x140': 0,
  'x141': 0,
  'x142': 0,
  'x143': 0,
  'x144': 1,
  'x145': 0,
  'x15': 1,
  'x16': 1,
  'x17': 1,
  'x18': 1,
  'x19': 0,
  'x2': 0,
  'x20': 0,
  'x21': 1,
  'x22': 1,
  'x23': 1,
  'x24': 1,
  'x25': 0,
  'x26': 0,
  'x27': 0,
  'x28': 0,
  'x29': 1,
  'x3': 1,
  'x30': 0,
  'x31': 0,
  'x32': 0,
  'x33': 1,
  'x34': 1,
  'x35': 0,
  'x36': 1,
  'x37': 1,
  'x38': 0,
  'x39': 1,
  'x4': 1,
  'x40': 1,
  'x41': 0,
  'x42': 0,
  'x43': 0,
  'x44': 0,
  'x45': 1,
  'x46': 1,
  'x47': 1,
  'x48': 0,
  'x49': 0,
  'x5': 0,
  'x50': 0,
  'x51': 1,
  'x52': 1,
  'x53': 1,
  'x54': 0,
  'x55': 1,
  'x56': 1,
  'x57': 1,
  'x58': 1,
  'x59': 1,
  'x6': 1,
  'x60': 0,
  'x61': 0,
  'x62': 1,
  'x63': 0,
  'x64': 0,
  'x65': 1,
  'x66': 0,
  'x67': 0,
  'x68': 1,
  'x69': 0,
  'x7': 0,
  'x70': 0,
  'x71': 0,
  'x72': 1,
  'x73': 0,
  'x74': 1,
  'x75': 1,
  'x76': 1,
  'x77': 1,
  'x78': 1,
  'x79': 0,
  'x8': 1,
  'x80': 0,
  'x81': 0,
  'x82': 1,
  'x83': 0,
  'x84': 0,
  'x85': 0,
  'x86': 0,
  'x87': 1,
  'x88': 1,
  'x89': 1,
  'x9': 1,
  'x90': 0,
  'x91': 0,
  'x92': 1,
  'x93': 0,
  'x94': 1,
  'x95': 1,
  'x96': 0,
  'x97': 1,
  'x98': 0,
  'x99': 0,
})

[2024-09-05 06:43:26,790][basic_search][INFO][generic_smbo.py:310] Iter 21, objectives: [inf].
[2024-09-05 06:43:26,796][basic_search][WARNING][generic_advisor.py:467] No enough successful initial trials! Sample random configuration.
[2024-09-05 06:43:26,800][basic_search][ERROR][generic_smbo.py:290] Exception in objective function:
Traceback (most recent call last):
  File "/gyc_data/fray_data/py38hwvenv/lib/python3.8/site-packages/openbox/utils/limit.py", line 62, in run_without_time_limit
    ret = obj_func(*obj_args, **obj_kwargs)
  File "BO_partition.py", line 72, in obj_func
    cost = self.black_box.get_cost_from_partitions(partitions)
  File "BO_partition.py", line 34, in get_cost_from_partitions
    partitions_cpp[i]=partitions[i]
IndexError: list index out of range

config: Configuration(values={
  'x0': 1,
  'x1': 1,
  'x10': 0,
  'x100': 0,
  'x101': 1,
  'x102': 0,
  'x103': 0,
  'x104': 1,
  'x105': 0,
  'x106': 0,
  'x107': 0,
  'x108': 1,
  'x109': 1,
  'x11': 1,
  'x110': 1,
  'x111': 0,
  'x112': 1,
  'x113': 1,
  'x114': 1,
  'x115': 1,
  'x116': 0,
  'x117': 0,
  'x118': 1,
  'x119': 0,
  'x12': 0,
  'x120': 0,
  'x121': 0,
  'x122': 0,
  'x123': 1,
  'x124': 0,
  'x125': 0,
  'x126': 0,
  'x127': 1,
  'x128': 0,
  'x129': 1,
  'x13': 1,
  'x130': 0,
  'x131': 1,
  'x132': 1,
  'x133': 0,
  'x134': 1,
  'x135': 1,
  'x136': 1,
  'x137': 0,
  'x138': 0,
  'x139': 0,
  'x14': 1,
  'x140': 1,
  'x141': 1,
  'x142': 1,
  'x143': 0,
  'x144': 0,
  'x145': 0,
  'x15': 1,
  'x16': 1,
  'x17': 0,
  'x18': 1,
  'x19': 0,
  'x2': 0,
  'x20': 1,
  'x21': 0,
  'x22': 0,
  'x23': 0,
  'x24': 1,
  'x25': 1,
  'x26': 0,
  'x27': 0,
  'x28': 0,
  'x29': 0,
  'x3': 1,
  'x30': 0,
  'x31': 0,
  'x32': 1,
  'x33': 1,
  'x34': 1,
  'x35': 1,
  'x36': 1,
  'x37': 1,
  'x38': 1,
  'x39': 1,
  'x4': 1,
  'x40': 0,
  'x41': 1,
  'x42': 0,
  'x43': 1,
  'x44': 0,
  'x45': 0,
  'x46': 0,
  'x47': 1,
  'x48': 1,
  'x49': 1,
  'x5': 1,
  'x50': 1,
  'x51': 0,
  'x52': 1,
  'x53': 1,
  'x54': 1,
  'x55': 1,
  'x56': 0,
  'x57': 0,
  'x58': 1,
  'x59': 0,
  'x6': 0,
  'x60': 1,
  'x61': 0,
  'x62': 1,
  'x63': 1,
  'x64': 1,
  'x65': 1,
  'x66': 0,
  'x67': 0,
  'x68': 0,
  'x69': 0,
  'x7': 1,
  'x70': 0,
  'x71': 0,
  'x72': 0,
  'x73': 0,
  'x74': 0,
  'x75': 0,
  'x76': 0,
  'x77': 1,
  'x78': 1,
  'x79': 0,
  'x8': 1,
  'x80': 1,
  'x81': 1,
  'x82': 1,
  'x83': 0,
  'x84': 1,
  'x85': 0,
  'x86': 0,
  'x87': 1,
  'x88': 0,
  'x89': 0,
  'x9': 0,
  'x90': 1,
  'x91': 0,
  'x92': 1,
  'x93': 0,
  'x94': 0,
  'x95': 1,
  'x96': 1,
  'x97': 0,
  'x98': 1,
  'x99': 1,
})

[2024-09-05 06:43:26,800][basic_search][INFO][generic_smbo.py:310] Iter 22, objectives: [inf].
[2024-09-05 06:43:26,807][basic_search][INFO][generic_advisor.py:457] Sample random config. rand_prob=0.100000.
[2024-09-05 06:43:26,810][basic_search][ERROR][generic_smbo.py:290] Exception in objective function:
Traceback (most recent call last):
  File "/gyc_data/fray_data/py38hwvenv/lib/python3.8/site-packages/openbox/utils/limit.py", line 62, in run_without_time_limit
    ret = obj_func(*obj_args, **obj_kwargs)
  File "BO_partition.py", line 72, in obj_func
    cost = self.black_box.get_cost_from_partitions(partitions)
  File "BO_partition.py", line 34, in get_cost_from_partitions
    partitions_cpp[i]=partitions[i]
IndexError: list index out of range

config: Configuration(values={
  'x0': 1,
  'x1': 1,
  'x10': 0,
  'x100': 0,
  'x101': 0,
  'x102': 0,
  'x103': 0,
  'x104': 1,
  'x105': 0,
  'x106': 0,
  'x107': 1,
  'x108': 0,
  'x109': 0,
  'x11': 0,
  'x110': 1,
  'x111': 1,
  'x112': 0,
  'x113': 0,
  'x114': 0,
  'x115': 0,
  'x116': 0,
  'x117': 0,
  'x118': 0,
  'x119': 1,
  'x12': 0,
  'x120': 0,
  'x121': 0,
  'x122': 1,
  'x123': 0,
  'x124': 0,
  'x125': 1,
  'x126': 0,
  'x127': 0,
  'x128': 0,
  'x129': 0,
  'x13': 0,
  'x130': 0,
  'x131': 0,
  'x132': 1,
  'x133': 0,
  'x134': 1,
  'x135': 0,
  'x136': 0,
  'x137': 1,
  'x138': 1,
  'x139': 1,
  'x14': 0,
  'x140': 0,
  'x141': 0,
  'x142': 0,
  'x143': 0,
  'x144': 0,
  'x145': 0,
  'x15': 1,
  'x16': 0,
  'x17': 1,
  'x18': 1,
  'x19': 1,
  'x2': 1,
  'x20': 0,
  'x21': 1,
  'x22': 0,
  'x23': 1,
  'x24': 0,
  'x25': 1,
  'x26': 0,
  'x27': 0,
  'x28': 1,
  'x29': 0,
  'x3': 0,
  'x30': 1,
  'x31': 0,
  'x32': 0,
  'x33': 0,
  'x34': 0,
  'x35': 0,
  'x36': 0,
  'x37': 0,
  'x38': 0,
  'x39': 1,
  'x4': 0,
  'x40': 0,
  'x41': 1,
  'x42': 1,
  'x43': 0,
  'x44': 1,
  'x45': 1,
  'x46': 0,
  'x47': 0,
  'x48': 0,
  'x49': 1,
  'x5': 0,
  'x50': 0,
  'x51': 0,
  'x52': 0,
  'x53': 1,
  'x54': 1,
  'x55': 0,
  'x56': 0,
  'x57': 0,
  'x58': 0,
  'x59': 1,
  'x6': 0,
  'x60': 1,
  'x61': 0,
  'x62': 1,
  'x63': 0,
  'x64': 1,
  'x65': 0,
  'x66': 0,
  'x67': 0,
  'x68': 1,
  'x69': 1,
  'x7': 1,
  'x70': 0,
  'x71': 1,
  'x72': 1,
  'x73': 0,
  'x74': 1,
  'x75': 0,
  'x76': 0,
  'x77': 1,
  'x78': 0,
  'x79': 0,
  'x8': 0,
  'x80': 1,
  'x81': 1,
  'x82': 0,
  'x83': 0,
  'x84': 0,
  'x85': 0,
  'x86': 1,
  'x87': 0,
  'x88': 1,
  'x89': 1,
  'x9': 1,
  'x90': 0,
  'x91': 0,
  'x92': 0,
  'x93': 0,
  'x94': 0,
  'x95': 0,
  'x96': 0,
  'x97': 0,
  'x98': 1,
  'x99': 1,
})

[2024-09-05 06:43:26,811][basic_search][INFO][generic_smbo.py:310] Iter 23, objectives: [inf].
[2024-09-05 06:43:26,818][basic_search][WARNING][generic_advisor.py:467] No enough successful initial trials! Sample random configuration.
[2024-09-05 06:43:26,821][basic_search][ERROR][generic_smbo.py:290] Exception in objective function:
Traceback (most recent call last):
  File "/gyc_data/fray_data/py38hwvenv/lib/python3.8/site-packages/openbox/utils/limit.py", line 62, in run_without_time_limit
    ret = obj_func(*obj_args, **obj_kwargs)
  File "BO_partition.py", line 72, in obj_func
    cost = self.black_box.get_cost_from_partitions(partitions)
  File "BO_partition.py", line 34, in get_cost_from_partitions
    partitions_cpp[i]=partitions[i]
IndexError: list index out of range

config: Configuration(values={
  'x0': 0,
  'x1': 0,
  'x10': 0,
  'x100': 1,
  'x101': 1,
  'x102': 1,
  'x103': 1,
  'x104': 1,
  'x105': 1,
  'x106': 0,
  'x107': 1,
  'x108': 0,
  'x109': 0,
  'x11': 0,
  'x110': 1,
  'x111': 1,
  'x112': 1,
  'x113': 0,
  'x114': 1,
  'x115': 0,
  'x116': 0,
  'x117': 0,
  'x118': 0,
  'x119': 0,
  'x12': 1,
  'x120': 0,
  'x121': 1,
  'x122': 0,
  'x123': 0,
  'x124': 1,
  'x125': 0,
  'x126': 0,
  'x127': 0,
  'x128': 0,
  'x129': 0,
  'x13': 1,
  'x130': 1,
  'x131': 1,
  'x132': 1,
  'x133': 0,
  'x134': 1,
  'x135': 1,
  'x136': 1,
  'x137': 1,
  'x138': 0,
  'x139': 0,
  'x14': 1,
  'x140': 0,
  'x141': 1,
  'x142': 1,
  'x143': 1,
  'x144': 0,
  'x145': 1,
  'x15': 1,
  'x16': 0,
  'x17': 0,
  'x18': 1,
  'x19': 0,
  'x2': 1,
  'x20': 1,
  'x21': 0,
  'x22': 1,
  'x23': 0,
  'x24': 1,
  'x25': 0,
  'x26': 0,
  'x27': 0,
  'x28': 0,
  'x29': 1,
  'x3': 0,
  'x30': 0,
  'x31': 1,
  'x32': 1,
  'x33': 0,
  'x34': 1,
  'x35': 1,
  'x36': 1,
  'x37': 1,
  'x38': 0,
  'x39': 1,
  'x4': 1,
  'x40': 1,
  'x41': 0,
  'x42': 0,
  'x43': 1,
  'x44': 1,
  'x45': 0,
  'x46': 1,
  'x47': 1,
  'x48': 1,
  'x49': 0,
  'x5': 1,
  'x50': 1,
  'x51': 0,
  'x52': 0,
  'x53': 1,
  'x54': 1,
  'x55': 0,
  'x56': 1,
  'x57': 1,
  'x58': 0,
  'x59': 0,
  'x6': 1,
  'x60': 0,
  'x61': 1,
  'x62': 0,
  'x63': 0,
  'x64': 0,
  'x65': 0,
  'x66': 0,
  'x67': 0,
  'x68': 1,
  'x69': 0,
  'x7': 1,
  'x70': 1,
  'x71': 1,
  'x72': 1,
  'x73': 0,
  'x74': 1,
  'x75': 0,
  'x76': 1,
  'x77': 0,
  'x78': 0,
  'x79': 0,
  'x8': 0,
  'x80': 1,
  'x81': 0,
  'x82': 0,
  'x83': 0,
  'x84': 1,
  'x85': 0,
  'x86': 1,
  'x87': 1,
  'x88': 0,
  'x89': 1,
  'x9': 1,
  'x90': 0,
  'x91': 1,
  'x92': 1,
  'x93': 1,
  'x94': 1,
  'x95': 1,
  'x96': 0,
  'x97': 0,
  'x98': 1,
  'x99': 0,
})

[2024-09-05 06:43:26,822][basic_search][INFO][generic_smbo.py:310] Iter 24, objectives: [inf].
[2024-09-05 06:43:26,829][basic_search][WARNING][generic_advisor.py:467] No enough successful initial trials! Sample random configuration.
[2024-09-05 06:43:26,833][basic_search][ERROR][generic_smbo.py:290] Exception in objective function:
Traceback (most recent call last):
  File "/gyc_data/fray_data/py38hwvenv/lib/python3.8/site-packages/openbox/utils/limit.py", line 62, in run_without_time_limit
    ret = obj_func(*obj_args, **obj_kwargs)
  File "BO_partition.py", line 72, in obj_func
    cost = self.black_box.get_cost_from_partitions(partitions)
  File "BO_partition.py", line 34, in get_cost_from_partitions
    partitions_cpp[i]=partitions[i]
IndexError: list index out of range

config: Configuration(values={
  'x0': 1,
  'x1': 1,
  'x10': 1,
  'x100': 0,
  'x101': 0,
  'x102': 1,
  'x103': 1,
  'x104': 1,
  'x105': 0,
  'x106': 0,
  'x107': 0,
  'x108': 1,
  'x109': 0,
  'x11': 1,
  'x110': 1,
  'x111': 0,
  'x112': 0,
  'x113': 1,
  'x114': 1,
  'x115': 0,
  'x116': 1,
  'x117': 1,
  'x118': 1,
  'x119': 0,
  'x12': 0,
  'x120': 1,
  'x121': 0,
  'x122': 1,
  'x123': 1,
  'x124': 1,
  'x125': 1,
  'x126': 1,
  'x127': 1,
  'x128': 1,
  'x129': 0,
  'x13': 1,
  'x130': 0,
  'x131': 0,
  'x132': 1,
  'x133': 1,
  'x134': 1,
  'x135': 1,
  'x136': 1,
  'x137': 0,
  'x138': 0,
  'x139': 0,
  'x14': 1,
  'x140': 1,
  'x141': 0,
  'x142': 0,
  'x143': 1,
  'x144': 0,
  'x145': 0,
  'x15': 1,
  'x16': 0,
  'x17': 0,
  'x18': 0,
  'x19': 1,
  'x2': 0,
  'x20': 0,
  'x21': 1,
  'x22': 1,
  'x23': 0,
  'x24': 0,
  'x25': 0,
  'x26': 0,
  'x27': 0,
  'x28': 0,
  'x29': 1,
  'x3': 0,
  'x30': 0,
  'x31': 0,
  'x32': 0,
  'x33': 1,
  'x34': 1,
  'x35': 0,
  'x36': 1,
  'x37': 1,
  'x38': 1,
  'x39': 0,
  'x4': 0,
  'x40': 0,
  'x41': 0,
  'x42': 1,
  'x43': 0,
  'x44': 1,
  'x45': 0,
  'x46': 0,
  'x47': 0,
  'x48': 1,
  'x49': 0,
  'x5': 0,
  'x50': 1,
  'x51': 1,
  'x52': 0,
  'x53': 1,
  'x54': 1,
  'x55': 1,
  'x56': 1,
  'x57': 0,
  'x58': 0,
  'x59': 1,
  'x6': 0,
  'x60': 1,
  'x61': 1,
  'x62': 0,
  'x63': 1,
  'x64': 0,
  'x65': 1,
  'x66': 1,
  'x67': 1,
  'x68': 0,
  'x69': 0,
  'x7': 0,
  'x70': 1,
  'x71': 0,
  'x72': 1,
  'x73': 0,
  'x74': 1,
  'x75': 1,
  'x76': 1,
  'x77': 0,
  'x78': 0,
  'x79': 0,
  'x8': 0,
  'x80': 1,
  'x81': 0,
  'x82': 1,
  'x83': 0,
  'x84': 1,
  'x85': 0,
  'x86': 0,
  'x87': 0,
  'x88': 1,
  'x89': 0,
  'x9': 1,
  'x90': 0,
  'x91': 0,
  'x92': 1,
  'x93': 0,
  'x94': 0,
  'x95': 0,
  'x96': 1,
  'x97': 1,
  'x98': 1,
  'x99': 0,
})

[2024-09-05 06:43:26,833][basic_search][INFO][generic_smbo.py:310] Iter 25, objectives: [inf].
[2024-09-05 06:43:26,840][basic_search][WARNING][generic_advisor.py:467] No enough successful initial trials! Sample random configuration.
[2024-09-05 06:43:26,844][basic_search][ERROR][generic_smbo.py:290] Exception in objective function:
Traceback (most recent call last):
  File "/gyc_data/fray_data/py38hwvenv/lib/python3.8/site-packages/openbox/utils/limit.py", line 62, in run_without_time_limit
    ret = obj_func(*obj_args, **obj_kwargs)
  File "BO_partition.py", line 72, in obj_func
    cost = self.black_box.get_cost_from_partitions(partitions)
  File "BO_partition.py", line 34, in get_cost_from_partitions
    partitions_cpp[i]=partitions[i]
IndexError: list index out of range

config: Configuration(values={
  'x0': 0,
  'x1': 0,
  'x10': 0,
  'x100': 1,
  'x101': 0,
  'x102': 0,
  'x103': 0,
  'x104': 1,
  'x105': 1,
  'x106': 0,
  'x107': 0,
  'x108': 0,
  'x109': 1,
  'x11': 1,
  'x110': 0,
  'x111': 0,
  'x112': 1,
  'x113': 1,
  'x114': 1,
  'x115': 1,
  'x116': 1,
  'x117': 1,
  'x118': 1,
  'x119': 1,
  'x12': 0,
  'x120': 1,
  'x121': 0,
  'x122': 1,
  'x123': 1,
  'x124': 0,
  'x125': 0,
  'x126': 1,
  'x127': 1,
  'x128': 1,
  'x129': 0,
  'x13': 0,
  'x130': 0,
  'x131': 1,
  'x132': 1,
  'x133': 0,
  'x134': 1,
  'x135': 1,
  'x136': 1,
  'x137': 0,
  'x138': 1,
  'x139': 0,
  'x14': 1,
  'x140': 0,
  'x141': 0,
  'x142': 0,
  'x143': 0,
  'x144': 0,
  'x145': 0,
  'x15': 0,
  'x16': 1,
  'x17': 0,
  'x18': 1,
  'x19': 1,
  'x2': 1,
  'x20': 0,
  'x21': 1,
  'x22': 1,
  'x23': 1,
  'x24': 1,
  'x25': 1,
  'x26': 1,
  'x27': 0,
  'x28': 1,
  'x29': 0,
  'x3': 0,
  'x30': 0,
  'x31': 0,
  'x32': 1,
  'x33': 0,
  'x34': 0,
  'x35': 1,
  'x36': 1,
  'x37': 1,
  'x38': 0,
  'x39': 0,
  'x4': 0,
  'x40': 0,
  'x41': 1,
  'x42': 0,
  'x43': 1,
  'x44': 1,
  'x45': 1,
  'x46': 1,
  'x47': 0,
  'x48': 0,
  'x49': 1,
  'x5': 0,
  'x50': 1,
  'x51': 1,
  'x52': 0,
  'x53': 1,
  'x54': 1,
  'x55': 0,
  'x56': 0,
  'x57': 1,
  'x58': 1,
  'x59': 1,
  'x6': 0,
  'x60': 0,
  'x61': 1,
  'x62': 0,
  'x63': 0,
  'x64': 1,
  'x65': 1,
  'x66': 0,
  'x67': 0,
  'x68': 0,
  'x69': 1,
  'x7': 0,
  'x70': 0,
  'x71': 0,
  'x72': 1,
  'x73': 1,
  'x74': 0,
  'x75': 0,
  'x76': 0,
  'x77': 1,
  'x78': 1,
  'x79': 0,
  'x8': 1,
  'x80': 0,
  'x81': 0,
  'x82': 0,
  'x83': 0,
  'x84': 1,
  'x85': 1,
  'x86': 0,
  'x87': 0,
  'x88': 1,
  'x89': 1,
  'x9': 1,
  'x90': 1,
  'x91': 0,
  'x92': 0,
  'x93': 1,
  'x94': 0,
  'x95': 1,
  'x96': 1,
  'x97': 1,
  'x98': 0,
  'x99': 0,
})

[2024-09-05 06:43:26,844][basic_search][INFO][generic_smbo.py:310] Iter 26, objectives: [inf].
[2024-09-05 06:43:26,852][basic_search][WARNING][generic_advisor.py:467] No enough successful initial trials! Sample random configuration.
[2024-09-05 06:43:26,856][basic_search][ERROR][generic_smbo.py:290] Exception in objective function:
Traceback (most recent call last):
  File "/gyc_data/fray_data/py38hwvenv/lib/python3.8/site-packages/openbox/utils/limit.py", line 62, in run_without_time_limit
    ret = obj_func(*obj_args, **obj_kwargs)
  File "BO_partition.py", line 72, in obj_func
    cost = self.black_box.get_cost_from_partitions(partitions)
  File "BO_partition.py", line 34, in get_cost_from_partitions
    partitions_cpp[i]=partitions[i]
IndexError: list index out of range

config: Configuration(values={
  'x0': 1,
  'x1': 1,
  'x10': 1,
  'x100': 0,
  'x101': 0,
  'x102': 1,
  'x103': 0,
  'x104': 0,
  'x105': 1,
  'x106': 1,
  'x107': 1,
  'x108': 0,
  'x109': 0,
  'x11': 1,
  'x110': 1,
  'x111': 1,
  'x112': 0,
  'x113': 0,
  'x114': 1,
  'x115': 0,
  'x116': 1,
  'x117': 0,
  'x118': 0,
  'x119': 1,
  'x12': 0,
  'x120': 0,
  'x121': 1,
  'x122': 1,
  'x123': 1,
  'x124': 0,
  'x125': 0,
  'x126': 0,
  'x127': 0,
  'x128': 0,
  'x129': 0,
  'x13': 0,
  'x130': 1,
  'x131': 0,
  'x132': 1,
  'x133': 1,
  'x134': 1,
  'x135': 1,
  'x136': 1,
  'x137': 1,
  'x138': 0,
  'x139': 0,
  'x14': 0,
  'x140': 0,
  'x141': 0,
  'x142': 0,
  'x143': 0,
  'x144': 0,
  'x145': 0,
  'x15': 1,
  'x16': 1,
  'x17': 0,
  'x18': 0,
  'x19': 1,
  'x2': 0,
  'x20': 1,
  'x21': 0,
  'x22': 0,
  'x23': 1,
  'x24': 0,
  'x25': 0,
  'x26': 0,
  'x27': 1,
  'x28': 1,
  'x29': 1,
  'x3': 0,
  'x30': 1,
  'x31': 0,
  'x32': 0,
  'x33': 0,
  'x34': 0,
  'x35': 1,
  'x36': 0,
  'x37': 1,
  'x38': 0,
  'x39': 1,
  'x4': 1,
  'x40': 1,
  'x41': 1,
  'x42': 1,
  'x43': 0,
  'x44': 1,
  'x45': 1,
  'x46': 1,
  'x47': 1,
  'x48': 0,
  'x49': 1,
  'x5': 1,
  'x50': 0,
  'x51': 0,
  'x52': 0,
  'x53': 0,
  'x54': 0,
  'x55': 0,
  'x56': 1,
  'x57': 0,
  'x58': 1,
  'x59': 1,
  'x6': 0,
  'x60': 0,
  'x61': 1,
  'x62': 1,
  'x63': 1,
  'x64': 1,
  'x65': 0,
  'x66': 0,
  'x67': 0,
  'x68': 1,
  'x69': 1,
  'x7': 0,
  'x70': 1,
  'x71': 1,
  'x72': 1,
  'x73': 1,
  'x74': 1,
  'x75': 0,
  'x76': 0,
  'x77': 1,
  'x78': 0,
  'x79': 0,
  'x8': 0,
  'x80': 1,
  'x81': 1,
  'x82': 0,
  'x83': 0,
  'x84': 0,
  'x85': 1,
  'x86': 0,
  'x87': 0,
  'x88': 0,
  'x89': 0,
  'x9': 1,
  'x90': 0,
  'x91': 0,
  'x92': 0,
  'x93': 0,
  'x94': 0,
  'x95': 1,
  'x96': 1,
  'x97': 0,
  'x98': 0,
  'x99': 1,
})

[2024-09-05 06:43:26,856][basic_search][INFO][generic_smbo.py:310] Iter 27, objectives: [inf].
[2024-09-05 06:43:26,864][basic_search][WARNING][generic_advisor.py:467] No enough successful initial trials! Sample random configuration.
[2024-09-05 06:43:26,868][basic_search][ERROR][generic_smbo.py:290] Exception in objective function:
Traceback (most recent call last):
  File "/gyc_data/fray_data/py38hwvenv/lib/python3.8/site-packages/openbox/utils/limit.py", line 62, in run_without_time_limit
    ret = obj_func(*obj_args, **obj_kwargs)
  File "BO_partition.py", line 72, in obj_func
    cost = self.black_box.get_cost_from_partitions(partitions)
  File "BO_partition.py", line 34, in get_cost_from_partitions
    partitions_cpp[i]=partitions[i]
IndexError: list index out of range

config: Configuration(values={
  'x0': 0,
  'x1': 1,
  'x10': 0,
  'x100': 1,
  'x101': 1,
  'x102': 1,
  'x103': 1,
  'x104': 0,
  'x105': 1,
  'x106': 1,
  'x107': 0,
  'x108': 1,
  'x109': 1,
  'x11': 1,
  'x110': 1,
  'x111': 1,
  'x112': 1,
  'x113': 0,
  'x114': 0,
  'x115': 0,
  'x116': 1,
  'x117': 0,
  'x118': 0,
  'x119': 0,
  'x12': 0,
  'x120': 0,
  'x121': 1,
  'x122': 1,
  'x123': 1,
  'x124': 0,
  'x125': 0,
  'x126': 1,
  'x127': 0,
  'x128': 0,
  'x129': 1,
  'x13': 0,
  'x130': 0,
  'x131': 0,
  'x132': 1,
  'x133': 0,
  'x134': 1,
  'x135': 0,
  'x136': 0,
  'x137': 0,
  'x138': 0,
  'x139': 1,
  'x14': 0,
  'x140': 1,
  'x141': 1,
  'x142': 1,
  'x143': 1,
  'x144': 1,
  'x145': 1,
  'x15': 1,
  'x16': 0,
  'x17': 1,
  'x18': 0,
  'x19': 0,
  'x2': 1,
  'x20': 0,
  'x21': 1,
  'x22': 0,
  'x23': 1,
  'x24': 1,
  'x25': 1,
  'x26': 1,
  'x27': 1,
  'x28': 0,
  'x29': 1,
  'x3': 0,
  'x30': 1,
  'x31': 1,
  'x32': 0,
  'x33': 1,
  'x34': 1,
  'x35': 0,
  'x36': 0,
  'x37': 1,
  'x38': 0,
  'x39': 0,
  'x4': 0,
  'x40': 0,
  'x41': 1,
  'x42': 1,
  'x43': 1,
  'x44': 1,
  'x45': 1,
  'x46': 0,
  'x47': 0,
  'x48': 1,
  'x49': 0,
  'x5': 1,
  'x50': 1,
  'x51': 0,
  'x52': 0,
  'x53': 0,
  'x54': 0,
  'x55': 0,
  'x56': 0,
  'x57': 1,
  'x58': 1,
  'x59': 1,
  'x6': 1,
  'x60': 0,
  'x61': 1,
  'x62': 1,
  'x63': 1,
  'x64': 1,
  'x65': 1,
  'x66': 1,
  'x67': 0,
  'x68': 0,
  'x69': 0,
  'x7': 1,
  'x70': 1,
  'x71': 0,
  'x72': 1,
  'x73': 1,
  'x74': 1,
  'x75': 0,
  'x76': 0,
  'x77': 1,
  'x78': 1,
  'x79': 0,
  'x8': 1,
  'x80': 1,
  'x81': 0,
  'x82': 1,
  'x83': 1,
  'x84': 0,
  'x85': 1,
  'x86': 1,
  'x87': 0,
  'x88': 1,
  'x89': 1,
  'x9': 1,
  'x90': 1,
  'x91': 1,
  'x92': 0,
  'x93': 1,
  'x94': 0,
  'x95': 1,
  'x96': 0,
  'x97': 0,
  'x98': 0,
  'x99': 0,
})

[2024-09-05 06:43:26,868][basic_search][INFO][generic_smbo.py:310] Iter 28, objectives: [inf].
[2024-09-05 06:43:26,876][basic_search][WARNING][generic_advisor.py:467] No enough successful initial trials! Sample random configuration.
[2024-09-05 06:43:26,880][basic_search][ERROR][generic_smbo.py:290] Exception in objective function:
Traceback (most recent call last):
  File "/gyc_data/fray_data/py38hwvenv/lib/python3.8/site-packages/openbox/utils/limit.py", line 62, in run_without_time_limit
    ret = obj_func(*obj_args, **obj_kwargs)
  File "BO_partition.py", line 72, in obj_func
    cost = self.black_box.get_cost_from_partitions(partitions)
  File "BO_partition.py", line 34, in get_cost_from_partitions
    partitions_cpp[i]=partitions[i]
IndexError: list index out of range

config: Configuration(values={
  'x0': 1,
  'x1': 1,
  'x10': 0,
  'x100': 1,
  'x101': 1,
  'x102': 1,
  'x103': 1,
  'x104': 1,
  'x105': 0,
  'x106': 0,
  'x107': 0,
  'x108': 0,
  'x109': 0,
  'x11': 0,
  'x110': 1,
  'x111': 1,
  'x112': 0,
  'x113': 1,
  'x114': 0,
  'x115': 1,
  'x116': 1,
  'x117': 0,
  'x118': 1,
  'x119': 0,
  'x12': 0,
  'x120': 0,
  'x121': 0,
  'x122': 1,
  'x123': 0,
  'x124': 1,
  'x125': 0,
  'x126': 1,
  'x127': 0,
  'x128': 0,
  'x129': 1,
  'x13': 1,
  'x130': 1,
  'x131': 0,
  'x132': 1,
  'x133': 1,
  'x134': 1,
  'x135': 0,
  'x136': 0,
  'x137': 1,
  'x138': 0,
  'x139': 1,
  'x14': 1,
  'x140': 1,
  'x141': 1,
  'x142': 1,
  'x143': 1,
  'x144': 1,
  'x145': 1,
  'x15': 0,
  'x16': 1,
  'x17': 0,
  'x18': 1,
  'x19': 1,
  'x2': 0,
  'x20': 1,
  'x21': 0,
  'x22': 1,
  'x23': 0,
  'x24': 0,
  'x25': 0,
  'x26': 1,
  'x27': 0,
  'x28': 1,
  'x29': 0,
  'x3': 1,
  'x30': 1,
  'x31': 1,
  'x32': 1,
  'x33': 0,
  'x34': 1,
  'x35': 1,
  'x36': 1,
  'x37': 0,
  'x38': 1,
  'x39': 1,
  'x4': 1,
  'x40': 0,
  'x41': 1,
  'x42': 0,
  'x43': 0,
  'x44': 1,
  'x45': 0,
  'x46': 0,
  'x47': 1,
  'x48': 1,
  'x49': 0,
  'x5': 1,
  'x50': 1,
  'x51': 0,
  'x52': 0,
  'x53': 1,
  'x54': 1,
  'x55': 1,
  'x56': 0,
  'x57': 0,
  'x58': 1,
  'x59': 1,
  'x6': 1,
  'x60': 0,
  'x61': 0,
  'x62': 0,
  'x63': 1,
  'x64': 0,
  'x65': 0,
  'x66': 0,
  'x67': 1,
  'x68': 1,
  'x69': 1,
  'x7': 1,
  'x70': 0,
  'x71': 1,
  'x72': 0,
  'x73': 0,
  'x74': 1,
  'x75': 1,
  'x76': 1,
  'x77': 1,
  'x78': 1,
  'x79': 1,
  'x8': 1,
  'x80': 1,
  'x81': 1,
  'x82': 0,
  'x83': 1,
  'x84': 0,
  'x85': 0,
  'x86': 0,
  'x87': 0,
  'x88': 1,
  'x89': 1,
  'x9': 1,
  'x90': 1,
  'x91': 0,
  'x92': 1,
  'x93': 1,
  'x94': 1,
  'x95': 0,
  'x96': 1,
  'x97': 0,
  'x98': 1,
  'x99': 1,
})

[2024-09-05 06:43:26,881][basic_search][INFO][generic_smbo.py:310] Iter 29, objectives: [inf].
[2024-09-05 06:43:26,889][basic_search][INFO][generic_advisor.py:457] Sample random config. rand_prob=0.100000.
[2024-09-05 06:43:26,892][basic_search][ERROR][generic_smbo.py:290] Exception in objective function:
Traceback (most recent call last):
  File "/gyc_data/fray_data/py38hwvenv/lib/python3.8/site-packages/openbox/utils/limit.py", line 62, in run_without_time_limit
    ret = obj_func(*obj_args, **obj_kwargs)
  File "BO_partition.py", line 72, in obj_func
    cost = self.black_box.get_cost_from_partitions(partitions)
  File "BO_partition.py", line 34, in get_cost_from_partitions
    partitions_cpp[i]=partitions[i]
IndexError: list index out of range

config: Configuration(values={
  'x0': 1,
  'x1': 1,
  'x10': 1,
  'x100': 1,
  'x101': 1,
  'x102': 1,
  'x103': 0,
  'x104': 1,
  'x105': 1,
  'x106': 0,
  'x107': 0,
  'x108': 0,
  'x109': 1,
  'x11': 0,
  'x110': 0,
  'x111': 1,
  'x112': 1,
  'x113': 1,
  'x114': 1,
  'x115': 0,
  'x116': 1,
  'x117': 0,
  'x118': 0,
  'x119': 0,
  'x12': 0,
  'x120': 1,
  'x121': 1,
  'x122': 0,
  'x123': 1,
  'x124': 1,
  'x125': 1,
  'x126': 0,
  'x127': 1,
  'x128': 1,
  'x129': 0,
  'x13': 1,
  'x130': 1,
  'x131': 1,
  'x132': 1,
  'x133': 0,
  'x134': 0,
  'x135': 1,
  'x136': 1,
  'x137': 1,
  'x138': 0,
  'x139': 0,
  'x14': 1,
  'x140': 1,
  'x141': 1,
  'x142': 1,
  'x143': 0,
  'x144': 1,
  'x145': 0,
  'x15': 0,
  'x16': 0,
  'x17': 1,
  'x18': 0,
  'x19': 1,
  'x2': 0,
  'x20': 1,
  'x21': 1,
  'x22': 1,
  'x23': 0,
  'x24': 1,
  'x25': 0,
  'x26': 1,
  'x27': 0,
  'x28': 0,
  'x29': 0,
  'x3': 1,
  'x30': 1,
  'x31': 0,
  'x32': 1,
  'x33': 0,
  'x34': 0,
  'x35': 1,
  'x36': 1,
  'x37': 1,
  'x38': 1,
  'x39': 1,
  'x4': 0,
  'x40': 0,
  'x41': 1,
  'x42': 0,
  'x43': 0,
  'x44': 0,
  'x45': 0,
  'x46': 1,
  'x47': 0,
  'x48': 0,
  'x49': 1,
  'x5': 1,
  'x50': 0,
  'x51': 0,
  'x52': 1,
  'x53': 1,
  'x54': 0,
  'x55': 1,
  'x56': 1,
  'x57': 1,
  'x58': 0,
  'x59': 0,
  'x6': 0,
  'x60': 1,
  'x61': 1,
  'x62': 1,
  'x63': 1,
  'x64': 1,
  'x65': 0,
  'x66': 1,
  'x67': 1,
  'x68': 0,
  'x69': 1,
  'x7': 0,
  'x70': 1,
  'x71': 1,
  'x72': 1,
  'x73': 0,
  'x74': 0,
  'x75': 1,
  'x76': 1,
  'x77': 1,
  'x78': 0,
  'x79': 1,
  'x8': 1,
  'x80': 0,
  'x81': 1,
  'x82': 1,
  'x83': 1,
  'x84': 1,
  'x85': 1,
  'x86': 0,
  'x87': 0,
  'x88': 0,
  'x89': 0,
  'x9': 0,
  'x90': 1,
  'x91': 0,
  'x92': 1,
  'x93': 0,
  'x94': 0,
  'x95': 0,
  'x96': 1,
  'x97': 1,
  'x98': 0,
  'x99': 0,
})

[2024-09-05 06:43:26,893][basic_search][INFO][generic_smbo.py:310] Iter 30, objectives: [inf].
[2024-09-05 06:43:26,902][basic_search][WARNING][generic_advisor.py:467] No enough successful initial trials! Sample random configuration.
[2024-09-05 06:43:26,905][basic_search][ERROR][generic_smbo.py:290] Exception in objective function:
Traceback (most recent call last):
  File "/gyc_data/fray_data/py38hwvenv/lib/python3.8/site-packages/openbox/utils/limit.py", line 62, in run_without_time_limit
    ret = obj_func(*obj_args, **obj_kwargs)
  File "BO_partition.py", line 72, in obj_func
    cost = self.black_box.get_cost_from_partitions(partitions)
  File "BO_partition.py", line 34, in get_cost_from_partitions
    partitions_cpp[i]=partitions[i]
IndexError: list index out of range

config: Configuration(values={
  'x0': 1,
  'x1': 0,
  'x10': 1,
  'x100': 1,
  'x101': 0,
  'x102': 0,
  'x103': 0,
  'x104': 0,
  'x105': 1,
  'x106': 1,
  'x107': 0,
  'x108': 1,
  'x109': 1,
  'x11': 1,
  'x110': 0,
  'x111': 0,
  'x112': 1,
  'x113': 1,
  'x114': 1,
  'x115': 1,
  'x116': 0,
  'x117': 1,
  'x118': 1,
  'x119': 0,
  'x12': 1,
  'x120': 0,
  'x121': 0,
  'x122': 0,
  'x123': 0,
  'x124': 1,
  'x125': 0,
  'x126': 1,
  'x127': 1,
  'x128': 0,
  'x129': 1,
  'x13': 1,
  'x130': 1,
  'x131': 0,
  'x132': 1,
  'x133': 0,
  'x134': 1,
  'x135': 0,
  'x136': 0,
  'x137': 1,
  'x138': 1,
  'x139': 1,
  'x14': 1,
  'x140': 1,
  'x141': 0,
  'x142': 1,
  'x143': 0,
  'x144': 0,
  'x145': 1,
  'x15': 0,
  'x16': 0,
  'x17': 1,
  'x18': 1,
  'x19': 0,
  'x2': 0,
  'x20': 1,
  'x21': 1,
  'x22': 1,
  'x23': 0,
  'x24': 0,
  'x25': 0,
  'x26': 1,
  'x27': 0,
  'x28': 1,
  'x29': 1,
  'x3': 0,
  'x30': 0,
  'x31': 0,
  'x32': 1,
  'x33': 0,
  'x34': 0,
  'x35': 0,
  'x36': 0,
  'x37': 0,
  'x38': 0,
  'x39': 1,
  'x4': 1,
  'x40': 1,
  'x41': 1,
  'x42': 1,
  'x43': 1,
  'x44': 1,
  'x45': 0,
  'x46': 1,
  'x47': 1,
  'x48': 0,
  'x49': 0,
  'x5': 0,
  'x50': 1,
  'x51': 0,
  'x52': 0,
  'x53': 1,
  'x54': 0,
  'x55': 0,
  'x56': 0,
  'x57': 1,
  'x58': 1,
  'x59': 1,
  'x6': 0,
  'x60': 0,
  'x61': 0,
  'x62': 0,
  'x63': 1,
  'x64': 1,
  'x65': 0,
  'x66': 1,
  'x67': 1,
  'x68': 0,
  'x69': 1,
  'x7': 0,
  'x70': 1,
  'x71': 0,
  'x72': 1,
  'x73': 1,
  'x74': 0,
  'x75': 1,
  'x76': 0,
  'x77': 1,
  'x78': 1,
  'x79': 1,
  'x8': 1,
  'x80': 1,
  'x81': 0,
  'x82': 1,
  'x83': 0,
  'x84': 0,
  'x85': 1,
  'x86': 0,
  'x87': 1,
  'x88': 0,
  'x89': 0,
  'x9': 0,
  'x90': 1,
  'x91': 0,
  'x92': 1,
  'x93': 0,
  'x94': 1,
  'x95': 1,
  'x96': 1,
  'x97': 0,
  'x98': 0,
  'x99': 1,
})

[2024-09-05 06:43:26,906][basic_search][INFO][generic_smbo.py:310] Iter 31, objectives: [inf].
[2024-09-05 06:43:26,915][basic_search][WARNING][generic_advisor.py:467] No enough successful initial trials! Sample random configuration.
[2024-09-05 06:43:26,919][basic_search][ERROR][generic_smbo.py:290] Exception in objective function:
Traceback (most recent call last):
  File "/gyc_data/fray_data/py38hwvenv/lib/python3.8/site-packages/openbox/utils/limit.py", line 62, in run_without_time_limit
    ret = obj_func(*obj_args, **obj_kwargs)
  File "BO_partition.py", line 72, in obj_func
    cost = self.black_box.get_cost_from_partitions(partitions)
  File "BO_partition.py", line 34, in get_cost_from_partitions
    partitions_cpp[i]=partitions[i]
IndexError: list index out of range

config: Configuration(values={
  'x0': 0,
  'x1': 1,
  'x10': 0,
  'x100': 1,
  'x101': 0,
  'x102': 0,
  'x103': 0,
  'x104': 1,
  'x105': 1,
  'x106': 1,
  'x107': 0,
  'x108': 1,
  'x109': 1,
  'x11': 0,
  'x110': 0,
  'x111': 1,
  'x112': 1,
  'x113': 1,
  'x114': 0,
  'x115': 1,
  'x116': 0,
  'x117': 1,
  'x118': 1,
  'x119': 0,
  'x12': 1,
  'x120': 1,
  'x121': 0,
  'x122': 0,
  'x123': 1,
  'x124': 1,
  'x125': 0,
  'x126': 1,
  'x127': 0,
  'x128': 0,
  'x129': 0,
  'x13': 1,
  'x130': 0,
  'x131': 0,
  'x132': 1,
  'x133': 0,
  'x134': 0,
  'x135': 0,
  'x136': 1,
  'x137': 0,
  'x138': 0,
  'x139': 1,
  'x14': 1,
  'x140': 0,
  'x141': 1,
  'x142': 0,
  'x143': 1,
  'x144': 1,
  'x145': 1,
  'x15': 0,
  'x16': 0,
  'x17': 1,
  'x18': 1,
  'x19': 1,
  'x2': 1,
  'x20': 1,
  'x21': 0,
  'x22': 1,
  'x23': 1,
  'x24': 1,
  'x25': 1,
  'x26': 1,
  'x27': 1,
  'x28': 0,
  'x29': 1,
  'x3': 0,
  'x30': 1,
  'x31': 0,
  'x32': 1,
  'x33': 1,
  'x34': 0,
  'x35': 1,
  'x36': 1,
  'x37': 0,
  'x38': 0,
  'x39': 1,
  'x4': 0,
  'x40': 0,
  'x41': 1,
  'x42': 0,
  'x43': 0,
  'x44': 1,
  'x45': 0,
  'x46': 1,
  'x47': 1,
  'x48': 0,
  'x49': 0,
  'x5': 0,
  'x50': 1,
  'x51': 0,
  'x52': 0,
  'x53': 1,
  'x54': 1,
  'x55': 1,
  'x56': 1,
  'x57': 0,
  'x58': 1,
  'x59': 0,
  'x6': 1,
  'x60': 0,
  'x61': 0,
  'x62': 0,
  'x63': 0,
  'x64': 0,
  'x65': 1,
  'x66': 1,
  'x67': 1,
  'x68': 1,
  'x69': 0,
  'x7': 0,
  'x70': 1,
  'x71': 1,
  'x72': 1,
  'x73': 1,
  'x74': 1,
  'x75': 1,
  'x76': 0,
  'x77': 1,
  'x78': 0,
  'x79': 0,
  'x8': 1,
  'x80': 0,
  'x81': 0,
  'x82': 0,
  'x83': 1,
  'x84': 0,
  'x85': 1,
  'x86': 1,
  'x87': 1,
  'x88': 0,
  'x89': 1,
  'x9': 1,
  'x90': 0,
  'x91': 1,
  'x92': 0,
  'x93': 1,
  'x94': 1,
  'x95': 0,
  'x96': 0,
  'x97': 1,
  'x98': 0,
  'x99': 1,
})

[2024-09-05 06:43:26,919][basic_search][INFO][generic_smbo.py:310] Iter 32, objectives: [inf].
[2024-09-05 06:43:26,928][basic_search][WARNING][generic_advisor.py:467] No enough successful initial trials! Sample random configuration.
[2024-09-05 06:43:26,932][basic_search][ERROR][generic_smbo.py:290] Exception in objective function:
Traceback (most recent call last):
  File "/gyc_data/fray_data/py38hwvenv/lib/python3.8/site-packages/openbox/utils/limit.py", line 62, in run_without_time_limit
    ret = obj_func(*obj_args, **obj_kwargs)
  File "BO_partition.py", line 72, in obj_func
    cost = self.black_box.get_cost_from_partitions(partitions)
  File "BO_partition.py", line 34, in get_cost_from_partitions
    partitions_cpp[i]=partitions[i]
IndexError: list index out of range

config: Configuration(values={
  'x0': 1,
  'x1': 1,
  'x10': 1,
  'x100': 1,
  'x101': 0,
  'x102': 0,
  'x103': 0,
  'x104': 0,
  'x105': 0,
  'x106': 1,
  'x107': 0,
  'x108': 0,
  'x109': 1,
  'x11': 1,
  'x110': 1,
  'x111': 1,
  'x112': 0,
  'x113': 0,
  'x114': 1,
  'x115': 1,
  'x116': 0,
  'x117': 1,
  'x118': 1,
  'x119': 1,
  'x12': 0,
  'x120': 1,
  'x121': 0,
  'x122': 1,
  'x123': 0,
  'x124': 1,
  'x125': 0,
  'x126': 1,
  'x127': 0,
  'x128': 0,
  'x129': 0,
  'x13': 0,
  'x130': 1,
  'x131': 0,
  'x132': 0,
  'x133': 0,
  'x134': 1,
  'x135': 0,
  'x136': 0,
  'x137': 0,
  'x138': 0,
  'x139': 1,
  'x14': 0,
  'x140': 1,
  'x141': 0,
  'x142': 1,
  'x143': 1,
  'x144': 1,
  'x145': 0,
  'x15': 0,
  'x16': 1,
  'x17': 1,
  'x18': 0,
  'x19': 0,
  'x2': 1,
  'x20': 1,
  'x21': 0,
  'x22': 1,
  'x23': 0,
  'x24': 0,
  'x25': 0,
  'x26': 1,
  'x27': 0,
  'x28': 1,
  'x29': 1,
  'x3': 0,
  'x30': 1,
  'x31': 1,
  'x32': 1,
  'x33': 0,
  'x34': 1,
  'x35': 1,
  'x36': 1,
  'x37': 1,
  'x38': 1,
  'x39': 1,
  'x4': 0,
  'x40': 0,
  'x41': 1,
  'x42': 0,
  'x43': 1,
  'x44': 1,
  'x45': 0,
  'x46': 1,
  'x47': 1,
  'x48': 0,
  'x49': 0,
  'x5': 1,
  'x50': 1,
  'x51': 0,
  'x52': 0,
  'x53': 0,
  'x54': 1,
  'x55': 0,
  'x56': 0,
  'x57': 1,
  'x58': 1,
  'x59': 0,
  'x6': 1,
  'x60': 1,
  'x61': 0,
  'x62': 0,
  'x63': 0,
  'x64': 0,
  'x65': 0,
  'x66': 0,
  'x67': 1,
  'x68': 1,
  'x69': 0,
  'x7': 1,
  'x70': 1,
  'x71': 0,
  'x72': 0,
  'x73': 0,
  'x74': 1,
  'x75': 1,
  'x76': 1,
  'x77': 0,
  'x78': 1,
  'x79': 0,
  'x8': 1,
  'x80': 0,
  'x81': 0,
  'x82': 1,
  'x83': 1,
  'x84': 0,
  'x85': 1,
  'x86': 1,
  'x87': 0,
  'x88': 0,
  'x89': 0,
  'x9': 0,
  'x90': 0,
  'x91': 0,
  'x92': 0,
  'x93': 1,
  'x94': 1,
  'x95': 0,
  'x96': 0,
  'x97': 0,
  'x98': 1,
  'x99': 0,
})

[2024-09-05 06:43:26,932][basic_search][INFO][generic_smbo.py:310] Iter 33, objectives: [inf].
[2024-09-05 06:43:26,942][basic_search][WARNING][generic_advisor.py:467] No enough successful initial trials! Sample random configuration.
[2024-09-05 06:43:26,945][basic_search][ERROR][generic_smbo.py:290] Exception in objective function:
Traceback (most recent call last):
  File "/gyc_data/fray_data/py38hwvenv/lib/python3.8/site-packages/openbox/utils/limit.py", line 62, in run_without_time_limit
    ret = obj_func(*obj_args, **obj_kwargs)
  File "BO_partition.py", line 72, in obj_func
    cost = self.black_box.get_cost_from_partitions(partitions)
  File "BO_partition.py", line 34, in get_cost_from_partitions
    partitions_cpp[i]=partitions[i]
IndexError: list index out of range

config: Configuration(values={
  'x0': 1,
  'x1': 0,
  'x10': 1,
  'x100': 1,
  'x101': 0,
  'x102': 0,
  'x103': 0,
  'x104': 1,
  'x105': 1,
  'x106': 1,
  'x107': 0,
  'x108': 1,
  'x109': 0,
  'x11': 0,
  'x110': 0,
  'x111': 0,
  'x112': 1,
  'x113': 1,
  'x114': 1,
  'x115': 1,
  'x116': 0,
  'x117': 1,
  'x118': 0,
  'x119': 1,
  'x12': 0,
  'x120': 0,
  'x121': 1,
  'x122': 1,
  'x123': 1,
  'x124': 0,
  'x125': 0,
  'x126': 0,
  'x127': 1,
  'x128': 0,
  'x129': 1,
  'x13': 0,
  'x130': 0,
  'x131': 0,
  'x132': 1,
  'x133': 0,
  'x134': 1,
  'x135': 0,
  'x136': 1,
  'x137': 0,
  'x138': 0,
  'x139': 0,
  'x14': 1,
  'x140': 1,
  'x141': 1,
  'x142': 0,
  'x143': 0,
  'x144': 1,
  'x145': 0,
  'x15': 0,
  'x16': 1,
  'x17': 0,
  'x18': 0,
  'x19': 0,
  'x2': 1,
  'x20': 0,
  'x21': 1,
  'x22': 1,
  'x23': 0,
  'x24': 1,
  'x25': 1,
  'x26': 1,
  'x27': 1,
  'x28': 0,
  'x29': 1,
  'x3': 1,
  'x30': 1,
  'x31': 0,
  'x32': 1,
  'x33': 0,
  'x34': 1,
  'x35': 0,
  'x36': 1,
  'x37': 0,
  'x38': 1,
  'x39': 0,
  'x4': 1,
  'x40': 0,
  'x41': 0,
  'x42': 0,
  'x43': 1,
  'x44': 0,
  'x45': 0,
  'x46': 0,
  'x47': 1,
  'x48': 0,
  'x49': 0,
  'x5': 1,
  'x50': 0,
  'x51': 0,
  'x52': 1,
  'x53': 0,
  'x54': 0,
  'x55': 0,
  'x56': 0,
  'x57': 0,
  'x58': 1,
  'x59': 0,
  'x6': 0,
  'x60': 1,
  'x61': 0,
  'x62': 1,
  'x63': 0,
  'x64': 0,
  'x65': 1,
  'x66': 1,
  'x67': 1,
  'x68': 0,
  'x69': 1,
  'x7': 1,
  'x70': 1,
  'x71': 0,
  'x72': 0,
  'x73': 1,
  'x74': 0,
  'x75': 1,
  'x76': 1,
  'x77': 1,
  'x78': 0,
  'x79': 1,
  'x8': 0,
  'x80': 1,
  'x81': 0,
  'x82': 0,
  'x83': 1,
  'x84': 1,
  'x85': 0,
  'x86': 0,
  'x87': 0,
  'x88': 0,
  'x89': 1,
  'x9': 0,
  'x90': 0,
  'x91': 1,
  'x92': 0,
  'x93': 1,
  'x94': 1,
  'x95': 0,
  'x96': 1,
  'x97': 0,
  'x98': 1,
  'x99': 0,
})

[2024-09-05 06:43:26,946][basic_search][INFO][generic_smbo.py:310] Iter 34, objectives: [inf].
[2024-09-05 06:43:26,955][basic_search][INFO][generic_advisor.py:457] Sample random config. rand_prob=0.100000.
[2024-09-05 06:43:26,959][basic_search][ERROR][generic_smbo.py:290] Exception in objective function:
Traceback (most recent call last):
  File "/gyc_data/fray_data/py38hwvenv/lib/python3.8/site-packages/openbox/utils/limit.py", line 62, in run_without_time_limit
    ret = obj_func(*obj_args, **obj_kwargs)
  File "BO_partition.py", line 72, in obj_func
    cost = self.black_box.get_cost_from_partitions(partitions)
  File "BO_partition.py", line 34, in get_cost_from_partitions
    partitions_cpp[i]=partitions[i]
IndexError: list index out of range

config: Configuration(values={
  'x0': 0,
  'x1': 1,
  'x10': 1,
  'x100': 1,
  'x101': 1,
  'x102': 0,
  'x103': 0,
  'x104': 0,
  'x105': 0,
  'x106': 1,
  'x107': 1,
  'x108': 1,
  'x109': 0,
  'x11': 1,
  'x110': 0,
  'x111': 1,
  'x112': 1,
  'x113': 0,
  'x114': 1,
  'x115': 0,
  'x116': 0,
  'x117': 1,
  'x118': 0,
  'x119': 1,
  'x12': 0,
  'x120': 1,
  'x121': 0,
  'x122': 1,
  'x123': 1,
  'x124': 1,
  'x125': 1,
  'x126': 1,
  'x127': 0,
  'x128': 1,
  'x129': 0,
  'x13': 0,
  'x130': 1,
  'x131': 1,
  'x132': 0,
  'x133': 0,
  'x134': 1,
  'x135': 1,
  'x136': 1,
  'x137': 0,
  'x138': 0,
  'x139': 0,
  'x14': 0,
  'x140': 0,
  'x141': 0,
  'x142': 1,
  'x143': 1,
  'x144': 1,
  'x145': 1,
  'x15': 1,
  'x16': 1,
  'x17': 0,
  'x18': 0,
  'x19': 1,
  'x2': 1,
  'x20': 0,
  'x21': 1,
  'x22': 0,
  'x23': 0,
  'x24': 0,
  'x25': 1,
  'x26': 0,
  'x27': 0,
  'x28': 1,
  'x29': 0,
  'x3': 0,
  'x30': 1,
  'x31': 1,
  'x32': 1,
  'x33': 0,
  'x34': 1,
  'x35': 0,
  'x36': 1,
  'x37': 1,
  'x38': 0,
  'x39': 0,
  'x4': 1,
  'x40': 1,
  'x41': 1,
  'x42': 1,
  'x43': 0,
  'x44': 0,
  'x45': 1,
  'x46': 0,
  'x47': 0,
  'x48': 1,
  'x49': 0,
  'x5': 1,
  'x50': 0,
  'x51': 0,
  'x52': 0,
  'x53': 0,
  'x54': 0,
  'x55': 0,
  'x56': 0,
  'x57': 0,
  'x58': 0,
  'x59': 0,
  'x6': 0,
  'x60': 1,
  'x61': 1,
  'x62': 1,
  'x63': 0,
  'x64': 1,
  'x65': 1,
  'x66': 0,
  'x67': 0,
  'x68': 1,
  'x69': 0,
  'x7': 0,
  'x70': 1,
  'x71': 0,
  'x72': 0,
  'x73': 0,
  'x74': 0,
  'x75': 0,
  'x76': 0,
  'x77': 0,
  'x78': 1,
  'x79': 0,
  'x8': 0,
  'x80': 0,
  'x81': 0,
  'x82': 1,
  'x83': 1,
  'x84': 0,
  'x85': 1,
  'x86': 0,
  'x87': 0,
  'x88': 1,
  'x89': 0,
  'x9': 1,
  'x90': 0,
  'x91': 1,
  'x92': 0,
  'x93': 1,
  'x94': 0,
  'x95': 0,
  'x96': 0,
  'x97': 0,
  'x98': 1,
  'x99': 0,
})

[2024-09-05 06:43:26,959][basic_search][INFO][generic_smbo.py:310] Iter 35, objectives: [inf].
[2024-09-05 06:43:26,969][basic_search][WARNING][generic_advisor.py:467] No enough successful initial trials! Sample random configuration.
[2024-09-05 06:43:26,973][basic_search][ERROR][generic_smbo.py:290] Exception in objective function:
Traceback (most recent call last):
  File "/gyc_data/fray_data/py38hwvenv/lib/python3.8/site-packages/openbox/utils/limit.py", line 62, in run_without_time_limit
    ret = obj_func(*obj_args, **obj_kwargs)
  File "BO_partition.py", line 72, in obj_func
    cost = self.black_box.get_cost_from_partitions(partitions)
  File "BO_partition.py", line 34, in get_cost_from_partitions
    partitions_cpp[i]=partitions[i]
IndexError: list index out of range

config: Configuration(values={
  'x0': 0,
  'x1': 0,
  'x10': 0,
  'x100': 1,
  'x101': 1,
  'x102': 0,
  'x103': 1,
  'x104': 1,
  'x105': 1,
  'x106': 1,
  'x107': 0,
  'x108': 1,
  'x109': 0,
  'x11': 0,
  'x110': 0,
  'x111': 0,
  'x112': 1,
  'x113': 0,
  'x114': 0,
  'x115': 0,
  'x116': 1,
  'x117': 1,
  'x118': 0,
  'x119': 1,
  'x12': 1,
  'x120': 1,
  'x121': 0,
  'x122': 0,
  'x123': 0,
  'x124': 0,
  'x125': 0,
  'x126': 0,
  'x127': 1,
  'x128': 0,
  'x129': 0,
  'x13': 1,
  'x130': 1,
  'x131': 1,
  'x132': 0,
  'x133': 1,
  'x134': 0,
  'x135': 1,
  'x136': 0,
  'x137': 0,
  'x138': 0,
  'x139': 1,
  'x14': 1,
  'x140': 1,
  'x141': 1,
  'x142': 1,
  'x143': 0,
  'x144': 1,
  'x145': 1,
  'x15': 0,
  'x16': 1,
  'x17': 1,
  'x18': 0,
  'x19': 0,
  'x2': 1,
  'x20': 1,
  'x21': 1,
  'x22': 0,
  'x23': 0,
  'x24': 0,
  'x25': 0,
  'x26': 0,
  'x27': 0,
  'x28': 1,
  'x29': 0,
  'x3': 1,
  'x30': 0,
  'x31': 0,
  'x32': 1,
  'x33': 1,
  'x34': 0,
  'x35': 0,
  'x36': 1,
  'x37': 0,
  'x38': 1,
  'x39': 1,
  'x4': 0,
  'x40': 0,
  'x41': 1,
  'x42': 1,
  'x43': 0,
  'x44': 0,
  'x45': 1,
  'x46': 1,
  'x47': 1,
  'x48': 0,
  'x49': 0,
  'x5': 1,
  'x50': 0,
  'x51': 1,
  'x52': 0,
  'x53': 1,
  'x54': 0,
  'x55': 1,
  'x56': 1,
  'x57': 0,
  'x58': 0,
  'x59': 1,
  'x6': 0,
  'x60': 1,
  'x61': 0,
  'x62': 1,
  'x63': 0,
  'x64': 0,
  'x65': 1,
  'x66': 1,
  'x67': 1,
  'x68': 1,
  'x69': 0,
  'x7': 1,
  'x70': 0,
  'x71': 0,
  'x72': 1,
  'x73': 0,
  'x74': 1,
  'x75': 1,
  'x76': 1,
  'x77': 0,
  'x78': 0,
  'x79': 1,
  'x8': 1,
  'x80': 1,
  'x81': 1,
  'x82': 1,
  'x83': 1,
  'x84': 1,
  'x85': 1,
  'x86': 0,
  'x87': 0,
  'x88': 0,
  'x89': 1,
  'x9': 0,
  'x90': 1,
  'x91': 1,
  'x92': 1,
  'x93': 0,
  'x94': 1,
  'x95': 1,
  'x96': 0,
  'x97': 1,
  'x98': 0,
  'x99': 1,
})

[2024-09-05 06:43:26,973][basic_search][INFO][generic_smbo.py:310] Iter 36, objectives: [inf].
[2024-09-05 06:43:26,984][basic_search][WARNING][generic_advisor.py:467] No enough successful initial trials! Sample random configuration.
[2024-09-05 06:43:26,988][basic_search][ERROR][generic_smbo.py:290] Exception in objective function:
Traceback (most recent call last):
  File "/gyc_data/fray_data/py38hwvenv/lib/python3.8/site-packages/openbox/utils/limit.py", line 62, in run_without_time_limit
    ret = obj_func(*obj_args, **obj_kwargs)
  File "BO_partition.py", line 72, in obj_func
    cost = self.black_box.get_cost_from_partitions(partitions)
  File "BO_partition.py", line 34, in get_cost_from_partitions
    partitions_cpp[i]=partitions[i]
IndexError: list index out of range

config: Configuration(values={
  'x0': 1,
  'x1': 1,
  'x10': 0,
  'x100': 1,
  'x101': 1,
  'x102': 0,
  'x103': 0,
  'x104': 0,
  'x105': 0,
  'x106': 1,
  'x107': 0,
  'x108': 1,
  'x109': 0,
  'x11': 0,
  'x110': 1,
  'x111': 0,
  'x112': 0,
  'x113': 0,
  'x114': 0,
  'x115': 0,
  'x116': 1,
  'x117': 1,
  'x118': 1,
  'x119': 0,
  'x12': 1,
  'x120': 0,
  'x121': 0,
  'x122': 1,
  'x123': 0,
  'x124': 0,
  'x125': 1,
  'x126': 0,
  'x127': 0,
  'x128': 1,
  'x129': 1,
  'x13': 1,
  'x130': 0,
  'x131': 1,
  'x132': 0,
  'x133': 0,
  'x134': 1,
  'x135': 1,
  'x136': 1,
  'x137': 0,
  'x138': 1,
  'x139': 1,
  'x14': 0,
  'x140': 1,
  'x141': 1,
  'x142': 1,
  'x143': 0,
  'x144': 1,
  'x145': 0,
  'x15': 0,
  'x16': 0,
  'x17': 1,
  'x18': 0,
  'x19': 0,
  'x2': 0,
  'x20': 1,
  'x21': 1,
  'x22': 0,
  'x23': 1,
  'x24': 1,
  'x25': 1,
  'x26': 1,
  'x27': 1,
  'x28': 1,
  'x29': 1,
  'x3': 0,
  'x30': 0,
  'x31': 0,
  'x32': 0,
  'x33': 1,
  'x34': 0,
  'x35': 0,
  'x36': 0,
  'x37': 0,
  'x38': 0,
  'x39': 0,
  'x4': 1,
  'x40': 0,
  'x41': 1,
  'x42': 1,
  'x43': 0,
  'x44': 0,
  'x45': 0,
  'x46': 0,
  'x47': 0,
  'x48': 1,
  'x49': 1,
  'x5': 0,
  'x50': 1,
  'x51': 0,
  'x52': 0,
  'x53': 0,
  'x54': 1,
  'x55': 0,
  'x56': 1,
  'x57': 0,
  'x58': 1,
  'x59': 1,
  'x6': 0,
  'x60': 0,
  'x61': 0,
  'x62': 0,
  'x63': 1,
  'x64': 1,
  'x65': 0,
  'x66': 1,
  'x67': 0,
  'x68': 0,
  'x69': 1,
  'x7': 0,
  'x70': 1,
  'x71': 1,
  'x72': 1,
  'x73': 0,
  'x74': 0,
  'x75': 0,
  'x76': 1,
  'x77': 1,
  'x78': 0,
  'x79': 1,
  'x8': 0,
  'x80': 0,
  'x81': 1,
  'x82': 1,
  'x83': 0,
  'x84': 1,
  'x85': 1,
  'x86': 1,
  'x87': 1,
  'x88': 1,
  'x89': 1,
  'x9': 1,
  'x90': 1,
  'x91': 1,
  'x92': 0,
  'x93': 1,
  'x94': 1,
  'x95': 1,
  'x96': 1,
  'x97': 1,
  'x98': 1,
  'x99': 0,
})

[2024-09-05 06:43:26,988][basic_search][INFO][generic_smbo.py:310] Iter 37, objectives: [inf].
[2024-09-05 06:43:26,999][basic_search][WARNING][generic_advisor.py:467] No enough successful initial trials! Sample random configuration.
[2024-09-05 06:43:27,003][basic_search][ERROR][generic_smbo.py:290] Exception in objective function:
Traceback (most recent call last):
  File "/gyc_data/fray_data/py38hwvenv/lib/python3.8/site-packages/openbox/utils/limit.py", line 62, in run_without_time_limit
    ret = obj_func(*obj_args, **obj_kwargs)
  File "BO_partition.py", line 72, in obj_func
    cost = self.black_box.get_cost_from_partitions(partitions)
  File "BO_partition.py", line 34, in get_cost_from_partitions
    partitions_cpp[i]=partitions[i]
IndexError: list index out of range

config: Configuration(values={
  'x0': 0,
  'x1': 0,
  'x10': 1,
  'x100': 0,
  'x101': 0,
  'x102': 0,
  'x103': 1,
  'x104': 0,
  'x105': 1,
  'x106': 1,
  'x107': 0,
  'x108': 1,
  'x109': 1,
  'x11': 1,
  'x110': 0,
  'x111': 1,
  'x112': 0,
  'x113': 1,
  'x114': 0,
  'x115': 0,
  'x116': 0,
  'x117': 0,
  'x118': 0,
  'x119': 1,
  'x12': 1,
  'x120': 1,
  'x121': 0,
  'x122': 1,
  'x123': 0,
  'x124': 1,
  'x125': 1,
  'x126': 1,
  'x127': 1,
  'x128': 1,
  'x129': 1,
  'x13': 1,
  'x130': 1,
  'x131': 1,
  'x132': 1,
  'x133': 1,
  'x134': 1,
  'x135': 1,
  'x136': 0,
  'x137': 0,
  'x138': 0,
  'x139': 1,
  'x14': 0,
  'x140': 0,
  'x141': 1,
  'x142': 0,
  'x143': 0,
  'x144': 1,
  'x145': 0,
  'x15': 0,
  'x16': 0,
  'x17': 0,
  'x18': 0,
  'x19': 1,
  'x2': 0,
  'x20': 1,
  'x21': 0,
  'x22': 0,
  'x23': 1,
  'x24': 0,
  'x25': 1,
  'x26': 0,
  'x27': 1,
  'x28': 0,
  'x29': 0,
  'x3': 1,
  'x30': 1,
  'x31': 1,
  'x32': 0,
  'x33': 1,
  'x34': 1,
  'x35': 0,
  'x36': 1,
  'x37': 1,
  'x38': 0,
  'x39': 1,
  'x4': 0,
  'x40': 0,
  'x41': 1,
  'x42': 1,
  'x43': 0,
  'x44': 0,
  'x45': 0,
  'x46': 1,
  'x47': 1,
  'x48': 0,
  'x49': 0,
  'x5': 1,
  'x50': 1,
  'x51': 0,
  'x52': 1,
  'x53': 0,
  'x54': 1,
  'x55': 1,
  'x56': 1,
  'x57': 1,
  'x58': 1,
  'x59': 1,
  'x6': 1,
  'x60': 1,
  'x61': 0,
  'x62': 1,
  'x63': 0,
  'x64': 1,
  'x65': 0,
  'x66': 1,
  'x67': 1,
  'x68': 1,
  'x69': 0,
  'x7': 0,
  'x70': 0,
  'x71': 1,
  'x72': 0,
  'x73': 0,
  'x74': 0,
  'x75': 0,
  'x76': 1,
  'x77': 1,
  'x78': 1,
  'x79': 0,
  'x8': 1,
  'x80': 1,
  'x81': 1,
  'x82': 1,
  'x83': 1,
  'x84': 0,
  'x85': 0,
  'x86': 0,
  'x87': 0,
  'x88': 0,
  'x89': 0,
  'x9': 1,
  'x90': 1,
  'x91': 1,
  'x92': 1,
  'x93': 1,
  'x94': 1,
  'x95': 1,
  'x96': 0,
  'x97': 1,
  'x98': 1,
  'x99': 0,
})

[2024-09-05 06:43:27,003][basic_search][INFO][generic_smbo.py:310] Iter 38, objectives: [inf].
[2024-09-05 06:43:27,014][basic_search][WARNING][generic_advisor.py:467] No enough successful initial trials! Sample random configuration.
[2024-09-05 06:43:27,018][basic_search][ERROR][generic_smbo.py:290] Exception in objective function:
Traceback (most recent call last):
  File "/gyc_data/fray_data/py38hwvenv/lib/python3.8/site-packages/openbox/utils/limit.py", line 62, in run_without_time_limit
    ret = obj_func(*obj_args, **obj_kwargs)
  File "BO_partition.py", line 72, in obj_func
    cost = self.black_box.get_cost_from_partitions(partitions)
  File "BO_partition.py", line 34, in get_cost_from_partitions
    partitions_cpp[i]=partitions[i]
IndexError: list index out of range

config: Configuration(values={
  'x0': 0,
  'x1': 1,
  'x10': 1,
  'x100': 1,
  'x101': 1,
  'x102': 0,
  'x103': 0,
  'x104': 1,
  'x105': 1,
  'x106': 0,
  'x107': 1,
  'x108': 0,
  'x109': 1,
  'x11': 1,
  'x110': 0,
  'x111': 1,
  'x112': 1,
  'x113': 0,
  'x114': 0,
  'x115': 0,
  'x116': 1,
  'x117': 0,
  'x118': 0,
  'x119': 0,
  'x12': 1,
  'x120': 0,
  'x121': 1,
  'x122': 1,
  'x123': 1,
  'x124': 0,
  'x125': 0,
  'x126': 0,
  'x127': 1,
  'x128': 1,
  'x129': 1,
  'x13': 1,
  'x130': 1,
  'x131': 0,
  'x132': 1,
  'x133': 0,
  'x134': 0,
  'x135': 1,
  'x136': 1,
  'x137': 0,
  'x138': 0,
  'x139': 0,
  'x14': 1,
  'x140': 1,
  'x141': 0,
  'x142': 0,
  'x143': 1,
  'x144': 0,
  'x145': 1,
  'x15': 1,
  'x16': 1,
  'x17': 0,
  'x18': 1,
  'x19': 0,
  'x2': 0,
  'x20': 0,
  'x21': 0,
  'x22': 0,
  'x23': 1,
  'x24': 0,
  'x25': 1,
  'x26': 0,
  'x27': 0,
  'x28': 1,
  'x29': 0,
  'x3': 0,
  'x30': 1,
  'x31': 0,
  'x32': 0,
  'x33': 1,
  'x34': 1,
  'x35': 1,
  'x36': 0,
  'x37': 1,
  'x38': 0,
  'x39': 1,
  'x4': 0,
  'x40': 0,
  'x41': 0,
  'x42': 1,
  'x43': 1,
  'x44': 1,
  'x45': 0,
  'x46': 0,
  'x47': 1,
  'x48': 1,
  'x49': 0,
  'x5': 1,
  'x50': 0,
  'x51': 0,
  'x52': 1,
  'x53': 0,
  'x54': 0,
  'x55': 0,
  'x56': 0,
  'x57': 1,
  'x58': 1,
  'x59': 0,
  'x6': 0,
  'x60': 0,
  'x61': 0,
  'x62': 0,
  'x63': 1,
  'x64': 1,
  'x65': 0,
  'x66': 1,
  'x67': 1,
  'x68': 1,
  'x69': 0,
  'x7': 1,
  'x70': 1,
  'x71': 1,
  'x72': 1,
  'x73': 0,
  'x74': 1,
  'x75': 1,
  'x76': 0,
  'x77': 1,
  'x78': 0,
  'x79': 0,
  'x8': 1,
  'x80': 0,
  'x81': 0,
  'x82': 0,
  'x83': 1,
  'x84': 1,
  'x85': 0,
  'x86': 1,
  'x87': 0,
  'x88': 1,
  'x89': 0,
  'x9': 1,
  'x90': 1,
  'x91': 0,
  'x92': 1,
  'x93': 1,
  'x94': 0,
  'x95': 0,
  'x96': 1,
  'x97': 0,
  'x98': 0,
  'x99': 0,
})

[2024-09-05 06:43:27,018][basic_search][INFO][generic_smbo.py:310] Iter 39, objectives: [inf].
[2024-09-05 06:43:27,029][basic_search][WARNING][generic_advisor.py:467] No enough successful initial trials! Sample random configuration.
[2024-09-05 06:43:27,033][basic_search][ERROR][generic_smbo.py:290] Exception in objective function:
Traceback (most recent call last):
  File "/gyc_data/fray_data/py38hwvenv/lib/python3.8/site-packages/openbox/utils/limit.py", line 62, in run_without_time_limit
    ret = obj_func(*obj_args, **obj_kwargs)
  File "BO_partition.py", line 72, in obj_func
    cost = self.black_box.get_cost_from_partitions(partitions)
  File "BO_partition.py", line 34, in get_cost_from_partitions
    partitions_cpp[i]=partitions[i]
IndexError: list index out of range

config: Configuration(values={
  'x0': 0,
  'x1': 0,
  'x10': 0,
  'x100': 1,
  'x101': 0,
  'x102': 1,
  'x103': 1,
  'x104': 0,
  'x105': 1,
  'x106': 0,
  'x107': 1,
  'x108': 0,
  'x109': 0,
  'x11': 1,
  'x110': 0,
  'x111': 1,
  'x112': 1,
  'x113': 1,
  'x114': 1,
  'x115': 0,
  'x116': 1,
  'x117': 1,
  'x118': 0,
  'x119': 1,
  'x12': 1,
  'x120': 1,
  'x121': 1,
  'x122': 1,
  'x123': 1,
  'x124': 0,
  'x125': 1,
  'x126': 1,
  'x127': 1,
  'x128': 1,
  'x129': 1,
  'x13': 0,
  'x130': 1,
  'x131': 0,
  'x132': 1,
  'x133': 0,
  'x134': 1,
  'x135': 1,
  'x136': 1,
  'x137': 0,
  'x138': 0,
  'x139': 1,
  'x14': 1,
  'x140': 0,
  'x141': 1,
  'x142': 1,
  'x143': 0,
  'x144': 1,
  'x145': 0,
  'x15': 1,
  'x16': 1,
  'x17': 1,
  'x18': 1,
  'x19': 0,
  'x2': 0,
  'x20': 1,
  'x21': 1,
  'x22': 0,
  'x23': 0,
  'x24': 0,
  'x25': 0,
  'x26': 1,
  'x27': 1,
  'x28': 0,
  'x29': 0,
  'x3': 0,
  'x30': 0,
  'x31': 1,
  'x32': 0,
  'x33': 0,
  'x34': 0,
  'x35': 1,
  'x36': 1,
  'x37': 1,
  'x38': 1,
  'x39': 1,
  'x4': 1,
  'x40': 0,
  'x41': 1,
  'x42': 0,
  'x43': 0,
  'x44': 1,
  'x45': 0,
  'x46': 0,
  'x47': 1,
  'x48': 0,
  'x49': 1,
  'x5': 0,
  'x50': 1,
  'x51': 1,
  'x52': 0,
  'x53': 0,
  'x54': 1,
  'x55': 0,
  'x56': 0,
  'x57': 1,
  'x58': 0,
  'x59': 0,
  'x6': 0,
  'x60': 0,
  'x61': 0,
  'x62': 1,
  'x63': 1,
  'x64': 0,
  'x65': 1,
  'x66': 0,
  'x67': 1,
  'x68': 0,
  'x69': 1,
  'x7': 0,
  'x70': 1,
  'x71': 0,
  'x72': 0,
  'x73': 0,
  'x74': 1,
  'x75': 1,
  'x76': 1,
  'x77': 0,
  'x78': 1,
  'x79': 1,
  'x8': 0,
  'x80': 0,
  'x81': 0,
  'x82': 0,
  'x83': 0,
  'x84': 1,
  'x85': 0,
  'x86': 0,
  'x87': 0,
  'x88': 1,
  'x89': 0,
  'x9': 1,
  'x90': 0,
  'x91': 1,
  'x92': 0,
  'x93': 1,
  'x94': 0,
  'x95': 0,
  'x96': 1,
  'x97': 1,
  'x98': 0,
  'x99': 1,
})

[2024-09-05 06:43:27,033][basic_search][INFO][generic_smbo.py:310] Iter 40, objectives: [inf].
[2024-09-05 06:43:27,045][basic_search][WARNING][generic_advisor.py:467] No enough successful initial trials! Sample random configuration.
[2024-09-05 06:43:27,048][basic_search][ERROR][generic_smbo.py:290] Exception in objective function:
Traceback (most recent call last):
  File "/gyc_data/fray_data/py38hwvenv/lib/python3.8/site-packages/openbox/utils/limit.py", line 62, in run_without_time_limit
    ret = obj_func(*obj_args, **obj_kwargs)
  File "BO_partition.py", line 72, in obj_func
    cost = self.black_box.get_cost_from_partitions(partitions)
  File "BO_partition.py", line 34, in get_cost_from_partitions
    partitions_cpp[i]=partitions[i]
IndexError: list index out of range

config: Configuration(values={
  'x0': 0,
  'x1': 0,
  'x10': 0,
  'x100': 1,
  'x101': 1,
  'x102': 1,
  'x103': 0,
  'x104': 0,
  'x105': 0,
  'x106': 0,
  'x107': 1,
  'x108': 0,
  'x109': 1,
  'x11': 0,
  'x110': 1,
  'x111': 0,
  'x112': 0,
  'x113': 1,
  'x114': 1,
  'x115': 0,
  'x116': 0,
  'x117': 0,
  'x118': 1,
  'x119': 0,
  'x12': 0,
  'x120': 0,
  'x121': 1,
  'x122': 1,
  'x123': 1,
  'x124': 1,
  'x125': 1,
  'x126': 1,
  'x127': 0,
  'x128': 0,
  'x129': 1,
  'x13': 1,
  'x130': 1,
  'x131': 1,
  'x132': 1,
  'x133': 0,
  'x134': 0,
  'x135': 0,
  'x136': 1,
  'x137': 1,
  'x138': 1,
  'x139': 1,
  'x14': 1,
  'x140': 0,
  'x141': 1,
  'x142': 0,
  'x143': 0,
  'x144': 1,
  'x145': 0,
  'x15': 0,
  'x16': 1,
  'x17': 1,
  'x18': 1,
  'x19': 1,
  'x2': 1,
  'x20': 0,
  'x21': 1,
  'x22': 1,
  'x23': 1,
  'x24': 0,
  'x25': 0,
  'x26': 0,
  'x27': 1,
  'x28': 0,
  'x29': 1,
  'x3': 0,
  'x30': 0,
  'x31': 0,
  'x32': 0,
  'x33': 1,
  'x34': 0,
  'x35': 1,
  'x36': 1,
  'x37': 1,
  'x38': 1,
  'x39': 1,
  'x4': 1,
  'x40': 1,
  'x41': 1,
  'x42': 0,
  'x43': 1,
  'x44': 1,
  'x45': 0,
  'x46': 1,
  'x47': 0,
  'x48': 0,
  'x49': 0,
  'x5': 0,
  'x50': 1,
  'x51': 1,
  'x52': 0,
  'x53': 1,
  'x54': 0,
  'x55': 1,
  'x56': 1,
  'x57': 0,
  'x58': 0,
  'x59': 1,
  'x6': 1,
  'x60': 0,
  'x61': 0,
  'x62': 1,
  'x63': 1,
  'x64': 1,
  'x65': 0,
  'x66': 1,
  'x67': 0,
  'x68': 1,
  'x69': 1,
  'x7': 1,
  'x70': 1,
  'x71': 0,
  'x72': 1,
  'x73': 1,
  'x74': 0,
  'x75': 1,
  'x76': 1,
  'x77': 1,
  'x78': 0,
  'x79': 0,
  'x8': 0,
  'x80': 1,
  'x81': 1,
  'x82': 0,
  'x83': 0,
  'x84': 1,
  'x85': 0,
  'x86': 1,
  'x87': 0,
  'x88': 1,
  'x89': 0,
  'x9': 1,
  'x90': 1,
  'x91': 0,
  'x92': 0,
  'x93': 0,
  'x94': 1,
  'x95': 0,
  'x96': 0,
  'x97': 0,
  'x98': 0,
  'x99': 1,
})

[2024-09-05 06:43:27,049][basic_search][INFO][generic_smbo.py:310] Iter 41, objectives: [inf].
[2024-09-05 06:43:27,060][basic_search][WARNING][generic_advisor.py:467] No enough successful initial trials! Sample random configuration.
[2024-09-05 06:43:27,064][basic_search][ERROR][generic_smbo.py:290] Exception in objective function:
Traceback (most recent call last):
  File "/gyc_data/fray_data/py38hwvenv/lib/python3.8/site-packages/openbox/utils/limit.py", line 62, in run_without_time_limit
    ret = obj_func(*obj_args, **obj_kwargs)
  File "BO_partition.py", line 72, in obj_func
    cost = self.black_box.get_cost_from_partitions(partitions)
  File "BO_partition.py", line 34, in get_cost_from_partitions
    partitions_cpp[i]=partitions[i]
IndexError: list index out of range

config: Configuration(values={
  'x0': 1,
  'x1': 0,
  'x10': 0,
  'x100': 0,
  'x101': 1,
  'x102': 1,
  'x103': 0,
  'x104': 0,
  'x105': 0,
  'x106': 1,
  'x107': 0,
  'x108': 1,
  'x109': 0,
  'x11': 1,
  'x110': 0,
  'x111': 1,
  'x112': 0,
  'x113': 1,
  'x114': 0,
  'x115': 1,
  'x116': 1,
  'x117': 1,
  'x118': 1,
  'x119': 1,
  'x12': 1,
  'x120': 0,
  'x121': 0,
  'x122': 0,
  'x123': 1,
  'x124': 1,
  'x125': 0,
  'x126': 1,
  'x127': 1,
  'x128': 0,
  'x129': 0,
  'x13': 0,
  'x130': 0,
  'x131': 1,
  'x132': 1,
  'x133': 0,
  'x134': 0,
  'x135': 0,
  'x136': 0,
  'x137': 0,
  'x138': 0,
  'x139': 0,
  'x14': 1,
  'x140': 1,
  'x141': 0,
  'x142': 0,
  'x143': 1,
  'x144': 0,
  'x145': 0,
  'x15': 0,
  'x16': 1,
  'x17': 1,
  'x18': 1,
  'x19': 1,
  'x2': 0,
  'x20': 1,
  'x21': 1,
  'x22': 0,
  'x23': 0,
  'x24': 0,
  'x25': 1,
  'x26': 1,
  'x27': 1,
  'x28': 1,
  'x29': 0,
  'x3': 1,
  'x30': 0,
  'x31': 1,
  'x32': 1,
  'x33': 1,
  'x34': 1,
  'x35': 1,
  'x36': 0,
  'x37': 1,
  'x38': 0,
  'x39': 1,
  'x4': 1,
  'x40': 1,
  'x41': 1,
  'x42': 1,
  'x43': 0,
  'x44': 0,
  'x45': 0,
  'x46': 0,
  'x47': 1,
  'x48': 0,
  'x49': 0,
  'x5': 1,
  'x50': 1,
  'x51': 1,
  'x52': 1,
  'x53': 1,
  'x54': 0,
  'x55': 0,
  'x56': 1,
  'x57': 1,
  'x58': 0,
  'x59': 0,
  'x6': 1,
  'x60': 0,
  'x61': 0,
  'x62': 1,
  'x63': 1,
  'x64': 0,
  'x65': 1,
  'x66': 0,
  'x67': 0,
  'x68': 1,
  'x69': 1,
  'x7': 0,
  'x70': 0,
  'x71': 0,
  'x72': 1,
  'x73': 1,
  'x74': 1,
  'x75': 0,
  'x76': 0,
  'x77': 0,
  'x78': 0,
  'x79': 0,
  'x8': 1,
  'x80': 0,
  'x81': 0,
  'x82': 1,
  'x83': 1,
  'x84': 1,
  'x85': 0,
  'x86': 0,
  'x87': 1,
  'x88': 1,
  'x89': 0,
  'x9': 0,
  'x90': 0,
  'x91': 0,
  'x92': 0,
  'x93': 0,
  'x94': 0,
  'x95': 0,
  'x96': 0,
  'x97': 1,
  'x98': 1,
  'x99': 1,
})

[2024-09-05 06:43:27,064][basic_search][INFO][generic_smbo.py:310] Iter 42, objectives: [inf].
[2024-09-05 06:43:27,076][basic_search][WARNING][generic_advisor.py:467] No enough successful initial trials! Sample random configuration.
[2024-09-05 06:43:27,080][basic_search][ERROR][generic_smbo.py:290] Exception in objective function:
Traceback (most recent call last):
  File "/gyc_data/fray_data/py38hwvenv/lib/python3.8/site-packages/openbox/utils/limit.py", line 62, in run_without_time_limit
    ret = obj_func(*obj_args, **obj_kwargs)
  File "BO_partition.py", line 72, in obj_func
    cost = self.black_box.get_cost_from_partitions(partitions)
  File "BO_partition.py", line 34, in get_cost_from_partitions
    partitions_cpp[i]=partitions[i]
IndexError: list index out of range

config: Configuration(values={
  'x0': 1,
  'x1': 0,
  'x10': 1,
  'x100': 1,
  'x101': 1,
  'x102': 1,
  'x103': 0,
  'x104': 0,
  'x105': 0,
  'x106': 0,
  'x107': 0,
  'x108': 1,
  'x109': 1,
  'x11': 0,
  'x110': 0,
  'x111': 0,
  'x112': 0,
  'x113': 0,
  'x114': 0,
  'x115': 0,
  'x116': 0,
  'x117': 1,
  'x118': 0,
  'x119': 1,
  'x12': 0,
  'x120': 0,
  'x121': 0,
  'x122': 0,
  'x123': 0,
  'x124': 1,
  'x125': 1,
  'x126': 1,
  'x127': 1,
  'x128': 1,
  'x129': 1,
  'x13': 0,
  'x130': 0,
  'x131': 0,
  'x132': 1,
  'x133': 0,
  'x134': 0,
  'x135': 0,
  'x136': 1,
  'x137': 0,
  'x138': 1,
  'x139': 1,
  'x14': 1,
  'x140': 0,
  'x141': 1,
  'x142': 1,
  'x143': 0,
  'x144': 1,
  'x145': 0,
  'x15': 0,
  'x16': 1,
  'x17': 1,
  'x18': 1,
  'x19': 1,
  'x2': 1,
  'x20': 1,
  'x21': 1,
  'x22': 1,
  'x23': 1,
  'x24': 1,
  'x25': 1,
  'x26': 0,
  'x27': 1,
  'x28': 1,
  'x29': 1,
  'x3': 1,
  'x30': 1,
  'x31': 0,
  'x32': 0,
  'x33': 1,
  'x34': 1,
  'x35': 1,
  'x36': 0,
  'x37': 1,
  'x38': 0,
  'x39': 0,
  'x4': 1,
  'x40': 0,
  'x41': 1,
  'x42': 1,
  'x43': 0,
  'x44': 0,
  'x45': 1,
  'x46': 1,
  'x47': 1,
  'x48': 1,
  'x49': 1,
  'x5': 1,
  'x50': 1,
  'x51': 0,
  'x52': 0,
  'x53': 1,
  'x54': 1,
  'x55': 0,
  'x56': 0,
  'x57': 0,
  'x58': 1,
  'x59': 0,
  'x6': 1,
  'x60': 1,
  'x61': 1,
  'x62': 0,
  'x63': 1,
  'x64': 1,
  'x65': 0,
  'x66': 0,
  'x67': 0,
  'x68': 0,
  'x69': 0,
  'x7': 0,
  'x70': 0,
  'x71': 1,
  'x72': 0,
  'x73': 0,
  'x74': 0,
  'x75': 0,
  'x76': 0,
  'x77': 0,
  'x78': 0,
  'x79': 1,
  'x8': 1,
  'x80': 1,
  'x81': 0,
  'x82': 1,
  'x83': 1,
  'x84': 1,
  'x85': 0,
  'x86': 0,
  'x87': 1,
  'x88': 0,
  'x89': 1,
  'x9': 0,
  'x90': 0,
  'x91': 0,
  'x92': 1,
  'x93': 0,
  'x94': 0,
  'x95': 0,
  'x96': 0,
  'x97': 0,
  'x98': 0,
  'x99': 0,
})

[2024-09-05 06:43:27,080][basic_search][INFO][generic_smbo.py:310] Iter 43, objectives: [inf].
[2024-09-05 06:43:27,093][basic_search][WARNING][generic_advisor.py:467] No enough successful initial trials! Sample random configuration.
[2024-09-05 06:43:27,097][basic_search][ERROR][generic_smbo.py:290] Exception in objective function:
Traceback (most recent call last):
  File "/gyc_data/fray_data/py38hwvenv/lib/python3.8/site-packages/openbox/utils/limit.py", line 62, in run_without_time_limit
    ret = obj_func(*obj_args, **obj_kwargs)
  File "BO_partition.py", line 72, in obj_func
    cost = self.black_box.get_cost_from_partitions(partitions)
  File "BO_partition.py", line 34, in get_cost_from_partitions
    partitions_cpp[i]=partitions[i]
IndexError: list index out of range

config: Configuration(values={
  'x0': 1,
  'x1': 1,
  'x10': 1,
  'x100': 1,
  'x101': 0,
  'x102': 1,
  'x103': 1,
  'x104': 1,
  'x105': 1,
  'x106': 0,
  'x107': 0,
  'x108': 0,
  'x109': 0,
  'x11': 0,
  'x110': 0,
  'x111': 0,
  'x112': 0,
  'x113': 0,
  'x114': 0,
  'x115': 1,
  'x116': 0,
  'x117': 1,
  'x118': 1,
  'x119': 0,
  'x12': 1,
  'x120': 0,
  'x121': 0,
  'x122': 0,
  'x123': 1,
  'x124': 0,
  'x125': 0,
  'x126': 0,
  'x127': 1,
  'x128': 1,
  'x129': 1,
  'x13': 0,
  'x130': 1,
  'x131': 0,
  'x132': 1,
  'x133': 0,
  'x134': 0,
  'x135': 0,
  'x136': 1,
  'x137': 0,
  'x138': 1,
  'x139': 1,
  'x14': 1,
  'x140': 0,
  'x141': 0,
  'x142': 0,
  'x143': 0,
  'x144': 0,
  'x145': 0,
  'x15': 1,
  'x16': 1,
  'x17': 1,
  'x18': 0,
  'x19': 1,
  'x2': 0,
  'x20': 0,
  'x21': 0,
  'x22': 1,
  'x23': 1,
  'x24': 0,
  'x25': 1,
  'x26': 1,
  'x27': 1,
  'x28': 0,
  'x29': 0,
  'x3': 1,
  'x30': 1,
  'x31': 1,
  'x32': 0,
  'x33': 0,
  'x34': 0,
  'x35': 1,
  'x36': 1,
  'x37': 1,
  'x38': 0,
  'x39': 0,
  'x4': 1,
  'x40': 0,
  'x41': 0,
  'x42': 0,
  'x43': 0,
  'x44': 1,
  'x45': 0,
  'x46': 0,
  'x47': 1,
  'x48': 0,
  'x49': 0,
  'x5': 0,
  'x50': 0,
  'x51': 1,
  'x52': 1,
  'x53': 1,
  'x54': 0,
  'x55': 0,
  'x56': 1,
  'x57': 0,
  'x58': 1,
  'x59': 0,
  'x6': 0,
  'x60': 0,
  'x61': 1,
  'x62': 0,
  'x63': 0,
  'x64': 1,
  'x65': 1,
  'x66': 0,
  'x67': 1,
  'x68': 1,
  'x69': 0,
  'x7': 0,
  'x70': 0,
  'x71': 0,
  'x72': 1,
  'x73': 0,
  'x74': 1,
  'x75': 0,
  'x76': 0,
  'x77': 1,
  'x78': 1,
  'x79': 1,
  'x8': 1,
  'x80': 0,
  'x81': 0,
  'x82': 1,
  'x83': 0,
  'x84': 0,
  'x85': 1,
  'x86': 1,
  'x87': 1,
  'x88': 1,
  'x89': 1,
  'x9': 1,
  'x90': 0,
  'x91': 0,
  'x92': 0,
  'x93': 0,
  'x94': 1,
  'x95': 0,
  'x96': 0,
  'x97': 0,
  'x98': 0,
  'x99': 0,
})

[2024-09-05 06:43:27,097][basic_search][INFO][generic_smbo.py:310] Iter 44, objectives: [inf].
[2024-09-05 06:43:27,109][basic_search][INFO][generic_advisor.py:457] Sample random config. rand_prob=0.100000.
[2024-09-05 06:43:27,113][basic_search][ERROR][generic_smbo.py:290] Exception in objective function:
Traceback (most recent call last):
  File "/gyc_data/fray_data/py38hwvenv/lib/python3.8/site-packages/openbox/utils/limit.py", line 62, in run_without_time_limit
    ret = obj_func(*obj_args, **obj_kwargs)
  File "BO_partition.py", line 72, in obj_func
    cost = self.black_box.get_cost_from_partitions(partitions)
  File "BO_partition.py", line 34, in get_cost_from_partitions
    partitions_cpp[i]=partitions[i]
IndexError: list index out of range

config: Configuration(values={
  'x0': 0,
  'x1': 0,
  'x10': 0,
  'x100': 0,
  'x101': 0,
  'x102': 1,
  'x103': 1,
  'x104': 1,
  'x105': 0,
  'x106': 1,
  'x107': 0,
  'x108': 0,
  'x109': 1,
  'x11': 1,
  'x110': 1,
  'x111': 1,
  'x112': 0,
  'x113': 1,
  'x114': 1,
  'x115': 1,
  'x116': 1,
  'x117': 1,
  'x118': 1,
  'x119': 0,
  'x12': 1,
  'x120': 0,
  'x121': 1,
  'x122': 0,
  'x123': 1,
  'x124': 0,
  'x125': 0,
  'x126': 1,
  'x127': 0,
  'x128': 1,
  'x129': 0,
  'x13': 0,
  'x130': 0,
  'x131': 0,
  'x132': 1,
  'x133': 1,
  'x134': 1,
  'x135': 0,
  'x136': 0,
  'x137': 0,
  'x138': 0,
  'x139': 1,
  'x14': 0,
  'x140': 0,
  'x141': 0,
  'x142': 1,
  'x143': 0,
  'x144': 1,
  'x145': 1,
  'x15': 0,
  'x16': 0,
  'x17': 1,
  'x18': 1,
  'x19': 0,
  'x2': 0,
  'x20': 0,
  'x21': 1,
  'x22': 0,
  'x23': 1,
  'x24': 1,
  'x25': 0,
  'x26': 1,
  'x27': 1,
  'x28': 1,
  'x29': 0,
  'x3': 1,
  'x30': 1,
  'x31': 0,
  'x32': 0,
  'x33': 0,
  'x34': 1,
  'x35': 0,
  'x36': 1,
  'x37': 1,
  'x38': 1,
  'x39': 0,
  'x4': 1,
  'x40': 1,
  'x41': 0,
  'x42': 1,
  'x43': 1,
  'x44': 0,
  'x45': 0,
  'x46': 0,
  'x47': 1,
  'x48': 0,
  'x49': 1,
  'x5': 0,
  'x50': 1,
  'x51': 0,
  'x52': 0,
  'x53': 0,
  'x54': 1,
  'x55': 0,
  'x56': 0,
  'x57': 1,
  'x58': 1,
  'x59': 0,
  'x6': 1,
  'x60': 0,
  'x61': 0,
  'x62': 1,
  'x63': 0,
  'x64': 0,
  'x65': 1,
  'x66': 0,
  'x67': 1,
  'x68': 1,
  'x69': 1,
  'x7': 0,
  'x70': 0,
  'x71': 0,
  'x72': 1,
  'x73': 1,
  'x74': 0,
  'x75': 0,
  'x76': 1,
  'x77': 0,
  'x78': 0,
  'x79': 1,
  'x8': 1,
  'x80': 1,
  'x81': 1,
  'x82': 0,
  'x83': 1,
  'x84': 1,
  'x85': 1,
  'x86': 0,
  'x87': 0,
  'x88': 0,
  'x89': 1,
  'x9': 0,
  'x90': 1,
  'x91': 0,
  'x92': 0,
  'x93': 1,
  'x94': 1,
  'x95': 0,
  'x96': 0,
  'x97': 0,
  'x98': 0,
  'x99': 0,
})

[2024-09-05 06:43:27,113][basic_search][INFO][generic_smbo.py:310] Iter 45, objectives: [inf].
[2024-09-05 06:43:27,126][basic_search][WARNING][generic_advisor.py:467] No enough successful initial trials! Sample random configuration.
[2024-09-05 06:43:27,129][basic_search][ERROR][generic_smbo.py:290] Exception in objective function:
Traceback (most recent call last):
  File "/gyc_data/fray_data/py38hwvenv/lib/python3.8/site-packages/openbox/utils/limit.py", line 62, in run_without_time_limit
    ret = obj_func(*obj_args, **obj_kwargs)
  File "BO_partition.py", line 72, in obj_func
    cost = self.black_box.get_cost_from_partitions(partitions)
  File "BO_partition.py", line 34, in get_cost_from_partitions
    partitions_cpp[i]=partitions[i]
IndexError: list index out of range

config: Configuration(values={
  'x0': 1,
  'x1': 1,
  'x10': 1,
  'x100': 1,
  'x101': 1,
  'x102': 1,
  'x103': 1,
  'x104': 1,
  'x105': 1,
  'x106': 1,
  'x107': 0,
  'x108': 0,
  'x109': 1,
  'x11': 1,
  'x110': 1,
  'x111': 1,
  'x112': 0,
  'x113': 1,
  'x114': 1,
  'x115': 1,
  'x116': 1,
  'x117': 1,
  'x118': 0,
  'x119': 1,
  'x12': 0,
  'x120': 0,
  'x121': 0,
  'x122': 0,
  'x123': 0,
  'x124': 0,
  'x125': 0,
  'x126': 1,
  'x127': 0,
  'x128': 1,
  'x129': 0,
  'x13': 0,
  'x130': 1,
  'x131': 1,
  'x132': 1,
  'x133': 1,
  'x134': 1,
  'x135': 1,
  'x136': 1,
  'x137': 1,
  'x138': 0,
  'x139': 0,
  'x14': 1,
  'x140': 0,
  'x141': 0,
  'x142': 0,
  'x143': 1,
  'x144': 0,
  'x145': 1,
  'x15': 1,
  'x16': 0,
  'x17': 1,
  'x18': 1,
  'x19': 1,
  'x2': 0,
  'x20': 0,
  'x21': 0,
  'x22': 0,
  'x23': 1,
  'x24': 0,
  'x25': 1,
  'x26': 1,
  'x27': 0,
  'x28': 1,
  'x29': 0,
  'x3': 0,
  'x30': 0,
  'x31': 1,
  'x32': 1,
  'x33': 0,
  'x34': 0,
  'x35': 1,
  'x36': 0,
  'x37': 1,
  'x38': 1,
  'x39': 1,
  'x4': 1,
  'x40': 0,
  'x41': 0,
  'x42': 0,
  'x43': 1,
  'x44': 0,
  'x45': 0,
  'x46': 1,
  'x47': 0,
  'x48': 1,
  'x49': 1,
  'x5': 0,
  'x50': 1,
  'x51': 0,
  'x52': 1,
  'x53': 1,
  'x54': 1,
  'x55': 0,
  'x56': 0,
  'x57': 1,
  'x58': 1,
  'x59': 0,
  'x6': 1,
  'x60': 0,
  'x61': 1,
  'x62': 0,
  'x63': 0,
  'x64': 1,
  'x65': 0,
  'x66': 0,
  'x67': 0,
  'x68': 0,
  'x69': 1,
  'x7': 0,
  'x70': 0,
  'x71': 0,
  'x72': 0,
  'x73': 1,
  'x74': 0,
  'x75': 1,
  'x76': 1,
  'x77': 0,
  'x78': 1,
  'x79': 0,
  'x8': 0,
  'x80': 1,
  'x81': 0,
  'x82': 1,
  'x83': 0,
  'x84': 1,
  'x85': 1,
  'x86': 1,
  'x87': 1,
  'x88': 0,
  'x89': 0,
  'x9': 0,
  'x90': 0,
  'x91': 1,
  'x92': 1,
  'x93': 0,
  'x94': 1,
  'x95': 1,
  'x96': 1,
  'x97': 1,
  'x98': 0,
  'x99': 0,
})

[2024-09-05 06:43:27,130][basic_search][INFO][generic_smbo.py:310] Iter 46, objectives: [inf].
[2024-09-05 06:43:27,143][basic_search][WARNING][generic_advisor.py:467] No enough successful initial trials! Sample random configuration.
[2024-09-05 06:43:27,147][basic_search][ERROR][generic_smbo.py:290] Exception in objective function:
Traceback (most recent call last):
  File "/gyc_data/fray_data/py38hwvenv/lib/python3.8/site-packages/openbox/utils/limit.py", line 62, in run_without_time_limit
    ret = obj_func(*obj_args, **obj_kwargs)
  File "BO_partition.py", line 72, in obj_func
    cost = self.black_box.get_cost_from_partitions(partitions)
  File "BO_partition.py", line 34, in get_cost_from_partitions
    partitions_cpp[i]=partitions[i]
IndexError: list index out of range

config: Configuration(values={
  'x0': 0,
  'x1': 1,
  'x10': 0,
  'x100': 1,
  'x101': 1,
  'x102': 0,
  'x103': 1,
  'x104': 1,
  'x105': 1,
  'x106': 1,
  'x107': 0,
  'x108': 1,
  'x109': 1,
  'x11': 1,
  'x110': 1,
  'x111': 1,
  'x112': 1,
  'x113': 0,
  'x114': 0,
  'x115': 1,
  'x116': 1,
  'x117': 0,
  'x118': 1,
  'x119': 0,
  'x12': 1,
  'x120': 0,
  'x121': 0,
  'x122': 0,
  'x123': 0,
  'x124': 1,
  'x125': 0,
  'x126': 0,
  'x127': 0,
  'x128': 0,
  'x129': 0,
  'x13': 1,
  'x130': 0,
  'x131': 1,
  'x132': 1,
  'x133': 1,
  'x134': 0,
  'x135': 0,
  'x136': 0,
  'x137': 0,
  'x138': 1,
  'x139': 1,
  'x14': 1,
  'x140': 0,
  'x141': 0,
  'x142': 1,
  'x143': 0,
  'x144': 0,
  'x145': 0,
  'x15': 1,
  'x16': 0,
  'x17': 1,
  'x18': 1,
  'x19': 1,
  'x2': 1,
  'x20': 0,
  'x21': 0,
  'x22': 1,
  'x23': 0,
  'x24': 1,
  'x25': 0,
  'x26': 1,
  'x27': 0,
  'x28': 0,
  'x29': 1,
  'x3': 0,
  'x30': 0,
  'x31': 1,
  'x32': 0,
  'x33': 1,
  'x34': 0,
  'x35': 0,
  'x36': 1,
  'x37': 1,
  'x38': 1,
  'x39': 1,
  'x4': 0,
  'x40': 1,
  'x41': 0,
  'x42': 0,
  'x43': 1,
  'x44': 1,
  'x45': 1,
  'x46': 0,
  'x47': 1,
  'x48': 1,
  'x49': 1,
  'x5': 0,
  'x50': 0,
  'x51': 1,
  'x52': 0,
  'x53': 1,
  'x54': 1,
  'x55': 1,
  'x56': 1,
  'x57': 1,
  'x58': 1,
  'x59': 1,
  'x6': 0,
  'x60': 1,
  'x61': 0,
  'x62': 0,
  'x63': 0,
  'x64': 0,
  'x65': 1,
  'x66': 1,
  'x67': 0,
  'x68': 0,
  'x69': 1,
  'x7': 0,
  'x70': 1,
  'x71': 1,
  'x72': 0,
  'x73': 1,
  'x74': 1,
  'x75': 0,
  'x76': 1,
  'x77': 0,
  'x78': 0,
  'x79': 1,
  'x8': 0,
  'x80': 0,
  'x81': 0,
  'x82': 0,
  'x83': 0,
  'x84': 0,
  'x85': 0,
  'x86': 1,
  'x87': 1,
  'x88': 1,
  'x89': 0,
  'x9': 1,
  'x90': 1,
  'x91': 0,
  'x92': 0,
  'x93': 0,
  'x94': 0,
  'x95': 1,
  'x96': 1,
  'x97': 0,
  'x98': 0,
  'x99': 1,
})

[2024-09-05 06:43:27,147][basic_search][INFO][generic_smbo.py:310] Iter 47, objectives: [inf].
[2024-09-05 06:43:27,160][basic_search][WARNING][generic_advisor.py:467] No enough successful initial trials! Sample random configuration.
[2024-09-05 06:43:27,164][basic_search][ERROR][generic_smbo.py:290] Exception in objective function:
Traceback (most recent call last):
  File "/gyc_data/fray_data/py38hwvenv/lib/python3.8/site-packages/openbox/utils/limit.py", line 62, in run_without_time_limit
    ret = obj_func(*obj_args, **obj_kwargs)
  File "BO_partition.py", line 72, in obj_func
    cost = self.black_box.get_cost_from_partitions(partitions)
  File "BO_partition.py", line 34, in get_cost_from_partitions
    partitions_cpp[i]=partitions[i]
IndexError: list index out of range

config: Configuration(values={
  'x0': 1,
  'x1': 0,
  'x10': 0,
  'x100': 0,
  'x101': 0,
  'x102': 1,
  'x103': 0,
  'x104': 0,
  'x105': 0,
  'x106': 1,
  'x107': 0,
  'x108': 1,
  'x109': 0,
  'x11': 1,
  'x110': 1,
  'x111': 1,
  'x112': 0,
  'x113': 1,
  'x114': 0,
  'x115': 0,
  'x116': 0,
  'x117': 0,
  'x118': 1,
  'x119': 1,
  'x12': 1,
  'x120': 1,
  'x121': 1,
  'x122': 0,
  'x123': 0,
  'x124': 1,
  'x125': 0,
  'x126': 1,
  'x127': 0,
  'x128': 0,
  'x129': 0,
  'x13': 1,
  'x130': 1,
  'x131': 0,
  'x132': 0,
  'x133': 0,
  'x134': 0,
  'x135': 1,
  'x136': 1,
  'x137': 0,
  'x138': 1,
  'x139': 0,
  'x14': 0,
  'x140': 0,
  'x141': 0,
  'x142': 0,
  'x143': 0,
  'x144': 0,
  'x145': 1,
  'x15': 0,
  'x16': 0,
  'x17': 1,
  'x18': 1,
  'x19': 0,
  'x2': 1,
  'x20': 1,
  'x21': 0,
  'x22': 1,
  'x23': 0,
  'x24': 0,
  'x25': 0,
  'x26': 0,
  'x27': 0,
  'x28': 1,
  'x29': 1,
  'x3': 1,
  'x30': 1,
  'x31': 1,
  'x32': 0,
  'x33': 0,
  'x34': 1,
  'x35': 0,
  'x36': 1,
  'x37': 1,
  'x38': 0,
  'x39': 0,
  'x4': 1,
  'x40': 0,
  'x41': 0,
  'x42': 1,
  'x43': 0,
  'x44': 0,
  'x45': 0,
  'x46': 0,
  'x47': 1,
  'x48': 0,
  'x49': 1,
  'x5': 1,
  'x50': 1,
  'x51': 0,
  'x52': 0,
  'x53': 1,
  'x54': 0,
  'x55': 0,
  'x56': 1,
  'x57': 0,
  'x58': 0,
  'x59': 1,
  'x6': 1,
  'x60': 1,
  'x61': 0,
  'x62': 0,
  'x63': 0,
  'x64': 0,
  'x65': 0,
  'x66': 1,
  'x67': 1,
  'x68': 1,
  'x69': 0,
  'x7': 1,
  'x70': 0,
  'x71': 0,
  'x72': 1,
  'x73': 0,
  'x74': 0,
  'x75': 0,
  'x76': 0,
  'x77': 1,
  'x78': 0,
  'x79': 0,
  'x8': 0,
  'x80': 0,
  'x81': 0,
  'x82': 1,
  'x83': 1,
  'x84': 1,
  'x85': 0,
  'x86': 0,
  'x87': 0,
  'x88': 0,
  'x89': 1,
  'x9': 1,
  'x90': 1,
  'x91': 1,
  'x92': 0,
  'x93': 1,
  'x94': 1,
  'x95': 1,
  'x96': 1,
  'x97': 0,
  'x98': 0,
  'x99': 1,
})

[2024-09-05 06:43:27,164][basic_search][INFO][generic_smbo.py:310] Iter 48, objectives: [inf].
[2024-09-05 06:43:27,178][basic_search][WARNING][generic_advisor.py:467] No enough successful initial trials! Sample random configuration.
[2024-09-05 06:43:27,182][basic_search][ERROR][generic_smbo.py:290] Exception in objective function:
Traceback (most recent call last):
  File "/gyc_data/fray_data/py38hwvenv/lib/python3.8/site-packages/openbox/utils/limit.py", line 62, in run_without_time_limit
    ret = obj_func(*obj_args, **obj_kwargs)
  File "BO_partition.py", line 72, in obj_func
    cost = self.black_box.get_cost_from_partitions(partitions)
  File "BO_partition.py", line 34, in get_cost_from_partitions
    partitions_cpp[i]=partitions[i]
IndexError: list index out of range

config: Configuration(values={
  'x0': 0,
  'x1': 1,
  'x10': 0,
  'x100': 0,
  'x101': 1,
  'x102': 1,
  'x103': 0,
  'x104': 0,
  'x105': 1,
  'x106': 1,
  'x107': 1,
  'x108': 1,
  'x109': 0,
  'x11': 0,
  'x110': 1,
  'x111': 0,
  'x112': 1,
  'x113': 0,
  'x114': 1,
  'x115': 1,
  'x116': 1,
  'x117': 0,
  'x118': 0,
  'x119': 1,
  'x12': 1,
  'x120': 1,
  'x121': 1,
  'x122': 0,
  'x123': 0,
  'x124': 1,
  'x125': 1,
  'x126': 1,
  'x127': 1,
  'x128': 1,
  'x129': 0,
  'x13': 1,
  'x130': 0,
  'x131': 1,
  'x132': 0,
  'x133': 0,
  'x134': 0,
  'x135': 0,
  'x136': 1,
  'x137': 0,
  'x138': 1,
  'x139': 1,
  'x14': 1,
  'x140': 0,
  'x141': 1,
  'x142': 1,
  'x143': 0,
  'x144': 0,
  'x145': 0,
  'x15': 1,
  'x16': 1,
  'x17': 0,
  'x18': 1,
  'x19': 0,
  'x2': 1,
  'x20': 1,
  'x21': 1,
  'x22': 1,
  'x23': 0,
  'x24': 0,
  'x25': 1,
  'x26': 1,
  'x27': 1,
  'x28': 1,
  'x29': 1,
  'x3': 0,
  'x30': 1,
  'x31': 0,
  'x32': 1,
  'x33': 0,
  'x34': 0,
  'x35': 1,
  'x36': 0,
  'x37': 0,
  'x38': 1,
  'x39': 0,
  'x4': 1,
  'x40': 0,
  'x41': 1,
  'x42': 0,
  'x43': 0,
  'x44': 0,
  'x45': 0,
  'x46': 1,
  'x47': 1,
  'x48': 0,
  'x49': 1,
  'x5': 0,
  'x50': 1,
  'x51': 1,
  'x52': 0,
  'x53': 1,
  'x54': 0,
  'x55': 0,
  'x56': 1,
  'x57': 1,
  'x58': 1,
  'x59': 1,
  'x6': 1,
  'x60': 0,
  'x61': 0,
  'x62': 0,
  'x63': 0,
  'x64': 1,
  'x65': 1,
  'x66': 0,
  'x67': 0,
  'x68': 0,
  'x69': 1,
  'x7': 0,
  'x70': 0,
  'x71': 0,
  'x72': 1,
  'x73': 0,
  'x74': 0,
  'x75': 1,
  'x76': 0,
  'x77': 0,
  'x78': 0,
  'x79': 0,
  'x8': 0,
  'x80': 0,
  'x81': 1,
  'x82': 0,
  'x83': 0,
  'x84': 0,
  'x85': 1,
  'x86': 1,
  'x87': 1,
  'x88': 1,
  'x89': 0,
  'x9': 0,
  'x90': 0,
  'x91': 0,
  'x92': 0,
  'x93': 1,
  'x94': 0,
  'x95': 0,
  'x96': 1,
  'x97': 0,
  'x98': 0,
  'x99': 0,
})

[2024-09-05 06:43:27,182][basic_search][INFO][generic_smbo.py:310] Iter 49, objectives: [inf].
[2024-09-05 06:43:27,196][basic_search][WARNING][generic_advisor.py:467] No enough successful initial trials! Sample random configuration.
[2024-09-05 06:43:27,200][basic_search][ERROR][generic_smbo.py:290] Exception in objective function:
Traceback (most recent call last):
  File "/gyc_data/fray_data/py38hwvenv/lib/python3.8/site-packages/openbox/utils/limit.py", line 62, in run_without_time_limit
    ret = obj_func(*obj_args, **obj_kwargs)
  File "BO_partition.py", line 72, in obj_func
    cost = self.black_box.get_cost_from_partitions(partitions)
  File "BO_partition.py", line 34, in get_cost_from_partitions
    partitions_cpp[i]=partitions[i]
IndexError: list index out of range

config: Configuration(values={
  'x0': 0,
  'x1': 1,
  'x10': 0,
  'x100': 0,
  'x101': 1,
  'x102': 1,
  'x103': 0,
  'x104': 1,
  'x105': 0,
  'x106': 0,
  'x107': 0,
  'x108': 0,
  'x109': 1,
  'x11': 0,
  'x110': 1,
  'x111': 0,
  'x112': 1,
  'x113': 1,
  'x114': 0,
  'x115': 1,
  'x116': 1,
  'x117': 1,
  'x118': 1,
  'x119': 0,
  'x12': 1,
  'x120': 1,
  'x121': 0,
  'x122': 1,
  'x123': 0,
  'x124': 0,
  'x125': 0,
  'x126': 0,
  'x127': 0,
  'x128': 0,
  'x129': 1,
  'x13': 1,
  'x130': 0,
  'x131': 0,
  'x132': 1,
  'x133': 0,
  'x134': 0,
  'x135': 1,
  'x136': 1,
  'x137': 1,
  'x138': 1,
  'x139': 0,
  'x14': 0,
  'x140': 0,
  'x141': 1,
  'x142': 0,
  'x143': 0,
  'x144': 1,
  'x145': 0,
  'x15': 0,
  'x16': 0,
  'x17': 1,
  'x18': 1,
  'x19': 0,
  'x2': 1,
  'x20': 0,
  'x21': 1,
  'x22': 0,
  'x23': 1,
  'x24': 0,
  'x25': 0,
  'x26': 1,
  'x27': 0,
  'x28': 1,
  'x29': 1,
  'x3': 0,
  'x30': 0,
  'x31': 0,
  'x32': 1,
  'x33': 1,
  'x34': 0,
  'x35': 1,
  'x36': 0,
  'x37': 0,
  'x38': 1,
  'x39': 1,
  'x4': 1,
  'x40': 1,
  'x41': 0,
  'x42': 1,
  'x43': 1,
  'x44': 0,
  'x45': 0,
  'x46': 1,
  'x47': 1,
  'x48': 1,
  'x49': 1,
  'x5': 1,
  'x50': 1,
  'x51': 1,
  'x52': 0,
  'x53': 1,
  'x54': 0,
  'x55': 1,
  'x56': 1,
  'x57': 0,
  'x58': 1,
  'x59': 1,
  'x6': 0,
  'x60': 0,
  'x61': 0,
  'x62': 0,
  'x63': 0,
  'x64': 1,
  'x65': 0,
  'x66': 1,
  'x67': 1,
  'x68': 1,
  'x69': 1,
  'x7': 0,
  'x70': 0,
  'x71': 1,
  'x72': 0,
  'x73': 1,
  'x74': 0,
  'x75': 0,
  'x76': 1,
  'x77': 0,
  'x78': 0,
  'x79': 0,
  'x8': 0,
  'x80': 1,
  'x81': 1,
  'x82': 0,
  'x83': 0,
  'x84': 0,
  'x85': 0,
  'x86': 0,
  'x87': 0,
  'x88': 1,
  'x89': 0,
  'x9': 0,
  'x90': 1,
  'x91': 0,
  'x92': 1,
  'x93': 1,
  'x94': 1,
  'x95': 0,
  'x96': 0,
  'x97': 0,
  'x98': 1,
  'x99': 1,
})

[2024-09-05 06:43:27,200][basic_search][INFO][generic_smbo.py:310] Iter 50, objectives: [inf].
[2024-09-05 06:43:27,213][basic_search][INFO][html_visualizer.py:96] Please open the html file to view visualization result: file:///gyc_data/fray_data/project_hw/logs_gray_clapboard_search/history/basic_search/basic_search_2024-09-05-06-43-26-658599.html
[2024-09-05 06:43:27,217][basic_search][WARNING][history.py:559] No feasible incumbent observations returned!
