[2024-09-11 08:24:34,145][basic_search][INFO][color_logger.py:203] Logfile: /gyc_data/fray_data/project_hw/logs_gray_clapboard_search/basic_search_2024-09-11-08-24-34-145295.log
[2024-09-11 08:24:34,500][basic_search][INFO][generic_advisor.py:231] [BO auto selection]  acq_type: ei. acq_optimizer_type: local_random.
[2024-09-11 08:24:34,506][basic_search][INFO][html_visualizer.py:462] Please open the html file to view visualization result: file:///gyc_data/fray_data/project_hw/logs_gray_clapboard_search/history/basic_search/basic_search_2024-09-11-08-24-34-504586.html
[2024-09-11 08:24:34,508][basic_search][ERROR][generic_smbo.py:290] Exception in objective function:
Traceback (most recent call last):
  File "/gyc_data/fray_data/py38hwvenv/lib/python3.8/site-packages/openbox/utils/limit.py", line 62, in run_without_time_limit
    ret = obj_func(*obj_args, **obj_kwargs)
  File "/gyc_data/fray_data/project_hw/BO_partition3.py", line 99, in obj_func
    cost = self.black_box.get_cost_from_partitions(partitions, scan_method)
  File "/gyc_data/fray_data/project_hw/BO_partition3.py", line 60, in get_cost_from_partitions
    scan_method_cpp[i] = scan_method[i]
IndexError: list index out of range

config: Configuration(values={
  's_0': 0,
  's_1': 0,
  's_10': 0,
  's_100': 0,
  's_101': 0,
  's_102': 0,
  's_103': 0,
  's_104': 0,
  's_105': 0,
  's_106': 0,
  's_107': 0,
  's_108': 0,
  's_109': 0,
  's_11': 0,
  's_110': 0,
  's_111': 0,
  's_112': 0,
  's_113': 0,
  's_114': 0,
  's_115': 0,
  's_116': 0,
  's_117': 0,
  's_118': 0,
  's_119': 0,
  's_12': 0,
  's_120': 0,
  's_121': 0,
  's_122': 0,
  's_123': 0,
  's_124': 0,
  's_125': 0,
  's_126': 0,
  's_127': 0,
  's_128': 0,
  's_129': 0,
  's_13': 0,
  's_130': 0,
  's_131': 0,
  's_132': 0,
  's_133': 0,
  's_134': 0,
  's_135': 0,
  's_136': 0,
  's_137': 0,
  's_138': 0,
  's_139': 0,
  's_14': 0,
  's_140': 0,
  's_141': 0,
  's_142': 0,
  's_143': 0,
  's_144': 0,
  's_145': 0,
  's_146': 0,
  's_15': 0,
  's_16': 0,
  's_17': 0,
  's_18': 0,
  's_19': 0,
  's_2': 0,
  's_20': 0,
  's_21': 0,
  's_22': 0,
  's_23': 0,
  's_24': 0,
  's_25': 0,
  's_26': 0,
  's_27': 0,
  's_28': 0,
  's_29': 0,
  's_3': 0,
  's_30': 0,
  's_31': 0,
  's_32': 0,
  's_33': 0,
  's_34': 0,
  's_35': 0,
  's_36': 0,
  's_37': 0,
  's_38': 0,
  's_39': 0,
  's_4': 0,
  's_40': 0,
  's_41': 0,
  's_42': 0,
  's_43': 0,
  's_44': 0,
  's_45': 0,
  's_46': 0,
  's_47': 0,
  's_48': 0,
  's_49': 0,
  's_5': 0,
  's_50': 0,
  's_51': 0,
  's_52': 0,
  's_53': 0,
  's_54': 0,
  's_55': 0,
  's_56': 0,
  's_57': 0,
  's_58': 0,
  's_59': 0,
  's_6': 0,
  's_60': 0,
  's_61': 0,
  's_62': 0,
  's_63': 0,
  's_64': 0,
  's_65': 0,
  's_66': 0,
  's_67': 0,
  's_68': 0,
  's_69': 0,
  's_7': 0,
  's_70': 0,
  's_71': 0,
  's_72': 0,
  's_73': 0,
  's_74': 0,
  's_75': 0,
  's_76': 0,
  's_77': 0,
  's_78': 0,
  's_79': 0,
  's_8': 0,
  's_80': 0,
  's_81': 0,
  's_82': 0,
  's_83': 0,
  's_84': 0,
  's_85': 0,
  's_86': 0,
  's_87': 0,
  's_88': 0,
  's_89': 0,
  's_9': 0,
  's_90': 0,
  's_91': 0,
  's_92': 0,
  's_93': 0,
  's_94': 0,
  's_95': 0,
  's_96': 0,
  's_97': 0,
  's_98': 0,
  's_99': 0,
  'x': 1,
})

[2024-09-11 08:24:34,508][basic_search][INFO][generic_smbo.py:310] Iter 1, objectives: [inf].
[2024-09-11 08:24:34,509][basic_search][ERROR][generic_smbo.py:290] Exception in objective function:
Traceback (most recent call last):
  File "/gyc_data/fray_data/py38hwvenv/lib/python3.8/site-packages/openbox/utils/limit.py", line 62, in run_without_time_limit
    ret = obj_func(*obj_args, **obj_kwargs)
  File "/gyc_data/fray_data/project_hw/BO_partition3.py", line 99, in obj_func
    cost = self.black_box.get_cost_from_partitions(partitions, scan_method)
  File "/gyc_data/fray_data/project_hw/BO_partition3.py", line 60, in get_cost_from_partitions
    scan_method_cpp[i] = scan_method[i]
IndexError: list index out of range

config: Configuration(values={
  's_0': 0,
  's_1': 1,
  's_10': 1,
  's_100': 0,
  's_101': 0,
  's_102': 1,
  's_103': 0,
  's_104': 1,
  's_105': 1,
  's_106': 1,
  's_107': 1,
  's_108': 0,
  's_109': 1,
  's_11': 1,
  's_110': 0,
  's_111': 1,
  's_112': 1,
  's_113': 0,
  's_114': 1,
  's_115': 0,
  's_116': 1,
  's_117': 1,
  's_118': 1,
  's_119': 1,
  's_12': 1,
  's_120': 0,
  's_121': 1,
  's_122': 0,
  's_123': 1,
  's_124': 1,
  's_125': 0,
  's_126': 1,
  's_127': 1,
  's_128': 1,
  's_129': 1,
  's_13': 1,
  's_130': 0,
  's_131': 0,
  's_132': 0,
  's_133': 1,
  's_134': 1,
  's_135': 0,
  's_136': 1,
  's_137': 0,
  's_138': 1,
  's_139': 1,
  's_14': 0,
  's_140': 0,
  's_141': 1,
  's_142': 0,
  's_143': 1,
  's_144': 0,
  's_145': 1,
  's_146': 1,
  's_15': 0,
  's_16': 1,
  's_17': 0,
  's_18': 1,
  's_19': 1,
  's_2': 0,
  's_20': 0,
  's_21': 1,
  's_22': 1,
  's_23': 1,
  's_24': 0,
  's_25': 0,
  's_26': 1,
  's_27': 1,
  's_28': 1,
  's_29': 0,
  's_3': 0,
  's_30': 1,
  's_31': 1,
  's_32': 0,
  's_33': 0,
  's_34': 1,
  's_35': 1,
  's_36': 1,
  's_37': 1,
  's_38': 0,
  's_39': 1,
  's_4': 1,
  's_40': 0,
  's_41': 0,
  's_42': 0,
  's_43': 1,
  's_44': 0,
  's_45': 1,
  's_46': 1,
  's_47': 1,
  's_48': 0,
  's_49': 0,
  's_5': 1,
  's_50': 1,
  's_51': 1,
  's_52': 0,
  's_53': 0,
  's_54': 0,
  's_55': 1,
  's_56': 0,
  's_57': 0,
  's_58': 1,
  's_59': 0,
  's_6': 0,
  's_60': 1,
  's_61': 1,
  's_62': 1,
  's_63': 1,
  's_64': 1,
  's_65': 0,
  's_66': 1,
  's_67': 0,
  's_68': 1,
  's_69': 1,
  's_7': 1,
  's_70': 0,
  's_71': 0,
  's_72': 1,
  's_73': 0,
  's_74': 1,
  's_75': 0,
  's_76': 0,
  's_77': 1,
  's_78': 1,
  's_79': 1,
  's_8': 1,
  's_80': 1,
  's_81': 0,
  's_82': 1,
  's_83': 1,
  's_84': 0,
  's_85': 1,
  's_86': 0,
  's_87': 1,
  's_88': 1,
  's_89': 1,
  's_9': 1,
  's_90': 1,
  's_91': 1,
  's_92': 1,
  's_93': 1,
  's_94': 0,
  's_95': 1,
  's_96': 1,
  's_97': 1,
  's_98': 1,
  's_99': 1,
  'x': 128,
})

[2024-09-11 08:24:34,510][basic_search][INFO][generic_smbo.py:310] Iter 2, objectives: [inf].
[2024-09-11 08:24:34,511][basic_search][ERROR][generic_smbo.py:290] Exception in objective function:
Traceback (most recent call last):
  File "/gyc_data/fray_data/py38hwvenv/lib/python3.8/site-packages/openbox/utils/limit.py", line 62, in run_without_time_limit
    ret = obj_func(*obj_args, **obj_kwargs)
  File "/gyc_data/fray_data/project_hw/BO_partition3.py", line 99, in obj_func
    cost = self.black_box.get_cost_from_partitions(partitions, scan_method)
  File "/gyc_data/fray_data/project_hw/BO_partition3.py", line 60, in get_cost_from_partitions
    scan_method_cpp[i] = scan_method[i]
IndexError: list index out of range

config: Configuration(values={
  's_0': 1,
  's_1': 0,
  's_10': 1,
  's_100': 1,
  's_101': 1,
  's_102': 0,
  's_103': 0,
  's_104': 1,
  's_105': 0,
  's_106': 0,
  's_107': 0,
  's_108': 1,
  's_109': 0,
  's_11': 1,
  's_110': 1,
  's_111': 1,
  's_112': 1,
  's_113': 1,
  's_114': 0,
  's_115': 1,
  's_116': 0,
  's_117': 1,
  's_118': 0,
  's_119': 1,
  's_12': 0,
  's_120': 1,
  's_121': 1,
  's_122': 1,
  's_123': 0,
  's_124': 1,
  's_125': 1,
  's_126': 0,
  's_127': 0,
  's_128': 1,
  's_129': 1,
  's_13': 1,
  's_130': 0,
  's_131': 0,
  's_132': 1,
  's_133': 1,
  's_134': 0,
  's_135': 1,
  's_136': 0,
  's_137': 1,
  's_138': 0,
  's_139': 1,
  's_14': 0,
  's_140': 1,
  's_141': 1,
  's_142': 0,
  's_143': 1,
  's_144': 1,
  's_145': 1,
  's_146': 1,
  's_15': 1,
  's_16': 1,
  's_17': 1,
  's_18': 1,
  's_19': 0,
  's_2': 0,
  's_20': 0,
  's_21': 1,
  's_22': 1,
  's_23': 0,
  's_24': 1,
  's_25': 1,
  's_26': 0,
  's_27': 0,
  's_28': 0,
  's_29': 0,
  's_3': 0,
  's_30': 1,
  's_31': 1,
  's_32': 1,
  's_33': 0,
  's_34': 1,
  's_35': 1,
  's_36': 1,
  's_37': 1,
  's_38': 1,
  's_39': 0,
  's_4': 1,
  's_40': 0,
  's_41': 1,
  's_42': 0,
  's_43': 1,
  's_44': 0,
  's_45': 1,
  's_46': 1,
  's_47': 0,
  's_48': 1,
  's_49': 1,
  's_5': 0,
  's_50': 0,
  's_51': 1,
  's_52': 0,
  's_53': 1,
  's_54': 1,
  's_55': 1,
  's_56': 0,
  's_57': 1,
  's_58': 0,
  's_59': 1,
  's_6': 0,
  's_60': 0,
  's_61': 0,
  's_62': 0,
  's_63': 0,
  's_64': 1,
  's_65': 0,
  's_66': 0,
  's_67': 1,
  's_68': 0,
  's_69': 0,
  's_7': 1,
  's_70': 1,
  's_71': 0,
  's_72': 0,
  's_73': 0,
  's_74': 0,
  's_75': 1,
  's_76': 1,
  's_77': 0,
  's_78': 0,
  's_79': 0,
  's_8': 0,
  's_80': 1,
  's_81': 1,
  's_82': 0,
  's_83': 1,
  's_84': 1,
  's_85': 1,
  's_86': 0,
  's_87': 1,
  's_88': 0,
  's_89': 1,
  's_9': 0,
  's_90': 0,
  's_91': 1,
  's_92': 0,
  's_93': 1,
  's_94': 1,
  's_95': 0,
  's_96': 0,
  's_97': 0,
  's_98': 1,
  's_99': 1,
  'x': 124,
})

[2024-09-11 08:24:34,511][basic_search][INFO][generic_smbo.py:310] Iter 3, objectives: [inf].
[2024-09-11 08:24:34,513][basic_search][ERROR][generic_smbo.py:290] Exception in objective function:
Traceback (most recent call last):
  File "/gyc_data/fray_data/py38hwvenv/lib/python3.8/site-packages/openbox/utils/limit.py", line 62, in run_without_time_limit
    ret = obj_func(*obj_args, **obj_kwargs)
  File "/gyc_data/fray_data/project_hw/BO_partition3.py", line 99, in obj_func
    cost = self.black_box.get_cost_from_partitions(partitions, scan_method)
  File "/gyc_data/fray_data/project_hw/BO_partition3.py", line 60, in get_cost_from_partitions
    scan_method_cpp[i] = scan_method[i]
IndexError: list index out of range

config: Configuration(values={
  's_0': 1,
  's_1': 1,
  's_10': 0,
  's_100': 0,
  's_101': 0,
  's_102': 1,
  's_103': 1,
  's_104': 0,
  's_105': 0,
  's_106': 0,
  's_107': 1,
  's_108': 1,
  's_109': 1,
  's_11': 0,
  's_110': 1,
  's_111': 1,
  's_112': 0,
  's_113': 0,
  's_114': 1,
  's_115': 0,
  's_116': 1,
  's_117': 0,
  's_118': 1,
  's_119': 0,
  's_12': 0,
  's_120': 1,
  's_121': 0,
  's_122': 0,
  's_123': 1,
  's_124': 1,
  's_125': 1,
  's_126': 1,
  's_127': 1,
  's_128': 0,
  's_129': 0,
  's_13': 1,
  's_130': 0,
  's_131': 1,
  's_132': 1,
  's_133': 1,
  's_134': 0,
  's_135': 0,
  's_136': 0,
  's_137': 0,
  's_138': 1,
  's_139': 0,
  's_14': 1,
  's_140': 1,
  's_141': 0,
  's_142': 1,
  's_143': 0,
  's_144': 1,
  's_145': 1,
  's_146': 0,
  's_15': 1,
  's_16': 1,
  's_17': 1,
  's_18': 1,
  's_19': 1,
  's_2': 0,
  's_20': 0,
  's_21': 0,
  's_22': 0,
  's_23': 0,
  's_24': 0,
  's_25': 1,
  's_26': 0,
  's_27': 1,
  's_28': 0,
  's_29': 0,
  's_3': 1,
  's_30': 0,
  's_31': 0,
  's_32': 1,
  's_33': 0,
  's_34': 0,
  's_35': 1,
  's_36': 1,
  's_37': 0,
  's_38': 1,
  's_39': 0,
  's_4': 0,
  's_40': 1,
  's_41': 1,
  's_42': 0,
  's_43': 1,
  's_44': 0,
  's_45': 0,
  's_46': 0,
  's_47': 1,
  's_48': 0,
  's_49': 1,
  's_5': 0,
  's_50': 1,
  's_51': 1,
  's_52': 1,
  's_53': 1,
  's_54': 0,
  's_55': 1,
  's_56': 1,
  's_57': 1,
  's_58': 0,
  's_59': 0,
  's_6': 1,
  's_60': 0,
  's_61': 1,
  's_62': 0,
  's_63': 1,
  's_64': 0,
  's_65': 1,
  's_66': 0,
  's_67': 1,
  's_68': 0,
  's_69': 1,
  's_7': 0,
  's_70': 1,
  's_71': 1,
  's_72': 1,
  's_73': 1,
  's_74': 1,
  's_75': 1,
  's_76': 0,
  's_77': 0,
  's_78': 1,
  's_79': 1,
  's_8': 1,
  's_80': 1,
  's_81': 1,
  's_82': 1,
  's_83': 1,
  's_84': 0,
  's_85': 0,
  's_86': 0,
  's_87': 0,
  's_88': 1,
  's_89': 0,
  's_9': 1,
  's_90': 0,
  's_91': 0,
  's_92': 1,
  's_93': 0,
  's_94': 1,
  's_95': 1,
  's_96': 0,
  's_97': 1,
  's_98': 0,
  's_99': 1,
  'x': 75,
})

[2024-09-11 08:24:34,513][basic_search][INFO][generic_smbo.py:310] Iter 4, objectives: [inf].
[2024-09-11 08:24:34,516][basic_search][ERROR][generic_smbo.py:290] Exception in objective function:
Traceback (most recent call last):
  File "/gyc_data/fray_data/py38hwvenv/lib/python3.8/site-packages/openbox/utils/limit.py", line 62, in run_without_time_limit
    ret = obj_func(*obj_args, **obj_kwargs)
  File "/gyc_data/fray_data/project_hw/BO_partition3.py", line 99, in obj_func
    cost = self.black_box.get_cost_from_partitions(partitions, scan_method)
  File "/gyc_data/fray_data/project_hw/BO_partition3.py", line 60, in get_cost_from_partitions
    scan_method_cpp[i] = scan_method[i]
IndexError: list index out of range

config: Configuration(values={
  's_0': 1,
  's_1': 1,
  's_10': 0,
  's_100': 0,
  's_101': 0,
  's_102': 0,
  's_103': 0,
  's_104': 0,
  's_105': 0,
  's_106': 1,
  's_107': 0,
  's_108': 0,
  's_109': 0,
  's_11': 0,
  's_110': 1,
  's_111': 0,
  's_112': 0,
  's_113': 0,
  's_114': 0,
  's_115': 1,
  's_116': 1,
  's_117': 0,
  's_118': 0,
  's_119': 0,
  's_12': 1,
  's_120': 0,
  's_121': 1,
  's_122': 1,
  's_123': 0,
  's_124': 0,
  's_125': 0,
  's_126': 0,
  's_127': 1,
  's_128': 1,
  's_129': 0,
  's_13': 1,
  's_130': 1,
  's_131': 1,
  's_132': 1,
  's_133': 0,
  's_134': 0,
  's_135': 1,
  's_136': 0,
  's_137': 1,
  's_138': 0,
  's_139': 1,
  's_14': 0,
  's_140': 1,
  's_141': 1,
  's_142': 0,
  's_143': 1,
  's_144': 0,
  's_145': 0,
  's_146': 1,
  's_15': 1,
  's_16': 1,
  's_17': 0,
  's_18': 1,
  's_19': 0,
  's_2': 0,
  's_20': 1,
  's_21': 0,
  's_22': 0,
  's_23': 0,
  's_24': 0,
  's_25': 0,
  's_26': 0,
  's_27': 1,
  's_28': 0,
  's_29': 1,
  's_3': 0,
  's_30': 1,
  's_31': 0,
  's_32': 1,
  's_33': 1,
  's_34': 1,
  's_35': 1,
  's_36': 1,
  's_37': 1,
  's_38': 1,
  's_39': 1,
  's_4': 1,
  's_40': 0,
  's_41': 0,
  's_42': 1,
  's_43': 0,
  's_44': 1,
  's_45': 0,
  's_46': 0,
  's_47': 0,
  's_48': 0,
  's_49': 1,
  's_5': 1,
  's_50': 1,
  's_51': 0,
  's_52': 1,
  's_53': 1,
  's_54': 0,
  's_55': 0,
  's_56': 0,
  's_57': 0,
  's_58': 1,
  's_59': 0,
  's_6': 1,
  's_60': 1,
  's_61': 0,
  's_62': 1,
  's_63': 0,
  's_64': 1,
  's_65': 1,
  's_66': 1,
  's_67': 1,
  's_68': 0,
  's_69': 1,
  's_7': 1,
  's_70': 0,
  's_71': 0,
  's_72': 1,
  's_73': 1,
  's_74': 1,
  's_75': 0,
  's_76': 1,
  's_77': 1,
  's_78': 0,
  's_79': 0,
  's_8': 0,
  's_80': 0,
  's_81': 0,
  's_82': 0,
  's_83': 1,
  's_84': 1,
  's_85': 1,
  's_86': 1,
  's_87': 1,
  's_88': 1,
  's_89': 1,
  's_9': 0,
  's_90': 1,
  's_91': 0,
  's_92': 1,
  's_93': 1,
  's_94': 1,
  's_95': 1,
  's_96': 1,
  's_97': 1,
  's_98': 1,
  's_99': 1,
  'x': 42,
})

[2024-09-11 08:24:34,516][basic_search][INFO][generic_smbo.py:310] Iter 5, objectives: [inf].
[2024-09-11 08:24:34,520][basic_search][ERROR][generic_smbo.py:290] Exception in objective function:
Traceback (most recent call last):
  File "/gyc_data/fray_data/py38hwvenv/lib/python3.8/site-packages/openbox/utils/limit.py", line 62, in run_without_time_limit
    ret = obj_func(*obj_args, **obj_kwargs)
  File "/gyc_data/fray_data/project_hw/BO_partition3.py", line 99, in obj_func
    cost = self.black_box.get_cost_from_partitions(partitions, scan_method)
  File "/gyc_data/fray_data/project_hw/BO_partition3.py", line 60, in get_cost_from_partitions
    scan_method_cpp[i] = scan_method[i]
IndexError: list index out of range

config: Configuration(values={
  's_0': 1,
  's_1': 1,
  's_10': 1,
  's_100': 0,
  's_101': 1,
  's_102': 0,
  's_103': 1,
  's_104': 0,
  's_105': 1,
  's_106': 1,
  's_107': 0,
  's_108': 1,
  's_109': 0,
  's_11': 1,
  's_110': 0,
  's_111': 0,
  's_112': 1,
  's_113': 1,
  's_114': 0,
  's_115': 1,
  's_116': 1,
  's_117': 0,
  's_118': 1,
  's_119': 1,
  's_12': 0,
  's_120': 0,
  's_121': 1,
  's_122': 1,
  's_123': 0,
  's_124': 0,
  's_125': 0,
  's_126': 1,
  's_127': 0,
  's_128': 0,
  's_129': 0,
  's_13': 1,
  's_130': 1,
  's_131': 0,
  's_132': 1,
  's_133': 0,
  's_134': 0,
  's_135': 1,
  's_136': 0,
  's_137': 1,
  's_138': 0,
  's_139': 0,
  's_14': 1,
  's_140': 0,
  's_141': 0,
  's_142': 1,
  's_143': 1,
  's_144': 0,
  's_145': 1,
  's_146': 0,
  's_15': 1,
  's_16': 0,
  's_17': 1,
  's_18': 0,
  's_19': 0,
  's_2': 1,
  's_20': 0,
  's_21': 1,
  's_22': 0,
  's_23': 1,
  's_24': 1,
  's_25': 0,
  's_26': 0,
  's_27': 1,
  's_28': 1,
  's_29': 0,
  's_3': 0,
  's_30': 1,
  's_31': 1,
  's_32': 0,
  's_33': 1,
  's_34': 1,
  's_35': 1,
  's_36': 0,
  's_37': 0,
  's_38': 1,
  's_39': 0,
  's_4': 0,
  's_40': 1,
  's_41': 0,
  's_42': 0,
  's_43': 0,
  's_44': 1,
  's_45': 1,
  's_46': 1,
  's_47': 0,
  's_48': 1,
  's_49': 0,
  's_5': 0,
  's_50': 1,
  's_51': 1,
  's_52': 0,
  's_53': 1,
  's_54': 0,
  's_55': 0,
  's_56': 0,
  's_57': 1,
  's_58': 0,
  's_59': 1,
  's_6': 1,
  's_60': 0,
  's_61': 0,
  's_62': 0,
  's_63': 1,
  's_64': 0,
  's_65': 1,
  's_66': 1,
  's_67': 0,
  's_68': 1,
  's_69': 1,
  's_7': 1,
  's_70': 1,
  's_71': 0,
  's_72': 1,
  's_73': 0,
  's_74': 0,
  's_75': 0,
  's_76': 1,
  's_77': 1,
  's_78': 1,
  's_79': 1,
  's_8': 1,
  's_80': 0,
  's_81': 0,
  's_82': 0,
  's_83': 0,
  's_84': 0,
  's_85': 1,
  's_86': 1,
  's_87': 0,
  's_88': 0,
  's_89': 0,
  's_9': 1,
  's_90': 0,
  's_91': 1,
  's_92': 0,
  's_93': 1,
  's_94': 0,
  's_95': 1,
  's_96': 1,
  's_97': 1,
  's_98': 1,
  's_99': 1,
  'x': 98,
})

[2024-09-11 08:24:34,520][basic_search][INFO][generic_smbo.py:310] Iter 6, objectives: [inf].
[2024-09-11 08:24:34,524][basic_search][ERROR][generic_smbo.py:290] Exception in objective function:
Traceback (most recent call last):
  File "/gyc_data/fray_data/py38hwvenv/lib/python3.8/site-packages/openbox/utils/limit.py", line 62, in run_without_time_limit
    ret = obj_func(*obj_args, **obj_kwargs)
  File "/gyc_data/fray_data/project_hw/BO_partition3.py", line 99, in obj_func
    cost = self.black_box.get_cost_from_partitions(partitions, scan_method)
  File "/gyc_data/fray_data/project_hw/BO_partition3.py", line 60, in get_cost_from_partitions
    scan_method_cpp[i] = scan_method[i]
IndexError: list index out of range

config: Configuration(values={
  's_0': 0,
  's_1': 1,
  's_10': 0,
  's_100': 1,
  's_101': 1,
  's_102': 0,
  's_103': 1,
  's_104': 1,
  's_105': 0,
  's_106': 1,
  's_107': 1,
  's_108': 0,
  's_109': 1,
  's_11': 0,
  's_110': 0,
  's_111': 1,
  's_112': 1,
  's_113': 1,
  's_114': 1,
  's_115': 1,
  's_116': 0,
  's_117': 0,
  's_118': 0,
  's_119': 1,
  's_12': 1,
  's_120': 1,
  's_121': 0,
  's_122': 1,
  's_123': 1,
  's_124': 0,
  's_125': 1,
  's_126': 0,
  's_127': 0,
  's_128': 1,
  's_129': 0,
  's_13': 1,
  's_130': 1,
  's_131': 1,
  's_132': 0,
  's_133': 1,
  's_134': 1,
  's_135': 0,
  's_136': 1,
  's_137': 0,
  's_138': 0,
  's_139': 1,
  's_14': 0,
  's_140': 1,
  's_141': 1,
  's_142': 1,
  's_143': 1,
  's_144': 1,
  's_145': 0,
  's_146': 0,
  's_15': 1,
  's_16': 1,
  's_17': 0,
  's_18': 1,
  's_19': 1,
  's_2': 1,
  's_20': 0,
  's_21': 1,
  's_22': 0,
  's_23': 1,
  's_24': 0,
  's_25': 0,
  's_26': 0,
  's_27': 0,
  's_28': 0,
  's_29': 1,
  's_3': 0,
  's_30': 1,
  's_31': 0,
  's_32': 0,
  's_33': 0,
  's_34': 1,
  's_35': 0,
  's_36': 1,
  's_37': 0,
  's_38': 0,
  's_39': 0,
  's_4': 0,
  's_40': 0,
  's_41': 1,
  's_42': 1,
  's_43': 1,
  's_44': 1,
  's_45': 1,
  's_46': 0,
  's_47': 0,
  's_48': 0,
  's_49': 1,
  's_5': 0,
  's_50': 0,
  's_51': 0,
  's_52': 1,
  's_53': 1,
  's_54': 0,
  's_55': 0,
  's_56': 1,
  's_57': 0,
  's_58': 1,
  's_59': 0,
  's_6': 0,
  's_60': 1,
  's_61': 1,
  's_62': 0,
  's_63': 1,
  's_64': 1,
  's_65': 1,
  's_66': 0,
  's_67': 1,
  's_68': 0,
  's_69': 0,
  's_7': 0,
  's_70': 0,
  's_71': 1,
  's_72': 1,
  's_73': 1,
  's_74': 0,
  's_75': 1,
  's_76': 1,
  's_77': 1,
  's_78': 1,
  's_79': 1,
  's_8': 1,
  's_80': 0,
  's_81': 1,
  's_82': 0,
  's_83': 1,
  's_84': 0,
  's_85': 1,
  's_86': 0,
  's_87': 0,
  's_88': 1,
  's_89': 0,
  's_9': 0,
  's_90': 0,
  's_91': 1,
  's_92': 0,
  's_93': 0,
  's_94': 0,
  's_95': 0,
  's_96': 1,
  's_97': 0,
  's_98': 0,
  's_99': 0,
  'x': 45,
})

[2024-09-11 08:24:34,524][basic_search][INFO][generic_smbo.py:310] Iter 7, objectives: [inf].
[2024-09-11 08:24:34,528][basic_search][ERROR][generic_smbo.py:290] Exception in objective function:
Traceback (most recent call last):
  File "/gyc_data/fray_data/py38hwvenv/lib/python3.8/site-packages/openbox/utils/limit.py", line 62, in run_without_time_limit
    ret = obj_func(*obj_args, **obj_kwargs)
  File "/gyc_data/fray_data/project_hw/BO_partition3.py", line 99, in obj_func
    cost = self.black_box.get_cost_from_partitions(partitions, scan_method)
  File "/gyc_data/fray_data/project_hw/BO_partition3.py", line 60, in get_cost_from_partitions
    scan_method_cpp[i] = scan_method[i]
IndexError: list index out of range

config: Configuration(values={
  's_0': 0,
  's_1': 1,
  's_10': 0,
  's_100': 1,
  's_101': 0,
  's_102': 0,
  's_103': 1,
  's_104': 1,
  's_105': 1,
  's_106': 0,
  's_107': 0,
  's_108': 0,
  's_109': 1,
  's_11': 1,
  's_110': 1,
  's_111': 0,
  's_112': 1,
  's_113': 1,
  's_114': 1,
  's_115': 0,
  's_116': 1,
  's_117': 1,
  's_118': 0,
  's_119': 1,
  's_12': 1,
  's_120': 1,
  's_121': 1,
  's_122': 1,
  's_123': 0,
  's_124': 0,
  's_125': 1,
  's_126': 0,
  's_127': 1,
  's_128': 1,
  's_129': 1,
  's_13': 1,
  's_130': 1,
  's_131': 0,
  's_132': 0,
  's_133': 1,
  's_134': 1,
  's_135': 1,
  's_136': 1,
  's_137': 1,
  's_138': 1,
  's_139': 1,
  's_14': 1,
  's_140': 0,
  's_141': 0,
  's_142': 1,
  's_143': 1,
  's_144': 1,
  's_145': 0,
  's_146': 1,
  's_15': 1,
  's_16': 1,
  's_17': 1,
  's_18': 1,
  's_19': 0,
  's_2': 1,
  's_20': 0,
  's_21': 1,
  's_22': 0,
  's_23': 0,
  's_24': 0,
  's_25': 1,
  's_26': 0,
  's_27': 0,
  's_28': 0,
  's_29': 1,
  's_3': 0,
  's_30': 0,
  's_31': 0,
  's_32': 1,
  's_33': 0,
  's_34': 0,
  's_35': 0,
  's_36': 0,
  's_37': 0,
  's_38': 1,
  's_39': 1,
  's_4': 0,
  's_40': 1,
  's_41': 0,
  's_42': 1,
  's_43': 1,
  's_44': 0,
  's_45': 1,
  's_46': 0,
  's_47': 1,
  's_48': 1,
  's_49': 0,
  's_5': 0,
  's_50': 0,
  's_51': 1,
  's_52': 1,
  's_53': 0,
  's_54': 1,
  's_55': 0,
  's_56': 0,
  's_57': 0,
  's_58': 1,
  's_59': 1,
  's_6': 0,
  's_60': 0,
  's_61': 0,
  's_62': 1,
  's_63': 0,
  's_64': 0,
  's_65': 0,
  's_66': 0,
  's_67': 0,
  's_68': 0,
  's_69': 0,
  's_7': 1,
  's_70': 0,
  's_71': 1,
  's_72': 0,
  's_73': 0,
  's_74': 1,
  's_75': 0,
  's_76': 0,
  's_77': 0,
  's_78': 1,
  's_79': 0,
  's_8': 1,
  's_80': 1,
  's_81': 0,
  's_82': 1,
  's_83': 0,
  's_84': 0,
  's_85': 0,
  's_86': 1,
  's_87': 1,
  's_88': 0,
  's_89': 1,
  's_9': 1,
  's_90': 1,
  's_91': 0,
  's_92': 1,
  's_93': 1,
  's_94': 0,
  's_95': 0,
  's_96': 1,
  's_97': 0,
  's_98': 0,
  's_99': 1,
  'x': 86,
})

[2024-09-11 08:24:34,528][basic_search][INFO][generic_smbo.py:310] Iter 8, objectives: [inf].
[2024-09-11 08:24:34,531][basic_search][ERROR][generic_smbo.py:290] Exception in objective function:
Traceback (most recent call last):
  File "/gyc_data/fray_data/py38hwvenv/lib/python3.8/site-packages/openbox/utils/limit.py", line 62, in run_without_time_limit
    ret = obj_func(*obj_args, **obj_kwargs)
  File "/gyc_data/fray_data/project_hw/BO_partition3.py", line 99, in obj_func
    cost = self.black_box.get_cost_from_partitions(partitions, scan_method)
  File "/gyc_data/fray_data/project_hw/BO_partition3.py", line 60, in get_cost_from_partitions
    scan_method_cpp[i] = scan_method[i]
IndexError: list index out of range

config: Configuration(values={
  's_0': 1,
  's_1': 1,
  's_10': 1,
  's_100': 0,
  's_101': 1,
  's_102': 1,
  's_103': 0,
  's_104': 1,
  's_105': 1,
  's_106': 0,
  's_107': 1,
  's_108': 1,
  's_109': 1,
  's_11': 0,
  's_110': 1,
  's_111': 1,
  's_112': 0,
  's_113': 1,
  's_114': 1,
  's_115': 0,
  's_116': 0,
  's_117': 0,
  's_118': 1,
  's_119': 0,
  's_12': 1,
  's_120': 0,
  's_121': 1,
  's_122': 1,
  's_123': 0,
  's_124': 1,
  's_125': 0,
  's_126': 0,
  's_127': 1,
  's_128': 0,
  's_129': 0,
  's_13': 1,
  's_130': 0,
  's_131': 0,
  's_132': 0,
  's_133': 0,
  's_134': 1,
  's_135': 1,
  's_136': 1,
  's_137': 0,
  's_138': 0,
  's_139': 0,
  's_14': 0,
  's_140': 0,
  's_141': 0,
  's_142': 1,
  's_143': 1,
  's_144': 0,
  's_145': 0,
  's_146': 0,
  's_15': 0,
  's_16': 1,
  's_17': 1,
  's_18': 1,
  's_19': 1,
  's_2': 1,
  's_20': 1,
  's_21': 0,
  's_22': 0,
  's_23': 0,
  's_24': 1,
  's_25': 1,
  's_26': 1,
  's_27': 0,
  's_28': 1,
  's_29': 1,
  's_3': 0,
  's_30': 1,
  's_31': 0,
  's_32': 1,
  's_33': 1,
  's_34': 1,
  's_35': 0,
  's_36': 0,
  's_37': 0,
  's_38': 0,
  's_39': 1,
  's_4': 0,
  's_40': 0,
  's_41': 1,
  's_42': 1,
  's_43': 1,
  's_44': 1,
  's_45': 1,
  's_46': 1,
  's_47': 1,
  's_48': 0,
  's_49': 0,
  's_5': 0,
  's_50': 0,
  's_51': 1,
  's_52': 0,
  's_53': 1,
  's_54': 0,
  's_55': 0,
  's_56': 1,
  's_57': 0,
  's_58': 0,
  's_59': 0,
  's_6': 1,
  's_60': 0,
  's_61': 0,
  's_62': 1,
  's_63': 0,
  's_64': 1,
  's_65': 0,
  's_66': 1,
  's_67': 1,
  's_68': 1,
  's_69': 0,
  's_7': 0,
  's_70': 0,
  's_71': 0,
  's_72': 0,
  's_73': 1,
  's_74': 0,
  's_75': 1,
  's_76': 1,
  's_77': 0,
  's_78': 1,
  's_79': 1,
  's_8': 0,
  's_80': 0,
  's_81': 0,
  's_82': 0,
  's_83': 0,
  's_84': 0,
  's_85': 1,
  's_86': 1,
  's_87': 0,
  's_88': 0,
  's_89': 1,
  's_9': 1,
  's_90': 0,
  's_91': 1,
  's_92': 1,
  's_93': 0,
  's_94': 1,
  's_95': 1,
  's_96': 0,
  's_97': 0,
  's_98': 0,
  's_99': 1,
  'x': 82,
})

[2024-09-11 08:24:34,531][basic_search][INFO][generic_smbo.py:310] Iter 9, objectives: [inf].
[2024-09-11 08:24:34,534][basic_search][ERROR][generic_smbo.py:290] Exception in objective function:
Traceback (most recent call last):
  File "/gyc_data/fray_data/py38hwvenv/lib/python3.8/site-packages/openbox/utils/limit.py", line 62, in run_without_time_limit
    ret = obj_func(*obj_args, **obj_kwargs)
  File "/gyc_data/fray_data/project_hw/BO_partition3.py", line 99, in obj_func
    cost = self.black_box.get_cost_from_partitions(partitions, scan_method)
  File "/gyc_data/fray_data/project_hw/BO_partition3.py", line 60, in get_cost_from_partitions
    scan_method_cpp[i] = scan_method[i]
IndexError: list index out of range

config: Configuration(values={
  's_0': 1,
  's_1': 1,
  's_10': 0,
  's_100': 0,
  's_101': 0,
  's_102': 0,
  's_103': 1,
  's_104': 0,
  's_105': 0,
  's_106': 0,
  's_107': 1,
  's_108': 1,
  's_109': 0,
  's_11': 0,
  's_110': 0,
  's_111': 0,
  's_112': 0,
  's_113': 0,
  's_114': 1,
  's_115': 1,
  's_116': 0,
  's_117': 0,
  's_118': 0,
  's_119': 0,
  's_12': 0,
  's_120': 0,
  's_121': 1,
  's_122': 0,
  's_123': 1,
  's_124': 0,
  's_125': 1,
  's_126': 1,
  's_127': 0,
  's_128': 0,
  's_129': 0,
  's_13': 0,
  's_130': 0,
  's_131': 1,
  's_132': 1,
  's_133': 0,
  's_134': 1,
  's_135': 1,
  's_136': 1,
  's_137': 0,
  's_138': 0,
  's_139': 1,
  's_14': 1,
  's_140': 1,
  's_141': 0,
  's_142': 1,
  's_143': 0,
  's_144': 1,
  's_145': 0,
  's_146': 0,
  's_15': 1,
  's_16': 0,
  's_17': 1,
  's_18': 0,
  's_19': 1,
  's_2': 0,
  's_20': 0,
  's_21': 0,
  's_22': 1,
  's_23': 1,
  's_24': 0,
  's_25': 0,
  's_26': 0,
  's_27': 0,
  's_28': 1,
  's_29': 1,
  's_3': 1,
  's_30': 0,
  's_31': 0,
  's_32': 1,
  's_33': 0,
  's_34': 0,
  's_35': 1,
  's_36': 1,
  's_37': 1,
  's_38': 1,
  's_39': 1,
  's_4': 1,
  's_40': 0,
  's_41': 0,
  's_42': 1,
  's_43': 1,
  's_44': 1,
  's_45': 1,
  's_46': 1,
  's_47': 0,
  's_48': 1,
  's_49': 0,
  's_5': 0,
  's_50': 1,
  's_51': 0,
  's_52': 0,
  's_53': 0,
  's_54': 1,
  's_55': 1,
  's_56': 1,
  's_57': 0,
  's_58': 0,
  's_59': 1,
  's_6': 0,
  's_60': 0,
  's_61': 1,
  's_62': 0,
  's_63': 0,
  's_64': 1,
  's_65': 0,
  's_66': 0,
  's_67': 1,
  's_68': 0,
  's_69': 1,
  's_7': 1,
  's_70': 1,
  's_71': 0,
  's_72': 1,
  's_73': 0,
  's_74': 1,
  's_75': 1,
  's_76': 1,
  's_77': 1,
  's_78': 0,
  's_79': 1,
  's_8': 1,
  's_80': 0,
  's_81': 0,
  's_82': 0,
  's_83': 1,
  's_84': 0,
  's_85': 1,
  's_86': 1,
  's_87': 0,
  's_88': 0,
  's_89': 1,
  's_9': 1,
  's_90': 1,
  's_91': 1,
  's_92': 1,
  's_93': 1,
  's_94': 0,
  's_95': 0,
  's_96': 0,
  's_97': 0,
  's_98': 0,
  's_99': 0,
  'x': 52,
})

[2024-09-11 08:24:34,535][basic_search][INFO][generic_smbo.py:310] Iter 10, objectives: [inf].
[2024-09-11 08:24:34,538][basic_search][INFO][html_visualizer.py:96] Please open the html file to view visualization result: file:///gyc_data/fray_data/project_hw/logs_gray_clapboard_search/history/basic_search/basic_search_2024-09-11-08-24-34-504586.html
[2024-09-11 08:24:34,542][basic_search][WARNING][history.py:559] No feasible incumbent observations returned!
